Workbook

Sheet README
A1: Validation of the object → EuroVoc mapping (Step 7)
A3: What to do
A4: 1. Go to the Validate sheet. Every row is part of the sample; the order is random.
A5: 2. Fill in the yellow columns: judgement (drop-down), Optional: better_concept (optional), notes.
A6: 3. Judge candidate 1 mainly, for the object as used in the context; use candidates 2-3 to decide 'partial'. | B6: JUDGE object vs cand_1
A7: 4. Leave the 'key' sheet alone until you are done; it holds the scores you should not see.
A8: 5. When finished, save and run: python eurovoc_review.py review --xlsx <this file>
A10: Judgement codes
A11: correct – candidate 1 is the right concept, or an acceptable close one.
A12: partial – candidate 1 is in the right area but too broad/narrow, or a lower candidate is right.
A13: wrong – no candidate fits the object.
A14: unclear – the object itself cannot be judged (placeholder, fragment, unresolved reference).
A16: Special rows
A17: Rows with several numbered contexts are frequent texts judged once for all their uses: judge the
A18: usual use; if the mapping fits some uses but not others, choose 'partial' and note it.
A19: Rows without candidates (only if checks were drawn): the object was left unmapped or dropped.
A20: correct = rightly so; wrong = a EuroVoc concept clearly exists / a real object was lost.
... A29: Example of a filled-in row (not part of the data)
A30: object | B30: cand_1 | C30: cand_2 | D30: judgement | E30: better_concept | F30: notes
A31: informatie | B31: informatie | C31: overdracht van informatie | D31: correct | F31: generic, but the concept matches

Sheet Validate
A1: row | B1: object | C1: raw_object | D1: cand_1 | E1: cand_2 | F1: cand_3 | G1: n_norms | H1: context | I1: judgement | J1: better_concept | K1: notes | L1: norm_id
A2: 1 | B2: verhouding tot het ICT-risico van de financiële entiteit | C2: in verhouding tot het ICT-risico van de financiële entiteit | D2: gevolgen van ICT | G2: 1 | H2: …is, vaardigheden en deskundigheid op het gebied van ICT-risico en over de nodige onafhankelijkheid. De frequentie en de focus van de ICT-audits staan in verhouding tot het ICT-risico van de financiële entiteit. | L2: 32022R2554:6:6:15
A3: 2 | B3: verplichtingen | D3: contract | G3: 27 | H3: [1] EU 32016R0679:30:5:7: De in de leden 1 en 2 bedoelde verplichtingen zijn niet van toepassing op ondernemingen of organisaties die minder dan 250 personen in dienst hebben, tenzij het waarschijnlijk is dat de verwerkin… [2] NL BWBR0009950:6.3:1:2: …ment en Markt kan met het oog op de doelstellingen, bedoeld in artikel 3, tweede en vierde lid, van richtlijn (EU) 2018/1972, op een redelijk verzoek verplichtingen opleggen om toegang te verlenen tot: a. kabels of bijbehorende faciliteiten binnen gebouwen of, b. indien het dichtst bij het netwerkaansluitpunt gel… [3] EU 32024R1689:53:2:8: De in lid 1, punten a) en b) genoemde verplichtingen gelden niet voor aanbieders van AI-modellen die worden vrijgegeven in het kader van een vrije en opensource licentie die de raadpleging, het gebruik,… | L3: 32016R0679:30:5:7, BWBR0009950:6.3:1:2, 32024R1689:53:2:8
A4: 3 | B4: misbruik | C4: vertraging of misbruik van het overstapproces | D4: rechtsmisbruik | E4: mishandeling | F4: machtsmisbruik | G4: 2 | H4: …e dat de levering niet langer dan één werkdag wordt onderbroken; c. werken te goeder trouw samen ten behoeve van het overstappen; d. veroorzaken geen vertraging of misbruik van het overstapproces, en e. zorgen ervoor dat het overstappen niet plaatsvindt zonder uitdrukkelijke toestemming van de abonnee. | L4: BWBR0009950:7.2c:2:3
A5: 4 | B5: informatie | D5: informatie | G5: 87 | H5: [1] EU 32024R1689:70:2:6: De lidstaten verstrekken de Commissie informatie over de identiteit en de taken van de aanmeldende autoriteiten en de markttoezichtautoriteiten, alsook over eventuele latere wijzigingen daarin. De l… [2] NL BWBR0009950:6a.9:1:2: …toriteit Consument en Markt kan op grond artikel 6a.2, eerste lid, de verplichting opleggen om door de Autoriteit Consument en Markt nader te bepalen informatie met betrekking tot door de Autoriteit Consument en Markt te bepalen vormen van toegang bekend te maken. Deze informatie kan onder meer betrekking heb… [3] EU 32016R0679:12:1:4: De verwerkingsverantwoordelijke neemt passende maatregelen opdat de betrokkene de in de artikelen 13 en 14 bedoelde informatie en de in de artikelen 15 tot en met 22 en artikel 34 bedoelde communicatie in verband met de verwerking in een beknopte, transparante, begrijpelijke … | L5: 32024R1689:70:2:6, BWBR0009950:6a.9:1:2, 32016R0679:12:1:4
A6: 5 | B6: nummergebruiker | C6: de nummergebruiker | D6: computergebruiker | E6: informatiegebruiker | G6: 2 | H6: De Autoriteit Consument en Markt stelt de nummergebruiker, voorzover deze bij de Autoriteit Consument en Markt bekend is, van de aanwijzing op de hoogte. | L6: BWBR0009950:7.3a:4:4
A7: 6 | B7: Archiefbescheiden van de Autoriteit Consument en Markt | C7: Archiefbescheiden van de Autoriteit Consument en Markt en aanvragen als bedoeld in het tweede lid | D7: Instituut voor de gezondheid en de veiligheid van de consument | E7: Europese Autoriteit voor effecten en markten | F7: Uitvoerend Agentschap voor consumenten, gezondheid, landbouw en voeding | G7: 1 | H7: Archiefbescheiden van de Autoriteit Consument en Markt en aanvragen als bedoeld in het tweede lid, worden overgedragen aan Onze Minister, voor zover zij niet overeenkomstig de Archiefwet 1995 zijn overgebracht naar een archiefbewaarplaats. | L7: BWBR0009950:20.15a:4:2
A8: 7 | B8: termijn | D8: procestermijn | E8: termijn voor publicatie | F8: terminologie | G8: 23 | H8: [1] EU 32022L2555:38:6:9: …de handeling aan het Europees Parlement en de Raad bezwaar heeft gemaakt, of indien zowel het Europees Parlement als de Raad voor het verstrijken van die termijn de Commissie hebben meegedeeld dat zij daartegen geen bezwaar zullen maken. Die termijn wordt op initiatief van het Europees Parlement of de Raad met… [2] NL BWBR0009950:14a.2:3:5: … na ontvangst van de melding of een verbod op grond van artikel 14a.4, eerste lid, wordt opgelegd. Indien nader onderzoek nodig is, kan Onze Minister de termijn verlengen met zes maanden. De termijn wordt opgeschort met ingang van de dag: a. waarop Onze Minister aanvullende informatie verzoekt tot de dag waar… [3] EU 32024R1689:80:2:4: …deze alle nodige maatregelen neemt om het AI-systeem in overeenstemming te brengen met de vereisten en verplichtingen van deze verordening, en binnen een termijn die de markttoezichtautoriteit kan voorschrijven passende corrigerende maatregelen neemt. | L8: 32022L2555:38:6:9, BWBR0009950:14a.2:3:5, 32024R1689:80:2:4
A9: 8 | B9: nadere regels | D9: betere regelgeving | G9: 54 | H9: [1] EU 32016R0679:88:1:1: Bij wet of bij collectieve overeenkomst kunnen de lidstaten nadere regels vaststellen ter bescherming van de rechten en vrijheden met betrekking tot de verwerking van de persoonsgegevens van werknemers in het kader van de a… [2] NL BWBR0009950:7.7:4:3: Bij of krachtens algemene maatregel van bestuur kunnen nadere regels worden gesteld met betrekking tot de in het derde lid bedoelde voorzieningen. [3] NL BWBR0052872:50:4:5: Bij regeling van Onze Minister van Economische Zaken kunnen nadere regels worden gesteld ten aanzien van het bepaalde in dit artikel. | L9: 32016R0679:88:1:1, BWBR0009950:7.7:4:3, BWBR0052872:50:4:5
A10: 9 | B10: beperkingen | C10: voorschriften en beperkingen | D10: beperking van bewegingsvrijheid | E10: verplichting | F10: beroepsverbod | G10: 13 | H10: Onze Minister kan aan de transitievergunning voorschriften en beperkingen verbinden, waaronder het voorschrift uitsluitend frequentieruimte te gebruiken in overeenstemming met de afspraken in de transitieovereenkomst bedoel… | L10: BWBR0009950:3.8a:4:9
A11: 10 | B11: onregelmatigheden | C11: onregelmatigheden, storingen en onverwachte prestaties | D11: onverkiesbaarheid | E11: onverdeeldheid | F11: ontvankelijkheid | G11: 3 | H11: …m met een hoog risico goed te begrijpen en de werking ervan naar behoren te kunnen monitoren, onder meer met het oog op het opsporen en aanpakken van onregelmatigheden, storingen en onverwachte prestaties; b) zich bewust te blijven van de mogelijke neiging om automatisch of te veel te vertrouwen op de output van een AI-systeem met een hoog risico (de z… | L11: 32024R1689:14:4:16
A12: 11 | B12: bijstand | D12: rechtsbijstand | E12: opstand | F12: rechtstoestand | G12: 14 | H12: … volgende taken: a. het monitoren en analyseren van cyberdreigingen, kwetsbaarheden en incidenten op nationaal niveau, en het op verzoek verlenen van bijstand aan de betrokken essentiële entiteit of belangrijke entiteit met betrekking tot het realtime of bijna-realtime monitoren van haar netwerk- en informa… | L12: BWBR0052872:16:2:4
A13: 12 | B13: toestemming | D13: verkoopvergunning | E13: wapenvergunning | F13: besluit | G13: 18 | H13: [1] EU 32016R0679:58:3:30: …ellingen en organen alsmede aan het publiek advies te verstrekken over aangelegenheden die verband houden met de bescherming van persoonsgegevens; c) toestemming te geven voor verwerking als bedoeld in artikel 36, lid 5, indien die voorafgaande toestemming door het lidstatelijke recht wordt voorgeschreven; d) … [2] NL BWBR0009950:3.20a:7:8: In afwijking van het eerste lid is toestemming niet vereist in bij of krachtens algemene maatregel van bestuur aan te wijzen gevallen. [3] EU 32016R0679:7:3:4: De betrokkene heeft het recht zijn toestemming te allen tijde in te trekken. Het intrekken van de toestemming laat de rechtmatigheid van de verwerking op basis van de toestemming vóór de intrekkin… | L13: 32016R0679:58:3:30, BWBR0009950:3.20a:7:8, 32016R0679:7:3:4
A14: 13 | B14: voorschriften | D14: verordening | G14: 35 | H14: [1] EU 32024R1689:99:1:1: Overeenkomstig de voorwaarden van deze verordening stellen de lidstaten de voorschriften vast voor sancties en andere handhavingsmaatregelen, die ook waarschuwingen en niet-monetaire maatregelen kunnen omvatten, die van toepassing zijn op… [2] NL BWBR0009950:7.9:whole:1: Bij ministeriële regeling kunnen voorschriften worden gesteld met betrekking tot het door een aanbieder van een openbaar elektronisch communicatienetwerk of openbare elektronische communicatiedien… [3] EU 32016R0679:43:6:13: De in lid 3 van dit artikel bedoelde voorschriften en de in artikel 42, lid 5, bedoelde criteria worden door de toezichthoudende autoriteit in een eenvoudig toegankelijke vorm openbaar gemaakt. De toezichthoudende autoriteiten delen die eisen en … | L14: 32024R1689:99:1:1, BWBR0009950:7.9:whole:1, 32016R0679:43:6:13
A15: 14 | B15: aanmelding | C15: de aanmelding | D15: aanklacht | E15: bekendmaking | F15: formulier | G15: 2 | H15: Wanneer de Commissie vaststelt dat een aangemelde instantie niet of niet meer aan de aanmeldingseisen voldoet, brengt zij de aanmeldende lidstaat daarvan op de hoogte en verzoekt zij deze lidstaat de nodige corrigerende maatregelen te nemen, en … | L15: 32024R1689:37:4:11
A16: 15 | B16: verordening | C16: deze verordening | D16: verordening | E16: verordening (EU) | G16: 3 | H16: …intrekking van die certificering leidt, onverminderd de verantwoordelijkheid van de verwerkingsverantwoordelijke of de verwerker voor de naleving van deze verordening. De accreditatie wordt afgegeven voor een maximumperiode van vijf jaar en kan onder dezelfde voorwaarden worden verlengd, mits het certificeringsorga… | L16: 32016R0679:43:4:11
A17: 16 | B17: vertaling van relevante informatie | C17: de vertaling van relevante informatie | D17: vertaling | G17: 1 | H17: …; c) de communicatie met andere instellingen en het brede publiek; d) het gebruik van elektronische middelen voor interne en externe communicatie; e) de vertaling van relevante informatie; f) de voorbereiding en follow-up van de bijeenkomsten van het Comité; g) de voorbereiding, opstelling en bekendmaking van adviezen, besluiten inzake… | L17: 32016R0679:75:6:9
A18: 17 | B18: erkenning | C18: Een erkenning | D18: bekendmaking | E18: beginsel van wederzijdse erkenning | F18: schenking | G18: 9 | H18: Een erkenning kan op verzoek van de erkende dienst worden ingetrokken. De erkende dienst voegt bij zijn verzoek een beëindigingsplan. Bij ministeriële regeling kun… | L18: BWBR0048156:14:1:3
A19: 18 | B19: verzoek | C19: aan het verzoek | D19: verplichting | E19: beschikking | F19: oproepen van gegevens | G19: 14 | H19: …t verstrekken van de gevraagde informatie of communicatie en het treffen van de gevraagde maatregelen gepaard gaan; ofwel b) weigeren gevolg te geven aan het verzoek. Het is aan de verwerkingsverantwoordelijke om de kennelijk ongegronde of buitensporige aard van het verzoek aan te tonen. | L19: 32016R0679:12:5:17
A20: 19 | B20: geaggregeerde beoordeling van het volwassenheidsniveau van de cyberbeveiligingscapaciteiten en -middelen in de hele Unie, met inbegrip van die op sectorniveau | C20: een geaggregeerde beoordeling van het volwassenheidsniveau van de cyberbeveiligingscapaciteiten en -middelen in de hele Unie, met inbegrip van die op sectorniveau, en van de mate waarin de nationale cyberbeveiligingsstrategieën van de lidstaten op elkaar zijn afgestemd | D20: weerbaarheid op het gebied van cyberbeveiliging | G20: 1 | H20: …p van kleine en middelgrote ondernemingen; d) een geaggregeerde beoordeling van het resultaat van de in artikel 19 bedoelde collegiale toetsingen; e) een geaggregeerde beoordeling van het volwassenheidsniveau van de cyberbeveiligingscapaciteiten en -middelen in de hele Unie, met inbegrip van die op sectorniveau, en van de mate waarin de nationale cyberbeveiligingsstrategieën van de lidstaten op elkaar zijn afgestemd. | L20: 32022L2555:18:1:9
A21: 20 | B21: elementen | C21: de in lid 2 bedoelde elementen | D21: profielen | E21: programmeren | F21: nanomaterialen | G21: 7 | H21: …is met betrekking tot de periode en de geografische en personele werkingssfeer. Bij haar beslissing over het verzoek houdt die instantie rekening met de in lid 2 bedoelde elementen. Een besluit dat nadelige rechtsgevolgen heeft voor een persoon mag niet uitsluitend worden genomen op basis van de output van het systeem voor biome… | L21: 32024R1689:5:3:18
A22: 21 | B22: bevoegde autoriteit | C22: de betrokken bevoegde autoriteit, bedoeld in artikel 8 van de Wet weerbaarheid kritieke entiteiten | D22: bevoegde nationale autoriteit | E22: verordenende bevoegdheid | F22: administratieve bevoegdheid | G22: 8 | H22: De betrokken bevoegde autoriteit, bedoeld in artikel 15, stelt de betrokken bevoegde autoriteit, bedoeld in artikel 8 van de Wet weerbaarheid kritieke entiteiten, op de hoogte van haar beoordeling van de naleving van het bepaalde bij of krachtens deze wet door een essentiële entiteit die tevens kritieke entite… | L22: BWBR0052872:56:2:3
A23: 22 | B23: AI-bureau | C23: het AI-bureau | D23: informatiebureau | E23: Publicatiebureau | F23: kantoorautomatisering | G23: 3 | H23: …bevoegdheden voor toezicht op en handhaving van hoofdstuk V, rekening houdend met de procedurele waarborgen krachtens artikel 94. De Commissie belast het AI-bureau met de uitvoering van deze taken, onverminderd de organisatiebevoegdheden van de Commissie en de bevoegdheidsverdeling tussen de lidstaten en de Unie… | L23: 32024R1689:88:1:2
A24: 23 | B24: risico | C24: op de relevante omstandigheden en risico’s | D24: risicomanagement | G24: 3 | H24: …van het systeem. De technische oplossingen die gericht zijn op het waarborgen van de cyberbeveiliging van AI-systemen met een hoog risico sluiten aan op de relevante omstandigheden en risico’s. De technische oplossingen voor het aanpakken van AI-specifieke kwetsbaarheden omvatten, waar passend, maatregelen voor het voorkomen, traceren, reag… | L24: 32024R1689:15:5:13
A25: 24 | B25: uitvoeringshandelingen | D25: uitvoeringsverordening | E25: uitvoeringsbesluit | F25: uitvoeringsrichtlijn | G25: 24 | H25: [1] EU 32022L2555:23:11:35: …delingen vast waarin nader wordt gespecificeerd in welke gevallen een incident als significant wordt beschouwd als bedoeld in lid 3. De Commissie kan dergelijke uitvoeringshandelingen vaststellen met betrekking tot andere essentiële en belangrijke entiteiten. De Commissie wisselt advies uit en werkt samen met de samenwerkingsgroep … [2] EU 32022L2555:21:5:14: Uiterlijk op 17 oktober 2024 stelt de Commissie uitvoeringshandelingen vast met de technische en methodologische vereisten van de in lid 2 bedoelde maatregelen met betrekking tot DNS-dienstverleners, registers voor tople… [3] EU 32016R0679:45:5:8: …bij uitvoeringshandelingen zonder terugwerkende kracht over tot intrekking, wijziging of schorsing van het in lid 3 van dit artikel bedoelde besluit. Die uitvoeringshandelingen worden vastgesteld volgens de in artikel 93, lid 2, bedoelde onderzoeksprocedure. Om naar behoren gemotiveerde dwingende redenen van urgentie, stelt … | L25: 32022L2555:23:11:35, 32022L2555:21:5:14, 32016R0679:45:5:8
A26: 25 | B26: effecten van de wijziging in de praktijk | C26: een verslag over de doeltreffendheid en de effecten van de wijziging van de artikelen 13.2a, 13.4 en 13.5 in de praktijk | D26: effecten van de digitale revolutie | E26: wijziging van het ministerie | G26: 1 | H26: …t in overeenstemming met Onze Minister binnen drie jaar na de inwerkingtreding van deze wet en vervolgens telkens na drie jaar aan de Staten-Generaal een verslag over de doeltreffendheid en de effecten van de wijziging van de artikelen 13.2a, 13.4 en 13.5 in de praktijk, voor zover die wijzigingen betrekking hebben op de implementatie van Richtlijn nr 2006/24/EG van het Europees Parlement en de Raad van de Europese U… | L26: BWBR0009950:13.9:whole:1
A27: 26 | B27: maatregelen | D27: bestuursmaatregel | E27: beheer | F27: besluit | G27: 27 | H27: [1] EU 32016R0679:34:3:5: …eist wanneer een van de volgende voorwaarden is vervuld: a) de verwerkingsverantwoordelijke heeft passende technische en organisatorische beschermingsmaatregelen genomen en deze maatregelen zijn toegepast op de persoonsgegevens waarop de inbreuk in verband met persoonsgegevens betrekking heeft, met name die we… [2] NL BWBR0009950:7.4:3:6: …diensten volledige, vergelijkbare, betrouwbare, gebruiksvriendelijke en actuele informatie bekend te maken over: a. de kwaliteit van hun diensten; b. de maatregelen die zijn genomen om gelijkwaardige toegang voor eindgebruikers met een handicap te waarborgen; c. de afhankelijkheid van de kwaliteit van de dienstverlening van externe factoren, indien van toepassing en indien de eindgebruikers consumenten zi… [3] EU 32016R0679:28:3:9: …n zich ertoe hebben verbonden vertrouwelijkheid in acht te nemen of door een passende wettelijke verplichting van vertrouwelijkheid zijn gebonden; c) alle overeenkomstig artikel 32 vereiste maatregelen neemt; d) aan de in de leden 2 en 4 bedoelde voorwaarden voor het in dienst nemen van een andere verwerker voldoet; e) rekening houdend met de aard v… | L27: 32016R0679:34:3:5, BWBR0009950:7.4:3:6, 32016R0679:28:3:9
A28: 27 | B28: elementen | C28: ten minste de volgende elementen | D28: profielen | E28: programmeren | F28: nanomaterialen | G28: 7 | H28: De contractuele overeenkomsten inzake het gebruik van ICT-diensten bevatten ten minste de volgende elementen: a) een duidelijke en volledige beschrijving van alle door de derde aanbieder van ICT-diensten te leveren functies en ICT-diensten, met vermelding of… | L28: 32022R2554:30:2:5
A29: 28 | B29: veiling | C29: een veiling | D29: veiling | G29: 1 | H29: …r overeenkomstig de bij of krachtens deze wet gestelde regels in aanmerking komt, wordt aan deze aanvrager het nummer toegekend zonder toepassing van een veiling. | L29: BWBR0009950:4.2:10:19
A30: 29 | B30: bindende aanwijzing | C30: een bindende aanwijzing | D30: verplicht advies | G30: 3 | H30: De bevoegde autoriteit kan een essentiële entiteit een bindende aanwijzing geven om binnen een daarbij gestelde redelijke termijn de daarin omschreven handelingen te verrichten of de daarin omschreven maatregelen te nemen te… | L30: BWBR0052872:74:whole:1
A31: 30 | B31: belanghebbenden | D31: belangengroep | E31: algemeen belang | F31: medeëigendom | G31: 3 | H31: …n informatie, voor zover er passende waarborgen voor de bescherming van persoonsgegevens en andere grondrechten en fundamentele vrijheden bestaan; c) belanghebbenden te betrekken bij besprekingen en activiteiten om de internationale samenwerking bij de handhaving van de wetgeving inzake de bescherming van persoons… | L31: 32016R0679:50:whole:4
A32: 31 | B32: gebruik laten maken van deze werken | C32: het gebruik laten maken van deze werken | D32: gebruik van robots | G32: 1 | H32: …standgehouden of opgeruimd. Voor de rechthebbende op of de beheerder van de genoemde bovengrondse ondersteuningswerken bestaat geen gedoogplicht voor het gebruik laten maken van deze werken. | L32: BWBR0009950:5.2:6:8
A33: 32 | B33: omvang | C33: de omvang en het algemene risicoprofiel van de financiële entiteit, en met de aard, schaal en complexiteit van de diensten, activiteiten en verrichtingen ervan | D33: omzettingstermijn | G33: 2 | H33: …kader voor ICT-risicobeheer verder te specificeren. Bij het opstellen van die ontwerpen van technische reguleringsnormen houden de ETA’s rekening met de omvang en het algemene risicoprofiel van de financiële entiteit, en met de aard, schaal en complexiteit van de diensten, activiteiten en verrichtingen ervan. De ETA’s leggen deze ontwerpen van technische reguleringsnormen uiterlijk op 17 januari 2024 voor aan de Commissie. Aan de Commissie wordt de bevoeg… | L33: 32022R2554:16:3:19
A34: 33 | B34: verplichting | D34: contract | G34: 38 | H34: [1] EU 32024R1689:57:1:4: … Commissie kan technische ondersteuning, advies en instrumenten verstrekken voor de oprichting en werking van AI-testomgevingen voor regelgeving. Aan de verplichting uit hoofde van de eerste alinea kan ook worden voldaan door deel te nemen aan een bestaande testomgeving, voor zover die deelname de deelnemende lidstaten een gelijkwaardig niveau v… [2] NL BWBR0052872:21a:1:1: …ten die de nationale veiligheid raken te voorkomen, legt hij in overeenstemming met Onze Minister een essentiële entiteit of een belangrijke entiteit de verplichting op om in de daarbij aangewezen onderdelen van haar netwerk- en informatiesystemen uitsluitend gebruik te maken van producten of diensten van anderen … [3] EU 32024R1689:50:2:7: …llende soorten content, de uitvoeringskosten en de algemeen erkende stand van de techniek, zoals tot uiting kan komen in relevante technische normen. Deze verplichting is niet van toepassing voor zover de AI-systemen een ondersteunende functie voor standaardbewerking vervullen of de door de gebruiksverantwoordelijke… | L34: 32024R1689:57:1:4, BWBR0052872:21a:1:1, 32024R1689:50:2:7
A35: 34 | B35: effectieve procedure om onjuiste informatie te melden | C35: in een effectieve procedure om onjuiste informatie te melden | D35: vertrouwelijke informatie | G35: 1 | H35: … duidelijk dat de gepresenteerde informatie geen volledig overzicht van de markt biedt, voordat de zoekresultaten worden getoond; g. de tool voorziet in een effectieve procedure om onjuiste informatie te melden; h. de tool voorziet in de mogelijkheid tot vergelijking van de prijzen, tarieven en kwaliteit van de dienstverlening van de aanbiedingen waartussen … | L35: BWBR0009950:7.3:5:9
A36: 35 | B36: aanvullende verklaring | C36: een aanvullende verklaring | D36: aangevulde realiteit | E36: officiële verklaring | F36: nota van toelichting | G36: 1 | H36: …ming van de doeleinden van de verwerking heeft de betrokkene het recht vervollediging van onvolledige persoonsgegevens te verkrijgen, onder meer door een aanvullende verklaring te verstrekken. | L36: 32016R0679:16:whole:3
A37: 36 | B37: latere wijzigingen | C37: alle latere wijzigingen daarvan | D37: gewijzigd voorstel | E37: invoering van vernieuwingen | G37: 4 | H37: Elke lidstaat deelt de Commissie uiterlijk op 25 mei 2018 de overeenkomstig lid 1 vastgestelde wetgevingsbepalingen mee, alsook onverwijld alle latere wijzigingen daarvan. | L37: 32016R0679:84:2:4
A38: 37 | B38: informatie, alsmede informatie of kan worden verkregen | C38: informatie die voor of tijdens onderhandelingen over interoperabiliteits- of toegangsovereenkomsten aan hen is verstrekt, alsmede informatie die bij de uitvoering van de overeenkomst is of kan worden verkregen | D38: informatie | G38: 2 | H38: Aanbieders van elektronische communicatienetwerken of aanbieders van elektronische communicatiediensten mogen informatie die voor of tijdens onderhandelingen over interoperabiliteits- of toegangsovereenkomsten aan hen is verstrekt, alsmede informatie die bij de uitvoering van de overeenkomst is of kan worden verkregen uitsluitend gebruiken voor het doel waarvoor deze informatie is verstrekt, respectievelijk uitsluitend gebruiken voor de uitvoering van de overeenkom… | L38: BWBR0009950:6.1:2:5
A39: 38 | B39: nummergebruikers | C39: de nummergebruikers | D39: computergebruiker | E39: informatiegebruiker | F39: hulp aan de gebruiker | G39: 1 | H39: Nummerhouders registreren binnen zes maanden na de inwerkingtreding van artikel 4.9, derde lid, onderdeel b, de nummergebruikers. De nummergebruiker krijgt het nummer op de dag van registratie door de nummerhouder van rechtswege in gebruik door de nummerhouder. | L39: BWBR0009950:20.16a:2:1
A40: 39 | B40: automatische waarschuwingsmechanismen | D40: systeem voor tijdige waarschuwing | E40: automatische informatieverwerking | F40: automatische regeling | G40: 1 | H40: …ogelijk en bepalen waarschuwingsdrempels en criteria om processen voor respons op ICT-gerelateerde incidenten in werking te stellen, met inbegrip van automatische waarschuwingsmechanismen voor de betrokken personeelsleden die belast zijn met de respons op ICT-gerelateerde incidenten. | L40: 32022R2554:10:2:8
...

Sheet key
A1: row | B1: kind | C1: stratum | D1: source | E1: level | F1: conf_1 | G1: pct_1 | H1: w_EU | I1: w_NL | J1: text
A2: 1 | B2: sample | C2: EU | emb low (p20-47) | D2: EU | E2: embedding | F2: 0.2776 | G2: 40.7 | J2: verhouding tot het ICT-risico van de financiële entiteit
A3: 2 | B3: census | C3: census | D3: EU+NL | E3: phrase | F3: 1 | H3: 4 | I3: 23 | J3: verplichtingen
A4: 3 | B4: sample | C4: NL | emb high (p73-100) | D4: NL | E4: embedding | F4: 0.4735 | G4: 92.9 | J4: misbruik
A5: 4 | B5: census | C5: census | D5: EU+NL | E5: phrase | F5: 1 | H5: 62 | I5: 25 | J5: informatie
A6: 5 | B6: sample | C6: NL | emb mid (p47-73) | D6: NL | E6: embedding | F6: 0.3806 | G6: 68.2 | J6: nummergebruiker
A7: 6 | B7: sample | C7: NL | emb low (p20-47) | D7: NL | E7: embedding | F7: 0.2621 | G7: 36.6 | J7: Archiefbescheiden van de Autoriteit Consument en Markt
A8: 7 | B8: census | C8: census | D8: EU+NL | E8: embedding | F8: 0.4231 | G8: 79.5 | H8: 10 | I8: 13 | J8: termijn
A9: 8 | B9: census | C9: census | D9: EU+NL | E9: embedding | F9: 0.2295 | G9: 27.9 | H9: 1 | I9: 53 | J9: nadere regels
A10: 9 | B10: sample | C10: NL | emb mid (p47-73) | D10: NL | E10: embedding | F10: 0.3393 | G10: 57.1 | J10: beperkingen
A11: 10 | B11: sample | C11: EU | emb mid (p47-73) | D11: EU | E11: embedding | F11: 0.3532 | G11: 60.9 | J11: onregelmatigheden
A12: 11 | B12: sample | C12: NL | emb high (p73-100) | D12: NL | E12: embedding | F12: 0.4014 | G12: 73.7 | J12: bijstand
A13: 12 | B13: census | C13: census | D13: EU+NL | E13: embedding | F13: 0.4161 | G13: 77.6 | H13: 9 | I13: 9 | J13: toestemming
A14: 13 | B14: census | C14: census | D14: EU+NL | E14: phrase | F14: 1 | H14: 2 | I14: 33 | J14: voorschriften
A15: 14 | B15: sample | C15: EU | emb mid (p47-73) | D15: EU | E15: embedding | F15: 0.3851 | G15: 69.4 | J15: aanmelding
A16: 15 | B16: sample | C16: EU | phrase | D16: EU | E16: phrase | F16: 0.8 | J16: verordening
A17: 16 | B17: sample | C17: EU | head + compound | D17: EU | E17: head | F17: 0.8 | J17: vertaling van relevante informatie
A18: 17 | B18: sample | C18: NL | emb low (p20-47) | D18: NL | E18: embedding | F18: 0.258 | G18: 35.5 | J18: erkenning
A19: 18 | B19: sample | C19: EU | emb high (p73-100) | D19: EU | E19: embedding | F19: 0.4423 | G19: 84.6 | J19: verzoek
A20: 19 | B20: sample | C20: EU | emb low (p20-47) | D20: EU | E20: embedding | F20: 0.2044 | G20: 21.2 | J20: geaggregeerde beoordeling van het volwassenheidsniveau van de cyberbeveiligingscapaciteiten en -middelen in de hele Unie, met inbegrip van die op sectorniveau
A21: 20 | B21: sample | C21: EU | emb low (p20-47) | D21: EU | E21: embedding | F21: 0.2301 | G21: 28 | J21: elementen
A22: 21 | B22: sample | C22: NL | emb high (p73-100) | D22: NL | E22: embedding | F22: 0.4877 | G22: 96.7 | J22: bevoegde autoriteit
A23: 22 | B23: sample | C23: EU | emb mid (p47-73) | D23: EU | E23: embedding | F23: 0.3399 | G23: 57.3 | J23: AI-bureau
A24: 23 | B24: sample | C24: EU | emb high (p73-100) | D24: EU | E24: embedding | F24: 0.4591 | G24: 89.1 | J24: risico
A25: 24 | B25: census | C25: census | D25: EU | E25: embedding | F25: 0.4236 | G25: 79.6 | H25: 24 | I25: 0 | J25: uitvoeringshandelingen
A26: 25 | B26: sample | C26: NL | emb high (p73-100) | D26: NL | E26: embedding | F26: 0.401 | G26: 73.6 | J26: effecten van de wijziging in de praktijk
A27: 26 | B27: census | C27: census | D27: EU+NL | E27: embedding | F27: 0.3601 | G27: 62.7 | H27: 18 | I27: 9 | J27: maatregelen
A28: 27 | B28: sample | C28: EU | emb low (p20-47) | D28: EU | E28: embedding | F28: 0.2301 | G28: 28 | J28: elementen
A29: 28 | B29: sample | C29: NL | phrase | D29: NL | E29: phrase | F29: 1 | J29: veiling
A30: 29 | B30: sample | C30: NL | emb low (p20-47) | D30: NL | E30: embedding | F30: 0.2602 | G30: 36.1 | J30: bindende aanwijzing
A31: 30 | B31: sample | C31: EU | emb high (p73-100) | D31: EU | E31: embedding | F31: 0.4267 | G31: 80.5 | J31: belanghebbenden
A32: 31 | B32: sample | C32: NL | emb low (p20-47) | D32: NL | E32: embedding | F32: 0.2193 | G32: 25.1 | J32: gebruik laten maken van deze werken
A33: 32 | B33: sample | C33: EU | emb low (p20-47) | D33: EU | E33: embedding | F33: 0.2041 | G33: 21.1 | J33: omvang
A34: 33 | B34: census | C34: census | D34: EU+NL | E34: phrase | F34: 1 | H34: 9 | I34: 29 | J34: verplichting
A35: 34 | B35: sample | C35: NL | emb low (p20-47) | D35: NL | E35: embedding | F35: 0.2023 | G35: 20.6 | J35: effectieve procedure om onjuiste informatie te melden
A36: 35 | B36: sample | C36: EU | emb high (p73-100) | D36: EU | E36: embedding | F36: 0.4247 | G36: 79.9 | J36: aanvullende verklaring
A37: 36 | B37: sample | C37: EU | emb low (p20-47) | D37: EU | E37: embedding | F37: 0.211 | G37: 22.9 | J37: latere wijzigingen
A38: 37 | B38: sample | C38: NL | head + compound | D38: NL | E38: head | F38: 0.8 | J38: informatie, alsmede informatie of kan worden verkregen
A39: 38 | B39: sample | C39: NL | emb mid (p47-73) | D39: NL | E39: embedding | F39: 0.3835 | G39: 68.9 | J39: nummergebruikers
A40: 39 | B40: sample | C40: EU | emb high (p73-100) | D40: EU | E40: embedding | F40: 0.4071 | G40: 75.2 | J40: automatische waarschuwingsmechanismen
...

Sheet Design
A1: Sample design
A2: What is estimated. The share of norm objects whose EuroVoc mapping is right, for EU law and for Dutch law, and the difference between the two. The sampling unit is therefore an object unit as it occurs in a norm, not a distinct string: a text used in 90 norms counts 90 times, as it does downstream, and each sampled unit is judged in the context of its own norm. Why these strata. Source (EU / NL) is a stratum because it is the comparison of interest; stratifying guarantees both sources get the same number of judgements regardless of their share. Within a source the strata follow the mapping cascade, because each level makes a different kind of claim and is expected to fail at a different rate: phrase (exact label), head + compound (lexical match on part of the object; compound is merged with head because it holds only 43 EU and 12 Dutch units, too few to estimate on its own), and the embedding matches split into three equal bands above the fallback percentile (20). Embedding matches are 80.7% of sampled EU units and 84.2% of Dutch ones, so their confidence bands carry most of the weight. Why these sizes. 50 judgements per source: the floor of 8 per cell keeps every cell measured, and the rest goes to the embedding bands in proportion to their size, because that is where the weight is. At 50% precision in every cell this gives about +/-13 points for EU law and +/-11 for Dutch law, and about +/-17 points on the EU - NL difference; only differences of roughly 24 points or more can be detected reliably (80% power). The sample is not proportional, so overall figures are weighted by N_h (the 'review' step), never by row count. What is left out. Unmapped units and norms whose object was dropped make no mapping claim; their shares are exact counts (table below). Norms without any object never reach the mapping. Optional checks of these, if drawn, are reported separately and never enter the precision figures.
A4: stratum | B4: source | C4: population N_h (unit occurrences) | D4: share of source's mapped units | E4: n judged | F4: why this stratum and this n
A5: EU | census | B5: EU | C5: 309 | D5: =IFERROR(C5/SUMIF($B$5:$B$16,B5,$C$5:$C$16),0) -> 0.12189349 | E5: 20 | F5: Occurrences of the 20 census texts in EU law; each text is judged once (shared with the other source).
A6: EU | phrase | B6: EU | C6: 111 | D6: =IFERROR(C6/SUMIF($B$5:$B$16,B6,$C$5:$C$16),0) -> 0.043786982 | E6: 8 | F6: Exact label match; expected to be the most reliable level. Floor only.
A7: EU | head + compound | B7: EU | C7: 318 | D7: =IFERROR(C7/SUMIF($B$5:$B$16,B7,$C$5:$C$16),0) -> 0.12544379 | E7: 8 | F7: Lexical match on part of the object (head word or compound part). Compound merged in: too few units to stand alone. Floor only.
A8: EU | emb low (p20-47) | B8: EU | C8: 570 | D8: =IFERROR(C8/SUMIF($B$5:$B$16,B8,$C$5:$C$16),0) -> 0.22485207 | E8: 11 | F8: Embedding match, lowest confidence band. Floor plus a share of the rest in proportion to its size.
A9: EU | emb mid (p47-73) | B9: EU | C9: 646 | D9: =IFERROR(C9/SUMIF($B$5:$B$16,B9,$C$5:$C$16),0) -> 0.25483235 | E9: 12 | F9: Embedding match, middle confidence band. Floor plus a share of the rest in proportion to its size.
A10: EU | emb high (p73-100) | B10: EU | C10: 581 | D10: =IFERROR(C10/SUMIF($B$5:$B$16,B10,$C$5:$C$16),0) -> 0.22919132 | E10: 11 | F10: Embedding match, highest confidence band. Floor plus a share of the rest in proportion to its size.
A11: NL | census | B11: NL | C11: 406 | D11: =IFERROR(C11/SUMIF($B$5:$B$16,B11,$C$5:$C$16),0) -> 0.22924901 | E11: 20 | F11: Occurrences of the 20 census texts in NL law; each text is judged once (shared with the other source).
A12: NL | phrase | B12: NL | C12: 55 | D12: =IFERROR(C12/SUMIF($B$5:$B$16,B12,$C$5:$C$16),0) -> 0.031055901 | E12: 8 | F12: Exact label match; expected to be the most reliable level. Floor only.
A13: NL | head + compound | B13: NL | C13: 161 | D13: =IFERROR(C13/SUMIF($B$5:$B$16,B13,$C$5:$C$16),0) -> 0.090909091 | E13: 8 | F13: Lexical match on part of the object (head word or compound part). Compound merged in: too few units to stand alone. Floor only.
A14: NL | emb low (p20-47) | B14: NL | C14: 371 | D14: =IFERROR(C14/SUMIF($B$5:$B$16,B14,$C$5:$C$16),0) -> 0.20948617 | E14: 11 | F14: Embedding match, lowest confidence band. Floor plus a share of the rest in proportion to its size.
A15: NL | emb mid (p47-73) | B15: NL | C15: 364 | D15: =IFERROR(C15/SUMIF($B$5:$B$16,B15,$C$5:$C$16),0) -> 0.2055336 | E15: 11 | F15: Embedding match, middle confidence band. Floor plus a share of the rest in proportion to its size.
A16: NL | emb high (p73-100) | B16: NL | C16: 414 | D16: =IFERROR(C16/SUMIF($B$5:$B$16,B16,$C$5:$C$16),0) -> 0.23376623 | E16: 12 | F16: Embedding match, highest confidence band. Floor plus a share of the rest in proportion to its size.
A18: Exact counts (no sampling)
B19: EU | C19: NL
A20: norms | B20: 3109 | C20: 2150
A21: object units | B21: 2936 | C21: 2020
A22: mapped units | B22: 2535 | C22: 1771
A23: unmapped units | B23: 401 | C23: 249
A24: norms with object dropped (no unit) | B24: 126 | C24: 138
A25: norms without any object | B25: 347 | C25: 149
A26: unmapped share of units | B26: =IFERROR(B23/B21,0) -> 0.13658038 | C26: =IFERROR(C23/C21,0) -> 0.12326733
A27: dropped share of norms | B27: =IFERROR(B24/B20,0) -> 0.040527501 | C27: =IFERROR(C24/C20,0) -> 0.064186047
A29: Census of frequent texts
A30: Why a census of the 20 most frequent texts. The mapping is computed per text, so one judgement settles every occurrence of a text, and an error in a frequent text repeats in every norm that uses it. The object texts are heavy-tailed: most occur once, a few occur dozens of times. A random sample of this size would draw the frequent texts by chance or not at all, which makes the estimate swing on luck; judging them all removes that part of the sampling error at the cost of one judgement each. How the texts were chosen. Not by hand: the texts are the top of the frequency ranking of mapped unit occurrences (all sources together), ties broken alphabetically, fixed before any judging. In particular they were not chosen because their mapping looked right or wrong, which would bias the estimate. The table lists each text with its counts. Why 20. Coverage grows quickly over the first texts and then flattens (coverage table to the right): the census costs one judgement per text, so it stops where a further text covers little more than a sampled unit would. It matters most for Dutch law, whose fixed formulas (e.g. 'nadere regels', 'regels') make a few texts a large share of all objects; leaving them to chance would make the EU - NL comparison depend on whether they happened to be drawn. How to judge a census row. Several contexts are shown, taken in turn from both sources. Judge the mapping for the way the text is used in them; if it fits some uses but not others, choose 'partial' and say so in the notes.
A32: rank | B32: text | C32: EU occurrences | D32: NL occurrences | E32: total | F32: share of all mapped units | G32: cumulative share | H32: why this text | J32: census size | K32: EU coverage | L32: NL coverage
A33: 1 | B33: regels | C33: 7 | D33: 85 | E33: =C33+D33 -> 92 | F33: =E33/4306 -> 0.021365536 | G33: =SUM($E$33:E33)/4306 -> 0.021365536 | H33: Frequency rank 1 of 2,359 distinct texts; used in both sources (mostly Dutch). One judgement covers its 92 norm occurrences. | J33: 5 | K33: 0.042209073 | L33: 0.12365895
A34: 2 | B34: informatie | C34: 62 | D34: 25 | E34: =C34+D34 -> 87 | F34: =E34/4306 -> 0.020204366 | G34: =SUM($E$33:E34)/4306 -> 0.041569902 | H34: Frequency rank 2 of 2,359 distinct texts; used in both sources (mostly EU). One judgement covers its 87 norm occurrences. | J34: 10 | K34: 0.077317554 | L34: 0.16770186
A35: 3 | B35: nadere regels | C35: 1 | D35: 53 | E35: =C35+D35 -> 54 | F35: =E35/4306 -> 0.012540641 | G35: =SUM($E$33:E35)/4306 -> 0.054110543 | H35: Frequency rank 3 of 2,359 distinct texts; used in both sources (mostly Dutch). One judgement covers its 54 norm occurrences. | J35: 20 | K35: 0.12189349 | L35: 0.22924901
A36: 4 | B36: besluit | C36: 27 | D36: 22 | E36: =C36+D36 -> 49 | F36: =E36/4306 -> 0.011379471 | G36: =SUM($E$33:E36)/4306 -> 0.065490014 | H36: Frequency rank 4 of 2,359 distinct texts; used in both sources (balanced). One judgement covers its 49 norm occurrences. | J36: 30 | K36: 0.15384615 | L36: 0.2676454
A37: 5 | B37: gegevens | C37: 10 | D37: 34 | E37: =C37+D37 -> 44 | F37: =E37/4306 -> 0.0102183 | G37: =SUM($E$33:E37)/4306 -> 0.075708314 | H37: Frequency rank 5 of 2,359 distinct texts; used in both sources (mostly Dutch). One judgement covers its 44 norm occurrences. | J37: 50 | K37: 0.19289941 | L37: 0.32523998
A38: 6 | B38: verplichting | C38: 9 | D38: 29 | E38: =C38+D38 -> 38 | F38: =E38/4306 -> 0.0088248955 | G38: =SUM($E$33:E38)/4306 -> 0.084533209 | H38: Frequency rank 6 of 2,359 distinct texts; used in both sources (mostly Dutch). One judgement covers its 38 norm occurrences. | J38: 100 | K38: 0.26666667 | L38: 0.39695088
A39: 7 | B39: verslag | C39: 34 | D39: 3 | E39: =C39+D39 -> 37 | F39: =E39/4306 -> 0.0085926614 | G39: =SUM($E$33:E39)/4306 -> 0.093125871 | H39: Frequency rank 7 of 2,359 distinct texts; used in both sources (mostly EU). One judgement covers its 37 norm occurrences.
A40: 8 | B40: voorschriften | C40: 2 | D40: 33 | E40: =C40+D40 -> 35 | F40: =E40/4306 -> 0.0081281932 | G40: =SUM($E$33:E40)/4306 -> 0.10125406 | H40: Frequency rank 8 of 2,359 distinct texts; used in both sources (mostly Dutch). One judgement covers its 35 norm occurrences.
A41: 9 | B41: advies | C41: 23 | D41: 6 | E41: =C41+D41 -> 29 | F41: =E41/4306 -> 0.0067347887 | G41: =SUM($E$33:E41)/4306 -> 0.10798885 | H41: Frequency rank 9 of 2,359 distinct texts; used in both sources (mostly EU). One judgement covers its 29 norm occurrences.
A42: 10 | B42: persoonsgegevens | C42: 21 | D42: 7 | E42: =C42+D42 -> 28 | F42: =E42/4306 -> 0.0065025546 | G42: =SUM($E$33:E42)/4306 -> 0.11449141 | H42: Frequency rank 10 of 2,359 distinct texts; used in both sources (mostly EU). One judgement covers its 28 norm occurrences.
A43: 11 | B43: maatregelen | C43: 18 | D43: 9 | E43: =C43+D43 -> 27 | F43: =E43/4306 -> 0.0062703205 | G43: =SUM($E$33:E43)/4306 -> 0.12076173 | H43: Frequency rank 11 of 2,359 distinct texts; used in both sources (mostly EU). One judgement covers its 27 norm occurrences.
A44: 12 | B44: verplichtingen | C44: 4 | D44: 23 | E44: =C44+D44 -> 27 | F44: =E44/4306 -> 0.0062703205 | G44: =SUM($E$33:E44)/4306 -> 0.12703205 | H44: Frequency rank 12 of 2,359 distinct texts; used in both sources (mostly Dutch). One judgement covers its 27 norm occurrences.
...

Sheet Summary
A1: stratum | B1: population N_h | C1: rows | D1: judged | E1: correct | F1: partial | G1: wrong | H1: unclear | I1: precision strict | J1: precision lenient | K1: strict 95% low | L1: strict 95% high | N1: z
A2: census | B2: 20 | C2: =COUNTIFS(key!$C$2:$C$121,A2) -> 20 | D2: =COUNTIFS(key!$C$2:$C$121,A2,Validate!$I$2:$I$121,"<>") -> 0 | E2: =COUNTIFS(key!$C$2:$C$121,A2,Validate!$I$2:$I$121,"correct") -> 0 | F2: =COUNTIFS(key!$C$2:$C$121,A2,Validate!$I$2:$I$121,"partial") -> 0 | G2: =COUNTIFS(key!$C$2:$C$121,A2,Validate!$I$2:$I$121,"wrong") -> 0 | H2: =COUNTIFS(key!$C$2:$C$121,A2,Validate!$I$2:$I$121,"unclear") -> 0 | I2: =IFERROR(E2/(D2-H2),"") | J2: =IFERROR((E2+F2)/(D2-H2),"") | K2: =IFERROR(MAX(0,(I2+$N$2^2/(2*(D2-H2)))/(1+$N$2^2/(D2-H2))-$N$2*SQRT(I2*(1-I2)/(D2-H2)+$N$2^2/(4*(D2-H2)^2))/(1+$N$2^2/(D2-H2))),"") | L2: =IFERROR(MIN(1,(I2+$N$2^2/(2*(D2-H2)))/(1+$N$2^2/(D2-H2))+$N$2*SQRT(I2*(1-I2)/(D2-H2)+$N$2^2/(4*(D2-H2)^2))/(1+$N$2^2/(D2-H2))),"") | N2: 1.96
A3: EU | phrase | B3: 111 | C3: =COUNTIFS(key!$C$2:$C$121,A3) -> 8 | D3: =COUNTIFS(key!$C$2:$C$121,A3,Validate!$I$2:$I$121,"<>") -> 0 | E3: =COUNTIFS(key!$C$2:$C$121,A3,Validate!$I$2:$I$121,"correct") -> 0 | F3: =COUNTIFS(key!$C$2:$C$121,A3,Validate!$I$2:$I$121,"partial") -> 0 | G3: =COUNTIFS(key!$C$2:$C$121,A3,Validate!$I$2:$I$121,"wrong") -> 0 | H3: =COUNTIFS(key!$C$2:$C$121,A3,Validate!$I$2:$I$121,"unclear") -> 0 | I3: =IFERROR(E3/(D3-H3),"") | J3: =IFERROR((E3+F3)/(D3-H3),"") | K3: =IFERROR(MAX(0,(I3+$N$2^2/(2*(D3-H3)))/(1+$N$2^2/(D3-H3))-$N$2*SQRT(I3*(1-I3)/(D3-H3)+$N$2^2/(4*(D3-H3)^2))/(1+$N$2^2/(D3-H3))),"") | L3: =IFERROR(MIN(1,(I3+$N$2^2/(2*(D3-H3)))/(1+$N$2^2/(D3-H3))+$N$2*SQRT(I3*(1-I3)/(D3-H3)+$N$2^2/(4*(D3-H3)^2))/(1+$N$2^2/(D3-H3))),"")
A4: EU | head + compound | B4: 318 | C4: =COUNTIFS(key!$C$2:$C$121,A4) -> 8 | D4: =COUNTIFS(key!$C$2:$C$121,A4,Validate!$I$2:$I$121,"<>") -> 0 | E4: =COUNTIFS(key!$C$2:$C$121,A4,Validate!$I$2:$I$121,"correct") -> 0 | F4: =COUNTIFS(key!$C$2:$C$121,A4,Validate!$I$2:$I$121,"partial") -> 0 | G4: =COUNTIFS(key!$C$2:$C$121,A4,Validate!$I$2:$I$121,"wrong") -> 0 | H4: =COUNTIFS(key!$C$2:$C$121,A4,Validate!$I$2:$I$121,"unclear") -> 0 | I4: =IFERROR(E4/(D4-H4),"") | J4: =IFERROR((E4+F4)/(D4-H4),"") | K4: =IFERROR(MAX(0,(I4+$N$2^2/(2*(D4-H4)))/(1+$N$2^2/(D4-H4))-$N$2*SQRT(I4*(1-I4)/(D4-H4)+$N$2^2/(4*(D4-H4)^2))/(1+$N$2^2/(D4-H4))),"") | L4: =IFERROR(MIN(1,(I4+$N$2^2/(2*(D4-H4)))/(1+$N$2^2/(D4-H4))+$N$2*SQRT(I4*(1-I4)/(D4-H4)+$N$2^2/(4*(D4-H4)^2))/(1+$N$2^2/(D4-H4))),"")
A5: EU | emb low (p20-47) | B5: 570 | C5: =COUNTIFS(key!$C$2:$C$121,A5) -> 11 | D5: =COUNTIFS(key!$C$2:$C$121,A5,Validate!$I$2:$I$121,"<>") -> 0 | E5: =COUNTIFS(key!$C$2:$C$121,A5,Validate!$I$2:$I$121,"correct") -> 0 | F5: =COUNTIFS(key!$C$2:$C$121,A5,Validate!$I$2:$I$121,"partial") -> 0 | G5: =COUNTIFS(key!$C$2:$C$121,A5,Validate!$I$2:$I$121,"wrong") -> 0 | H5: =COUNTIFS(key!$C$2:$C$121,A5,Validate!$I$2:$I$121,"unclear") -> 0 | I5: =IFERROR(E5/(D5-H5),"") | J5: =IFERROR((E5+F5)/(D5-H5),"") | K5: =IFERROR(MAX(0,(I5+$N$2^2/(2*(D5-H5)))/(1+$N$2^2/(D5-H5))-$N$2*SQRT(I5*(1-I5)/(D5-H5)+$N$2^2/(4*(D5-H5)^2))/(1+$N$2^2/(D5-H5))),"") | L5: =IFERROR(MIN(1,(I5+$N$2^2/(2*(D5-H5)))/(1+$N$2^2/(D5-H5))+$N$2*SQRT(I5*(1-I5)/(D5-H5)+$N$2^2/(4*(D5-H5)^2))/(1+$N$2^2/(D5-H5))),"")
A6: EU | emb mid (p47-73) | B6: 646 | C6: =COUNTIFS(key!$C$2:$C$121,A6) -> 12 | D6: =COUNTIFS(key!$C$2:$C$121,A6,Validate!$I$2:$I$121,"<>") -> 0 | E6: =COUNTIFS(key!$C$2:$C$121,A6,Validate!$I$2:$I$121,"correct") -> 0 | F6: =COUNTIFS(key!$C$2:$C$121,A6,Validate!$I$2:$I$121,"partial") -> 0 | G6: =COUNTIFS(key!$C$2:$C$121,A6,Validate!$I$2:$I$121,"wrong") -> 0 | H6: =COUNTIFS(key!$C$2:$C$121,A6,Validate!$I$2:$I$121,"unclear") -> 0 | I6: =IFERROR(E6/(D6-H6),"") | J6: =IFERROR((E6+F6)/(D6-H6),"") | K6: =IFERROR(MAX(0,(I6+$N$2^2/(2*(D6-H6)))/(1+$N$2^2/(D6-H6))-$N$2*SQRT(I6*(1-I6)/(D6-H6)+$N$2^2/(4*(D6-H6)^2))/(1+$N$2^2/(D6-H6))),"") | L6: =IFERROR(MIN(1,(I6+$N$2^2/(2*(D6-H6)))/(1+$N$2^2/(D6-H6))+$N$2*SQRT(I6*(1-I6)/(D6-H6)+$N$2^2/(4*(D6-H6)^2))/(1+$N$2^2/(D6-H6))),"")
A7: EU | emb high (p73-100) | B7: 581 | C7: =COUNTIFS(key!$C$2:$C$121,A7) -> 11 | D7: =COUNTIFS(key!$C$2:$C$121,A7,Validate!$I$2:$I$121,"<>") -> 0 | E7: =COUNTIFS(key!$C$2:$C$121,A7,Validate!$I$2:$I$121,"correct") -> 0 | F7: =COUNTIFS(key!$C$2:$C$121,A7,Validate!$I$2:$I$121,"partial") -> 0 | G7: =COUNTIFS(key!$C$2:$C$121,A7,Validate!$I$2:$I$121,"wrong") -> 0 | H7: =COUNTIFS(key!$C$2:$C$121,A7,Validate!$I$2:$I$121,"unclear") -> 0 | I7: =IFERROR(E7/(D7-H7),"") | J7: =IFERROR((E7+F7)/(D7-H7),"") | K7: =IFERROR(MAX(0,(I7+$N$2^2/(2*(D7-H7)))/(1+$N$2^2/(D7-H7))-$N$2*SQRT(I7*(1-I7)/(D7-H7)+$N$2^2/(4*(D7-H7)^2))/(1+$N$2^2/(D7-H7))),"") | L7: =IFERROR(MIN(1,(I7+$N$2^2/(2*(D7-H7)))/(1+$N$2^2/(D7-H7))+$N$2*SQRT(I7*(1-I7)/(D7-H7)+$N$2^2/(4*(D7-H7)^2))/(1+$N$2^2/(D7-H7))),"")
A8: NL | phrase | B8: 55 | C8: =COUNTIFS(key!$C$2:$C$121,A8) -> 8 | D8: =COUNTIFS(key!$C$2:$C$121,A8,Validate!$I$2:$I$121,"<>") -> 0 | E8: =COUNTIFS(key!$C$2:$C$121,A8,Validate!$I$2:$I$121,"correct") -> 0 | F8: =COUNTIFS(key!$C$2:$C$121,A8,Validate!$I$2:$I$121,"partial") -> 0 | G8: =COUNTIFS(key!$C$2:$C$121,A8,Validate!$I$2:$I$121,"wrong") -> 0 | H8: =COUNTIFS(key!$C$2:$C$121,A8,Validate!$I$2:$I$121,"unclear") -> 0 | I8: =IFERROR(E8/(D8-H8),"") | J8: =IFERROR((E8+F8)/(D8-H8),"") | K8: =IFERROR(MAX(0,(I8+$N$2^2/(2*(D8-H8)))/(1+$N$2^2/(D8-H8))-$N$2*SQRT(I8*(1-I8)/(D8-H8)+$N$2^2/(4*(D8-H8)^2))/(1+$N$2^2/(D8-H8))),"") | L8: =IFERROR(MIN(1,(I8+$N$2^2/(2*(D8-H8)))/(1+$N$2^2/(D8-H8))+$N$2*SQRT(I8*(1-I8)/(D8-H8)+$N$2^2/(4*(D8-H8)^2))/(1+$N$2^2/(D8-H8))),"")
A9: NL | head + compound | B9: 161 | C9: =COUNTIFS(key!$C$2:$C$121,A9) -> 8 | D9: =COUNTIFS(key!$C$2:$C$121,A9,Validate!$I$2:$I$121,"<>") -> 0 | E9: =COUNTIFS(key!$C$2:$C$121,A9,Validate!$I$2:$I$121,"correct") -> 0 | F9: =COUNTIFS(key!$C$2:$C$121,A9,Validate!$I$2:$I$121,"partial") -> 0 | G9: =COUNTIFS(key!$C$2:$C$121,A9,Validate!$I$2:$I$121,"wrong") -> 0 | H9: =COUNTIFS(key!$C$2:$C$121,A9,Validate!$I$2:$I$121,"unclear") -> 0 | I9: =IFERROR(E9/(D9-H9),"") | J9: =IFERROR((E9+F9)/(D9-H9),"") | K9: =IFERROR(MAX(0,(I9+$N$2^2/(2*(D9-H9)))/(1+$N$2^2/(D9-H9))-$N$2*SQRT(I9*(1-I9)/(D9-H9)+$N$2^2/(4*(D9-H9)^2))/(1+$N$2^2/(D9-H9))),"") | L9: =IFERROR(MIN(1,(I9+$N$2^2/(2*(D9-H9)))/(1+$N$2^2/(D9-H9))+$N$2*SQRT(I9*(1-I9)/(D9-H9)+$N$2^2/(4*(D9-H9)^2))/(1+$N$2^2/(D9-H9))),"")
A10: NL | emb low (p20-47) | B10: 371 | C10: =COUNTIFS(key!$C$2:$C$121,A10) -> 11 | D10: =COUNTIFS(key!$C$2:$C$121,A10,Validate!$I$2:$I$121,"<>") -> 0 | E10: =COUNTIFS(key!$C$2:$C$121,A10,Validate!$I$2:$I$121,"correct") -> 0 | F10: =COUNTIFS(key!$C$2:$C$121,A10,Validate!$I$2:$I$121,"partial") -> 0 | G10: =COUNTIFS(key!$C$2:$C$121,A10,Validate!$I$2:$I$121,"wrong") -> 0 | H10: =COUNTIFS(key!$C$2:$C$121,A10,Validate!$I$2:$I$121,"unclear") -> 0 | I10: =IFERROR(E10/(D10-H10),"") | J10: =IFERROR((E10+F10)/(D10-H10),"") | K10: =IFERROR(MAX(0,(I10+$N$2^2/(2*(D10-H10)))/(1+$N$2^2/(D10-H10))-$N$2*SQRT(I10*(1-I10)/(D10-H10)+$N$2^2/(4*(D10-H10)^2))/(1+$N$2^2/(D10-H10))),"") | L10: =IFERROR(MIN(1,(I10+$N$2^2/(2*(D10-H10)))/(1+$N$2^2/(D10-H10))+$N$2*SQRT(I10*(1-I10)/(D10-H10)+$N$2^2/(4*(D10-H10)^2))/(1+$N$2^2/(D10-H10))),"")
A11: NL | emb mid (p47-73) | B11: 364 | C11: =COUNTIFS(key!$C$2:$C$121,A11) -> 11 | D11: =COUNTIFS(key!$C$2:$C$121,A11,Validate!$I$2:$I$121,"<>") -> 0 | E11: =COUNTIFS(key!$C$2:$C$121,A11,Validate!$I$2:$I$121,"correct") -> 0 | F11: =COUNTIFS(key!$C$2:$C$121,A11,Validate!$I$2:$I$121,"partial") -> 0 | G11: =COUNTIFS(key!$C$2:$C$121,A11,Validate!$I$2:$I$121,"wrong") -> 0 | H11: =COUNTIFS(key!$C$2:$C$121,A11,Validate!$I$2:$I$121,"unclear") -> 0 | I11: =IFERROR(E11/(D11-H11),"") | J11: =IFERROR((E11+F11)/(D11-H11),"") | K11: =IFERROR(MAX(0,(I11+$N$2^2/(2*(D11-H11)))/(1+$N$2^2/(D11-H11))-$N$2*SQRT(I11*(1-I11)/(D11-H11)+$N$2^2/(4*(D11-H11)^2))/(1+$N$2^2/(D11-H11))),"") | L11: =IFERROR(MIN(1,(I11+$N$2^2/(2*(D11-H11)))/(1+$N$2^2/(D11-H11))+$N$2*SQRT(I11*(1-I11)/(D11-H11)+$N$2^2/(4*(D11-H11)^2))/(1+$N$2^2/(D11-H11))),"")
A12: NL | emb high (p73-100) | B12: 414 | C12: =COUNTIFS(key!$C$2:$C$121,A12) -> 12 | D12: =COUNTIFS(key!$C$2:$C$121,A12,Validate!$I$2:$I$121,"<>") -> 0 | E12: =COUNTIFS(key!$C$2:$C$121,A12,Validate!$I$2:$I$121,"correct") -> 0 | F12: =COUNTIFS(key!$C$2:$C$121,A12,Validate!$I$2:$I$121,"partial") -> 0 | G12: =COUNTIFS(key!$C$2:$C$121,A12,Validate!$I$2:$I$121,"wrong") -> 0 | H12: =COUNTIFS(key!$C$2:$C$121,A12,Validate!$I$2:$I$121,"unclear") -> 0 | I12: =IFERROR(E12/(D12-H12),"") | J12: =IFERROR((E12+F12)/(D12-H12),"") | K12: =IFERROR(MAX(0,(I12+$N$2^2/(2*(D12-H12)))/(1+$N$2^2/(D12-H12))-$N$2*SQRT(I12*(1-I12)/(D12-H12)+$N$2^2/(4*(D12-H12)^2))/(1+$N$2^2/(D12-H12))),"") | L12: =IFERROR(MIN(1,(I12+$N$2^2/(2*(D12-H12)))/(1+$N$2^2/(D12-H12))+$N$2*SQRT(I12*(1-I12)/(D12-H12)+$N$2^2/(4*(D12-H12)^2))/(1+$N$2^2/(D12-H12))),"")
A14: Per-stratum figures only; they are unweighted and the census row counts texts, not occurrences.
A15: Weighted precision per source, the EU - NL difference and the mix-adjusted comparison come from: python eurovoc_review.py review --xlsx <this file>
A16: Strict = correct; lenient = correct + partial; unclear is excluded. Intervals: Wilson, z in N2.
A17: Check strata (if any) measure whether leaving an object unmapped / dropping it was right; they never enter the precision totals.
