Workbook

Sheet README
A1: Validation of the object → EuroVoc mapping (Step 7)
A3: What to do
A4: 1. Go to the Validate sheet. Rows with in_sample = yes (green) come first: judge those.
A5: 2. Fill in the yellow columns only: judgement (drop-down), better_concept (optional), notes.
A6: 3. Judge candidate 1 mainly; use candidates 2-3 to decide 'partial'.
A7: 4. The Summary sheet updates automatically as you fill in judgements.
A9: Judgement codes
A10: correct – candidate 1 is the right concept, or an acceptable close one.
A11: partial – candidate 1 is in the right area but too broad/narrow, or a lower candidate is right.
A12: wrong – no candidate fits the object.
A13: unclear – the object itself cannot be judged (placeholder, fragment, unresolved reference).
A14: For unmapped objects: 'correct' = rightly left unmapped; 'wrong' = a EuroVoc concept clearly exists.
... A28: Example of a filled-in row (not part of the data)
A29: object | B29: level | C29: cand_1 | D29: conf_1 | E29: judgement | F29: better_concept | G29: notes
A30: ten minste de in lid 6 bepaalde informatie | B30: head | C30: informatie | D30: 0.8 | E30: partial | F30: melding | G30: concept right but generic; the object refers to lid 6

Sheet Validate
A1: in_sample | B1: stratum | C1: object | D1: raw_object | E1: norm_type | F1: head | G1: level | H1: matched_label | I1: cand_1 | J1: conf_1 | K1: pct_1 | L1: cand_2 | M1: conf_2 | N1: cand_3 | O1: conf_3 | P1: n_norms | Q1: example_norm | R1: context | S1: judgement | T1: better_concept | U1: notes
A2: yes | B2: phrase | C2: advies | D2: informatie en advies over dreigingen en incidenten met betrekking tot hun netwerk- en informatiesystemen | E2: phrase | F2: advies | G2: phrase | H2: advies | I2: advies | J2: 0.8 | L2: advies (EU) | M2: 0.8 | P2: 2 | Q2: BWBR0052872:96:1:2 | R2: …stellen door Onze Minister of een andere in afwijking hiervan bij of krachtens algemene maatregel van bestuur hiervoor aan te wijzen instantie; en b. informatie en advies over dreigingen en incidenten met betrekking tot hun netwerk- en informatiesystemen van Onze Minister of een andere in afwijking hiervan bij of krachtens algemene maatregel van bestuur hiervoor aan te wijzen instantie.
A3: yes | B3: phrase | C3: begroting | D3: de begroting | E3: phrase | F3: begroting | G3: phrase | H3: begroting | I3: begroting | J3: 1 | P3: 1 | Q3: BWBR0040940:11:3:3 | R3: De Autoriteit persoonsgegevens stelt de begroting vast in overeenstemming met het budget, bedoeld in het tweede lid.
A4: yes | B4: phrase | C4: bevoegdheden | D4: de bevoegdheden | E4: phrase | F4: bevoegdheid | G4: phrase | H4: bevoegdheid | I4: politieke bevoegdheid | J4: 1 | P4: 1 | Q4: BWBR0040940:14:1:2 | R4: De Autoriteit persoonsgegevens is bevoegd om de taken uit te voeren en de bevoegdheden uit te oefenen die bij of krachtens de verordening zijn toegekend aan de toezichthoudende autoriteit.
A5: yes | B5: phrase | C5: cyberdreiging | D5: het aan het CSIRT gemelde incident, bijna-incident of cyberdreiging | E5: phrase | F5: cyberdreiging | G5: phrase | H5: cyberdreiging | I5: informatieoorlog | J5: 1 | P5: 1 | Q5: BWBR0052872:39:2:5 | R5: Als dat passend is en in elk geval als het aan het CSIRT gemelde incident, bijna-incident of cyberdreiging, bedoeld in het eerste lid, betrekking heeft op twee of meer lidstaten van de Europese Unie, stelt het centrale contactpunt de centrale contactpunten…
A6: yes | B6: phrase | C6: Enisa | D6: de Europese Commissie en Enisa | E6: phrase | F6: enisa | G6: phrase | H6: enisa | I6: Agentschap van de Europese Unie voor cyberbeveiliging | J6: 1 | P6: 1 | Q6: BWBR0052872:60:4:5 | R6: … de betrokken bevoegde autoriteit van de andere lidstaat van de Europese Unie over de voorgenomen afwijzing en, wanneer de lidstaat daartoe verzoekt, de Europese Commissie en Enisa.
A7: yes | B7: phrase | C7: Europese Commissie | D7: de Europese Commissie en Enisa | E7: phrase | F7: europese | G7: phrase | H7: europees commissie | I7: Europese Commissie | J7: 1 | P7: 1 | Q7: BWBR0052872:60:4:5 | R7: … de betrokken bevoegde autoriteit van de andere lidstaat van de Europese Unie over de voorgenomen afwijzing en, wanneer de lidstaat daartoe verzoekt, de Europese Commissie en Enisa.
A8: yes | B8: phrase | C8: toezichthoudende bevoegdheden | D8: hun toezichthoudende bevoegdheden | E8: phrase | F8: bevoegdheid | G8: phrase | H8: toezichthouden bevoegdheid | I8: toezichthoudende bevoegdheid | J8: 1 | P8: 1 | Q8: BWBR0052872:68:3:3 | R8: Ten behoeve van het verlenen van de bijstand, bedoeld in het tweede lid, kunnen de toezichthouders hun toezichthoudende bevoegdheden toepassen.
A9: yes | B9: phrase | C9: verplichtingen | D9: de verplichtingen uit de artikelen 25 tot en met 30 | E9: phrase | F9: verplichting | G9: phrase | H9: verplichting | I9: contract | J9: 1 | P9: 1 | Q9: BWBR0052872:31:1:1 | R9: …le entiteit of belangrijke entiteit significante incidenten moet melden en indien deze eisen ten minste gelijkwaardig zijn aan die uit deze wet, zijn de verplichtingen uit de artikelen 25 tot en met 30 niet van toepassing op die specifieke entiteit.
A10: yes | B10: phrase | C10: voorziening | E10: phrase | F10: voorziening | G10: phrase | H10: voorziening | I10: voorziening | J10: 1 | P10: 1 | Q10: BWBR0040940:20:8:8 | R10: Tegen het aanhouden van het verzoek door de Afdeling bestuursrechtspraak van de Raad van State, staat geen voorziening open.
A11: yes | B11: phrase | C11: woning | D11: een woning | E11: phrase | F11: woning | G11: phrase | H11: woning | I11: huisvesting | J11: 1 | P11: 1 | Q11: BWBR0040940:15:2:2 | R11: De in het eerste lid bedoelde personen zijn bevoegd een woning te betreden zonder toestemming van de bewoner.
A12: yes | B12: head | C12: aanbieder die voor 16 januari 2023 op grond van de Wet beveiliging netwerk- en informatiesystemen is aangewezen als aanbieder van een essentiële dienst | D12: een aanbieder die voor 16 januari 2023 op grond van de Wet beveiliging netwerk- en informatiesystemen is aangewezen als aanbieder van een essentiële dienst | E12: head | F12: aanbieder | G12: head | H12: aanbieder | I12: provider | J12: 0.8 | P12: 1 | Q12: BWBR0052872:10:whole:1 | R12: Bij regeling of besluit van Onze Minister die het aangaat, na overleg met Onze Minister, kan worden aangewezen als essentiële entiteit: een aanbieder die voor 16 januari 2023 op grond van de Wet beveiliging netwerk- en informatiesystemen is aangewezen als aanbieder van een essentiële dienst.
A13: yes | B13: head | C13: aanvullende technische ondersteuning | E13: head | F13: ondersteuning | G13: head | H13: ondersteuning | I13: economische steun | J13: 0.8 | P13: 1 | Q13: BWBR0052872:36:2:1 | R13: Het CSIRT verleent aanvullende technische ondersteuning indien de betrokken entiteit daar om verzoekt.
A14: yes | B14: head | C14: informatie over dreigingen en incidenten met betrekking tot hun netwerk- en informatiesystemen | D14: informatie en advies over dreigingen en incidenten met betrekking tot hun netwerk- en informatiesystemen | E14: phrase | F14: informatie | G14: head | H14: informatie | I14: informatie | J14: 0.8 | P14: 1 | Q14: BWBR0052872:96:1:2 | R14: …stellen door Onze Minister of een andere in afwijking hiervan bij of krachtens algemene maatregel van bestuur hiervoor aan te wijzen instantie; en b. informatie en advies over dreigingen en incidenten met betrekking tot hun netwerk- en informatiesystemen van Onze Minister of een andere in afwijking hiervan bij of krachtens algemene maatregel van bestuur hiervoor aan te wijzen instantie.
A15: yes | B15: head | C15: informatie over een incident, bijna-incident of cyberdreiging | E15: head | F15: informatie | G15: head | H15: informatie | I15: informatie | J15: 0.8 | P15: 1 | Q15: BWBR0052872:40:2:2 | R15: Het CSIRT verstrekt de bevoegde autoriteit, bedoeld in artikel 8 van de Wet weerbaarheid kritieke entiteiten, informatie over een incident, bijna-incident of cyberdreiging dat overeenkomstig artikel 33, eerste lid, onderdeel a, is gemeld door een essentiële entiteit die tevens een kritieke entiteit is als bedoeld in de …
A16: yes | B16: head | C16: overgang van die registergoederen | D16: de overgang van die registergoederen | E16: head | F16: overgang | G16: head | H16: overgang | I16: menopauze | J16: 0.8 | P16: 1 | Q16: BWBR0040940:48a:6:3 | R16: Ingeval krachtens het vierde en het vijfde lid registergoederen overgaan, doet Onze Minister van Financiën de overgang van die registergoederen onverwijld inschrijven in de openbare registers, bedoeld in afdeling 2 van titel 1 van Boek 3 van het Burgerlijk Wetboek. Artikel 24, eerste lid, van…
A17: yes | B17: head | C17: relevante informatie die hierover is gemeld tijdig aan het centrale contactpunt wordt verstrekt | D17: dat de relevante informatie die hierover is gemeld tijdig aan het centrale contactpunt wordt verstrekt | E17: head | F17: informatie | G17: head | H17: informatie | I17: informatie | J17: 0.8 | P17: 1 | Q17: BWBR0052872:39:1:2 | R17: …enten, bijna-incidenten en cyberdreigingen. In geval van een grensoverschrijdend of sectoroverschrijdend significant incident, zorgt het CSIRT ervoor dat de relevante informatie die hierover is gemeld tijdig aan het centrale contactpunt wordt verstrekt.
A18: yes | B18: head | C18: samenvattend verslag | D18: een samenvattend verslag | E18: head | F18: verslag | G18: head | H18: verslag | I18: verslag | J18: 0.8 | P18: 1 | Q18: BWBR0052872:39:5:8 | R18: Het centrale contactpunt dient elke drie maanden bij Enisa een samenvattend verslag in met geanonimiseerde en geaggregeerde gegevens over gemelde significante incidenten, incidenten, bijna-incidenten en cyberdreigingen.
A19: yes | B19: head | C19: significante cyberdreiging | D19: de desbetreffende significante cyberdreiging | E19: head | F19: cyberdreiging | G19: head | H19: cyberdreiging | I19: informatieoorlog | J19: 0.8 | P19: 1 | Q19: BWBR0052872:30:2:3 | R19: …erwijld mee welke maatregelen die ontvangers kunnen nemen in reactie op die dreiging. Indien nodig stelt de entiteit die ontvangers ook in kennis van de desbetreffende significante cyberdreiging.
A20: yes | B20: head | C20: Staat dan wel Onze Minister | D20: de Staat dan wel Onze Minister | E20: head | F20: minister | G20: head | H20: minister | I20: minister | J20: 0.8 | P20: 1 | Q20: BWBR0040940:48a:7:5 | R20: …Autoriteit persoonsgegevens is betrokken, treedt op het tijdstip van inwerkingtreding van dit artikel de Autoriteit persoonsgegevens in de plaats van de Staat dan wel Onze Minister.
A21: yes | B21: head | C21: verplichtingen van de verordening | D21: de verplichtingen en rechten, bedoeld in de artikelen 12 tot en met 21 en artikel 34 van de verordening | E21: phrase | F21: verplichting | G21: head | H21: verplichting | I21: contract | J21: 0.8 | P21: 1 | Q21: BWBR0040940:41:1:1 | R21: De verwerkingsverantwoordelijke kan de verplichtingen en rechten, bedoeld in de artikelen 12 tot en met 21 en artikel 34 van de verordening, buiten toepassing laten voor zover zulks noodzakelijk en evenredig is ter waarborging van: a. de nationale veiligheid; b. landsverdediging; c. de op…
A22: yes | B22: compound | C22: eindverslag | D22: een eindverslag | E22: compound | F22: eindverslag | G22: compound | H22: verslag | I22: verslag | J22: 0.6 | P22: 2 | Q22: BWBR0052872:29:1:1 | R22: De essentiële entiteit of belangrijke entiteit dient uiterlijk één maand na de melding, bedoeld in artikel 27, eerste lid, een eindverslag in bij haar CSIRT en haar bevoegde autoriteit waarin het volgende is opgenomen: a. een gedetailleerde beschrijving van het incident, de ernst en de g…
A23: yes | B23: compound | C23: instelling voor hoger onderwijs.1, onder g, van de Wet op het hoger onderwijs en wetenschappelijk onderzoek | D23: een instelling voor hoger onderwijs als bedoeld in artikel 1.1, onder g, van de Wet op het hoger onderwijs en wetenschappelijk onderzoek | E23: compound | F23: instelling | G23: compound | H23: telling | I23: telling | J23: 0.6 | P23: 2 | Q23: BWBR0052872:11:1:1 | R23: Bij regeling of besluit van Onze Minister van Onderwijs, Cultuur en Wetenschap, na overleg met Onze Minister, kan een instelling voor hoger onderwijs als bedoeld in artikel 1.1, onder g, van de Wet op het hoger onderwijs en wetenschappelijk onderzoek als essentiële entiteit worden aangewezen.
A24: yes | B24: compound | C24: nationale cyberbeveiligingsstrategie | D24: de nationale cyberbeveiligingsstrategie | E24: compound | F24: cyberbeveiligingsstrategie | G24: compound | H24: strategie | I24: krijgskunde | J24: 0.6 | P24: 2 | Q24: BWBR0052872:19:3:3 | R24: Onze Minister beoordeelt in overeenstemming met Onze Ministers die het aangaan de nationale cyberbeveiligingsstrategie regelmatig en ten minste om de vijf jaar, op basis van kernprestatie-indicatoren. Hij werkt de nationale cyberbeveiligingsstrategie in overeenstemmin…
A25: yes | B25: compound | C25: nationale cyberbeveiligingsstrategie van de NIS2-richtlijn | D25: een nationale cyberbeveiligingsstrategie als bedoeld in artikel 7, eerste lid, van de NIS2-richtlijn | E25: compound | F25: cyberbeveiligingsstrategie | G25: compound | H25: strategie | I25: krijgskunde | J25: 0.6 | P25: 1 | Q25: BWBR0052872:19:1:1 | R25: Onze Minister stelt in overeenstemming met Onze Ministers die het aangaan een nationale cyberbeveiligingsstrategie als bedoeld in artikel 7, eerste lid, van de NIS2-richtlijn vast.
A26: yes | B26: compound | C26: of beheersmaatregelen mogelijk en realiseerbaar zijn die de nationale veiligheidsrisico’s die in het geding zijn voldoende beschermen | E26: compound | F26: veiligheidsrisico | G26: compound | H26: risico | I26: gedekt risico | J26: 0.6 | P26: 1 | Q26: BWBR0052872:21a:2:2 | R26: In het kader van de beoordeling van de noodzaak, bedoeld in het eerste lid, beoordeelt Onze Minister die het aangaat in elk geval of beheersmaatregelen mogelijk en realiseerbaar zijn die de nationale veiligheidsrisico’s die in het geding zijn voldoende beschermen.
A27: yes | B27: compound | C27: oversightforum dat is opgericht | D27: het oversightforum dat is opgericht op grond van artikel 32, eerste lid, van de Verordening (EU) 2022/2554 | E27: compound | F27: oversightforum | G27: compound | H27: forum | I27: forum | J27: 0.6 | P27: 1 | Q27: BWBR0052872:57:2:3 | R27: De bevoegde autoriteit stelt het oversightforum dat is opgericht op grond van artikel 32, eerste lid, van de Verordening (EU) 2022/2554 in kennis wanneer zij haar toezichts- en handhavingsbevoegdheden uitoefent om ervoor te zorgen dat een essentiële entiteit of belangrijke entiteit, d…
A28: yes | B28: compound | C28: Toestemming | E28: compound | F28: toestemming | G28: compound | H28: stemming | I28: stemming | J28: 0.6 | P28: 1 | Q28: BWBR0040940:5:3:3 | R28: Toestemming kan te allen tijde worden ingetrokken door: a. de wettelijk vertegenwoordiger; b. de betrokkene die de leeftijd van twaalf jaren heeft bereikt, en c.…
A29: yes | B29: compound | C29: toestemming | D29: de toestemming | E29: compound | F29: toestemming | G29: compound | H29: stemming | I29: stemming | J29: 0.6 | P29: 1 | Q29: BWBR0040940:5:1:1 | R29: …erdeel elf, van de verordening en de betrokkene heeft de leeftijd van zestien jaren nog niet bereikt, is in plaats van toestemming van de betrokkene, de toestemming van zijn wettelijk vertegenwoordiger vereist.
A30: yes | B30: compound | C30: Toestemming b | D30: Toestemming als bedoeld in het tweede lid, onderdeel b | E30: compound | F30: toestemming | G30: compound | H30: stemming | I30: stemming | J30: 0.6 | P30: 1 | Q30: BWBR0040940:28:3:3 | R30: Toestemming als bedoeld in het tweede lid, onderdeel b, is niet vereist, indien het vragen van uitdrukkelijke toestemming onmogelijk blijkt of een onevenredige inspanning vergt.
A31: yes | B31: compound | C31: voortgangsverslag | D31: een voortgangsverslag | E31: compound | F31: voortgangsverslag | G31: compound | H31: verslag | I31: verslag | J31: 0.6 | P31: 1 | Q31: BWBR0052872:29:2:2 | R31: …ent dat het eindverslag had moeten worden ingediend, dient de essentiële entiteit of belangrijke entiteit op dat moment in plaats van een eindverslag een voortgangsverslag in waarin wordt ingegaan op de aspecten, genoemd in het eerste lid. Zij dient een eindverslag in binnen één maand nadat het incident is afgehandeld.
A32: yes | B32: embedding p20-47 | C32: analyses | D32: analyses en technisch onderzoek | E32: phrase | F32: analyse | G32: embedding | I32: statistische analyse | J32: 0.2937 | K32: 45 | L32: documentaire analyse | M32: 0.226 | N32: sociale analyse | O32: 0.2226 | P32: 1 | Q32: BWBR0052872:96:2:3 | R32: …ster onderscheidenlijk de andere instantie, bedoeld in het eerste lid, verricht ten behoeve van het uitvoeren van de in het eerste lid bedoelde taken analyses en technisch onderzoek, naar aanleiding van de in het eerste lid genoemde dreigingen en incidenten of aanwijzingen daarvoor, niet zijnde onderzoek naar personen of organisa…
A33: yes | B33: embedding p20-47 | C33: verwerking van genetische gegevens, biometrische gegevens met het oog op de unieke identificatie van een persoon | D33: verwerking van persoonsgegevens waaruit ras of etnische afkomst, politieke opvattingen, religieuze of levensbeschouwelijke overtuigingen, of het lidmaatschap van een vakbond blijken, en verwerking van genetische gegevens, biometrische gegevens met het oog op de unieke identificatie van een persoon, of gegevens over gezondheid, of gegevens met betrekking tot iemands seksueel gedrag of seksuele gerichtheid | E33: embedding | F33: verwerking | G33: embedding | I33: gegevensverwerking | J33: 0.2872 | K33: 43.2 | L33: genetische informatiedatabase | M33: 0.2125 | P33: 1 | Q33: BWBR0040940:22:1:1 | R33: Overeenkomstig artikel 9, eerste lid, van de verordening zijn verwerking van persoonsgegevens waaruit ras of etnische afkomst, politieke opvattingen, religieuze of levensbeschouwelijke overtuigingen, of het lidmaatschap van een vakbond blijken, en verwerking van genetische gegevens, biometrische gegevens met het oog op de unieke identificatie van een persoon, of gegevens over gezondheid, of gegevens met betrekking tot iemands seksueel gedrag of seksuele gerichtheid verboden.
A34: yes | B34: embedding p20-47 | C34: afspraken | E34: embedding | F34: afspraak | G34: embedding | I34: communicatie | J34: 0.2866 | K34: 43.1 | L34: afspraak tussen ondernemingen | M34: 0.281 | N34: besprekingen | O34: 0.2359 | P34: 1 | Q34: BWBR0040940:19:1:1 | R34: De Autoriteit persoonsgegevens is bevoegd om in het belang van een efficiënt en effectief toezicht op de verwerking van persoonsgegevens afspraken te maken met andere toezichthouders en daartoe gezamenlijk met deze toezichthouders samenwerkingsprotocollen vast te stellen. Een samenwerkingsprotoc…
A35: yes | B35: embedding p20-47 | C35: nummers die dienen ter identificatie | D35: nummers die dienen ter identificatie als bedoeld in artikel 46 | E35: embedding | F35: nummer | G35: embedding | I35: identiteitsbewijs | J35: 0.2675 | K35: 38 | L35: radiofrequentie-identificatie | M35: 0.202 | P35: 1 | Q35: BWBR0040940:47a:2:2 | R35: …llingsbesluit worden bepaald dat de commissie of het adviescollege ten behoeve van het in de instellingsregeling of instellingsbesluit opgenomen doel nummers die dienen ter identificatie als bedoeld in artikel 46 kan verwerken. In de instellingsregeling worden passende waarborgen voor de rechten en vrijheden van de betrokkene vastgesteld.
A36: yes | B36: embedding p20-47 | C36: last onder bestuursdwang | D36: een last onder bestuursdwang | E36: embedding | F36: last | G36: embedding | I36: openbaarheid van het bestuur | J36: 0.2496 | K36: 33.2 | L36: slachtoffer onder burgerbevolking | M36: 0.2323 | N36: nuttige last | O36: 0.2236 | P36: 3 | Q36: BWBR0052872:75:whole:1 | R36: De bevoegde autoriteit is bevoegd tot oplegging van een last onder bestuursdwang aan een essentiële entiteit ter handhaving van het bepaalde bij of krachtens deze wet en het bepaalde in de op grond van de artikelen 21, vijfde lid,…
A37: yes | B37: embedding p20-47 | C37: nummer dat ter identificatie van een persoon bij wet is voorgeschreven | D37: Een nummer dat ter identificatie van een persoon bij wet is voorgeschreven | E37: embedding | F37: nummer | G37: embedding | I37: identiteitsbewijs | J37: 0.2452 | K37: 32 | P37: 1 | Q37: BWBR0040940:46:whole:1 | R37: Een nummer dat ter identificatie van een persoon bij wet is voorgeschreven, wordt bij de verwerking van persoonsgegevens slechts gebruikt ter uitvoering van de desbetreffende wet dan wel voor doeleinden bij de wet bepaald.
A38: yes | B38: embedding p20-47 | C38: last onder dwangsom | D38: een last onder dwangsom | E38: embedding | F38: last | G38: embedding | I38: door de EU opgelegde dwangsom | J38: 0.2382 | K38: 30.2 | L38: nuttige last | M38: 0.2235 | N38: ernstige acute ondervoeding | O38: 0.2052 | P38: 2 | Q38: BWBR0052872:90:whole:1 | R38: De bevoegde autoriteit kan een entiteit die domeinnaamregistratiediensten verleent een last onder dwangsom opleggen in geval van overtreding van het bepaalde bij of krachtens de artikelen 42, 44, 47, 49 en 50.
A39: yes | B39: embedding p20-47 | C39: kosten van de beveiligingsscan | D39: de kosten van de beveiligingsscan | E39: embedding | F39: kost | G39: embedding | I39: kosten van milieubescherming | J39: 0.2372 | K39: 29.9 | L39: kosten van gezondheidsschade | M39: 0.2115 | P39: 2 | Q39: BWBR0052872:71:2:3 | R39: De bevoegde autoriteit draagt de kosten van de beveiligingsscan.
A40: yes | B40: embedding p20-47 | C40: verbod om andere bijzondere categorieën van persoonsgegevens te verwerken | D40: Het verbod om andere bijzondere categorieën van persoonsgegevens te verwerken | E40: embedding | F40: verbod | G40: embedding | I40: gegevensbescherming | J40: 0.2368 | K40: 29.8 | P40: 1 | Q40: BWBR0040940:30:5:5 | R40: Het verbod om andere bijzondere categorieën van persoonsgegevens te verwerken is niet van toepassing, indien de verwerking noodzakelijk is in aanvulling op de verwerking van gegevens over gezondheid, bedoeld in het derde lid, a…
...

Sheet Summary
A1: stratum | B1: objects | C1: in sample | D1: judged | E1: correct | F1: partial | G1: wrong | H1: unclear | I1: precision (strict) | J1: precision (lenient)
A2: phrase | B2: 21 | C2: =COUNTIFS(Validate!$B$2:$B$81,A2,Validate!$A$2:$A$81,"yes") -> 10 | D2: =COUNTIFS(Validate!$B$2:$B$81,A2,Validate!$S$2:$S$81,"<>") -> 0 | E2: =COUNTIFS(Validate!$B$2:$B$81,A2,Validate!$S$2:$S$81,"correct") -> 0 | F2: =COUNTIFS(Validate!$B$2:$B$81,A2,Validate!$S$2:$S$81,"partial") -> 0 | G2: =COUNTIFS(Validate!$B$2:$B$81,A2,Validate!$S$2:$S$81,"wrong") -> 0 | H2: =COUNTIFS(Validate!$B$2:$B$81,A2,Validate!$S$2:$S$81,"unclear") -> 0 | I2: =IFERROR(E2/(D2-H2),"") | J2: =IFERROR((E2+F2)/(D2-H2),"")
A3: head | B3: 31 | C3: =COUNTIFS(Validate!$B$2:$B$81,A3,Validate!$A$2:$A$81,"yes") -> 10 | D3: =COUNTIFS(Validate!$B$2:$B$81,A3,Validate!$S$2:$S$81,"<>") -> 0 | E3: =COUNTIFS(Validate!$B$2:$B$81,A3,Validate!$S$2:$S$81,"correct") -> 0 | F3: =COUNTIFS(Validate!$B$2:$B$81,A3,Validate!$S$2:$S$81,"partial") -> 0 | G3: =COUNTIFS(Validate!$B$2:$B$81,A3,Validate!$S$2:$S$81,"wrong") -> 0 | H3: =COUNTIFS(Validate!$B$2:$B$81,A3,Validate!$S$2:$S$81,"unclear") -> 0 | I3: =IFERROR(E3/(D3-H3),"") | J3: =IFERROR((E3+F3)/(D3-H3),"")
A4: compound | B4: 12 | C4: =COUNTIFS(Validate!$B$2:$B$81,A4,Validate!$A$2:$A$81,"yes") -> 10 | D4: =COUNTIFS(Validate!$B$2:$B$81,A4,Validate!$S$2:$S$81,"<>") -> 0 | E4: =COUNTIFS(Validate!$B$2:$B$81,A4,Validate!$S$2:$S$81,"correct") -> 0 | F4: =COUNTIFS(Validate!$B$2:$B$81,A4,Validate!$S$2:$S$81,"partial") -> 0 | G4: =COUNTIFS(Validate!$B$2:$B$81,A4,Validate!$S$2:$S$81,"wrong") -> 0 | H4: =COUNTIFS(Validate!$B$2:$B$81,A4,Validate!$S$2:$S$81,"unclear") -> 0 | I4: =IFERROR(E4/(D4-H4),"") | J4: =IFERROR((E4+F4)/(D4-H4),"")
A5: embedding p20-47 | B5: 59 | C5: =COUNTIFS(Validate!$B$2:$B$81,A5,Validate!$A$2:$A$81,"yes") -> 10 | D5: =COUNTIFS(Validate!$B$2:$B$81,A5,Validate!$S$2:$S$81,"<>") -> 0 | E5: =COUNTIFS(Validate!$B$2:$B$81,A5,Validate!$S$2:$S$81,"correct") -> 0 | F5: =COUNTIFS(Validate!$B$2:$B$81,A5,Validate!$S$2:$S$81,"partial") -> 0 | G5: =COUNTIFS(Validate!$B$2:$B$81,A5,Validate!$S$2:$S$81,"wrong") -> 0 | H5: =COUNTIFS(Validate!$B$2:$B$81,A5,Validate!$S$2:$S$81,"unclear") -> 0 | I5: =IFERROR(E5/(D5-H5),"") | J5: =IFERROR((E5+F5)/(D5-H5),"")
A6: embedding p47-73 | B6: 46 | C6: =COUNTIFS(Validate!$B$2:$B$81,A6,Validate!$A$2:$A$81,"yes") -> 10 | D6: =COUNTIFS(Validate!$B$2:$B$81,A6,Validate!$S$2:$S$81,"<>") -> 0 | E6: =COUNTIFS(Validate!$B$2:$B$81,A6,Validate!$S$2:$S$81,"correct") -> 0 | F6: =COUNTIFS(Validate!$B$2:$B$81,A6,Validate!$S$2:$S$81,"partial") -> 0 | G6: =COUNTIFS(Validate!$B$2:$B$81,A6,Validate!$S$2:$S$81,"wrong") -> 0 | H6: =COUNTIFS(Validate!$B$2:$B$81,A6,Validate!$S$2:$S$81,"unclear") -> 0 | I6: =IFERROR(E6/(D6-H6),"") | J6: =IFERROR((E6+F6)/(D6-H6),"")
A7: embedding p73-100 | B7: 34 | C7: =COUNTIFS(Validate!$B$2:$B$81,A7,Validate!$A$2:$A$81,"yes") -> 10 | D7: =COUNTIFS(Validate!$B$2:$B$81,A7,Validate!$S$2:$S$81,"<>") -> 0 | E7: =COUNTIFS(Validate!$B$2:$B$81,A7,Validate!$S$2:$S$81,"correct") -> 0 | F7: =COUNTIFS(Validate!$B$2:$B$81,A7,Validate!$S$2:$S$81,"partial") -> 0 | G7: =COUNTIFS(Validate!$B$2:$B$81,A7,Validate!$S$2:$S$81,"wrong") -> 0 | H7: =COUNTIFS(Validate!$B$2:$B$81,A7,Validate!$S$2:$S$81,"unclear") -> 0 | I7: =IFERROR(E7/(D7-H7),"") | J7: =IFERROR((E7+F7)/(D7-H7),"")
A8: unmapped | B8: 46 | C8: =COUNTIFS(Validate!$B$2:$B$81,A8,Validate!$A$2:$A$81,"yes") -> 10 | D8: =COUNTIFS(Validate!$B$2:$B$81,A8,Validate!$S$2:$S$81,"<>") -> 0 | E8: =COUNTIFS(Validate!$B$2:$B$81,A8,Validate!$S$2:$S$81,"correct") -> 0 | F8: =COUNTIFS(Validate!$B$2:$B$81,A8,Validate!$S$2:$S$81,"partial") -> 0 | G8: =COUNTIFS(Validate!$B$2:$B$81,A8,Validate!$S$2:$S$81,"wrong") -> 0 | H8: =COUNTIFS(Validate!$B$2:$B$81,A8,Validate!$S$2:$S$81,"unclear") -> 0 | I8: =IFERROR(E8/(D8-H8),"") | J8: =IFERROR((E8+F8)/(D8-H8),"")
A9: no unit: no_object | B9: 24 | C9: =COUNTIFS(Validate!$B$2:$B$81,A9,Validate!$A$2:$A$81,"yes") -> 5 | D9: =COUNTIFS(Validate!$B$2:$B$81,A9,Validate!$S$2:$S$81,"<>") -> 0 | E9: =COUNTIFS(Validate!$B$2:$B$81,A9,Validate!$S$2:$S$81,"correct") -> 0 | F9: =COUNTIFS(Validate!$B$2:$B$81,A9,Validate!$S$2:$S$81,"partial") -> 0 | G9: =COUNTIFS(Validate!$B$2:$B$81,A9,Validate!$S$2:$S$81,"wrong") -> 0 | H9: =COUNTIFS(Validate!$B$2:$B$81,A9,Validate!$S$2:$S$81,"unclear") -> 0 | I9: =IFERROR(E9/(D9-H9),"") | J9: =IFERROR((E9+F9)/(D9-H9),"")
A10: no unit: unknown | B10: 21 | C10: =COUNTIFS(Validate!$B$2:$B$81,A10,Validate!$A$2:$A$81,"yes") -> 5 | D10: =COUNTIFS(Validate!$B$2:$B$81,A10,Validate!$S$2:$S$81,"<>") -> 0 | E10: =COUNTIFS(Validate!$B$2:$B$81,A10,Validate!$S$2:$S$81,"correct") -> 0 | F10: =COUNTIFS(Validate!$B$2:$B$81,A10,Validate!$S$2:$S$81,"partial") -> 0 | G10: =COUNTIFS(Validate!$B$2:$B$81,A10,Validate!$S$2:$S$81,"wrong") -> 0 | H10: =COUNTIFS(Validate!$B$2:$B$81,A10,Validate!$S$2:$S$81,"unclear") -> 0 | I10: =IFERROR(E10/(D10-H10),"") | J10: =IFERROR((E10+F10)/(D10-H10),"")
A11: total | B11: =SUM(B2:B10) -> 294 | C11: =SUM(C2:C10) -> 80 | D11: =SUM(D2:D10) -> 0 | E11: =SUM(E2:E10) -> 0 | F11: =SUM(F2:F10) -> 0 | G11: =SUM(G2:G10) -> 0 | H11: =SUM(H2:H10) -> 0 | I11: =IFERROR(E11/(D11-H11),"") | J11: =IFERROR((E11+F11)/(D11-H11),"")
A13: Precision excludes 'unclear'. Strict = correct only; lenient = correct + partial.
A14: For 'unmapped', precision means: share of objects rightly left unmapped. For 'no unit' strata: share of norms that rightly have no unit.
A15: Embedding bands split the range above the fallback percentile (20) into three equal parts.
A16: 'objects' is the full count per stratum; Validate holds only the sample.
A17: With 10 judged per stratum, precision per stratum is a rough indication (about ±31 points at worst, 95%); the total is much tighter.
A19: norm_type | B19: norms | C19: rows in sample
A20: embedding | B20: 217 | C20: 28
A21: unknown | B21: 74 | C21: 11
A22: phrase | B22: 35 | C22: 16
A23: head | B23: 31 | C23: 10
A24: no_object | B24: 24 | C24: 5
A25: compound | B25: 15 | C25: 10

Sheet Norms
A1: norm_id | B1: object | C1: units | D1: level | E1: cand_1 | F1: conf_1 | G1: cand_2 | H1: cand_3 | I1: norm_type
A2: BWBR0052872:3:whole:1 | B2: regels | C2: regels | D2: embedding | E2: reglement | F2: 0.3594 | G2: prijsregels | I2: embedding
A3: BWBR0052872:5:2:1 | B3: deze wet | C3: wet | D3: phrase | E3: wet | F3: 1 | I3: phrase
A4: BWBR0052872:9:1:1 | B4: een in bijlage 1 of bijlage 2 van deze wet genoemde entiteit | C4: entiteit | D4: embedding | E4: wooneenheid | F4: 0.3066 | G4: anciënniteit | H4: nationaliteit | I4: embedding
A5: BWBR0052872:9:2:2 | B5: de aanwijzing | C5: aanwijzing | D5: embedding | E5: aanwerving | F5: 0.4128 | G5: uitwijzing | H5: aanbeveling | I5: embedding
A6: BWBR0052872:10:whole:1 | B6: een aanbieder die voor 16 januari 2023 op grond van de Wet beveiliging netwerk- en informatiesystemen is aangewezen als aanbieder van een essentiële dienst | C6: aanbieder die voor 16 januari 2023 op grond van de Wet beveiliging netwerk- en informatiesystemen is aangewezen als aanbieder van een essentiële dienst | D6: head | E6: provider | F6: 0.8 | I6: head
A7: BWBR0052872:11:1:1 | B7: een instelling voor hoger onderwijs als bedoeld in artikel 1.1, onder g, van de Wet op het hoger onderwijs en wetenschappelijk onderzoek | C7: instelling voor hoger onderwijs.1, onder g, van de Wet op het hoger onderwijs en wetenschappelijk onderzoek | D7: compound | E7: telling | F7: 0.6 | I7: compound
A8: BWBR0052872:11:2:2 | B8: de aanwijzing, bedoeld in het eerste lid | C8: aanwijzing | D8: embedding | E8: aanwerving | F8: 0.4128 | G8: uitwijzing | H8: aanbeveling | I8: embedding
A9: BWBR0052872:13:1:1 | B9: een instelling voor hoger onderwijs als bedoeld in artikel 1.1, onder g, van de Wet op het hoger onderwijs en wetenschappelijk onderzoek | C9: instelling voor hoger onderwijs.1, onder g, van de Wet op het hoger onderwijs en wetenschappelijk onderzoek | D9: compound | E9: telling | F9: 0.6 | I9: compound
A10: BWBR0052872:13:2:2 | B10: de aanwijzing, bedoeld in het eerste lid | C10: aanwijzing | D10: embedding | E10: aanwerving | F10: 0.4128 | G10: uitwijzing | H10: aanbeveling | I10: embedding
A11: BWBR0052872:14:whole:1 | B11: het centrale contactpunt | C11: centrale contactpunt | D11: embedding | E11: telefooncentrale | F11: 0.2604 | G11: centrale | I11: embedding
A12: BWBR0052872:14:whole:2 | B12: de volgende taken | C12: taken | I12: unknown
A13: BWBR0052872:14:whole:3 | B13: voor grensoverschrijdende samenwerking van de autoriteiten van Nederland met de relevante autoriteiten van andere lidstaten van de Europese Unie, de Europese Commissie en Enisa | C13: grensoverschrijdende samenwerking van de autoriteiten van Nederland met de relevante autoriteiten van andere lidstaten van de Europese Unie, de Europese Commissie en Enisa | D13: embedding | E13: Europese grensoverschrijdende samenwerking | F13: 0.3502 | G13: Europees Agentschap voor het beheer van de operationele samenwerking aan de buitengrenzen van de lidstaten van de Europese Unie | H13: intergouvernementele samenwerking (EU) | I13: embedding
A14: BWBR0052872:14:whole:4 | B14: voor sectoroverschrijdende samenwerking tussen de bevoegde autoriteiten binnen Nederland | C14: sectoroverschrijdende samenwerking tussen de bevoegde autoriteiten binnen Nederland | D14: embedding | E14: samenwerking tussen Instellingen | F14: 0.2747 | G14: samenwerking tussen ondernemingen | H14: intergouvernementele samenwerking (EU) | I14: embedding
A15: BWBR0052872:14:whole:5 | B15: de overige in deze wet genoemde taken | C15: overige genoemde taken | D15: embedding | E15: aanvullend werk | F15: 0.2728 | G15: aangevulde realiteit | H15: aanvullende begroting | I15: embedding
A16: BWBR0052872:15:6:1 | B16: de bestuursrechtelijke handhaving van het bepaalde bij of krachtens deze wet | C16: bestuursrechtelijke handhaving van het bepaalde bij of | D16: embedding | E16: bestuursrecht | F16: 0.208 | I16: embedding
A17: BWBR0052872:15:6:2 | B17: de bestuursrechtelijke handhaving van het bepaalde in de op grond van de artikelen 21, vijfde lid, en 23, elfde lid, van de NIS2-richtlijn vastgestelde uitvoeringshandelingen en de op grond van artikel 24, tweede lid, van de NIS2-richtlijn vastgestelde gedelegeerde handelingen | C17: bestuursrechtelijke handhaving van het bepaalde in de uitvoeringshandelingen en de gedelegeerde handelingen | I17: unknown
A18: BWBR0052872:15:6:3 | B18: de overige in deze wet genoemde taken van de bevoegde autoriteit | C18: overige genoemde taken van de bevoegde autoriteit | D18: embedding | E18: bevoegde nationale autoriteit | F18: 0.3538 | G18: verordenende bevoegdheid | H18: bevoegdheden | I18: embedding
A19: BWBR0052872:16:1:1 | B19: het CSIRT | C19: CSIRT | I19: unknown
A20: BWBR0052872:16:3:2 | B20: een openbaar toegankelijk netwerk- en informatiesysteem van een essentiële entiteit en belangrijke entiteit | C20: openbaar toegankelijk netwerk- en informatiesysteem van een essentiële entiteit en belangrijke entiteit | D20: head | E20: informatiesysteem | F20: 0.8 | I20: head
A21: BWBR0052872:16:3:3 | B21: tot negatieve gevolgen voor de dienstverlening van de betrokken entiteit | C21: negatieve gevolgen voor de dienstverlening van de betrokken entiteit | I21: unknown
A22: BWBR0052872:16:4:4 | B22: prioriteit | C22: prioriteit | D22: embedding | E22: budgettaire prioriteit | F22: 0.4211 | G22: prioriteitszone | H22: economische prioriteit | I22: embedding
A23: BWBR0052872:16:5:5 | B23: samenwerkingsrelaties | C23: samenwerkingsrelaties | D23: embedding | E23: samenwerkingsovereenkomst | F23: 0.3975 | G23: samenwerkingsraad | H23: samenwerkingsbeleid | I23: embedding
A24: BWBR0052872:16:6:6 | B24: de invoering en het gebruik van gemeenschappelijke of gestandaardiseerde praktijken, classificatieschema’s en taxonomieën | C24: invoering | gebruik van gemeenschappelijke of gestandaardiseerde praktijken, classificatieschema’s en taxonomieën | D24: embedding | E24: invoer | F24: 0.4621 | G24: invoervergunning | H24: invoerregeling | I24: embedding
A25: BWBR0052872:16:7:7 | B25: regels | C25: regels | D25: embedding | E25: reglement | F25: 0.3594 | G25: prijsregels | I25: embedding
A26: BWBR0052872:17:1:1 | B26: een CSIRT | C26: CSIRT | I26: unknown
A27: BWBR0052872:19:1:1 | B27: een nationale cyberbeveiligingsstrategie als bedoeld in artikel 7, eerste lid, van de NIS2-richtlijn | C27: nationale cyberbeveiligingsstrategie van de NIS2-richtlijn | D27: compound | E27: krijgskunde | F27: 0.6 | I27: compound
A28: BWBR0052872:19:2:2 | B28: beleid | C28: beleid | D28: embedding | E28: beleidsvorming | F28: 0.4117 | G28: beleidsanalyse | H28: overheidsbeleid | I28: embedding
A29: BWBR0052872:19:3:3 | B29: de nationale cyberbeveiligingsstrategie | C29: nationale cyberbeveiligingsstrategie | D29: compound | E29: krijgskunde | F29: 0.6 | I29: compound
A30: BWBR0052872:19:3:4 | B30: de nationale cyberbeveiligingsstrategie | C30: nationale cyberbeveiligingsstrategie | D30: compound | E30: krijgskunde | F30: 0.6 | I30: compound
A31: BWBR0052872:20:whole:1 | B31: een nationaal plan voor grootschalige cyberbeveiligingsincidenten en crisisrespons | C31: nationaal plan voor grootschalige cyberbeveiligingsincidenten en crisisrespons | D31: embedding | E31: netwerk- en internetbeveiliging | F31: 0.2214 | I31: embedding
A32: BWBR0052872:21:3:1 | B32: het volgende | I32: unknown
A33: BWBR0052872:21:4:2 | B33: de specifieke kwetsbaarheden van elke rechtstreekse leverancier en dienstverlener | C33: specifieke kwetsbaarheden van elke rechtstreekse leverancier en dienstverlener | I33: unknown
A34: BWBR0052872:21:4:3 | B34: de algemene kwaliteit van de producten en de cyberbeveiligingspraktijken van haar leveranciers en dienstverleners, met inbegrip van hun veilige ontwikkelingsprocedures | C34: algemene kwaliteit van de producten | cyberbeveiligingspraktijken van haar leveranciers en dienstverleners, met inbegrip van hun veilige ontwikkelingsprocedures | D34: embedding | E34: kwaliteit van het product | F34: 0.4631 | G34: kwaliteitsbeheersing van industrieproducten | H34: kwaliteit van het milieu | I34: embedding
A35: BWBR0052872:21:4:4 | B35: de resultaten van de door de samenwerkingsgroep op grond van artikel 22, eerste lid, van de NIS2-richtlijn uitgevoerde gecoördineerde beveiligingsrisicobeoordelingen van kritieke toeleveringsketens | C35: resultaten van de door de samenwerkingsgroep van de NIS2-richtlijn uitgevoerde gecoördineerde beveiligingsrisicobeoordelingen van kritieke toeleveringsketens | I35: unknown
A36: BWBR0052872:21:4:5 | I36: no_object
A37: BWBR0052872:21:5:6 | B37: regels | C37: regels | D37: embedding | E37: reglement | F37: 0.3594 | G37: prijsregels | I37: embedding
A38: BWBR0052872:21:5:7 | B38: eisen | C38: eisen | D38: embedding | E38: ei | F38: 0.2408 | I38: embedding
A39: BWBR0052872:21a:1:1 | B39: producten of diensten van anderen dan de daarbij door Onze Minister die het aangaat genoemde partij | C39: producten of diensten van anderen dan de daarbij door Onze Minister die het aangaat genoemde partij | I39: unknown
A40: BWBR0052872:21a:2:2 | B40: of beheersmaatregelen mogelijk en realiseerbaar zijn die de nationale veiligheidsrisico’s die in het geding zijn voldoende beschermen | C40: of beheersmaatregelen mogelijk en realiseerbaar zijn die de nationale veiligheidsrisico’s die in het geding zijn voldoende beschermen | D40: compound | E40: gedekt risico | F40: 0.6 | I40: compound
...
