Workbook

Sheet Instructions
A1: Actor mapping review
A2: Each row of the Review sheet is an actor unit in a norm (census rows show up to 3 norms that use the same unit). 'Assigned' is what the system mapped the unit to. Judge whether that is right, from the norm text and the actor phrase. The Inventory sheet lists every known actor with its definition.
A3: Assessment (yellow)
A4: Assigned an actor [ID]:
A5: correct the unit is this actor.
A6: partial right actor family but too broad or too narrow (another entry fits better), or right for some census contexts only.
A7: wrong another actor, or not an actor at all.
A8: Assigned 'an actor of class X (no inventory entry)':
A9: correct an actor, no inventory entry fits, and class X fits.
A10: partial an actor and class X fits, but an inventory entry fits (missed entry).
A11: wrong the class does not fit, or it is not an actor.
A12: Assigned 'not an actor (dropped)':
... A23: Unit: de Autoriteit Consument en Markt | Assigned: not an actor (dropped) | Assessment: wrong | What is wrong?: actor, not in inventory | Correct actor: Autoriteit Consument en Markt

Sheet Review
A1: # | B1: Norm(s) | C1: Actor phrase | D1: Unit | E1: Assigned | F1: Assigned: definition or source | G1: Assessment | H1: What is wrong? | I1: Correct actor | J1: Note
A2: 1 | B2: 32016R0679:73:2:2 | C2: De ambtstermijn van de voorzitter en de vicevoorzitters | D2: vicevoorzitters | E2: an actor of class 'office' (no inventory entry)
A3: 2 | B3: 32024R1689:92:5:7 | C3: de personen die krachtens de wet of hun statuten gemachtigd zijn om hen te vertegenwoordigen | D3: personen | E3: an actor of class 'person' (no inventory entry)
A4: 3 | B4: 32024R1689:60:4:2 | C4: Aanbieders of potentiële aanbieders | D4: Aanbieders | E4: aanbieder [32024R1689:aanbieder] | F4: Defined in 32024R1689 art. 3: een natuurlijke of rechtspersoon, overheidsinstantie, agentschap of ander orgaan die/dat een AI-systeem of een AI-model voor algemene doeleinden ontwikkelt of laat ontwikkelen en dat systeem of model in de handel brengt of het AI-systeem in gebruik stelt onder de eigen naam of merk, al dan niet tegen betaling
A5: 4 | B5: [1] 32024R1689:36:1:1 [2] 32024R1689:28:1:3 [3] 32024R1689:36:8:27 | C5: [1] De aanmeldende autoriteit [2] een aanmeldende autoriteit [3] de aanmeldende autoriteit | D5: aanmeldende autoriteit | E5: aanmeldende autoriteit [32024R1689:aanmeldende_autoriteit] | F5: Defined in 32024R1689 art. 3: de nationale autoriteit die verantwoordelijk is voor het opzetten en uitvoeren van de noodzakelijke procedures voor de beoordeling, aanwijzing en kennisgeving van de conformiteitsbeoordelingsinstanties en de monitoring hiervan
A6: 5 | B6: 32016R0679:65:6:15 | C6: Het in lid 1 van dit artikel bedoelde besluit | D6: besluit | E6: not an actor (dropped)
A7: 6 | B7: 32024R1689:26:8:16 | C7: Gebruiksverantwoordelijken van AI-systemen met een hoog risico die de hoedanigheid van overheidsinstanties of instellingen, organen of instanties van de Unie hebben | D7: Gebruiksverantwoordelijken van AI-systemen met een hoog risico | E7: gebruiksverantwoordelijke [32024R1689:gebruiksverantwoordelijke] | F7: Defined in 32024R1689 art. 3: een natuurlijke of rechtspersoon, overheidsinstantie, agentschap of ander orgaan die/dat een AI-systeem onder eigen verantwoordelijkheid gebruikt, tenzij het AI-systeem wordt gebruikt in het kader van een persoonlijke niet-beroepsactiviteit
A8: 7 | B8: 32016R0679:83:9:14 | C8: De boeten | D8: boeten | E8: not an actor (dropped)
A9: 8 | B9: 32016R0679:42:7:7 | C9: de in artikel 43 bedoelde certificerende organen of door de bevoegde toezichthoudende autoriteit | D9: bevoegde toezichthoudende autoriteit | E9: toezichthoudende autoriteit [32016R0679:toezichthoudende_autoriteit] | F9: Defined in 32016R0679 art. 4: een door een lidstaat ingevolge artikel 51 ingestelde onafhankelijke overheidsinstantie
A10: 9 | B10: 32024R1689:101:5:9 | C10: Het Hof van Justitie van de Europese Unie | D10: Hof van Justitie van de Europese Unie | E10: Hof van Justitie [KEY:EU:hof_van_justitie] | F10: Known actor (not defined), class institution, valid in eu. Aliases: Hof van Justitie van de Europese Unie.
A11: 10 | B11: 32024R1689:30:2:2 | C11: Aanmeldende autoriteiten | D11: Aanmeldende autoriteiten | E11: aanmeldende autoriteit [32024R1689:aanmeldende_autoriteit] | F11: Defined in 32024R1689 art. 3: de nationale autoriteit die verantwoordelijk is voor het opzetten en uitvoeren van de noodzakelijke procedures voor de beoordeling, aanwijzing en kennisgeving van de conformiteitsbeoordelingsinstanties en de monitoring hiervan
A12: 11 | B12: [1] 32024R1689:56:6:10 [2] 32024R1689:56:6:7 [3] 32024R1689:56:9:20 | C12: [1] Het AI-bureau en de AI-board [2] Het AI-bureau en de AI-board [3] Het AI-bureau | D12: AI-bureau | E12: AI-bureau [32024R1689:aibureau] | F12: Defined in 32024R1689 art. 3: de taak van de Commissie waarbij zij bijdraagt aan de uitvoering van, de monitoring van en het toezicht op AI-systemen en AI-modellen voor algemene doeleinden, en AI-governance, als bepaald in het besluit van de Commissie van 24 januari 2024; verwijzingen in deze verordening naar het AI-bureau worden begrepen als verwijzingen naar de Commissie
A13: 12 | B13: [1] 32024R1689:35:2:2 [2] 32024R1689:52:4:6 [3] 32024R1689:5:6:14 | C13: [1] De Commissie [2] De Commissie [3] de Commissie | D13: Commissie | E13: Commissie [KEY:EU:commissie] | F13: Known actor (not defined), class institution, valid in eu. Aliases: Europese Commissie.
A14: 13 | B14: 32016R0679:65:5:9 | C14: De voorzitter van het Comité | D14: voorzitter van het Comité | E14: voorzitter [KEY:32016R0679:voorzitter] | F14: Known actor (not defined), class office, valid in 32016R0679. Aliases: voorzitter van het Comité. Part of KEY:32016R0679:comite.
A15: 14 | B15: 32016R0679:89:1:1 | C15: Die waarborgen | D15: waarborgen | E15: not an actor (dropped)
A16: 15 | B16: [1] 32024R1689:31:7:7 [2] 32024R1689:31:2:1 [3] 32024R1689:31:6:3 | C16: [1] Aangemelde instanties [2] Aangemelde instanties [3] Aangemelde instanties | D16: Aangemelde instanties | E16: aangemelde instantie [32024R1689:aangemelde_instantie] | F16: Defined in 32024R1689 art. 3: een conformiteitsbeoordelingsinstantie die overeenkomstig deze verordening en andere relevante harmonisatiewetgeving van de Unie, is aangemeld
A17: 16 | B17: 32024R1689:30:1:1 | C17: Aanmeldende autoriteiten | D17: Aanmeldende autoriteiten | E17: aanmeldende autoriteit [32024R1689:aanmeldende_autoriteit] | F17: Defined in 32024R1689 art. 3: de nationale autoriteit die verantwoordelijk is voor het opzetten en uitvoeren van de noodzakelijke procedures voor de beoordeling, aanwijzing en kennisgeving van de conformiteitsbeoordelingsinstanties en de monitoring hiervan
A18: 17 | B18: 32016R0679:74:1:3 | C18: De voorzitter | D18: voorzitter | E18: voorzitter [KEY:32016R0679:voorzitter] | F18: Known actor (not defined), class office, valid in 32016R0679. Aliases: voorzitter van het Comité. Part of KEY:32016R0679:comite.
A19: 18 | B19: 32024R1689:90:3:4 | C19: Gekwalificeerde waarschuwingen | D19: Gekwalificeerde waarschuwingen | E19: not an actor (dropped)
A20: 19 | B20: 32024R1689:57:7:10 | C20: markttoezichtautoriteiten en aangemelde instanties | D20: markttoezichtautoriteiten en aangemelde instanties | E20: aangemelde instantie [32024R1689:aangemelde_instantie] | F20: Defined in 32024R1689 art. 3: een conformiteitsbeoordelingsinstantie die overeenkomstig deze verordening en andere relevante harmonisatiewetgeving van de Unie, is aangemeld
A21: 20 | B21: [1] 32016R0679:39:1:5 [2] 32016R0679:39:1:3 [3] 32016R0679:39:2:9 | C21: [1] de functionaris voor gegevensbescherming [2] de functionaris voor gegevensbescherming [3] De functionaris voor gegevensbescherming | D21: functionaris voor gegevensbescherming | E21: functionaris voor gegevensbescherming [KEY:32016R0679:functionaris_voor_gegevensbescherming] | F21: Known actor (not defined), class office, valid in 32016R0679.
A22: 21 | B22: [1] 32024R1689:59:1:6 [2] 32024R1689:93:1:4 [3] 32024R1689:17:4:6 | C22: [1] aanbieders [2] aanbieders [3] aanbieders die in de hoedanigheid van financiële instellingen onderworpen zijn aan eisen met betrekking tot hun interne governance, regelingen of processen uit hoofde van het desbetreffende Unierecht inzake financiële diensten | D22: aanbieders | E22: aanbieder [32024R1689:aanbieder] | F22: Defined in 32024R1689 art. 3: een natuurlijke of rechtspersoon, overheidsinstantie, agentschap of ander orgaan die/dat een AI-systeem of een AI-model voor algemene doeleinden ontwikkelt of laat ontwikkelen en dat systeem of model in de handel brengt of het AI-systeem in gebruik stelt onder de eigen naam of merk, al dan niet tegen betaling
A23: 22 | B23: 32024R1689:78:2:2 | C23: De autoriteiten die op grond van lid 1 bij de toepassing van deze verordening betrokken zijn | D23: autoriteiten | E23: an actor of class 'authority' (no inventory entry)
A24: 23 | B24: 32024R1689:86:1:1 | C24: Elke getroffen persoon | D24: getroffen persoon | E24: an actor of class 'person' (no inventory entry)
A25: 24 | B25: 32024R1689:11:1:3 | C25: Kmo’s, met inbegrip van start-ups, die ervoor kiezen de in bijlage IV vereiste informatie op vereenvoudigde wijze te verstrekken | D25: Kmo’s | E25: kmo [KEY:32024R1689:kmo] | F25: Known actor (not defined), class party, valid in 32024R1689. Aliases: kmo, met inbegrip van start-ups.
A26: 25 | B26: 32024R1689:95:3:2 | C26: Gedragscodes | D26: Gedragscodes | E26: not an actor (dropped)
A27: 26 | B27: [1] 32016R0679:60:9:21 [2] 32016R0679:60:9:19 [3] 32016R0679:56:6:6 | C27: [1] De leidende toezichthoudende autoriteit [2] De leidende toezichthoudende autoriteit [3] De leidende toezichthoudende autoriteit | D27: leidende toezichthoudende autoriteit | E27: leidende toezichthoudende autoriteit [KEY:32016R0679:leidende_toezichthoudende_autoriteit] | F27: Known actor (not defined), class authority, valid in 32016R0679.
A28: 27 | B28: 32024R1689:28:1:4 | C28: Deze procedures | D28: procedures | E28: not an actor (dropped)
A29: 28 | B29: [1] 32016R0679:50:whole:6 [2] 32016R0679:63:whole:1 [3] 32016R0679:50:whole:2 | C29: [1] de Commissie en de toezichthoudende autoriteiten [2] de toezichthoudende autoriteiten [3] de Commissie en de toezichthoudende autoriteiten | D29: toezichthoudende autoriteiten | E29: toezichthoudende autoriteit [32016R0679:toezichthoudende_autoriteit] | F29: Defined in 32016R0679 art. 4: een door een lidstaat ingevolge artikel 51 ingestelde onafhankelijke overheidsinstantie
A30: 29 | B30: 32024R1689:57:12:26 | C30: andere bevoegde autoriteiten die verantwoordelijk zijn voor ander Unierecht en nationaal recht | D30: bevoegde autoriteiten | E30: an actor of class 'authority' (no inventory entry)
A31: 30 | B31: 32024R1689:37:4:7 | C31: de aanmeldende lidstaat | D31: aanmeldende lidstaat | E31: lidstaat [KEY:EU:lidstaat] | F31: Known actor (not defined), class state, valid in eu.
A32: 31 | B32: [1] 32016R0679:70:1:11 [2] 32016R0679:40:11:18 [3] 32016R0679:72:2:2 | C32: [1] Het Comité [2] Het Comité [3] Het Comité | D32: Comité | E32: Comité [KEY:32016R0679:comite] | F32: Known actor (not defined), class body, valid in 32016R0679. Aliases: Europees Comité voor gegevensbescherming.
A33: 32 | B33: 32024R1689:46:3:5 | C33: de markttoezichtautoriteit | D33: markttoezichtautoriteit | E33: markttoezichtautoriteit [32024R1689:markttoezichtautoriteit] | F33: Defined in 32024R1689 art. 3: de nationale autoriteit die de activiteiten verricht en maatregelen neemt als bedoeld in Verordening (EU) 2019/1020
A34: 33 | B34: 32024R1689:50:2:2 | C34: Aanbieders van AI-systemen, met inbegrip van AI-systemen voor algemene doeleinden | D34: Aanbieders van AI-systemen | E34: aanbieder [32024R1689:aanbieder] | F34: Defined in 32024R1689 art. 3: een natuurlijke of rechtspersoon, overheidsinstantie, agentschap of ander orgaan die/dat een AI-systeem of een AI-model voor algemene doeleinden ontwikkelt of laat ontwikkelen en dat systeem of model in de handel brengt of het AI-systeem in gebruik stelt onder de eigen naam of merk, al dan niet tegen betaling
A35: 34 | B35: 32024R1689:97:3:3 | C35: Het besluit tot intrekking | D35: besluit tot intrekking | E35: not an actor (dropped)
A36: 35 | B36: 32016R0679:75:6:9 | C36: Het secretariaat | D36: secretariaat | E36: secretariaat [KEY:32016R0679:secretariaat] | F36: Known actor (not defined), class office, valid in 32016R0679. Aliases: secretariaat van het Comité. Part of KEY:32016R0679:comite.
A37: 36 | B37: [1] 32016R0679:58:2:13 [2] 32016R0679:56:3:4 [3] 32016R0679:40:6:12 | C37: [1] Elk toezichthoudende autoriteit [2] de toezichthoudende autoriteit [3] de toezichthoudende autoriteit | D37: toezichthoudende autoriteit | E37: toezichthoudende autoriteit [32016R0679:toezichthoudende_autoriteit] | F37: Defined in 32016R0679 art. 4: een door een lidstaat ingevolge artikel 51 ingestelde onafhankelijke overheidsinstantie
A38: 37 | B38: [1] 32016R0679:15:1:2 [2] 32016R0679:17:1:1 [3] 32016R0679:22:1:1 | C38: [1] De betrokkene [2] De betrokkene [3] De betrokkene | D38: betrokkene | E38: de betrokkene [32016R0679:de_betrokkene] | F38: Defined in 32016R0679 art. 4: alle informatie over een geïdentificeerde of identificeerbare natuurlijke persoon
A39: 38 | B39: [1] 32016R0679:37:4:5 [2] 32016R0679:28:4:7 [3] 32016R0679:27:4:4 | C39: [1] de verwerkingsverantwoordelijke of de verwerker of verenigingen en andere organen die categorieën van verwerkingsverantwoordelijken of verwerkers vertegenwoordigen [2] de andere verwerker [3] de verwerkingsverantwoordelijke of de verwerker | D39: verwerker | E39: verwerker [32016R0679:verwerker] | F39: Defined in 32016R0679 art. 4: een natuurlijke persoon of rechtspersoon, een overheidsinstantie, een dienst of een ander orgaan die/dat ten behoeve van de verwerkingsverantwoordelijke persoonsgegevens verwerkt
A40: 39 | B40: 32016R0679:41:1:1 | C40: een orgaan | D40: orgaan | E40: an actor of class 'body' (no inventory entry)
...

Sheet Inventory
A1: id | B1: label | C1: aliases | D1: kind | E1: valid in | F1: class | G1: part of | H1: definition or source
A2: 32024R1689:aanbieder | B2: aanbieder | D2: defined | E2: 32024R1689 | F2: party | H2: een natuurlijke of rechtspersoon, overheidsinstantie, agentschap of ander orgaan die/dat een AI-systeem of een AI-model voor algemene doeleinden ontwikkelt of laat ontwikkelen en dat systeem of model in de handel brengt of het AI-systeem in gebruik stelt onder de eigen naam of merk, al dan niet tegen betaling
A3: 32024R1689:gebruiksverantwoordelijke | B3: gebruiksverantwoordelijke | D3: defined | E3: 32024R1689 | F3: party | H3: een natuurlijke of rechtspersoon, overheidsinstantie, agentschap of ander orgaan die/dat een AI-systeem onder eigen verantwoordelijkheid gebruikt, tenzij het AI-systeem wordt gebruikt in het kader van een persoonlijke niet-beroepsactiviteit
A4: 32024R1689:gemachtigde | B4: gemachtigde | D4: defined | E4: 32024R1689 | F4: party | H4: een natuurlijke of rechtspersoon die zich bevindt of gevestigd is in de Unie die een schriftelijke machtiging heeft gekregen en aanvaard van een aanbieder van een AI-systeem of een AI-model voor algemene doeleinden om namens die aanbieder de verplichtingen en procedures van deze verordening respectievelijk na te komen en uit te voeren
A5: 32024R1689:importeur | B5: importeur | D5: defined | E5: 32024R1689 | F5: party | H5: een natuurlijke of rechtspersoon die zich bevindt of gevestigd is in de Unie die een AI-systeem in de handel brengt dat de naam of het merk van een in een derde land gevestigde natuurlijke of rechtspersoon draagt
A6: 32024R1689:distributeur | B6: distributeur | D6: defined | E6: 32024R1689 | F6: party | H6: een andere natuurlijke persoon of rechtspersoon in de toeleveringsketen dan de aanbieder of de importeur, die een AI-systeem in de Unie op de markt aanbiedt
A7: 32024R1689:operator | B7: operator | D7: defined | E7: 32024R1689 | F7: party | H7: een aanbieder, productfabrikant, gebruiksverantwoordelijke, gemachtigde, importeur of distributeur
A8: 32024R1689:aanmeldende_autoriteit | B8: aanmeldende autoriteit | D8: defined | E8: 32024R1689 | F8: authority | H8: de nationale autoriteit die verantwoordelijk is voor het opzetten en uitvoeren van de noodzakelijke procedures voor de beoordeling, aanwijzing en kennisgeving van de conformiteitsbeoordelingsinstanties en de monitoring hiervan
A9: 32024R1689:conformiteitsbeoordelingsinstantie | B9: conformiteitsbeoordelingsinstantie | D9: defined | E9: 32024R1689 | F9: body | H9: een instantie die als derde partij conformiteits-beoordelingsactiviteiten verricht, zoals onder meer testen, certificeren en inspecteren
A10: 32024R1689:aangemelde_instantie | B10: aangemelde instantie | D10: defined | E10: 32024R1689 | F10: body | H10: een conformiteitsbeoordelingsinstantie die overeenkomstig deze verordening en andere relevante harmonisatiewetgeving van de Unie, is aangemeld
A11: 32024R1689:markttoezichtautoriteit | B11: markttoezichtautoriteit | D11: defined | E11: 32024R1689 | F11: authority | H11: de nationale autoriteit die de activiteiten verricht en maatregelen neemt als bedoeld in Verordening (EU) 2019/1020
A12: 32024R1689:rechtshandhavingsinstantie | B12: rechtshandhavingsinstantie | D12: defined | E12: 32024R1689 | F12: body | H12: a) iedere overheidsinstantie die bevoegd is voor de voorkoming van, het onderzoek naar, de opsporing en de vervolging van strafbare feiten of de uitvoering van straffen, met inbegrip van de bescherming tegen en de voorkoming van gevaren voor de openbare veiligheid, of b) ieder ander orgaan dat of iedere andere entiteit die krachtens het recht van de lidstaten is gemachtigd openbaar gezag en openbare bevoegdheden uit te oefenen met het oog op de voorkoming van, het onderzoek naar, de opsporing en
A13: 32024R1689:aibureau | B13: AI-bureau | D13: defined | E13: 32024R1689 | F13: body | H13: de taak van de Commissie waarbij zij bijdraagt aan de uitvoering van, de monitoring van en het toezicht op AI-systemen en AI-modellen voor algemene doeleinden, en AI-governance, als bepaald in het besluit van de Commissie van 24 januari 2024; verwijzingen in deze verordening naar het AI-bureau worden begrepen als verwijzingen naar de Commissie
... A66: 32022L2555:onderzoeksorganisatie | B66: onderzoeksorganisatie | D66: defined | E66: 32022L2555 | F66: party | H66: een entiteit die als hoofddoel heeft het verrichten van toegepast onderzoek of experimentele ontwikkeling met het oog op de exploitatie van de resultaten van dat onderzoek voor commerciële doeleinden, met uitsluiting van onderwijsinstellingen.
A67: KEY:EU:commissie | B67: Commissie | C67: Europese Commissie | D67: key | E67: eu | F67: institution | H67: curated
A68: KEY:EU:lidstaat | B68: lidstaat | D68: key | E68: eu | F68: state | H68: curated
A69: KEY:EU:europees_parlement | B69: Europees Parlement | D69: key | E69: eu | F69: institution | H69: curated
A70: KEY:EU:raad | B70: Raad | C70: Raad van de Europese Unie | D70: key | E70: eu | F70: institution | H70: curated
A71: KEY:EU:hof_van_justitie | B71: Hof van Justitie | C71: Hof van Justitie van de Europese Unie | D71: key | E71: eu | F71: institution | H71: curated
A72: KEY:EU:europese_toezichthouder_voor_gegevensbescherming | B72: Europese Toezichthouder voor gegevensbescherming | D72: key | E72: eu | F72: authority | H72: curated
A73: KEY:EU:gerecht | B73: gerecht | C73: bevoegd gerecht; nationaal gerecht | D73: key | E73: eu | F73: institution | H73: curated
A74: KEY:EU:overheidsinstantie | B74: overheidsinstantie | D74: key | E74: eu | F74: authority | H74: curated
A75: KEY:EU:nationale_accreditatieinstantie | B75: nationale accreditatie-instantie | C75: accreditatie-instantie | D75: key | E75: eu | F75: body | H75: curated
A76: KEY:32016R0679:comite | B76: Comité | C76: Europees Comité voor gegevensbescherming | D76: key | E76: 32016R0679 | F76: body | H76: curated
A77: KEY:32016R0679:voorzitter | B77: voorzitter | C77: voorzitter van het Comité | D77: key | E77: 32016R0679 | F77: office | G77: KEY:32016R0679:comite | H77: curated
A78: KEY:32016R0679:secretariaat | B78: secretariaat | C78: secretariaat van het Comité | D78: key | E78: 32016R0679 | F78: office | G78: KEY:32016R0679:comite | H78: curated
A79: KEY:32016R0679:leidende_toezichthoudende_autoriteit | B79: leidende toezichthoudende autoriteit | D79: key | E79: 32016R0679 | F79: authority | H79: curated
A80: KEY:32016R0679:functionaris_voor_gegevensbescherming | B80: functionaris voor gegevensbescherming | D80: key | E80: 32016R0679 | F80: office | H80: curated
A81: KEY:32016R0679:certificeringsorgaan | B81: certificeringsorgaan | D81: key | E81: 32016R0679 | F81: body | H81: curated
A82: KEY:32016R0679:vereniging | B82: vereniging | C82: verenigingen en andere organen die categorieën van verwerkingsverantwoordelijken of verwerkers vertegenwoordigen | D82: key | E82: 32016R0679 | F82: party | H82: curated
A83: KEY:32024R1689:aiboard | B83: AI-board | C83: Europese raad voor artificiële intelligentie | D83: key | E83: 32024R1689 | F83: body | H83: curated
A84: KEY:32024R1689:adviesforum | B84: adviesforum | D84: key | E84: 32024R1689 | F84: body | H84: curated
A85: KEY:32024R1689:wetenschappelijk_panel | B85: wetenschappelijk panel | C85: wetenschappelijk panel van onafhankelijke deskundigen | D85: key | E85: 32024R1689 | F85: body | H85: curated
A86: KEY:32024R1689:productfabrikant | B86: productfabrikant | D86: key | E86: 32024R1689 | F86: party | H86: curated
A87: KEY:32024R1689:permanente_subgroep_voor_markttoezicht | B87: permanente subgroep voor markttoezicht | C87: subgroep | D87: key | E87: 32024R1689 | F87: body | G87: KEY:32024R1689:aiboard | H87: curated
A88: KEY:32024R1689:gegevensbeschermingsautoriteit | B88: gegevensbeschermingsautoriteit | C88: nationale gegevensbeschermingsautoriteit | D88: key | E88: 32024R1689 | F88: authority | H88: curated
A89: KEY:32024R1689:civielebeschermingsautoriteit | B89: civielebeschermingsautoriteit | D89: key | E89: 32024R1689 | F89: authority | H89: curated
A90: KEY:32024R1689:kmo | B90: kmo | C90: kmo, met inbegrip van start-ups | D90: key | E90: 32024R1689 | F90: party | H90: curated

Sheet key
A1: # | B1: stratum | C1: kind | D1: source | E1: level | F1: unit | G1: result | H1: actor_id | I1: fallback_class | J1: role_keys | K1: occ_EU | L1: occ_NL | M1: group_occ | N1: norm_ids
A2: 1 | B2: EU | fallback | C2: sample | D2: EU | E2: fallback | F2: vicevoorzitters | G2: class:office | I2: office | J2: vicevoorzitter | K2: 0 | L2: 0 | M2: 2 | N2: 32016R0679:73:2:2
A3: 2 | B3: EU | fallback | C3: sample | D3: EU | E3: fallback | F3: personen | G3: class:person | I3: person | J3: person | K3: 0 | L3: 0 | M3: 1 | N3: 32024R1689:92:5:7
A4: 3 | B4: EU | exact | C4: sample | D4: EU | E4: exact | F4: Aanbieders | G4: 32024R1689:aanbieder | H4: 32024R1689:aanbieder | J4: aanbieder | K4: 0 | L4: 0 | M4: 12 | N4: 32024R1689:60:4:2
A5: 4 | B5: census | C5: census | D5: EU | E5: exact | F5: aanmeldende autoriteit | G5: 32024R1689:aanmeldende_autoriteit | H5: 32024R1689:aanmeldende_autoriteit | J5: aanmeld autoriteit / autoriteit | K5: 23 | L5: 0 | M5: 23 | N5: 32024R1689:36:1:1, 32024R1689:28:1:3, 32024R1689:36:8:27
A6: 5 | B6: EU | not_actor | C6: sample | D6: EU | E6: not_actor | F6: besluit | G6: not_actor | J6: besluit | K6: 0 | L6: 0 | M6: 2 | N6: 32016R0679:65:6:15
A7: 6 | B7: EU | shortened | C7: sample | D7: EU | E7: shortened | F7: Gebruiksverantwoordelijken van AI-systemen met een hoog risico | G7: 32024R1689:gebruiksverantwoordelijke | H7: 32024R1689:gebruiksverantwoordelijke | J7: gebruiksverantwoord aisystem hog risico / gebruiksverantwoord aisystem hog / gebruiksverantwoord aisystem / gebruiksverantwoord | K7: 0 | L7: 0 | M7: 3 | N7: 32024R1689:26:8:16
A8: 7 | B8: EU | not_actor | C8: sample | D8: EU | E8: not_actor | F8: boeten | G8: not_actor | J8: boet | K8: 0 | L8: 0 | M8: 1 | N8: 32016R0679:83:9:14
A9: 8 | B9: EU | shortened | C9: sample | D9: EU | E9: shortened | F9: bevoegde toezichthoudende autoriteit | G9: 32016R0679:toezichthoudende_autoriteit | H9: 32016R0679:toezichthoudende_autoriteit | J9: bevoegd toezichthoud autoriteit / toezichthoud autoriteit / autoriteit | K9: 0 | L9: 0 | M9: 10 | N9: 32016R0679:42:7:7
A10: 9 | B10: EU | exact | C10: sample | D10: EU | E10: exact | F10: Hof van Justitie van de Europese Unie | G10: KEY:EU:hof_van_justitie | H10: KEY:EU:hof_van_justitie | J10: hof justitie europes unie / hof justitie europes / hof justitie / hof | K10: 0 | L10: 0 | M10: 3 | N10: 32024R1689:101:5:9
A11: 10 | B11: EU | exact | C11: sample | D11: EU | E11: exact | F11: Aanmeldende autoriteiten | G11: 32024R1689:aanmeldende_autoriteit | H11: 32024R1689:aanmeldende_autoriteit | J11: aanmeld autoriteit / autoriteit | K11: 0 | L11: 0 | M11: 9 | N11: 32024R1689:30:2:2
A12: 11 | B12: census | C12: census | D12: EU | E12: exact | F12: AI-bureau | G12: 32024R1689:aibureau | H12: 32024R1689:aibureau | J12: aibureau | K12: 37 | L12: 0 | M12: 37 | N12: 32024R1689:56:6:10, 32024R1689:56:6:7, 32024R1689:56:9:20
A13: 12 | B13: census | C13: census | D13: EU | E13: exact | F13: Commissie | G13: KEY:EU:commissie | H13: KEY:EU:commissie | J13: commissie | K13: 160 | L13: 0 | M13: 160 | N13: 32024R1689:35:2:2, 32024R1689:52:4:6, 32024R1689:5:6:14
A14: 13 | B14: EU | exact | C14: sample | D14: EU | E14: exact | F14: voorzitter van het Comité | G14: KEY:32016R0679:voorzitter | H14: KEY:32016R0679:voorzitter | J14: voorzitter comit / voorzitter | K14: 0 | L14: 0 | M14: 6 | N14: 32016R0679:65:5:9
A15: 14 | B15: EU | not_actor | C15: sample | D15: EU | E15: not_actor | F15: waarborgen | G15: not_actor | J15: waarborg | K15: 0 | L15: 0 | M15: 1 | N15: 32016R0679:89:1:1
A16: 15 | B16: census | C16: census | D16: EU | E16: exact | F16: Aangemelde instanties | G16: 32024R1689:aangemelde_instantie | H16: 32024R1689:aangemelde_instantie | J16: aangemeld instantie / instantie | K16: 24 | L16: 0 | M16: 24 | N16: 32024R1689:31:7:7, 32024R1689:31:2:1, 32024R1689:31:6:3
A17: 16 | B17: EU | exact | C17: sample | D17: EU | E17: exact | F17: Aanmeldende autoriteiten | G17: 32024R1689:aanmeldende_autoriteit | H17: 32024R1689:aanmeldende_autoriteit | J17: aanmeld autoriteit / autoriteit | K17: 0 | L17: 0 | M17: 9 | N17: 32024R1689:30:1:1
A18: 17 | B18: EU | exact | C18: sample | D18: EU | E18: exact | F18: voorzitter | G18: KEY:32016R0679:voorzitter | H18: KEY:32016R0679:voorzitter | J18: voorzitter | K18: 0 | L18: 0 | M18: 6 | N18: 32016R0679:74:1:3
A19: 18 | B19: EU | not_actor | C19: sample | D19: EU | E19: not_actor | F19: Gekwalificeerde waarschuwingen | G19: not_actor | J19: gekwalificeerd waarschuw / waarschuw | K19: 0 | L19: 0 | M19: 2 | N19: 32024R1689:90:3:4
A20: 19 | B20: EU | shortened | C20: sample | D20: EU | E20: shortened | F20: markttoezichtautoriteiten en aangemelde instanties | G20: 32024R1689:aangemelde_instantie | H20: 32024R1689:aangemelde_instantie | J20: markttoezichtautoriteit aangemeld instantie / aangemeld instantie / instantie | K20: 0 | L20: 0 | M20: 1 | N20: 32024R1689:57:7:10
A21: 20 | B21: census | C21: census | D21: EU | E21: exact | F21: functionaris voor gegevensbescherming | G21: KEY:32016R0679:functionaris_voor_gegevensbescherming | H21: KEY:32016R0679:functionaris_voor_gegevensbescherming | J21: functionari gegevensbescherm / functionari | K21: 15 | L21: 0 | M21: 15 | N21: 32016R0679:39:1:5, 32016R0679:39:1:3, 32016R0679:39:2:9
A22: 21 | B22: census | C22: census | D22: EU | E22: exact | F22: aanbieders | G22: 32024R1689:aanbieder | H22: 32024R1689:aanbieder | J22: aanbieder | K22: 17 | L22: 0 | M22: 17 | N22: 32024R1689:59:1:6, 32024R1689:93:1:4, 32024R1689:17:4:6
A23: 22 | B23: EU | fallback | C23: sample | D23: EU | E23: fallback | F23: autoriteiten | G23: class:authority | I23: authority | J23: autoriteit | K23: 0 | L23: 0 | M23: 3 | N23: 32024R1689:78:2:2
A24: 23 | B24: EU | fallback | C24: sample | D24: EU | E24: fallback | F24: getroffen persoon | G24: class:person | I24: person | J24: getroff person / person | K24: 0 | L24: 0 | M24: 1 | N24: 32024R1689:86:1:1
A25: 24 | B25: EU | exact | C25: sample | D25: EU | E25: exact | F25: Kmo’s | G25: KEY:32024R1689:kmo | H25: KEY:32024R1689:kmo | J25: kmo | K25: 0 | L25: 0 | M25: 2 | N25: 32024R1689:11:1:3
A26: 25 | B26: EU | not_actor | C26: sample | D26: EU | E26: not_actor | F26: Gedragscodes | G26: not_actor | J26: gedragscod | K26: 0 | L26: 0 | M26: 1 | N26: 32024R1689:95:3:2
A27: 26 | B27: census | C27: census | D27: EU | E27: exact | F27: leidende toezichthoudende autoriteit | G27: KEY:32016R0679:leidende_toezichthoudende_autoriteit | H27: KEY:32016R0679:leidende_toezichthoudende_autoriteit | J27: leidend toezichthoud autoriteit / toezichthoud autoriteit / autoriteit | K27: 19 | L27: 0 | M27: 19 | N27: 32016R0679:60:9:21, 32016R0679:60:9:19, 32016R0679:56:6:6
A28: 27 | B28: EU | not_actor | C28: sample | D28: EU | E28: not_actor | F28: procedures | G28: not_actor | J28: procedur | K28: 0 | L28: 0 | M28: 1 | N28: 32024R1689:28:1:4
A29: 28 | B29: census | C29: census | D29: EU | E29: exact | F29: toezichthoudende autoriteiten | G29: 32016R0679:toezichthoudende_autoriteit | H29: 32016R0679:toezichthoudende_autoriteit | J29: toezichthoud autoriteit / autoriteit | K29: 16 | L29: 0 | M29: 16 | N29: 32016R0679:50:whole:6, 32016R0679:63:whole:1, 32016R0679:50:whole:2
A30: 29 | B30: EU | fallback | C30: sample | D30: EU | E30: fallback | F30: bevoegde autoriteiten | G30: class:authority | I30: authority | J30: bevoegd autoriteit / autoriteit | K30: 0 | L30: 0 | M30: 3 | N30: 32024R1689:57:12:26
A31: 30 | B31: EU | shortened | C31: sample | D31: EU | E31: shortened | F31: aanmeldende lidstaat | G31: KEY:EU:lidstaat | H31: KEY:EU:lidstaat | J31: aanmeld lidstat / lidstat | K31: 0 | L31: 0 | M31: 3 | N31: 32024R1689:37:4:7
A32: 31 | B32: census | C32: census | D32: EU | E32: exact | F32: Comité | G32: KEY:32016R0679:comite | H32: KEY:32016R0679:comite | J32: comit | K32: 50 | L32: 0 | M32: 50 | N32: 32016R0679:70:1:11, 32016R0679:40:11:18, 32016R0679:72:2:2
A33: 32 | B33: EU | exact | C33: sample | D33: EU | E33: exact | F33: markttoezichtautoriteit | G33: 32024R1689:markttoezichtautoriteit | H33: 32024R1689:markttoezichtautoriteit | J33: markttoezichtautoriteit | K33: 0 | L33: 0 | M33: 15 | N33: 32024R1689:46:3:5
A34: 33 | B34: EU | shortened | C34: sample | D34: EU | E34: shortened | F34: Aanbieders van AI-systemen | G34: 32024R1689:aanbieder | H34: 32024R1689:aanbieder | J34: aanbieder aisystem / aanbieder | K34: 0 | L34: 0 | M34: 3 | N34: 32024R1689:50:2:2
A35: 34 | B35: EU | not_actor | C35: sample | D35: EU | E35: not_actor | F35: besluit tot intrekking | G35: not_actor | J35: besluit intrek / besluit | K35: 0 | L35: 0 | M35: 2 | N35: 32024R1689:97:3:3
A36: 35 | B36: EU | exact | C36: sample | D36: EU | E36: exact | F36: secretariaat | G36: KEY:32016R0679:secretariaat | H36: KEY:32016R0679:secretariaat | J36: secretariaat | K36: 0 | L36: 0 | M36: 9 | N36: 32016R0679:75:6:9
A37: 36 | B37: census | C37: census | D37: EU | E37: exact | F37: toezichthoudende autoriteit | G37: 32016R0679:toezichthoudende_autoriteit | H37: 32016R0679:toezichthoudende_autoriteit | J37: toezichthoud autoriteit / autoriteit | K37: 80 | L37: 0 | M37: 80 | N37: 32016R0679:58:2:13, 32016R0679:56:3:4, 32016R0679:40:6:12
A38: 37 | B38: census | C38: census | D38: EU | E38: exact | F38: betrokkene | G38: 32016R0679:de_betrokkene | H38: 32016R0679:de_betrokkene | J38: betrok | K38: 26 | L38: 0 | M38: 26 | N38: 32016R0679:15:1:2, 32016R0679:17:1:1, 32016R0679:22:1:1
A39: 38 | B39: census | C39: census | D39: EU | E39: exact | F39: verwerker | G39: 32016R0679:verwerker | H39: 32016R0679:verwerker | J39: verwerker | K39: 36 | L39: 0 | M39: 36 | N39: 32016R0679:37:4:5, 32016R0679:28:4:7, 32016R0679:27:4:4
A40: 39 | B40: EU | fallback | C40: sample | D40: EU | E40: fallback | F40: orgaan | G40: class:body | I40: body | J40: organ | K40: 0 | L40: 0 | M40: 5 | N40: 32016R0679:41:1:1
...

Sheet weights
A1: stratum | B1: source | C1: level | D1: N_h
A2: EU | exact | B2: EU | C2: exact | D2: 191
A3: EU | shortened | B3: EU | C3: shortened | D3: 106
A4: EU | fallback | B4: EU | C4: fallback | D4: 82
A5: EU | not_actor | B5: EU | C5: not_actor | D5: 142
A6: NL | exact | B6: NL | C6: exact | D6: 0
A7: NL | shortened | B7: NL | C7: shortened | D7: 0
A8: NL | fallback | B8: NL | C8: fallback | D8: 0
A9: NL | not_actor | B9: NL | C9: not_actor | D9: 0

Sheet Design
A1: Sample design
A2: What is validated. Each actor unit of a norm is mapped to an inventory actor (exact or shortened match), to the broad class of its head word (fallback) or to nothing (not an actor, dropped). Each result is a claim the labeller checks from the norm text: is this the actor, is it an actor of this class without an entry, is it really not an actor? Population. The sampling unit is an actor unit as it occurs in a norm, so a unit used in many norms counts as often as it is used downstream, and each is judged in its own norm. 1,290 unit occurrences: EU 1,290, Dutch 0. Norms with status pronoun, missing or no_units have no unit and make no mapping claim; they are exact counts (table below). The source is taken from the document id: BWBR ids are Dutch, all others EU. Census. The result of a unit is the same wherever it gets the same ID, class or 'not an actor', so one judgement settles all those occurrences. The 20 most frequent (unit, result) groups are judged in full, each once, against up to 3 contexts taken in turn from both sources. They are the top of the frequency ranking, ties broken alphabetically, fixed before any judging. A census group that fits some uses but not others is labelled partial. The coverage curve below shows where a further group would cover little more than one sampled unit. Strata. Outside the census, units are stratified by source, so the EU-Dutch comparison gets the same number of judgements on each side, and by match level, because each level makes a different claim and can fail at its own rate. Each source gets 50 judgements: a floor of 8 per stratum, the rest in proportion to N_h. A norm gives at most 1 sampled unit. Precision. In the worst case (50% in every stratum) each source's precision is known to about +/-5 points (EU) and +/-nan (Dutch), at 80% to +/-4 and +/-nan; the EU-Dutch difference to about +/-nan points. The census adds no sampling error. Overall figures weight each stratum by N_h and each census group by its occurrences, never by row count. Blind. The labeller sees the norm, the unit and what it was mapped to, but not the match level or the role keys; those are in the hidden key sheet, and the rows are shuffled. A fallback or 'not an actor' result is visible as such, since it is the claim being judged. Consistency. Every distinct unit was mapped again with the current inventory; 3 of 304 differed. Adding actors to the inventory changes the strata, so the sample is drawn after the inventory is updated.
A4: stratum | B4: source | C4: level | D4: population N_h | E4: share of source | F4: n sampled | G4: why this stratum and this n
A5: EU | exact | B5: EU | C5: exact | D5: 191 | E5: =IFERROR(D5/SUMIFS($D$5:$D$12,$B$5:$B$12,B5),0) | F5: 15 | G5: The full role key equals an inventory label or alias: the safest route. Checks the inventory entries of the common actors.
A6: EU | shortened | B6: EU | C6: shortened | D6: 106 | E6: =IFERROR(D6/SUMIFS($D$5:$D$12,$B$5:$B$12,B6),0) | F6: 11 | G6: Words were dropped until a key matched: the riskiest route to an ID (an entry too broad, or the wrong one).
A7: EU | fallback | B7: EU | C7: fallback | D7: 82 | E7: =IFERROR(D7/SUMIFS($D$5:$D$12,$B$5:$B$12,B7),0) | F7: 11 | G7: No entry matched; only the head word's class. Is it an actor, is the class right, and was an inventory entry missed?
A8: EU | not_actor | B8: EU | C8: not_actor | D8: 142 | E8: =IFERROR(D8/SUMIFS($D$5:$D$12,$B$5:$B$12,B8),0) | F8: 13 | G8: Dropped as not an actor. Its errors are actors lost to the whole actor filter (recall of the mapping).
A9: NL | exact | B9: NL | C9: exact | D9: 0 | E9: =IFERROR(D9/SUMIFS($D$5:$D$12,$B$5:$B$12,B9),0) | F9: 0 | G9: The full role key equals an inventory label or alias: the safest route. Checks the inventory entries of the common actors.
A10: NL | shortened | B10: NL | C10: shortened | D10: 0 | E10: =IFERROR(D10/SUMIFS($D$5:$D$12,$B$5:$B$12,B10),0) | F10: 0 | G10: Words were dropped until a key matched: the riskiest route to an ID (an entry too broad, or the wrong one).
A11: NL | fallback | B11: NL | C11: fallback | D11: 0 | E11: =IFERROR(D11/SUMIFS($D$5:$D$12,$B$5:$B$12,B11),0) | F11: 0 | G11: No entry matched; only the head word's class. Is it an actor, is the class right, and was an inventory entry missed?
A12: NL | not_actor | B12: NL | C12: not_actor | D12: 0 | E12: =IFERROR(D12/SUMIFS($D$5:$D$12,$B$5:$B$12,B12),0) | F12: 0 | G12: Dropped as not an actor. Its errors are actors lost to the whole actor filter (recall of the mapping).
A13: total outside the census | D13: =SUM(D5:D12) | F13: =SUM(F5:F12)
A15: Census: the 20 most frequent (unit, result) groups, judged once each
A16: # | B16: unit | C16: assigned | D16: level | E16: EU | F16: NL
A17: 1 | B17: Commissie | C17: KEY:EU:commissie | D17: exact | E17: 160 | F17: 0
A18: 2 | B18: verwerkingsverantwoordelijke | C18: 32016R0679:verwerkingsverantwoordelijke | D18: exact | E18: 99 | F18: 0
A19: 3 | B19: toezichthoudende autoriteit | C19: 32016R0679:toezichthoudende_autoriteit | D19: exact | E19: 80 | F19: 0
A20: 4 | B20: Comité | C20: KEY:32016R0679:comite | D20: exact | E20: 50 | F20: 0
A21: 5 | B21: lidstaten | C21: KEY:EU:lidstaat | D21: exact | E21: 45 | F21: 0
A22: 6 | B22: AI-bureau | C22: 32024R1689:aibureau | D22: exact | E22: 37 | F22: 0
A23: 7 | B23: lidstaat | C23: KEY:EU:lidstaat | D23: exact | E23: 37 | F23: 0
A24: 8 | B24: verwerker | C24: 32016R0679:verwerker | D24: exact | E24: 36 | F24: 0
A25: 9 | B25: betrokkene | C25: 32016R0679:de_betrokkene | D25: exact | E25: 26 | F25: 0
A26: 10 | B26: Aangemelde instanties | C26: 32024R1689:aangemelde_instantie | D26: exact | E26: 24 | F26: 0
A27: 11 | B27: aanmeldende autoriteit | C27: 32024R1689:aanmeldende_autoriteit | D27: exact | E27: 23 | F27: 0
A28: 12 | B28: aanbieder | C28: 32024R1689:aanbieder | D28: exact | E28: 21 | F28: 0
... A36: 20 | B36: gebruiksverantwoordelijke | C36: 32024R1689:gebruiksverantwoordelijke | D36: exact | E36: 15 | F36: 0
A37: total | E37: =SUM(E17:E36) | F37: =SUM(F17:F36)
A39: Coverage: share of unit occurrences covered by the most frequent groups
A40: census size | B40: EU | C40: NL
A41: 5 | B41: 0.33643411 | C41: 0
A42: 10 | B42: 0.46046512 | C42: 0
A43: 20 | B43: 0.59612403 | C43: 0
A44: 30 | B44: 0.67364341 | C44: 0
A45: 50 | B45: 0.7496124 | C45: 0
A46: 100 | B46: 0.83953488 | C46: 0
A48: Exact counts (not sampled)
B49: EU | C49: NL | D49: total
A50: norms
A51: ... status fallback | B51: 54 | C51: 0 | D51: =B51+C51
...

Sheet Summary
A1: stratum | B1: rows | C1: judged | D1: correct | E1: partial | F1: wrong | G1: unclear | H1: strict | I1: lenient | J1: strict 95% low | K1: strict 95% high | M1: z
A2: EU | exact | B2: =COUNTIFS(key!$B$2:$B$71,A2) | C2: =COUNTIFS(key!$B$2:$B$71,A2,Review!$G$2:$G$71,"<>") | D2: =COUNTIFS(key!$B$2:$B$71,A2,Review!$G$2:$G$71,"correct") | E2: =COUNTIFS(key!$B$2:$B$71,A2,Review!$G$2:$G$71,"partial") | F2: =COUNTIFS(key!$B$2:$B$71,A2,Review!$G$2:$G$71,"wrong") | G2: =COUNTIFS(key!$B$2:$B$71,A2,Review!$G$2:$G$71,"unclear") | H2: =IFERROR(D2/(C2-G2),"") | I2: =IFERROR((D2+E2)/(C2-G2),"") | J2: =IFERROR(MAX(0,(H2+$M$2^2/(2*(C2-G2)))/(1+$M$2^2/(C2-G2))-$M$2*SQRT(H2*(1-H2)/(C2-G2)+$M$2^2/(4*(C2-G2)^2))/(1+$M$2^2/(C2-G2))),"") | K2: =IFERROR(MIN(1,(H2+$M$2^2/(2*(C2-G2)))/(1+$M$2^2/(C2-G2))+$M$2*SQRT(H2*(1-H2)/(C2-G2)+$M$2^2/(4*(C2-G2)^2))/(1+$M$2^2/(C2-G2))),"") | M2: 1.96
A3: EU | shortened | B3: =COUNTIFS(key!$B$2:$B$71,A3) | C3: =COUNTIFS(key!$B$2:$B$71,A3,Review!$G$2:$G$71,"<>") | D3: =COUNTIFS(key!$B$2:$B$71,A3,Review!$G$2:$G$71,"correct") | E3: =COUNTIFS(key!$B$2:$B$71,A3,Review!$G$2:$G$71,"partial") | F3: =COUNTIFS(key!$B$2:$B$71,A3,Review!$G$2:$G$71,"wrong") | G3: =COUNTIFS(key!$B$2:$B$71,A3,Review!$G$2:$G$71,"unclear") | H3: =IFERROR(D3/(C3-G3),"") | I3: =IFERROR((D3+E3)/(C3-G3),"") | J3: =IFERROR(MAX(0,(H3+$M$2^2/(2*(C3-G3)))/(1+$M$2^2/(C3-G3))-$M$2*SQRT(H3*(1-H3)/(C3-G3)+$M$2^2/(4*(C3-G3)^2))/(1+$M$2^2/(C3-G3))),"") | K3: =IFERROR(MIN(1,(H3+$M$2^2/(2*(C3-G3)))/(1+$M$2^2/(C3-G3))+$M$2*SQRT(H3*(1-H3)/(C3-G3)+$M$2^2/(4*(C3-G3)^2))/(1+$M$2^2/(C3-G3))),"")
A4: EU | fallback | B4: =COUNTIFS(key!$B$2:$B$71,A4) | C4: =COUNTIFS(key!$B$2:$B$71,A4,Review!$G$2:$G$71,"<>") | D4: =COUNTIFS(key!$B$2:$B$71,A4,Review!$G$2:$G$71,"correct") | E4: =COUNTIFS(key!$B$2:$B$71,A4,Review!$G$2:$G$71,"partial") | F4: =COUNTIFS(key!$B$2:$B$71,A4,Review!$G$2:$G$71,"wrong") | G4: =COUNTIFS(key!$B$2:$B$71,A4,Review!$G$2:$G$71,"unclear") | H4: =IFERROR(D4/(C4-G4),"") | I4: =IFERROR((D4+E4)/(C4-G4),"") | J4: =IFERROR(MAX(0,(H4+$M$2^2/(2*(C4-G4)))/(1+$M$2^2/(C4-G4))-$M$2*SQRT(H4*(1-H4)/(C4-G4)+$M$2^2/(4*(C4-G4)^2))/(1+$M$2^2/(C4-G4))),"") | K4: =IFERROR(MIN(1,(H4+$M$2^2/(2*(C4-G4)))/(1+$M$2^2/(C4-G4))+$M$2*SQRT(H4*(1-H4)/(C4-G4)+$M$2^2/(4*(C4-G4)^2))/(1+$M$2^2/(C4-G4))),"")
A5: EU | not_actor | B5: =COUNTIFS(key!$B$2:$B$71,A5) | C5: =COUNTIFS(key!$B$2:$B$71,A5,Review!$G$2:$G$71,"<>") | D5: =COUNTIFS(key!$B$2:$B$71,A5,Review!$G$2:$G$71,"correct") | E5: =COUNTIFS(key!$B$2:$B$71,A5,Review!$G$2:$G$71,"partial") | F5: =COUNTIFS(key!$B$2:$B$71,A5,Review!$G$2:$G$71,"wrong") | G5: =COUNTIFS(key!$B$2:$B$71,A5,Review!$G$2:$G$71,"unclear") | H5: =IFERROR(D5/(C5-G5),"") | I5: =IFERROR((D5+E5)/(C5-G5),"") | J5: =IFERROR(MAX(0,(H5+$M$2^2/(2*(C5-G5)))/(1+$M$2^2/(C5-G5))-$M$2*SQRT(H5*(1-H5)/(C5-G5)+$M$2^2/(4*(C5-G5)^2))/(1+$M$2^2/(C5-G5))),"") | K5: =IFERROR(MIN(1,(H5+$M$2^2/(2*(C5-G5)))/(1+$M$2^2/(C5-G5))+$M$2*SQRT(H5*(1-H5)/(C5-G5)+$M$2^2/(4*(C5-G5)^2))/(1+$M$2^2/(C5-G5))),"")
A6: NL | exact | B6: =COUNTIFS(key!$B$2:$B$71,A6) | C6: =COUNTIFS(key!$B$2:$B$71,A6,Review!$G$2:$G$71,"<>") | D6: =COUNTIFS(key!$B$2:$B$71,A6,Review!$G$2:$G$71,"correct") | E6: =COUNTIFS(key!$B$2:$B$71,A6,Review!$G$2:$G$71,"partial") | F6: =COUNTIFS(key!$B$2:$B$71,A6,Review!$G$2:$G$71,"wrong") | G6: =COUNTIFS(key!$B$2:$B$71,A6,Review!$G$2:$G$71,"unclear") | H6: =IFERROR(D6/(C6-G6),"") | I6: =IFERROR((D6+E6)/(C6-G6),"") | J6: =IFERROR(MAX(0,(H6+$M$2^2/(2*(C6-G6)))/(1+$M$2^2/(C6-G6))-$M$2*SQRT(H6*(1-H6)/(C6-G6)+$M$2^2/(4*(C6-G6)^2))/(1+$M$2^2/(C6-G6))),"") | K6: =IFERROR(MIN(1,(H6+$M$2^2/(2*(C6-G6)))/(1+$M$2^2/(C6-G6))+$M$2*SQRT(H6*(1-H6)/(C6-G6)+$M$2^2/(4*(C6-G6)^2))/(1+$M$2^2/(C6-G6))),"")
A7: NL | shortened | B7: =COUNTIFS(key!$B$2:$B$71,A7) | C7: =COUNTIFS(key!$B$2:$B$71,A7,Review!$G$2:$G$71,"<>") | D7: =COUNTIFS(key!$B$2:$B$71,A7,Review!$G$2:$G$71,"correct") | E7: =COUNTIFS(key!$B$2:$B$71,A7,Review!$G$2:$G$71,"partial") | F7: =COUNTIFS(key!$B$2:$B$71,A7,Review!$G$2:$G$71,"wrong") | G7: =COUNTIFS(key!$B$2:$B$71,A7,Review!$G$2:$G$71,"unclear") | H7: =IFERROR(D7/(C7-G7),"") | I7: =IFERROR((D7+E7)/(C7-G7),"") | J7: =IFERROR(MAX(0,(H7+$M$2^2/(2*(C7-G7)))/(1+$M$2^2/(C7-G7))-$M$2*SQRT(H7*(1-H7)/(C7-G7)+$M$2^2/(4*(C7-G7)^2))/(1+$M$2^2/(C7-G7))),"") | K7: =IFERROR(MIN(1,(H7+$M$2^2/(2*(C7-G7)))/(1+$M$2^2/(C7-G7))+$M$2*SQRT(H7*(1-H7)/(C7-G7)+$M$2^2/(4*(C7-G7)^2))/(1+$M$2^2/(C7-G7))),"")
A8: NL | fallback | B8: =COUNTIFS(key!$B$2:$B$71,A8) | C8: =COUNTIFS(key!$B$2:$B$71,A8,Review!$G$2:$G$71,"<>") | D8: =COUNTIFS(key!$B$2:$B$71,A8,Review!$G$2:$G$71,"correct") | E8: =COUNTIFS(key!$B$2:$B$71,A8,Review!$G$2:$G$71,"partial") | F8: =COUNTIFS(key!$B$2:$B$71,A8,Review!$G$2:$G$71,"wrong") | G8: =COUNTIFS(key!$B$2:$B$71,A8,Review!$G$2:$G$71,"unclear") | H8: =IFERROR(D8/(C8-G8),"") | I8: =IFERROR((D8+E8)/(C8-G8),"") | J8: =IFERROR(MAX(0,(H8+$M$2^2/(2*(C8-G8)))/(1+$M$2^2/(C8-G8))-$M$2*SQRT(H8*(1-H8)/(C8-G8)+$M$2^2/(4*(C8-G8)^2))/(1+$M$2^2/(C8-G8))),"") | K8: =IFERROR(MIN(1,(H8+$M$2^2/(2*(C8-G8)))/(1+$M$2^2/(C8-G8))+$M$2*SQRT(H8*(1-H8)/(C8-G8)+$M$2^2/(4*(C8-G8)^2))/(1+$M$2^2/(C8-G8))),"")
A9: NL | not_actor | B9: =COUNTIFS(key!$B$2:$B$71,A9) | C9: =COUNTIFS(key!$B$2:$B$71,A9,Review!$G$2:$G$71,"<>") | D9: =COUNTIFS(key!$B$2:$B$71,A9,Review!$G$2:$G$71,"correct") | E9: =COUNTIFS(key!$B$2:$B$71,A9,Review!$G$2:$G$71,"partial") | F9: =COUNTIFS(key!$B$2:$B$71,A9,Review!$G$2:$G$71,"wrong") | G9: =COUNTIFS(key!$B$2:$B$71,A9,Review!$G$2:$G$71,"unclear") | H9: =IFERROR(D9/(C9-G9),"") | I9: =IFERROR((D9+E9)/(C9-G9),"") | J9: =IFERROR(MAX(0,(H9+$M$2^2/(2*(C9-G9)))/(1+$M$2^2/(C9-G9))-$M$2*SQRT(H9*(1-H9)/(C9-G9)+$M$2^2/(4*(C9-G9)^2))/(1+$M$2^2/(C9-G9))),"") | K9: =IFERROR(MIN(1,(H9+$M$2^2/(2*(C9-G9)))/(1+$M$2^2/(C9-G9))+$M$2*SQRT(H9*(1-H9)/(C9-G9)+$M$2^2/(4*(C9-G9)^2))/(1+$M$2^2/(C9-G9))),"")
A10: census | B10: =COUNTIFS(key!$B$2:$B$71,A10) | C10: =COUNTIFS(key!$B$2:$B$71,A10,Review!$G$2:$G$71,"<>") | D10: =COUNTIFS(key!$B$2:$B$71,A10,Review!$G$2:$G$71,"correct") | E10: =COUNTIFS(key!$B$2:$B$71,A10,Review!$G$2:$G$71,"partial") | F10: =COUNTIFS(key!$B$2:$B$71,A10,Review!$G$2:$G$71,"wrong") | G10: =COUNTIFS(key!$B$2:$B$71,A10,Review!$G$2:$G$71,"unclear") | H10: =IFERROR(D10/(C10-G10),"") | I10: =IFERROR((D10+E10)/(C10-G10),"") | J10: =IFERROR(MAX(0,(H10+$M$2^2/(2*(C10-G10)))/(1+$M$2^2/(C10-G10))-$M$2*SQRT(H10*(1-H10)/(C10-G10)+$M$2^2/(4*(C10-G10)^2))/(1+$M$2^2/(C10-G10))),"") | K10: =IFERROR(MIN(1,(H10+$M$2^2/(2*(C10-G10)))/(1+$M$2^2/(C10-G10))+$M$2*SQRT(H10*(1-H10)/(C10-G10)+$M$2^2/(4*(C10-G10)^2))/(1+$M$2^2/(C10-G10))),"")
A12: Per stratum, unweighted; 'unclear' is excluded. Census rows count once each here; the review step weights them by their occurrences.
A13: Weighted figures per source and level, the EU-Dutch difference, lost actors, error kinds and inventory additions: python actor_map_review.py review --xlsx <this file>
