Workbook

Sheet Instructions
A1: Actor mapping review
A3: Each row of the Review sheet is one actor of a norm and the decision the system made for it. Judge the decision, using the norm text where it helps.
A5: What the system decides (column G)
A6: exact / shortened: the actor is the inventory entry in column H. 'shortened' means words were dropped to find it (e.g. 'bevoegde toezichthoudende autoriteit' -> toezichthoudende autoriteit).
A7: fallback: the unit is an actor, but none of the entries fits; only a broad class is given (column J).
A8: not_actor: the unit is not an actor (a document, decision, system, ...).
A10: What to fill in (yellow cells only)
A11: K system correct? yes / no / unsure.
A12: exact/shortened: yes if the actor in the norm is this entry (a sub-role of it also counts as yes, e.g. 'betrokken aanbieder' -> aanbieder).
A13: fallback: yes if it is an actor and no entry on the Inventory sheet fits it.
A14: not_actor: yes if the unit is indeed not an actor.
A15: L correct answer, only when K is 'no': an actor ID from the Inventory sheet, 'fallback' (an actor without a fitting entry) or 'not_actor'.
... A19: Example row (format only)
A20: case | B20: document | C20: norm_id | D20: raw actor (as extracted) | E20: actor unit (cleaned) | F20: norm text | G20: system: match | H20: system: actor ID | I20: system: label | J20: system: fallback class | K20: REVIEW: system correct? | L20: REVIEW: correct answer (if no) | M20: REVIEW: notes
A21: 0 | B21: 32016R0679 | C21: 32016R0679:57:1:3 | D21: De bevoegde toezichthoudende autoriteit | E21: bevoegde toezichthoudende autoriteit | F21: (norm text) | G21: shortened | H21: 32016R0679:toezichthoudende_autoriteit | I21: toezichthoudende autoriteit | K21: yes
A23: The sample has 40 cases. Scores update on the Scores sheet as you fill in column K and L.

Sheet Review
A1: case | B1: document | C1: norm_id | D1: raw actor (as extracted) | E1: actor unit (cleaned) | F1: norm text | G1: system: match | H1: system: actor ID | I1: system: label | J1: system: fallback class | K1: REVIEW: system correct? | L1: REVIEW: correct answer (if no) | M1: REVIEW: notes
A2: 1 | B2: 32016R0679 | C2: 32016R0679:27:2:2 | D2: incidentele verwerking | E2: incidentele verwerking | G2: not_actor
A3: 2 | B3: 32024R1689 | C3: 32024R1689:73:1:1 | D3: Aanbieders van in de Unie in de handel gebrachte AI-systemen met een hoog risico | E3: Aanbieders van in de Unie in de handel gebrachte AI-systemen met een hoog risico | G3: shortened | H3: 32024R1689:aanbieder | I3: aanbieder
A4: 3 | B4: 32016R0679 | C4: 32016R0679:28:4:5 | D4: de eerste verwerker | E4: eerste verwerker | G4: shortened | H4: 32016R0679:verwerker | I4: verwerker
A5: 4 | B5: 32016R0679 | C5: 32016R0679:32:4:3 | D5: iedere natuurlijke persoon die handelt onder het gezag van de verwerkingsverantwoordelijke of van de verwerker en toegang heeft tot persoonsgegevens | E5: natuurlijke persoon | G5: fallback | J5: person
A6: 5 | B6: 32024R1689 | C6: 32024R1689:37:4:7 | D6: de aanmeldende lidstaat | E6: aanmeldende lidstaat | G6: shortened | H6: KEY:EU:lidstaat | I6: lidstaat
A7: 6 | B7: 32016R0679 | C7: 32016R0679:75:3:2 | D7: De personeelsleden van de Europese Toezichthouder voor gegevensbescherming die betrokken zijn bij de uitvoering van de krachtens deze verordening aan het Comité opgedragen taken | E7: personeelsleden van de Europese Toezichthouder voor gegevensbescherming | G7: fallback | J7: office
A8: 7 | B8: 32024R1689 | C8: 32024R1689:10:3:3 | D8: Datasets voor training, validatie en tests | E8: Datasets voor training, validatie en tests | G8: not_actor
A9: 8 | B9: 32024R1689 | C9: 32024R1689:56:5:5 | D9: De kernprestatie-indicatoren en rapportageverplichtingen | E9: rapportageverplichtingen | G9: not_actor
A10: 9 | B10: 32016R0679 | C10: 32016R0679:45:5:4 | D10: De Commissie | E10: Commissie | G10: exact | H10: KEY:EU:commissie | I10: Commissie
A11: 10 | B11: 32024R1689 | C11: 32024R1689:67:6:4 | D11: Het adviesforum | E11: adviesforum | G11: exact | H11: KEY:32024R1689:adviesforum | I11: adviesforum
A12: 11 | B12: 32024R1689 | C12: 32024R1689:33:3:4 | D12: een onderaannemer of dochteronderneming | E12: onderaannemer | G12: fallback | J12: party
A13: 12 | B13: 32016R0679 | C13: 32016R0679:73:2:3 | D13: De ambtstermijn van de voorzitter en de vicevoorzitters | E13: ambtstermijn van de voorzitter | G13: not_actor
A14: 13 | B14: 32016R0679 | C14: 32016R0679:64:4:6 | D14: De toezichthoudende autoriteiten en de Commissie | E14: toezichthoudende autoriteiten en de Commissie | G14: shortened | H14: KEY:EU:commissie | I14: Commissie
A15: 14 | B15: 32024R1689 | C15: 32024R1689:31:7:8 | D15: hun personeel, comités, dochterondernemingen, onderaannemers, geassocieerde instanties of personeel van externe instanties | E15: geassocieerde instanties | G15: fallback | J15: body
A16: 15 | B16: 32024R1689 | C16: 32024R1689:45:1:1 | D16: Aangemelde instanties | E16: Aangemelde instanties | G16: exact | H16: 32024R1689:aangemelde_instantie | I16: aangemelde instantie
A17: 16 | B17: 32024R1689 | C17: 32024R1689:72:3:2 | D17: Het plan voor monitoring na het in de handel brengen | E17: plan voor monitoring na het in de handel brengen | G17: not_actor
A18: 17 | B18: 32024R1689 | C18: 32024R1689:5:6:15 | D18: Nationale markttoezichtautoriteiten en nationale gegevensbeschermingsautoriteiten van lidstaten die op grond van lid 4 in kennis zijn gesteld van het gebruik van systemen voor biometrische identificatie op afstand in real time in openbare ruimten met het oog op de rechtshandhaving | E18: nationale gegevensbeschermingsautoriteiten van lidstaten | G18: shortened | H18: KEY:32024R1689:gegevensbeschermingsautoriteit | I18: gegevensbeschermingsautoriteit
A19: 18 | B19: 32016R0679 | C19: 32016R0679:68:6:7 | D19: de Europese Toezichthouder voor gegevensbescherming | E19: Europese Toezichthouder voor gegevensbescherming | G19: exact | H19: KEY:EU:europese_toezichthouder_voor_gegevensbescherming | I19: Europese Toezichthouder voor gegevensbescherming
A20: 19 | B20: 32016R0679 | C20: 32016R0679:39:1:8 | D20: de functionaris voor gegevensbescherming | E20: functionaris voor gegevensbescherming | G20: exact | H20: KEY:32016R0679:functionaris_voor_gegevensbescherming | I20: functionaris voor gegevensbescherming
A21: 20 | B21: 32016R0679 | C21: 32016R0679:76:1:1 | D21: het comité | E21: comité | G21: exact | H21: KEY:32016R0679:comite | I21: Comité
A22: 21 | B22: 32016R0679 | C22: 32016R0679:42:7:7 | D22: de in artikel 43 bedoelde certificerende organen of door de bevoegde toezichthoudende autoriteit | E22: certificerende organen | G22: fallback | J22: body
A23: 22 | B23: 32024R1689 | C23: 32024R1689:22:1:1 | D23: Aanbieders die in derde landen zijn gevestigd | E23: Aanbieders | G23: exact | H23: 32024R1689:aanbieder | I23: aanbieder
A24: 23 | B24: 32024R1689 | C24: 32024R1689:74:6:5 | D24: de relevante nationale autoriteit die verantwoordelijk is voor het financiële toezicht op die instellingen krachtens die wetgeving | E24: relevante nationale autoriteit | G24: fallback | J24: authority
A25: 24 | B25: 32024R1689 | C25: 32024R1689:54:5:5 | D25: De gemachtigde | E25: gemachtigde | G25: exact | H25: 32024R1689:gemachtigde | I25: gemachtigde
A26: 25 | B26: 32024R1689 | C26: 32024R1689:24:5:11 | D26: distributeurs van een AI-systeem met een hoog risico | E26: distributeurs van een AI-systeem met een hoog risico | G26: shortened | H26: 32024R1689:distributeur | I26: distributeur
A27: 26 | B27: 32016R0679 | C27: 32016R0679:33:5:6 | D27: Die documentatie | E27: documentatie | G27: not_actor
A28: 27 | B28: 32016R0679 | C28: 32016R0679:91:1:1 | D28: kerken en religieuze verenigingen of gemeenschappen | E28: kerken | G28: fallback | J28: party
A29: 28 | B29: 32016R0679 | C29: 32016R0679:43:4:3 | D29: De in lid 1 bedoelde certificeringsorganen | E29: certificeringsorganen | G29: exact | H29: KEY:32016R0679:certificeringsorgaan | I29: certificeringsorgaan
A30: 29 | B30: 32024R1689 | C30: 32024R1689:99:1:3 | D30: de sancties | E30: sancties | G30: not_actor
A31: 30 | B31: 32016R0679 | C31: 32016R0679:92:3:3 | D31: Het Europees Parlement of de Raad | E31: Raad | G31: exact | H31: KEY:EU:raad | I31: Raad
A32: 31 | B32: 32016R0679 | C32: 32016R0679:62:5:9 | D32: De lidstaat op het grondgebied waarvan de schade is veroorzaakt | E32: lidstaat op het grondgebied | G32: shortened | H32: KEY:EU:lidstaat | I32: lidstaat
A33: 32 | B33: 32024R1689 | C33: 32024R1689:46:2:1 | D33: rechtshandhavingsinstanties of civielebeschermingsautoriteiten | E33: civielebeschermingsautoriteiten | G33: exact | H33: KEY:32024R1689:civielebeschermingsautoriteit | I33: civielebeschermingsautoriteit
A34: 33 | B34: 32024R1689 | C34: 32024R1689:36:3:5 | D34: Die laatste aangemelde instantie | E34: laatste aangemelde instantie | G34: shortened | H34: 32024R1689:aangemelde_instantie | I34: aangemelde instantie
A35: 34 | B35: 32024R1689 | C35: 32024R1689:28:7:12 | D35: Bekwame personeelsleden | E35: Bekwame personeelsleden | G35: fallback | J35: office
A36: 35 | B36: 32016R0679 | C36: 32016R0679:75:6:4 | D36: Het secretariaat | E36: secretariaat | G36: exact | H36: KEY:32016R0679:secretariaat | I36: secretariaat
A37: 36 | B37: 32016R0679 | C37: 32016R0679:26:2:1 | D37: de gezamenlijke verwerkingsverantwoordelijken | E37: gezamenlijke verwerkingsverantwoordelijken | G37: shortened | H37: 32016R0679:verwerkingsverantwoordelijke | I37: verwerkingsverantwoordelijke
A38: 37 | B38: 32024R1689 | C38: 32024R1689:65:6:5 | D38: De permanente subgroep voor markttoezicht | E38: permanente subgroep voor markttoezicht | G38: exact | H38: KEY:32024R1689:permanente_subgroep_voor_markttoezicht | I38: permanente subgroep voor markttoezicht
A39: 38 | B39: 32024R1689 | C39: 32024R1689:46:2:1 | D39: rechtshandhavingsinstanties of civielebeschermingsautoriteiten | E39: rechtshandhavingsinstanties | G39: exact | H39: 32024R1689:rechtshandhavingsinstantie | I39: rechtshandhavingsinstantie
A40: 39 | B40: 32016R0679 | C40: 32016R0679:61:3:5 | D40: Verzoeken om bijstand | E40: Verzoeken om bijstand | G40: not_actor
...

Sheet Scores
A1: Validation scores (update as the Review sheet is filled in)
A3: stratum (system match) | B3: cases | C3: reviewed (yes+no) | D3: correct (yes) | E3: accuracy | F3: unsure | G3: share of all unit uses | H3: accuracy x share
A4: exact | B4: =COUNTIF(Review!$G$2:$G$41,A4) | C4: =COUNTIFS(Review!$G$2:$G$41,A4,Review!$K$2:$K$41,"yes")+COUNTIFS(Review!$G$2:$G$41,A4,Review!$K$2:$K$41,"no") | D4: =COUNTIFS(Review!$G$2:$G$41,A4,Review!$K$2:$K$41,"yes") | E4: =IF(C4=0,"",D4/C4) | F4: =COUNTIFS(Review!$G$2:$G$41,A4,Review!$K$2:$K$41,"unsure") | G4: 0.731 | H4: =IF(C4=0,"",E4*G4)
A5: shortened | B5: =COUNTIF(Review!$G$2:$G$41,A5) | C5: =COUNTIFS(Review!$G$2:$G$41,A5,Review!$K$2:$K$41,"yes")+COUNTIFS(Review!$G$2:$G$41,A5,Review!$K$2:$K$41,"no") | D5: =COUNTIFS(Review!$G$2:$G$41,A5,Review!$K$2:$K$41,"yes") | E5: =IF(C5=0,"",D5/C5) | F5: =COUNTIFS(Review!$G$2:$G$41,A5,Review!$K$2:$K$41,"unsure") | G5: 0.0953 | H5: =IF(C5=0,"",E5*G5)
A6: fallback | B6: =COUNTIF(Review!$G$2:$G$41,A6) | C6: =COUNTIFS(Review!$G$2:$G$41,A6,Review!$K$2:$K$41,"yes")+COUNTIFS(Review!$G$2:$G$41,A6,Review!$K$2:$K$41,"no") | D6: =COUNTIFS(Review!$G$2:$G$41,A6,Review!$K$2:$K$41,"yes") | E6: =IF(C6=0,"",D6/C6) | F6: =COUNTIFS(Review!$G$2:$G$41,A6,Review!$K$2:$K$41,"unsure") | G6: 0.0636 | H6: =IF(C6=0,"",E6*G6)
A7: not_actor | B7: =COUNTIF(Review!$G$2:$G$41,A7) | C7: =COUNTIFS(Review!$G$2:$G$41,A7,Review!$K$2:$K$41,"yes")+COUNTIFS(Review!$G$2:$G$41,A7,Review!$K$2:$K$41,"no") | D7: =COUNTIFS(Review!$G$2:$G$41,A7,Review!$K$2:$K$41,"yes") | E7: =IF(C7=0,"",D7/C7) | F7: =COUNTIFS(Review!$G$2:$G$41,A7,Review!$K$2:$K$41,"unsure") | G7: 0.1101 | H7: =IF(C7=0,"",E7*G7)
A8: all (unweighted) | B8: =SUM(B4:B7) | C8: =SUM(C4:C7) | D8: =SUM(D4:D7) | E8: =IF(C8=0,"",D8/C8) | F8: =SUM(F4:F7) | G8: =SUM(G4:G7)
A9: all (weighted to real shares) | E9: =IF(SUMIFS(G4:G7,C4:C7,">0")=0,"",SUMPRODUCT(E4:E7,G4:G7)/SUMIFS(G4:G7,C4:C7,">0"))
A10: 95% interval, unweighted (Wilson) | E10: =IF(C8=0,"",(E8+1.96^2/(2*C8)-1.96*SQRT(E8*(1-E8)/C8+1.96^2/(4*C8^2)))/(1+1.96^2/C8)) | F10: =IF(C8=0,"",(E8+1.96^2/(2*C8)+1.96*SQRT(E8*(1-E8)/C8+1.96^2/(4*C8^2)))/(1+1.96^2/C8)) | G10: low / high
A12: Errors by kind
A13: wrong actor ID (exact/shortened, answer is another ID) | B13: =COUNTIFS(Review!$G$2:$G$41,"exact",Review!$K$2:$K$41,"no",Review!$L$2:$L$41,"<>fallback",Review!$L$2:$L$41,"<>not_actor",Review!$L$2:$L$41,"<>")+COUNTIFS(Review!$G$2:$G$41,"shortened",Review!$K$2:$K$41,"no",Review!$L$2:$L$41,"<>fallback",Review!$L$2:$L$41,"<>not_actor",Review!$L$2:$L$41,"<>")
A14: ID given, but should be fallback | B14: =COUNTIFS(Review!$G$2:$G$41,"exact",Review!$K$2:$K$41,"no",Review!$L$2:$L$41,"fallback")+COUNTIFS(Review!$G$2:$G$41,"shortened",Review!$K$2:$K$41,"no",Review!$L$2:$L$41,"fallback")
A15: taken for an actor, but is not one | B15: =COUNTIFS(Review!$G$2:$G$41,"<>not_actor",Review!$K$2:$K$41,"no",Review!$L$2:$L$41,"not_actor")
A16: fallback, but an entry fits | B16: =COUNTIFS(Review!$G$2:$G$41,"fallback",Review!$K$2:$K$41,"no",Review!$L$2:$L$41,"<>not_actor",Review!$L$2:$L$41,"<>fallback",Review!$L$2:$L$41,"<>")
A17: not_actor, but is an actor (missed) | B17: =COUNTIFS(Review!$G$2:$G$41,"not_actor",Review!$K$2:$K$41,"no")
A18: 'no' without a correct answer in column L | B18: =COUNTIFS(Review!$K$2:$K$41,"no",Review!$L$2:$L$41,"")
A20: By document
A21: document | B21: cases | C21: reviewed (yes+no) | D21: correct (yes) | E21: accuracy
A22: 32016R0679 | B22: =COUNTIF(Review!$B$2:$B$41,A22) | C22: =COUNTIFS(Review!$B$2:$B$41,A22,Review!$K$2:$K$41,"yes")+COUNTIFS(Review!$B$2:$B$41,A22,Review!$K$2:$K$41,"no") | D22: =COUNTIFS(Review!$B$2:$B$41,A22,Review!$K$2:$K$41,"yes") | E22: =IF(C22=0,"",D22/C22)
A23: 32024R1689 | B23: =COUNTIF(Review!$B$2:$B$41,A23) | C23: =COUNTIFS(Review!$B$2:$B$41,A23,Review!$K$2:$K$41,"yes")+COUNTIFS(Review!$B$2:$B$41,A23,Review!$K$2:$K$41,"no") | D23: =COUNTIFS(Review!$B$2:$B$41,A23,Review!$K$2:$K$41,"yes") | E23: =IF(C23=0,"",D23/C23)

Sheet Inventory
A1: actor ID | B1: label | C1: aliases | D1: kind | E1: valid for | F1: class
A2: 32024R1689:aanbieder | B2: aanbieder | D2: defined | E2: 32024R1689 | F2: party
A3: 32024R1689:gebruiksverantwoordelijke | B3: gebruiksverantwoordelijke | D3: defined | E3: 32024R1689 | F3: party
A4: 32024R1689:gemachtigde | B4: gemachtigde | D4: defined | E4: 32024R1689 | F4: party
A5: 32024R1689:importeur | B5: importeur | D5: defined | E5: 32024R1689 | F5: party
A6: 32024R1689:distributeur | B6: distributeur | D6: defined | E6: 32024R1689 | F6: party
A7: 32024R1689:operator | B7: operator | D7: defined | E7: 32024R1689 | F7: party
A8: 32024R1689:aanmeldende_autoriteit | B8: aanmeldende autoriteit | D8: defined | E8: 32024R1689 | F8: authority
A9: 32024R1689:conformiteitsbeoordelingsinstantie | B9: conformiteitsbeoordelingsinstantie | D9: defined | E9: 32024R1689 | F9: body
A10: 32024R1689:aangemelde_instantie | B10: aangemelde instantie | D10: defined | E10: 32024R1689 | F10: body
A11: 32024R1689:markttoezichtautoriteit | B11: markttoezichtautoriteit | D11: defined | E11: 32024R1689 | F11: authority
A12: 32024R1689:rechtshandhavingsinstantie | B12: rechtshandhavingsinstantie | D12: defined | E12: 32024R1689 | F12: body
A13: 32024R1689:aibureau | B13: AI-bureau | D13: defined | E13: 32024R1689 | F13: body
... A66: 32022L2555:onderzoeksorganisatie | B66: onderzoeksorganisatie | D66: defined | E66: 32022L2555 | F66: party
A67: KEY:EU:commissie | B67: Commissie | C67: Europese Commissie | D67: key | E67: eu | F67: institution
A68: KEY:EU:lidstaat | B68: lidstaat | D68: key | E68: eu | F68: state
A69: KEY:EU:europees_parlement | B69: Europees Parlement | D69: key | E69: eu | F69: institution
A70: KEY:EU:raad | B70: Raad | C70: Raad van de Europese Unie | D70: key | E70: eu | F70: institution
A71: KEY:EU:hof_van_justitie | B71: Hof van Justitie | C71: Hof van Justitie van de Europese Unie | D71: key | E71: eu (not in 32022R2554) | F71: institution
A72: KEY:EU:europese_toezichthouder_voor_gegevensbescherming | B72: Europese Toezichthouder voor gegevensbescherming | D72: key | E72: eu | F72: authority
A73: KEY:EU:gerecht | B73: gerecht | C73: bevoegd gerecht; nationaal gerecht | D73: key | E73: eu | F73: institution
A74: KEY:EU:overheidsinstantie | B74: overheidsinstantie | D74: key | E74: eu (not in 32022L2555, 32022R2554) | F74: authority
A75: KEY:EU:nationale_accreditatieinstantie | B75: nationale accreditatie-instantie | C75: accreditatie-instantie | D75: key | E75: eu | F75: body
A76: KEY:32016R0679:comite | B76: Comité | C76: Europees Comité voor gegevensbescherming | D76: key | E76: 32016R0679 | F76: body
A77: KEY:32016R0679:voorzitter | B77: voorzitter | C77: voorzitter van het Comité | D77: key | E77: 32016R0679 | F77: office
A78: KEY:32016R0679:secretariaat | B78: secretariaat | C78: secretariaat van het Comité | D78: key | E78: 32016R0679 | F78: office
A79: KEY:32016R0679:leidende_toezichthoudende_autoriteit | B79: leidende toezichthoudende autoriteit | D79: key | E79: 32016R0679 | F79: authority
A80: KEY:32016R0679:functionaris_voor_gegevensbescherming | B80: functionaris voor gegevensbescherming | D80: key | E80: 32016R0679 | F80: office
A81: KEY:32016R0679:certificeringsorgaan | B81: certificeringsorgaan | D81: key | E81: 32016R0679 | F81: body
A82: KEY:32016R0679:vereniging | B82: vereniging | C82: verenigingen en andere organen die categorieën van verwerkingsverantwoordelijken of verwerkers vertegenwoordigen | D82: key | E82: 32016R0679 | F82: party
A83: KEY:32024R1689:aiboard | B83: AI-board | C83: Europese raad voor artificiële intelligentie | D83: key | E83: 32024R1689 | F83: body
A84: KEY:32024R1689:adviesforum | B84: adviesforum | D84: key | E84: 32024R1689 | F84: body
A85: KEY:32024R1689:wetenschappelijk_panel | B85: wetenschappelijk panel | C85: wetenschappelijk panel van onafhankelijke deskundigen | D85: key | E85: 32024R1689 | F85: body
A86: KEY:32024R1689:productfabrikant | B86: productfabrikant | D86: key | E86: 32024R1689 | F86: party
A87: KEY:32024R1689:permanente_subgroep_voor_markttoezicht | B87: permanente subgroep voor markttoezicht | C87: subgroep | D87: key | E87: 32024R1689 | F87: body
A88: KEY:32024R1689:gegevensbeschermingsautoriteit | B88: gegevensbeschermingsautoriteit | C88: nationale gegevensbeschermingsautoriteit | D88: key | E88: 32024R1689 | F88: authority
A89: KEY:32024R1689:civielebeschermingsautoriteit | B89: civielebeschermingsautoriteit | D89: key | E89: 32024R1689 | F89: authority
A90: KEY:32024R1689:kmo | B90: kmo | C90: kmo, met inbegrip van start-ups | D90: key | E90: 32024R1689 | F90: party
A91: fallback | B91: an actor without a fitting entry | E91: all
A92: not_actor | B92: not an actor | E92: all
