Workbook

Sheet Instructions
A1: Actor relation review
A3: Each row of the Review sheet is a pair of actors (A and B) and the relation the system gives them. Choose the correct relation in the yellow column, using the definitions and how the actors are written in the norms. Judge the legal relation between the two actors, not whether two particular norms conflict.
A4: The Labels sheet lists every relation with its score. Mind the direction: 'subtype: A is a kind of B' is not the same as 'B is a kind of A'.
A5: Strata: 'found' rows check relations the system found; 'different' and 'unknown' rows check pairs where it found none, to see which relations are missing.
A7: Fill in (yellow cells only)
A8: REVIEW: correct relation - one label from the list, or 'unsure'.
A9: REVIEW: notes - for example the article that shows the relation.
A10: The grey columns after the notes are filled in by formulas.
A12: Example row (format only)
A13: case | B13: stratum | C13: documents | D13: actor A | E13: A: definition or source | F13: A: as written in norms | G13: actor B | H13: B: definition or source | I13: B: as written in norms | J13: system: relation | K13: system: score | L13: system: evidence | M13: norm pairs affected | N13: REVIEW: correct relation | O13: REVIEW: notes
A14: 0 | B14: found | C14: 32016R0679 | D14: 32016R0679:betrokken_toezichthoudende_autoriteit | E14: ... | F14: betrokken toezichthoudende autoriteit | G14: 32016R0679:toezichthoudende_autoriteit | H14: ... | I14: toezichthoudende autoriteit | J14: subtype: A is a kind of B | K14: 0.8 | L14: label: ... | M14: 120 | N14: subtype: A is a kind of B

Sheet Review
A1: case | B1: stratum | C1: documents | D1: actor A | E1: A: definition or source | F1: A: as written in norms | G1: actor B | H1: B: definition or source | I1: B: as written in norms | J1: system: relation | K1: system: score | L1: system: evidence | M1: norm pairs affected | N1: REVIEW: correct relation | O1: REVIEW: notes | P1: reviewer score | Q1: agrees | R1: same sign | S1: score error
A2: 1 | B2: different | C2: 32016R0679 | D2: 32016R0679:verwerker | E2: 32016R0679 art. 4: een natuurlijke persoon of rechtspersoon, een overheidsinstantie, een dienst of een ander orgaan die/dat ten behoeve van de verwerkingsverantwoordelijke persoonsgegevens verwerkt | F2: verwerker, verwerkers, eerste verwerker | G2: KEY:EU:commissie | H2: Known actor (not defined), class institution. Aliases: Europese Commissie. | I2: Commissie, toezichthoudende autoriteiten en de Commissie | J2: different | K2: -0.25 | M2: 6279 | P2: =IF(OR(N2="",N2="unsure"),"",INDEX(Labels!$B$2:$B$15,MATCH(N2,Labels!$A$2:$A$15,0))) | Q2: =IF(P2="","",IF(N2=J2,1,0)) | R2: =IF(P2="","",IF(SIGN(P2)=SIGN(K2),1,0)) | S2: =IF(P2="","",ABS(P2-K2))
A3: 2 | B3: found | C3: 32024R1689 | D3: 32024R1689:importeur | E3: 32024R1689 art. 3: een natuurlijke of rechtspersoon die zich bevindt of gevestigd is in de Unie die een AI-systeem in de handel brengt dat de naam of het merk van een in een derde land gevestigde natuurlijke of rechtspersoon draagt | F3: Importeurs, importeur | G3: KEY:32024R1689:productfabrikant | H3: Known actor (not defined), class party. | I3: productfabrikant | J3: sibling | K3: 0.15 | L3: derived: both 32024R1689:operator | M3: 7 | P3: =IF(OR(N3="",N3="unsure"),"",INDEX(Labels!$B$2:$B$15,MATCH(N3,Labels!$A$2:$A$15,0))) | Q3: =IF(P3="","",IF(N3=J3,1,0)) | R3: =IF(P3="","",IF(SIGN(P3)=SIGN(K3),1,0)) | S3: =IF(P3="","",ABS(P3-K3))
A4: 3 | B4: unknown | C4: 32016R0679, 32024R1689 | D4: 32016R0679:toezichthoudende_autoriteit | E4: 32016R0679 art. 4: een door een lidstaat ingevolge artikel 51 ingestelde onafhankelijke overheidsinstantie | F4: toezichthoudende autoriteit, toezichthoudende autoriteiten, bevoegde toezichthoudende autoriteit | G4: 32024R1689:gemachtigde | H4: 32024R1689 art. 3: een natuurlijke of rechtspersoon die zich bevindt of gevestigd is in de Unie die een schriftelijke machtiging heeft gekregen en aanvaard van een aanbieder van een AI-systeem of een AI-model voor algemene doeleinden om namens die aanbieder de verplichtingen en procedures van deze verordening respectievelijk na te komen en uit te voeren | I4: gemachtigde | J4: unknown | K4: 0 | M4: 565 | P4: =IF(OR(N4="",N4="unsure"),"",INDEX(Labels!$B$2:$B$15,MATCH(N4,Labels!$A$2:$A$15,0))) | Q4: =IF(P4="","",IF(N4=J4,1,0)) | R4: =IF(P4="","",IF(SIGN(P4)=SIGN(K4),1,0)) | S4: =IF(P4="","",ABS(P4-K4))
A5: 4 | B5: found | C5: 32024R1689 | D5: 32024R1689:aanbieder_verder_in_de_aiwaardeketen | E5: 32024R1689 art. 3: een aanbieder van een AI-systeem, met inbegrip van een AI-systeem voor algemene doeleinden, waarin een AI-model is geïntegreerd, ongeacht of het AI-model door hemzelf wordt verstrekt en verticaal geïntegreerd is of door een andere entiteit wordt aangeboden op basis van contractuele betrekkingen. | F5: Aanbieders verder in de AI-waardeketen | G5: 32024R1689:operator | H5: 32024R1689 art. 3: een aanbieder, productfabrikant, gebruiksverantwoordelijke, gemachtigde, importeur of distributeur | I5: betrokken operatoren, operatoren, operators | J5: subtype, two steps: A ... B | K5: 0.6 | L5: derived: via 32024R1689:aanbieder | M5: 6 | P5: =IF(OR(N5="",N5="unsure"),"",INDEX(Labels!$B$2:$B$15,MATCH(N5,Labels!$A$2:$A$15,0))) | Q5: =IF(P5="","",IF(N5=J5,1,0)) | R5: =IF(P5="","",IF(SIGN(P5)=SIGN(K5),1,0)) | S5: =IF(P5="","",ABS(P5-K5))
A6: 5 | B6: different | C6: 32024R1689 | D6: 32024R1689:importeur | E6: 32024R1689 art. 3: een natuurlijke of rechtspersoon die zich bevindt of gevestigd is in de Unie die een AI-systeem in de handel brengt dat de naam of het merk van een in een derde land gevestigde natuurlijke of rechtspersoon draagt | F6: Importeurs, importeur | G6: KEY:EU:commissie | H6: Known actor (not defined), class institution. Aliases: Europese Commissie. | I6: Commissie, toezichthoudende autoriteiten en de Commissie | J6: different | K6: -0.25 | M6: 1127 | P6: =IF(OR(N6="",N6="unsure"),"",INDEX(Labels!$B$2:$B$15,MATCH(N6,Labels!$A$2:$A$15,0))) | Q6: =IF(P6="","",IF(N6=J6,1,0)) | R6: =IF(P6="","",IF(SIGN(P6)=SIGN(K6),1,0)) | S6: =IF(P6="","",ABS(P6-K6))
A7: 6 | B7: different | C7: 32016R0679 | D7: 32016R0679:verwerker | E7: 32016R0679 art. 4: een natuurlijke persoon of rechtspersoon, een overheidsinstantie, een dienst of een ander orgaan die/dat ten behoeve van de verwerkingsverantwoordelijke persoonsgegevens verwerkt | F7: verwerker, verwerkers, eerste verwerker | G7: KEY:EU:lidstaat | H7: Known actor (not defined), class state. | I7: lidstaten, lidstaat, aanmeldende lidstaat | J7: different | K7: -0.25 | M7: 3588 | P7: =IF(OR(N7="",N7="unsure"),"",INDEX(Labels!$B$2:$B$15,MATCH(N7,Labels!$A$2:$A$15,0))) | Q7: =IF(P7="","",IF(N7=J7,1,0)) | R7: =IF(P7="","",IF(SIGN(P7)=SIGN(K7),1,0)) | S7: =IF(P7="","",ABS(P7-K7))
A8: 7 | B8: found | C8: 32024R1689 | D8: KEY:32024R1689:permanente_subgroep_voor_markttoezicht | E8: Known actor (not defined), class body. Aliases: subgroep. Part of KEY:32024R1689:aiboard. | F8: permanente subgroep voor markttoezicht | G8: KEY:32024R1689:aiboard | H8: Known actor (not defined), class body. Aliases: Europese raad voor artificiële intelligentie. | I8: AI-board | J8: part of: A in B | K8: 0.5 | L8: inventory: part_of in inventory | M8: 9 | P8: =IF(OR(N8="",N8="unsure"),"",INDEX(Labels!$B$2:$B$15,MATCH(N8,Labels!$A$2:$A$15,0))) | Q8: =IF(P8="","",IF(N8=J8,1,0)) | R8: =IF(P8="","",IF(SIGN(P8)=SIGN(K8),1,0)) | S8: =IF(P8="","",ABS(P8-K8))
A9: 8 | B9: different | C9: 32016R0679 | D9: 32016R0679:toezichthoudende_autoriteit | E9: 32016R0679 art. 4: een door een lidstaat ingevolge artikel 51 ingestelde onafhankelijke overheidsinstantie | F9: toezichthoudende autoriteit, toezichthoudende autoriteiten, bevoegde toezichthoudende autoriteit | G9: 32016R0679:verwerker | H9: 32016R0679 art. 4: een natuurlijke persoon of rechtspersoon, een overheidsinstantie, een dienst of een ander orgaan die/dat ten behoeve van de verwerkingsverantwoordelijke persoonsgegevens verwerkt | I9: verwerker, verwerkers, eerste verwerker | J9: different | K9: -0.25 | M9: 4407 | P9: =IF(OR(N9="",N9="unsure"),"",INDEX(Labels!$B$2:$B$15,MATCH(N9,Labels!$A$2:$A$15,0))) | Q9: =IF(P9="","",IF(N9=J9,1,0)) | R9: =IF(P9="","",IF(SIGN(P9)=SIGN(K9),1,0)) | S9: =IF(P9="","",ABS(P9-K9))
A10: 9 | B10: unknown | C10: 32016R0679, 32024R1689 | D10: 32016R0679:verwerker | E10: 32016R0679 art. 4: een natuurlijke persoon of rechtspersoon, een overheidsinstantie, een dienst of een ander orgaan die/dat ten behoeve van de verwerkingsverantwoordelijke persoonsgegevens verwerkt | F10: verwerker, verwerkers, eerste verwerker | G10: 32024R1689:aanbieder | H10: 32024R1689 art. 3: een natuurlijke of rechtspersoon, overheidsinstantie, agentschap of ander orgaan die/dat een AI-systeem of een AI-model voor algemene doeleinden ontwikkelt of laat ontwikkelen en dat systeem of model in de handel brengt of het AI-systeem in gebruik stelt onder de eigen naam of merk, al dan niet tegen betaling | I10: aanbieder, aanbieders, Aanbieders van AI-systemen met een hoog risico | J10: unknown | K10: 0 | M10: 4056 | P10: =IF(OR(N10="",N10="unsure"),"",INDEX(Labels!$B$2:$B$15,MATCH(N10,Labels!$A$2:$A$15,0))) | Q10: =IF(P10="","",IF(N10=J10,1,0)) | R10: =IF(P10="","",IF(SIGN(P10)=SIGN(K10),1,0)) | S10: =IF(P10="","",ABS(P10-K10))
A11: 10 | B11: found | C11: 32024R1689 | D11: 32024R1689:gemachtigde | E11: 32024R1689 art. 3: een natuurlijke of rechtspersoon die zich bevindt of gevestigd is in de Unie die een schriftelijke machtiging heeft gekregen en aanvaard van een aanbieder van een AI-systeem of een AI-model voor algemene doeleinden om namens die aanbieder de verplichtingen en procedures van deze verordening respectievelijk na te komen en uit te voeren | F11: gemachtigde | G11: 32024R1689:operator | H11: 32024R1689 art. 3: een aanbieder, productfabrikant, gebruiksverantwoordelijke, gemachtigde, importeur of distributeur | I11: betrokken operatoren, operatoren, operators | J11: subtype: A is a kind of B | K11: 0.8 | L11: definition: een aanbieder, productfabrikant, gebruiksverantwoordelijke, gemachtigde, importeur of distributeur | M11: 30 | P11: =IF(OR(N11="",N11="unsure"),"",INDEX(Labels!$B$2:$B$15,MATCH(N11,Labels!$A$2:$A$15,0))) | Q11: =IF(P11="","",IF(N11=J11,1,0)) | R11: =IF(P11="","",IF(SIGN(P11)=SIGN(K11),1,0)) | S11: =IF(P11="","",ABS(P11-K11))
A12: 11 | B12: different | C12: 32024R1689 | D12: 32024R1689:aanmeldende_autoriteit | E12: 32024R1689 art. 3: de nationale autoriteit die verantwoordelijk is voor het opzetten en uitvoeren van de noodzakelijke procedures voor de beoordeling, aanwijzing en kennisgeving van de conformiteitsbeoordelingsinstanties en de monitoring hiervan | F12: aanmeldende autoriteit, Aanmeldende autoriteiten | G12: 32024R1689:distributeur | H12: 32024R1689 art. 3: een andere natuurlijke persoon of rechtspersoon in de toeleveringsketen dan de aanbieder of de importeur, die een AI-systeem in de Unie op de markt aanbiedt | I12: distributeur, Distributeurs, distributeurs | J12: different | K12: -0.25 | M12: 448 | P12: =IF(OR(N12="",N12="unsure"),"",INDEX(Labels!$B$2:$B$15,MATCH(N12,Labels!$A$2:$A$15,0))) | Q12: =IF(P12="","",IF(N12=J12,1,0)) | R12: =IF(P12="","",IF(SIGN(P12)=SIGN(K12),1,0)) | S12: =IF(P12="","",ABS(P12-K12))
A13: 12 | B13: found | C13: 32016R0679 | D13: 32016R0679:betrokken_toezichthoudende_autoriteit | E13: 32016R0679 art. 4: een toezichthoudende autoriteit die betrokken is bij de verwerking van persoonsgegevens omdat: a) de verwerkingsverantwoordelijke of de verwerker op het grondgebied van de lidstaat van die toezichthoudende autoriteit is gevestigd; b) de betrokkenen die in de lidstaat van die toezichthoudende autoriteit verblijven, door de verwerking wezenlijke gevolgen ondervinden of waarschijnlijk zullen ondervinden; of c) bij die toezichthoudende autoriteit een klacht is ingediend | F13: betrokken toezichthoudende autoriteiten, betrokken toezichthoudende autoriteit | G13: KEY:32016R0679:leidende_toezichthoudende_autoriteit | H13: Known actor (not defined), class authority. | I13: leidende toezichthoudende autoriteit | J13: sibling | K13: 0.15 | L13: derived: both 32016R0679:toezichthoudende_autoriteit | M13: 114 | P13: =IF(OR(N13="",N13="unsure"),"",INDEX(Labels!$B$2:$B$15,MATCH(N13,Labels!$A$2:$A$15,0))) | Q13: =IF(P13="","",IF(N13=J13,1,0)) | R13: =IF(P13="","",IF(SIGN(P13)=SIGN(K13),1,0)) | S13: =IF(P13="","",ABS(P13-K13))
A14: 13 | B14: found | C14: 32016R0679 | D14: 32016R0679:betrokken_toezichthoudende_autoriteit | E14: 32016R0679 art. 4: een toezichthoudende autoriteit die betrokken is bij de verwerking van persoonsgegevens omdat: a) de verwerkingsverantwoordelijke of de verwerker op het grondgebied van de lidstaat van die toezichthoudende autoriteit is gevestigd; b) de betrokkenen die in de lidstaat van die toezichthoudende autoriteit verblijven, door de verwerking wezenlijke gevolgen ondervinden of waarschijnlijk zullen ondervinden; of c) bij die toezichthoudende autoriteit een klacht is ingediend | F14: betrokken toezichthoudende autoriteiten, betrokken toezichthoudende autoriteit | G14: KEY:EU:lidstaat | H14: Known actor (not defined), class state. | I14: lidstaten, lidstaat, aanmeldende lidstaat | J14: subtype, two steps: A ... B | K14: 0.6 | L14: derived: via 32016R0679:toezichthoudende_autoriteit | M14: 552 | P14: =IF(OR(N14="",N14="unsure"),"",INDEX(Labels!$B$2:$B$15,MATCH(N14,Labels!$A$2:$A$15,0))) | Q14: =IF(P14="","",IF(N14=J14,1,0)) | R14: =IF(P14="","",IF(SIGN(P14)=SIGN(K14),1,0)) | S14: =IF(P14="","",ABS(P14-K14))
A15: 14 | B15: unknown | C15: 32016R0679, 32024R1689 | D15: 32024R1689:importeur | E15: 32024R1689 art. 3: een natuurlijke of rechtspersoon die zich bevindt of gevestigd is in de Unie die een AI-systeem in de handel brengt dat de naam of het merk van een in een derde land gevestigde natuurlijke of rechtspersoon draagt | F15: Importeurs, importeur | G15: KEY:32016R0679:functionaris_voor_gegevensbescherming | H15: Known actor (not defined), class office. | I15: functionaris voor gegevensbescherming | J15: unknown | K15: 0 | M15: 105 | P15: =IF(OR(N15="",N15="unsure"),"",INDEX(Labels!$B$2:$B$15,MATCH(N15,Labels!$A$2:$A$15,0))) | Q15: =IF(P15="","",IF(N15=J15,1,0)) | R15: =IF(P15="","",IF(SIGN(P15)=SIGN(K15),1,0)) | S15: =IF(P15="","",ABS(P15-K15))
A16: 15 | B16: found | C16: 32024R1689 | D16: 32024R1689:aibureau | E16: 32024R1689 art. 3: de taak van de Commissie waarbij zij bijdraagt aan de uitvoering van, de monitoring van en het toezicht op AI-systemen en AI-modellen voor algemene doeleinden, en AI-governance, als bepaald in het besluit van de Commissie van 24 januari 2024; verwijzingen in deze verordening naar het AI-bureau worden begrepen als verwijzingen naar de Commissie | F16: AI-bureau | G16: KEY:EU:commissie | H16: Known actor (not defined), class institution. Aliases: Europese Commissie. | I16: Commissie, toezichthoudende autoriteiten en de Commissie | J16: part of: A in B | K16: 0.5 | L16: definition: de taak van de Commissie | M16: 5957 | P16: =IF(OR(N16="",N16="unsure"),"",INDEX(Labels!$B$2:$B$15,MATCH(N16,Labels!$A$2:$A$15,0))) | Q16: =IF(P16="","",IF(N16=J16,1,0)) | R16: =IF(P16="","",IF(SIGN(P16)=SIGN(K16),1,0)) | S16: =IF(P16="","",ABS(P16-K16))
A17: 16 | B17: unknown | C17: 32016R0679, 32024R1689 | D17: 32024R1689:markttoezichtautoriteit | E17: 32024R1689 art. 3: de nationale autoriteit die de activiteiten verricht en maatregelen neemt als bedoeld in Verordening (EU) 2019/1020 | F17: markttoezichtautoriteit, markttoezichtautoriteiten, Markttoezichtautoriteiten | G17: KEY:32016R0679:secretariaat | H17: Known actor (not defined), class office. Aliases: secretariaat van het Comité. Part of KEY:32016R0679:comite. | I17: secretariaat, secretariaat van het Comité | J17: unknown | K17: 0 | M17: 340 | P17: =IF(OR(N17="",N17="unsure"),"",INDEX(Labels!$B$2:$B$15,MATCH(N17,Labels!$A$2:$A$15,0))) | Q17: =IF(P17="","",IF(N17=J17,1,0)) | R17: =IF(P17="","",IF(SIGN(P17)=SIGN(K17),1,0)) | S17: =IF(P17="","",ABS(P17-K17))
A18: 17 | B18: different | C18: 32016R0679 | D18: 32016R0679:verwerkingsverantwoordelijke | E18: 32016R0679 art. 4: een natuurlijke persoon of rechtspersoon, een overheidsinstantie, een dienst of een ander orgaan die/dat, alleen of samen met anderen, het doel van en de middelen voor de verwerking van persoonsgegevens vaststelt; wanneer de doelstellingen van en de middelen voor deze verwerking in het Unierecht of het lidstatelijke recht worden vastgesteld, kan daarin worden bepaald wie de verwerkingsverantwoordelijke is of volgens welke criteria deze wordt aangewezen | F18: verwerkingsverantwoordelijke, verwerkingsverantwoordelijken, gezamenlijke verwerkingsverantwoordelijken | G18: KEY:EU:lidstaat | H18: Known actor (not defined), class state. | I18: lidstaten, lidstaat, aanmeldende lidstaat | J18: different | K18: -0.25 | M18: 9568 | P18: =IF(OR(N18="",N18="unsure"),"",INDEX(Labels!$B$2:$B$15,MATCH(N18,Labels!$A$2:$A$15,0))) | Q18: =IF(P18="","",IF(N18=J18,1,0)) | R18: =IF(P18="","",IF(SIGN(P18)=SIGN(K18),1,0)) | S18: =IF(P18="","",ABS(P18-K18))
A19: 18 | B19: different | C19: 32016R0679 | D19: KEY:32016R0679:voorzitter | E19: Known actor (not defined), class office. Aliases: voorzitter van het Comité. Part of KEY:32016R0679:comite. | F19: voorzitter van het Comité, voorzitter | G19: KEY:EU:lidstaat | H19: Known actor (not defined), class state. | I19: lidstaten, lidstaat, aanmeldende lidstaat | J19: different | K19: -0.25 | M19: 1104 | P19: =IF(OR(N19="",N19="unsure"),"",INDEX(Labels!$B$2:$B$15,MATCH(N19,Labels!$A$2:$A$15,0))) | Q19: =IF(P19="","",IF(N19=J19,1,0)) | R19: =IF(P19="","",IF(SIGN(P19)=SIGN(K19),1,0)) | S19: =IF(P19="","",ABS(P19-K19))
A20: 19 | B20: different | C20: 32016R0679 | D20: KEY:32016R0679:certificeringsorgaan | E20: Known actor (not defined), class body. | F20: certificeringsorganen | G20: KEY:32016R0679:comite | H20: Known actor (not defined), class body. Aliases: Europees Comité voor gegevensbescherming. | I20: Comité, comité | J20: different | K20: -0.25 | M20: 153 | P20: =IF(OR(N20="",N20="unsure"),"",INDEX(Labels!$B$2:$B$15,MATCH(N20,Labels!$A$2:$A$15,0))) | Q20: =IF(P20="","",IF(N20=J20,1,0)) | R20: =IF(P20="","",IF(SIGN(P20)=SIGN(K20),1,0)) | S20: =IF(P20="","",ABS(P20-K20))
A21: 20 | B21: found | C21: 32024R1689 | D21: 32024R1689:gemachtigde | E21: 32024R1689 art. 3: een natuurlijke of rechtspersoon die zich bevindt of gevestigd is in de Unie die een schriftelijke machtiging heeft gekregen en aanvaard van een aanbieder van een AI-systeem of een AI-model voor algemene doeleinden om namens die aanbieder de verplichtingen en procedures van deze verordening respectievelijk na te komen en uit te voeren | F21: gemachtigde | G21: KEY:32024R1689:productfabrikant | H21: Known actor (not defined), class party. | I21: productfabrikant | J21: sibling | K21: 0.15 | L21: derived: both 32024R1689:operator | M21: 5 | P21: =IF(OR(N21="",N21="unsure"),"",INDEX(Labels!$B$2:$B$15,MATCH(N21,Labels!$A$2:$A$15,0))) | Q21: =IF(P21="","",IF(N21=J21,1,0)) | R21: =IF(P21="","",IF(SIGN(P21)=SIGN(K21),1,0)) | S21: =IF(P21="","",ABS(P21-K21))
A22: 21 | B22: found | C22: 32024R1689 | D22: KEY:32024R1689:productfabrikant | E22: Known actor (not defined), class party. | F22: productfabrikant | G22: 32024R1689:operator | H22: 32024R1689 art. 3: een aanbieder, productfabrikant, gebruiksverantwoordelijke, gemachtigde, importeur of distributeur | I22: betrokken operatoren, operatoren, operators | J22: subtype: A is a kind of B | K22: 0.8 | L22: definition: een aanbieder, productfabrikant, gebruiksverantwoordelijke, gemachtigde, importeur of distributeur | M22: 6 | P22: =IF(OR(N22="",N22="unsure"),"",INDEX(Labels!$B$2:$B$15,MATCH(N22,Labels!$A$2:$A$15,0))) | Q22: =IF(P22="","",IF(N22=J22,1,0)) | R22: =IF(P22="","",IF(SIGN(P22)=SIGN(K22),1,0)) | S22: =IF(P22="","",ABS(P22-K22))
A23: 22 | B23: different | C23: 32024R1689 | D23: 32024R1689:aanbieder | E23: 32024R1689 art. 3: een natuurlijke of rechtspersoon, overheidsinstantie, agentschap of ander orgaan die/dat een AI-systeem of een AI-model voor algemene doeleinden ontwikkelt of laat ontwikkelen en dat systeem of model in de handel brengt of het AI-systeem in gebruik stelt onder de eigen naam of merk, al dan niet tegen betaling | F23: aanbieder, aanbieders, Aanbieders van AI-systemen met een hoog risico | G23: KEY:EU:commissie | H23: Known actor (not defined), class institution. Aliases: Europese Commissie. | I23: Commissie, toezichthoudende autoriteiten en de Commissie | J23: different | K23: -0.25 | M23: 16744 | P23: =IF(OR(N23="",N23="unsure"),"",INDEX(Labels!$B$2:$B$15,MATCH(N23,Labels!$A$2:$A$15,0))) | Q23: =IF(P23="","",IF(N23=J23,1,0)) | R23: =IF(P23="","",IF(SIGN(P23)=SIGN(K23),1,0)) | S23: =IF(P23="","",ABS(P23-K23))
A24: 23 | B24: found | C24: 32024R1689 | D24: 32024R1689:distributeur | E24: 32024R1689 art. 3: een andere natuurlijke persoon of rechtspersoon in de toeleveringsketen dan de aanbieder of de importeur, die een AI-systeem in de Unie op de markt aanbiedt | F24: distributeur, Distributeurs, distributeurs | G24: 32024R1689:importeur | H24: 32024R1689 art. 3: een natuurlijke of rechtspersoon die zich bevindt of gevestigd is in de Unie die een AI-systeem in de handel brengt dat de naam of het merk van een in een derde land gevestigde natuurlijke of rechtspersoon draagt | I24: Importeurs, importeur | J24: sibling | K24: 0.15 | L24: derived: both 32024R1689:operator | M24: 98 | P24: =IF(OR(N24="",N24="unsure"),"",INDEX(Labels!$B$2:$B$15,MATCH(N24,Labels!$A$2:$A$15,0))) | Q24: =IF(P24="","",IF(N24=J24,1,0)) | R24: =IF(P24="","",IF(SIGN(P24)=SIGN(K24),1,0)) | S24: =IF(P24="","",ABS(P24-K24))
A25: 24 | B25: found | C25: 32024R1689 | D25: 32024R1689:aanbieder | E25: 32024R1689 art. 3: een natuurlijke of rechtspersoon, overheidsinstantie, agentschap of ander orgaan die/dat een AI-systeem of een AI-model voor algemene doeleinden ontwikkelt of laat ontwikkelen en dat systeem of model in de handel brengt of het AI-systeem in gebruik stelt onder de eigen naam of merk, al dan niet tegen betaling | F25: aanbieder, aanbieders, Aanbieders van AI-systemen met een hoog risico | G25: 32024R1689:distributeur | H25: 32024R1689 art. 3: een andere natuurlijke persoon of rechtspersoon in de toeleveringsketen dan de aanbieder of de importeur, die een AI-systeem in de Unie op de markt aanbiedt | I25: distributeur, Distributeurs, distributeurs | J25: sibling | K25: 0.15 | L25: derived: both 32024R1689:operator | M25: 1456 | P25: =IF(OR(N25="",N25="unsure"),"",INDEX(Labels!$B$2:$B$15,MATCH(N25,Labels!$A$2:$A$15,0))) | Q25: =IF(P25="","",IF(N25=J25,1,0)) | R25: =IF(P25="","",IF(SIGN(P25)=SIGN(K25),1,0)) | S25: =IF(P25="","",ABS(P25-K25))
A26: 25 | B26: unknown | C26: 32016R0679, 32024R1689 | D26: 32024R1689:aibureau | E26: 32024R1689 art. 3: de taak van de Commissie waarbij zij bijdraagt aan de uitvoering van, de monitoring van en het toezicht op AI-systemen en AI-modellen voor algemene doeleinden, en AI-governance, als bepaald in het besluit van de Commissie van 24 januari 2024; verwijzingen in deze verordening naar het AI-bureau worden begrepen als verwijzingen naar de Commissie | F26: AI-bureau | G26: KEY:32016R0679:certificeringsorgaan | H26: Known actor (not defined), class body. | I26: certificeringsorganen | J26: unknown | K26: 0 | M26: 111 | P26: =IF(OR(N26="",N26="unsure"),"",INDEX(Labels!$B$2:$B$15,MATCH(N26,Labels!$A$2:$A$15,0))) | Q26: =IF(P26="","",IF(N26=J26,1,0)) | R26: =IF(P26="","",IF(SIGN(P26)=SIGN(K26),1,0)) | S26: =IF(P26="","",ABS(P26-K26))
A27: 26 | B27: unknown | C27: 32016R0679, 32024R1689 | D27: 32016R0679:toezichthoudende_autoriteit | E27: 32016R0679 art. 4: een door een lidstaat ingevolge artikel 51 ingestelde onafhankelijke overheidsinstantie | F27: toezichthoudende autoriteit, toezichthoudende autoriteiten, bevoegde toezichthoudende autoriteit | G27: 32024R1689:aanbieder | H27: 32024R1689 art. 3: een natuurlijke of rechtspersoon, overheidsinstantie, agentschap of ander orgaan die/dat een AI-systeem of een AI-model voor algemene doeleinden ontwikkelt of laat ontwikkelen en dat systeem of model in de handel brengt of het AI-systeem in gebruik stelt onder de eigen naam of merk, al dan niet tegen betaling | I27: aanbieder, aanbieders, Aanbieders van AI-systemen met een hoog risico | J27: unknown | K27: 0 | M27: 11752 | P27: =IF(OR(N27="",N27="unsure"),"",INDEX(Labels!$B$2:$B$15,MATCH(N27,Labels!$A$2:$A$15,0))) | Q27: =IF(P27="","",IF(N27=J27,1,0)) | R27: =IF(P27="","",IF(SIGN(P27)=SIGN(K27),1,0)) | S27: =IF(P27="","",ABS(P27-K27))
A28: 27 | B28: found | C28: 32016R0679 | D28: KEY:32016R0679:secretariaat | E28: Known actor (not defined), class office. Aliases: secretariaat van het Comité. Part of KEY:32016R0679:comite. | F28: secretariaat, secretariaat van het Comité | G28: KEY:32016R0679:comite | H28: Known actor (not defined), class body. Aliases: Europees Comité voor gegevensbescherming. | I28: Comité, comité | J28: part of: A in B | K28: 0.5 | L28: inventory: part_of in inventory | M28: 510 | P28: =IF(OR(N28="",N28="unsure"),"",INDEX(Labels!$B$2:$B$15,MATCH(N28,Labels!$A$2:$A$15,0))) | Q28: =IF(P28="","",IF(N28=J28,1,0)) | R28: =IF(P28="","",IF(SIGN(P28)=SIGN(K28),1,0)) | S28: =IF(P28="","",ABS(P28-K28))
A29: 28 | B29: different | C29: 32024R1689 | D29: 32024R1689:aanbieder | E29: 32024R1689 art. 3: een natuurlijke of rechtspersoon, overheidsinstantie, agentschap of ander orgaan die/dat een AI-systeem of een AI-model voor algemene doeleinden ontwikkelt of laat ontwikkelen en dat systeem of model in de handel brengt of het AI-systeem in gebruik stelt onder de eigen naam of merk, al dan niet tegen betaling | F29: aanbieder, aanbieders, Aanbieders van AI-systemen met een hoog risico | G29: 32024R1689:markttoezichtautoriteit | H29: 32024R1689 art. 3: de nationale autoriteit die de activiteiten verricht en maatregelen neemt als bedoeld in Verordening (EU) 2019/1020 | I29: markttoezichtautoriteit, markttoezichtautoriteiten, Markttoezichtautoriteiten | J29: different | K29: -0.25 | M29: 3536 | P29: =IF(OR(N29="",N29="unsure"),"",INDEX(Labels!$B$2:$B$15,MATCH(N29,Labels!$A$2:$A$15,0))) | Q29: =IF(P29="","",IF(N29=J29,1,0)) | R29: =IF(P29="","",IF(SIGN(P29)=SIGN(K29),1,0)) | S29: =IF(P29="","",ABS(P29-K29))
A30: 29 | B30: different | C30: 32016R0679 | D30: 32016R0679:vertegenwoordiger | E30: 32016R0679 art. 4: een in de Unie gevestigde natuurlijke persoon of rechtspersoon die uit hoofde van artikel 27 schriftelijk door de verwerkingsverantwoordelijke of de verwerker is aangewezen om de verwerkingsverantwoordelijke of de verwerker te vertegenwoordigen in verband met hun respectieve verplichtingen krachtens deze verordening | F30: vertegenwoordiger van de verwerkingsverantwoordelijke, vertegenwoordiger, vertegenwoordiger van de verwerker | G30: 32016R0679:verwerkingsverantwoordelijke | H30: 32016R0679 art. 4: een natuurlijke persoon of rechtspersoon, een overheidsinstantie, een dienst of een ander orgaan die/dat, alleen of samen met anderen, het doel van en de middelen voor de verwerking van persoonsgegevens vaststelt; wanneer de doelstellingen van en de middelen voor deze verwerking in het Unierecht of het lidstatelijke recht worden vastgesteld, kan daarin worden bepaald wie de verwerkingsverantwoordelijke is of volgens welke criteria deze wordt aangewezen | I30: verwerkingsverantwoordelijke, verwerkingsverantwoordelijken, gezamenlijke verwerkingsverantwoordelijken | J30: different | K30: -0.25 | M30: 520 | P30: =IF(OR(N30="",N30="unsure"),"",INDEX(Labels!$B$2:$B$15,MATCH(N30,Labels!$A$2:$A$15,0))) | Q30: =IF(P30="","",IF(N30=J30,1,0)) | R30: =IF(P30="","",IF(SIGN(P30)=SIGN(K30),1,0)) | S30: =IF(P30="","",ABS(P30-K30))
A31: 30 | B31: unknown | C31: 32016R0679, 32024R1689 | D31: 32016R0679:de_betrokkene | E31: 32016R0679 art. 4: alle informatie over een geïdentificeerde of identificeerbare natuurlijke persoon | F31: betrokkene | G31: 32024R1689:aangemelde_instantie | H31: 32024R1689 art. 3: een conformiteitsbeoordelingsinstantie die overeenkomstig deze verordening en andere relevante harmonisatiewetgeving van de Unie, is aangemeld | I31: Aangemelde instanties, aangemelde instantie, aangemelde instanties | J31: unknown | K31: 0 | M31: 1196 | P31: =IF(OR(N31="",N31="unsure"),"",INDEX(Labels!$B$2:$B$15,MATCH(N31,Labels!$A$2:$A$15,0))) | Q31: =IF(P31="","",IF(N31=J31,1,0)) | R31: =IF(P31="","",IF(SIGN(P31)=SIGN(K31),1,0)) | S31: =IF(P31="","",ABS(P31-K31))
A32: 31 | B32: found | C32: 32016R0679 | D32: KEY:32016R0679:voorzitter | E32: Known actor (not defined), class office. Aliases: voorzitter van het Comité. Part of KEY:32016R0679:comite. | F32: voorzitter van het Comité, voorzitter | G32: KEY:32016R0679:comite | H32: Known actor (not defined), class body. Aliases: Europees Comité voor gegevensbescherming. | I32: Comité, comité | J32: part of: A in B | K32: 0.5 | L32: inventory: part_of in inventory | M32: 612 | P32: =IF(OR(N32="",N32="unsure"),"",INDEX(Labels!$B$2:$B$15,MATCH(N32,Labels!$A$2:$A$15,0))) | Q32: =IF(P32="","",IF(N32=J32,1,0)) | R32: =IF(P32="","",IF(SIGN(P32)=SIGN(K32),1,0)) | S32: =IF(P32="","",ABS(P32-K32))
A33: 32 | B33: unknown | C33: 32016R0679, 32024R1689 | D33: 32024R1689:nationale_bevoegde_autoriteit | E33: 32024R1689 art. 3: een aanmeldende autoriteit of een de markttoezichtautoriteit; wat betreft AI-systemen die door instellingen, organen en instanties van de EU in gebruik worden gesteld of worden gebruikt, worden verwijzingen naar nationale bevoegde autoriteiten of markttoezichtautoriteiten in deze verordening begrepen als verwijzingen naar de Europese Toezichthouder voor gegevensbescherming | F33: nationale bevoegde autoriteiten, Nationale bevoegde autoriteiten | G33: KEY:32016R0679:comite | H33: Known actor (not defined), class body. Aliases: Europees Comité voor gegevensbescherming. | I33: Comité, comité | J33: unknown | K33: 0 | M33: 867 | P33: =IF(OR(N33="",N33="unsure"),"",INDEX(Labels!$B$2:$B$15,MATCH(N33,Labels!$A$2:$A$15,0))) | Q33: =IF(P33="","",IF(N33=J33,1,0)) | R33: =IF(P33="","",IF(SIGN(P33)=SIGN(K33),1,0)) | S33: =IF(P33="","",ABS(P33-K33))
A34: 33 | B34: unknown | C34: 32016R0679, 32024R1689 | D34: 32016R0679:verwerker | E34: 32016R0679 art. 4: een natuurlijke persoon of rechtspersoon, een overheidsinstantie, een dienst of een ander orgaan die/dat ten behoeve van de verwerkingsverantwoordelijke persoonsgegevens verwerkt | F34: verwerker, verwerkers, eerste verwerker | G34: 32024R1689:aanmeldende_autoriteit | H34: 32024R1689 art. 3: de nationale autoriteit die verantwoordelijk is voor het opzetten en uitvoeren van de noodzakelijke procedures voor de beoordeling, aanwijzing en kennisgeving van de conformiteitsbeoordelingsinstanties en de monitoring hiervan | I34: aanmeldende autoriteit, Aanmeldende autoriteiten | J34: unknown | K34: 0 | M34: 1248 | P34: =IF(OR(N34="",N34="unsure"),"",INDEX(Labels!$B$2:$B$15,MATCH(N34,Labels!$A$2:$A$15,0))) | Q34: =IF(P34="","",IF(N34=J34,1,0)) | R34: =IF(P34="","",IF(SIGN(P34)=SIGN(K34),1,0)) | S34: =IF(P34="","",ABS(P34-K34))
A35: 34 | B35: found | C35: 32024R1689 | D35: 32024R1689:markttoezichtautoriteit | E35: 32024R1689 art. 3: de nationale autoriteit die de activiteiten verricht en maatregelen neemt als bedoeld in Verordening (EU) 2019/1020 | F35: markttoezichtautoriteit, markttoezichtautoriteiten, Markttoezichtautoriteiten | G35: 32024R1689:nationale_bevoegde_autoriteit | H35: 32024R1689 art. 3: een aanmeldende autoriteit of een de markttoezichtautoriteit; wat betreft AI-systemen die door instellingen, organen en instanties van de EU in gebruik worden gesteld of worden gebruikt, worden verwijzingen naar nationale bevoegde autoriteiten of markttoezichtautoriteiten in deze verordening begrepen als verwijzingen naar de Europese Toezichthouder voor gegevensbescherming | I35: nationale bevoegde autoriteiten, Nationale bevoegde autoriteiten | J35: subtype: A is a kind of B | K35: 0.8 | L35: definition: een aanmeldende autoriteit of een de markttoezichtautoriteit | M35: 578 | P35: =IF(OR(N35="",N35="unsure"),"",INDEX(Labels!$B$2:$B$15,MATCH(N35,Labels!$A$2:$A$15,0))) | Q35: =IF(P35="","",IF(N35=J35,1,0)) | R35: =IF(P35="","",IF(SIGN(P35)=SIGN(K35),1,0)) | S35: =IF(P35="","",ABS(P35-K35))
A36: 35 | B36: different | C36: 32024R1689 | D36: 32024R1689:aibureau | E36: 32024R1689 art. 3: de taak van de Commissie waarbij zij bijdraagt aan de uitvoering van, de monitoring van en het toezicht op AI-systemen en AI-modellen voor algemene doeleinden, en AI-governance, als bepaald in het besluit van de Commissie van 24 januari 2024; verwijzingen in deze verordening naar het AI-bureau worden begrepen als verwijzingen naar de Commissie | F36: AI-bureau | G36: KEY:EU:lidstaat | H36: Known actor (not defined), class state. | I36: lidstaten, lidstaat, aanmeldende lidstaat | J36: different | K36: -0.25 | M36: 3404 | P36: =IF(OR(N36="",N36="unsure"),"",INDEX(Labels!$B$2:$B$15,MATCH(N36,Labels!$A$2:$A$15,0))) | Q36: =IF(P36="","",IF(N36=J36,1,0)) | R36: =IF(P36="","",IF(SIGN(P36)=SIGN(K36),1,0)) | S36: =IF(P36="","",ABS(P36-K36))
A37: 36 | B37: found | C37: 32024R1689 | D37: 32024R1689:rechtshandhavingsinstantie | E37: 32024R1689 art. 3: a) iedere overheidsinstantie die bevoegd is voor de voorkoming van, het onderzoek naar, de opsporing en de vervolging van strafbare feiten of de uitvoering van straffen, met inbegrip van de bescherming tegen en de voorkoming van gevaren voor de openbare veiligheid, of b) ieder ander orgaan dat of iedere andere entiteit die krachtens het recht van de lidstaten is gemachtigd openbaar gezag en openbare bevoegdheden uit te oefenen met het oog op de voorkoming van, het onderzoek naar, de opsporing en de vervolging van strafbare feiten of de uitvoering van straffen, met inbegrip v | F37: rechtshandhavingsinstanties | G37: KEY:EU:overheidsinstantie | H37: Known actor (not defined), class authority. | I37: overheidsinstantie in kwestie | J37: subtype: A is a kind of B | K37: 0.8 | L37: definition: iedere overheidsinstantie | M37: 2 | P37: =IF(OR(N37="",N37="unsure"),"",INDEX(Labels!$B$2:$B$15,MATCH(N37,Labels!$A$2:$A$15,0))) | Q37: =IF(P37="","",IF(N37=J37,1,0)) | R37: =IF(P37="","",IF(SIGN(P37)=SIGN(K37),1,0)) | S37: =IF(P37="","",ABS(P37-K37))
A38: 37 | B38: different | C38: 32016R0679 | D38: 32016R0679:verwerkingsverantwoordelijke | E38: 32016R0679 art. 4: een natuurlijke persoon of rechtspersoon, een overheidsinstantie, een dienst of een ander orgaan die/dat, alleen of samen met anderen, het doel van en de middelen voor de verwerking van persoonsgegevens vaststelt; wanneer de doelstellingen van en de middelen voor deze verwerking in het Unierecht of het lidstatelijke recht worden vastgesteld, kan daarin worden bepaald wie de verwerkingsverantwoordelijke is of volgens welke criteria deze wordt aangewezen | F38: verwerkingsverantwoordelijke, verwerkingsverantwoordelijken, gezamenlijke verwerkingsverantwoordelijken | G38: KEY:EU:commissie | H38: Known actor (not defined), class institution. Aliases: Europese Commissie. | I38: Commissie, toezichthoudende autoriteiten en de Commissie | J38: different | K38: -0.25 | M38: 16744 | P38: =IF(OR(N38="",N38="unsure"),"",INDEX(Labels!$B$2:$B$15,MATCH(N38,Labels!$A$2:$A$15,0))) | Q38: =IF(P38="","",IF(N38=J38,1,0)) | R38: =IF(P38="","",IF(SIGN(P38)=SIGN(K38),1,0)) | S38: =IF(P38="","",ABS(P38-K38))
A39: 38 | B39: unknown | C39: 32016R0679, 32024R1689 | D39: 32024R1689:aanbieder | E39: 32024R1689 art. 3: een natuurlijke of rechtspersoon, overheidsinstantie, agentschap of ander orgaan die/dat een AI-systeem of een AI-model voor algemene doeleinden ontwikkelt of laat ontwikkelen en dat systeem of model in de handel brengt of het AI-systeem in gebruik stelt onder de eigen naam of merk, al dan niet tegen betaling | F39: aanbieder, aanbieders, Aanbieders van AI-systemen met een hoog risico | G39: KEY:32016R0679:comite | H39: Known actor (not defined), class body. Aliases: Europees Comité voor gegevensbescherming. | I39: Comité, comité | J39: unknown | K39: 0 | M39: 5304 | P39: =IF(OR(N39="",N39="unsure"),"",INDEX(Labels!$B$2:$B$15,MATCH(N39,Labels!$A$2:$A$15,0))) | Q39: =IF(P39="","",IF(N39=J39,1,0)) | R39: =IF(P39="","",IF(SIGN(P39)=SIGN(K39),1,0)) | S39: =IF(P39="","",ABS(P39-K39))
A40: 39 | B40: different | C40: 32016R0679 | D40: 32016R0679:toezichthoudende_autoriteit | E40: 32016R0679 art. 4: een door een lidstaat ingevolge artikel 51 ingestelde onafhankelijke overheidsinstantie | F40: toezichthoudende autoriteit, toezichthoudende autoriteiten, bevoegde toezichthoudende autoriteit | G40: KEY:EU:commissie | H40: Known actor (not defined), class institution. Aliases: Europese Commissie. | I40: Commissie, toezichthoudende autoriteiten en de Commissie | J40: different | K40: -0.25 | M40: 18193 | P40: =IF(OR(N40="",N40="unsure"),"",INDEX(Labels!$B$2:$B$15,MATCH(N40,Labels!$A$2:$A$15,0))) | Q40: =IF(P40="","",IF(N40=J40,1,0)) | R40: =IF(P40="","",IF(SIGN(P40)=SIGN(K40),1,0)) | S40: =IF(P40="","",ABS(P40-K40))
...

Sheet Scores
A1: Relation validation scores (update as the Review sheet is filled in)
A3: stratum | B3: cases | C3: reviewed | D3: agreement | E3: same sign | F3: positive per reviewer | G3: mean score error | H3: share of all ID pairs
A4: found | B4: =COUNTIF(Review!$B$2:$B$41,A4) -> 16 | C4: =COUNTIFS(Review!$B$2:$B$41,A4,Review!$P$2:$P$41,">-2") -> 0 | D4: =IF(C4=0,"",SUMIFS(Review!$Q$2:$Q$41,Review!$B$2:$B$41,A4)/C4) | E4: =IF(C4=0,"",SUMIFS(Review!$R$2:$R$41,Review!$B$2:$B$41,A4)/C4) | F4: =IF(C4=0,"",COUNTIFS(Review!$B$2:$B$41,A4,Review!$P$2:$P$41,">0")/C4) | G4: =IF(C4=0,"",SUMIFS(Review!$S$2:$S$41,Review!$B$2:$B$41,A4)/C4) | H4: 0.0469
A5: different | B5: =COUNTIF(Review!$B$2:$B$41,A5) -> 14 | C5: =COUNTIFS(Review!$B$2:$B$41,A5,Review!$P$2:$P$41,">-2") -> 0 | D5: =IF(C5=0,"",SUMIFS(Review!$Q$2:$Q$41,Review!$B$2:$B$41,A5)/C5) | E5: =IF(C5=0,"",SUMIFS(Review!$R$2:$R$41,Review!$B$2:$B$41,A5)/C5) | F5: =IF(C5=0,"",COUNTIFS(Review!$B$2:$B$41,A5,Review!$P$2:$P$41,">0")/C5) | G5: =IF(C5=0,"",SUMIFS(Review!$S$2:$S$41,Review!$B$2:$B$41,A5)/C5) | H5: 0.6373
A6: unknown | B6: =COUNTIF(Review!$B$2:$B$41,A6) -> 10 | C6: =COUNTIFS(Review!$B$2:$B$41,A6,Review!$P$2:$P$41,">-2") -> 0 | D6: =IF(C6=0,"",SUMIFS(Review!$Q$2:$Q$41,Review!$B$2:$B$41,A6)/C6) | E6: =IF(C6=0,"",SUMIFS(Review!$R$2:$R$41,Review!$B$2:$B$41,A6)/C6) | F6: =IF(C6=0,"",COUNTIFS(Review!$B$2:$B$41,A6,Review!$P$2:$P$41,">0")/C6) | G6: =IF(C6=0,"",SUMIFS(Review!$S$2:$S$41,Review!$B$2:$B$41,A6)/C6) | H6: 0.3158
A7: all | B7: =SUM(B4:B6) -> 40 | C7: =SUM(C4:C6) -> 0 | D7: =IF(C7=0,"",SUM(Review!$Q$2:$Q$41)/C7) | E7: =IF(C7=0,"",SUM(Review!$R$2:$R$41)/C7) | F7: =IF(C7=0,"",COUNTIF(Review!$P$2:$P$41,">0")/C7) | G7: =IF(C7=0,"",SUM(Review!$S$2:$S$41)/C7)
A9: Reading the strata
A10: found: agreement = precision of the relations the system found.
A11: different, unknown: 'positive per reviewer' = share of affected norm pairs whose relation the system misses (pairs were drawn in proportion to norm pairs affected).
A12: same sign: system and reviewer agree on +, 0 or -; a pair the system calls 'unknown' (0) never has the same sign as a reviewed label, so read 'unknown' by the column F.
A13: share of all ID pairs (blue): share of all ID pairs in each stratum when the sample was drawn, computed by actor_relations_validate.py.

Sheet Labels
A1: relation | B1: score | C1: meaning
A2: same / equivalent | B2: 1 | C2: the same actor, or the same actor under two documents
A3: instance: A is B | B3: 0.9 | C3: A is the named body that fills role B (or the reverse)
A4: subtype: A is a kind of B | B4: 0.8 | C4: every A is a B
A5: subtype: B is a kind of A | B5: 0.8 | C5: every B is an A
A6: subtype, two steps: A ... B | B6: 0.6 | C6: A is a kind of a kind of B
A7: subtype, two steps: B ... A | B7: 0.6 | C7: B is a kind of a kind of A
A8: part of: A in B | B8: 0.5 | C8: A belongs to B (chair of a board, office of the Commission)
A9: part of: B in A | B9: 0.5 | C9: B belongs to A
A10: can be the same entity | B10: 0.4 | C10: different roles often held by one organisation
A11: linked roles | B11: 0.2 | C11: different actors whose roles are tied (controller and processor)
A12: sibling | B12: 0.15 | C12: two kinds of the same actor (provider and importer)
A13: different | B13: -0.25 | C13: clearly different actors
A14: unknown | B14: 0 | C14: used by the system only: the IDs never share a document
A15: unsure | C15: the reviewer cannot decide
