Workbook

Sheet README
A1: Validation of the object → EuroVoc mapping (Step 7)
A3: What to do
A4: 1. Go to the Validate sheet. Rows with in_sample = yes (green) come first: judge those.
A5: 2. Fill in the yellow columns only: judgement (drop-down), better_concept (optional), notes.
A6: 3. Judge candidate 1 mainly; use candidates 2-3 to decide 'partial'.
A7: 4. The Summary sheet updates automatically as you fill in judgements.
A9: Judgement codes
A10: correct – candidate 1 is the right concept, or an acceptable close one.
A11: partial – candidate 1 is in the right area but too broad/narrow, or a lower candidate is right.
A12: wrong – no candidate fits the object.
A13: unclear – the object itself cannot be judged (placeholder, fragment, unresolved reference).
A14: For unmapped objects: 'correct' = rightly left unmapped; 'wrong' = a EuroVoc concept clearly exists.
... A25: Example of a filled-in row (not part of the data)
A26: object | B26: level | C26: cand_1 | D26: conf_1 | E26: judgement | F26: better_concept | G26: notes
A27: ten minste de in lid 6 bepaalde informatie | B27: head | C27: informatie | D27: 0.8 | E27: partial | F27: melding | G27: concept right but generic; the object refers to lid 6

Sheet Validate
A1: in_sample | B1: stratum | C1: object | D1: raw_object | E1: head | F1: level | G1: matched_label | H1: cand_1 | I1: conf_1 | J1: pct_1 | K1: cand_2 | L1: conf_2 | M1: cand_3 | N1: conf_3 | O1: n_norms | P1: example_norm | Q1: context | R1: judgement | S1: better_concept | T1: notes
A2: yes | B2: phrase | C2: aansprakelijkheid | D2: van aansprakelijkheid op grond van lid 2 | E2: aansprakelijkheid | F2: phrase | G2: aansprakelijkheid | H2: aansprakelijkheid | I2: 1 | O2: 1 | P2: 32016R0679:82:3:4 | Q2: Een verwerkingsverantwoordelijke of verwerker wordt van aansprakelijkheid op grond van lid 2 vrijgesteld indien hij bewijst dat hij op geen enkele wijze verantwoordelijk is voor het schadeveroorzakende feit.
A3: yes | B3: phrase | C3: besluit | D3: haar besluit | E3: besluit | F3: phrase | G3: besluit | H3: besluit | I3: 0.8 | K3: besluit (EU) | L3: 0.8 | O3: 18 | P3: 32024R1689:46:5:11 | Q3: …bben de mogelijkheid hun standpunten uiteen te zetten. Met het oog daarop besluit de Commissie of de toelating gerechtvaardigd is. De Commissie richt haar besluit aan de betrokken lidstaat en de relevante operatoren.
A4: yes | B4: phrase | C4: comité | D4: het in artikel 22 van Verordening (EU) nr. 1025/2012 bedoelde comité | E4: comité | F4: phrase | G4: comité | H4: comité (EU) | I4: 1 | O4: 1 | P4: 32024R1689:41:2:1 | Q4: Alvorens een ontwerpuitvoeringshandeling op te stellen, stelt de Commissie het in artikel 22 van Verordening (EU) nr. 1025/2012 bedoelde comité ervan in kennis dat zij van oordeel is dat aan de voorwaarden van lid 1 van dit artikel is voldaan.
A5: yes | B5: phrase | C5: documentatie | D5: de in artikel 18 bedoelde documentatie | E5: documentatie | F5: phrase | G5: documentatie | H5: documentatie | I5: 1 | O5: 6 | P5: 32024R1689:16:whole:3 | Q5: … of geregistreerd merk en hun contactadres; c) beschikken over een systeem voor kwaliteitsbeheer dat in overeenstemming is met artikel 17; d) bewaren de in artikel 18 bedoelde documentatie; e) bewaren de in artikel 19 bedoelde logs die automatisch door hun AI-systemen met een hoog risico zijn gegenereerd, wanneer zij hierover de control…
A6: yes | B6: phrase | C6: grenzen | E6: grens | F6: phrase | G6: grens | H6: grens | I6: 1 | O6: 1 | P6: 32016R0679:49:5:7 | Q6: …dequaatheidsbesluit kunnen in Unierechtelijke of lidstaatrechtelijke bepalingen of bepalingen om gewichtige redenen van openbaar belang uitdrukkelijk grenzen worden gesteld aan de doorgifte van specifieke categorieën van persoonsgegevens aan een derde land of een internationale organisatie. De lidstaten st…
A7: yes | B7: phrase | C7: grondrechten | D7: Significante risico’s voor de gezondheid en veiligheid en de grondrechten | E7: grondrecht | F7: phrase | G7: grondrecht | H7: grondrechten | I7: 0.8 | K7: grondeigendom | L7: 0.8 | O7: 1 | P7: 32024R1689:57:11:18 | Q7: …e of corrigerende bevoegdheden van de bevoegde autoriteiten die toezicht houden binnen de testomgevingen onverlet, ook op regionaal of lokaal niveau. Significante risico’s voor de gezondheid en veiligheid en de grondrechten die tijdens het ontwikkelen en testen van dergelijke AI-systemen worden vastgesteld, worden op adequate wijze beperkt. De nationale bevoegde autorite…
A8: yes | B8: phrase | C8: pseudonimisering | E8: pseudonimisering | F8: phrase | G8: pseudonimisering | H8: anonimisering | I8: 1 | O8: 1 | P8: 32016R0679:89:1:2 | Q8: …rganisatorische maatregelen zijn getroffen om de inachtneming van het beginsel van minimale gegevensverwerking te garanderen. Deze maatregelen kunnen pseudonimisering omvatten, mits aldus die doeleinden in kwestie kunnen worden verwezenlijkt. Wanneer die doeleinden kunnen worden verwezenlijkt door verdere verwerkin…
A9: yes | B9: phrase | C9: rollen | D9: de rollen en taken van de nationale bevoegde autoriteiten overeenkomstig dit hoofdstuk | E9: rol | F9: phrase | G9: rol | H9: grondbewerking | I9: 1 | O9: 1 | P9: 32024R1689:57:3:7 | Q9: …houder voor gegevensbescherming kan ook een AI-testomgeving voor regelgeving opzetten voor de instellingen, organen en instanties van de Unie, en kan de rollen en taken van de nationale bevoegde autoriteiten overeenkomstig dit hoofdstuk uitoefenen.
A10: yes | B10: phrase | C10: schadevergoeding | E10: schadevergoeding | F10: phrase | G10: schadevergoeding | H10: schadevergoeding | I10: 1 | O10: 1 | P10: 32016R0679:82:1:1 | Q10: …ateriële schade heeft geleden ten gevolge van een inbreuk op deze verordening, heeft het recht om van de verwerkingsverantwoordelijke of de verwerker schadevergoeding te ontvangen voor de geleden schade.
A11: yes | B11: phrase | C11: verslag | E11: verslag | F11: phrase | G11: verslag | H11: verslag | I11: 1 | O11: 12 | P11: 32024R1689:56:5:4 | Q11: Het AI-bureau streeft ernaar ervoor te zorgen dat de deelnemers aan de praktijkcodes regelmatig verslag uitbrengen aan het AI-bureau over de uitvoering van de verbintenissen en de genomen maatregelen en de resultaten daarvan, onder meer waar nodig gemet…
A12: yes | B12: head | C12: aanvullende informatie | E12: informatie | F12: head | G12: informatie | H12: informatie | I12: 0.8 | O12: 1 | P12: 32016R0679:12:6:13 | Q12: …j redenen heeft om te twijfelen aan de identiteit van de natuurlijke persoon die het verzoek indient als bedoeld in de artikelen 15 tot en met 21, om aanvullende informatie vragen die nodig is ter bevestiging van de identiteit van de betrokkene.
A13: yes | B13: head | C13: Administratieve geldboeten | E13: geldboet | F13: head | G13: geldboet | H13: geldboete | I13: 0.8 | O13: 1 | P13: 32016R0679:83:2:2 | Q13: Administratieve geldboeten worden, naargelang de omstandigheden van het concrete geval, opgelegd naast of in plaats van de in artikel 58, lid 2, onder a) tot en met h) en onder…
A14: yes | B14: head | C14: afdoende garanties met betrekking tot het toepassen van passende technische en organisatorische maatregelen | E14: garantie | F14: head | G14: garantie | H14: garantie | I14: 0.8 | O14: 1 | P14: 32016R0679:28:4:7 | Q14: …lid 3 bedoelde overeenkomst of andere rechtshandeling tussen de verwerkingsverantwoordelijke en de verwerker zijn opgenomen, met name de verplichting afdoende garanties met betrekking tot het toepassen van passende technische en organisatorische maatregelen te bieden opdat de verwerking aan het bepaalde in deze verordening voldoet. Wanneer de andere verwerker zijn verplichtingen inzake gegevensbeschermin…
A15: yes | B15: head | C15: geharmoniseerde norm | D15: de geharmoniseerde norm | E15: norm | F15: head | G15: norm | H15: norm | I15: 0.8 | O15: 1 | P15: 32024R1689:41:4:2 | Q15: …aan de Commissie voorstelt met het oog op de bekendmaking van de referentie ervan in het Publicatieblad van de Europese Unie, beoordeelt de Commissie de geharmoniseerde norm overeenkomstig Verordening (EU) nr. 1025/2012. Wanneer de referentie van een geharmoniseerde norm in het Publicatieblad van de Europese Unie wordt be…
A16: yes | B16: head | C16: informatie en documentatie met betrekking tot de door hen genomen maatregelen | D16: alle informatie en documentatie met betrekking tot de op grond van de leden 1 tot en met 4 door hen genomen maatregelen | E16: informatie | F16: head | G16: informatie | H16: informatie | I16: 0.8 | O16: 1 | P16: 32024R1689:24:5:11 | Q16: …een met redenen omkleed verzoek van een relevante bevoegde autoriteit verstrekken distributeurs van een AI-systeem met een hoog risico die autoriteit alle informatie en documentatie met betrekking tot de op grond van de leden 1 tot en met 4 door hen genomen maatregelen die nodig zijn om aan te tonen dat het systeem voldoet aan de eisen van afdeling 2.
A17: yes | B17: head | C17: Persoonsgegevens betreffende strafrechtelijke veroordelingen | D17: Persoonsgegevens betreffende strafrechtelijke veroordelingen en strafbare feiten of daarmee verband houdende veiligheidsmaatregelen | E17: veroordeling | F17: head | G17: veroordeling | H17: strafsanctie | I17: 0.8 | O17: 1 | P17: 32016R0679:10:whole:1 | Q17: Persoonsgegevens betreffende strafrechtelijke veroordelingen en strafbare feiten of daarmee verband houdende veiligheidsmaatregelen mogen op grond van artikel 6, lid 1, alleen worden verwerkt onder toezicht van de overheid of indien de verwerking is toegestaan bij Unierechtelijke …
A18: yes | B18: head | C18: richtsnoeren, aanbevelingen en beste praktijken | E18: aanbeveling | F18: head | G18: aanbeveling | H18: aanbeveling (EU) | I18: 0.64 | K18: aanbeveling | L18: 0.64 | O18: 2 | P18: 32016R0679:70:1:5 | Q18: …ie wat betreft bindende bedrijfsvoorschriften tussen verwerkingsverantwoordelijken, verwerkers, en toezichthoudende autoriteiten; d) uitvaardigen van richtsnoeren, aanbevelingen en beste praktijken inzake procedures voor het wissen van links, kopieën of reproducties van persoonsgegevens uit algemeen beschikbare communicatiediensten als bedoeld i…
A19: yes | B19: head | C19: van de volgende besluiten | D19: een van de volgende besluiten | E19: besluit | F19: head | G19: besluit | H19: besluit (EU) | I19: 0.64 | K19: besluit | L19: 0.64 | O19: 1 | P19: 32024R1689:76:3:3 | Q19: …gebracht of andere redenen heeft om aan te nemen dat niet aan de in de artikelen 60 en 61 bepaalde voorwaarden wordt voldaan, kan op haar grondgebied een van de volgende besluiten nemen, naargelang van het geval: a) de tests onder reële omstandigheden opschorten of beëindigen; b) aanbieders of potentiële aanbieders en gebruiksv…
A20: yes | B20: head | C20: verplichtingen van die andere verwerker | D20: voor het nakomen van de verplichtingen van die andere verwerker | E20: verplichting | F20: head | G20: verplichting | H20: contract | I20: 0.8 | O20: 1 | P20: 32016R0679:28:4:5 | Q20: …plichtingen inzake gegevensbescherming niet nakomt, blijft de eerste verwerker ten aanzien van de verwerkingsverantwoordelijke volledig aansprakelijk voor het nakomen van de verplichtingen van die andere verwerker.
A21: yes | B21: head | C21: voorschriften voor sancties en andere handhavingsmaatregelen | D21: de in lid 1 bedoelde voorschriften voor sancties en andere handhavingsmaatregelen | E21: voorschrift | F21: head | G21: voorschrift | H21: verordening | I21: 0.8 | O21: 1 | P21: 32024R1689:99:2:5 | Q21: De lidstaten stellen de Commissie onverwijld en uiterlijk op de datum van toepassing in kennis van de in lid 1 bedoelde voorschriften voor sancties en andere handhavingsmaatregelen en delen haar onverwijld alle latere wijzigingen daarvan mee.
A22: yes | B22: compound | C22: doelstelling van algemeen belang | D22: aan een doelstelling van algemeen belang | E22: doelstelling | F22: compound | G22: telling | H22: telling | I22: 0.6 | O22: 1 | P22: 32016R0679:6:3:3 | Q22: …erking, zoals die voor andere specifieke verwerkingssituaties als bedoeld in hoofdstuk IX. Het Unierecht of het lidstatelijke recht moet beantwoorden aan een doelstelling van algemeen belang en moet evenredig zijn met het nagestreefde gerechtvaardigde doel.
A23: yes | B23: compound | C23: eindverslag waarin de in de testomgeving uitgevoerde activiteiten en de daarmee verband houdende resultaten en leerresultaten worden beschreven | D23: een eindverslag waarin de in de testomgeving uitgevoerde activiteiten en de daarmee verband houdende resultaten en leerresultaten worden beschreven | E23: eindverslag | F23: compound | G23: verslag | H23: verslag | I23: 0.6 | O23: 1 | P23: 32024R1689:57:7:12 | Q23: …kt de bevoegde autoriteit een schriftelijk bewijs van de met succes in de testomgeving uitgevoerde activiteiten. De bevoegde autoriteit verstrekt ook een eindverslag waarin de in de testomgeving uitgevoerde activiteiten en de daarmee verband houdende resultaten en leerresultaten worden beschreven. Aanbieders kunnen dergelijke documentatie gebruiken om bij het conformiteitsbeoordelingsproces of relevante markttoezicht-activiteiten aan te tonen …
A24: yes | B24: compound | C24: geïnformeerde toestemming | D24: De geïnformeerde toestemming | E24: toestemming | F24: compound | G24: stemming | H24: stemming | I24: 0.6 | O24: 2 | P24: 32024R1689:61:2:2 | Q24: De geïnformeerde toestemming wordt gedateerd en gedocumenteerd en er wordt een kopie verstrekt aan de proefpersonen of hun wettelijke vertegenwoordiger.
A25: yes | B25: compound | C25: of de doelstellingen worden verwezenlijkt | D25: of de doelstellingen daarvan worden verwezenlijkt | E25: doelstelling | F25: compound | G25: telling | H25: telling | I25: 0.6 | O25: 1 | P25: 32024R1689:56:6:9 | Q25: … en de AI-board beoordelen of de praktijkcodes betrekking hebben op de verplichtingen van de artikelen 53 en 55, en monitoren en evalueren regelmatig of de doelstellingen daarvan worden verwezenlijkt. Zij maken hun beoordeling of de praktijkcodes toereikend zijn bekend. De Commissie kan door middel van een uitvoeringshandeling een praktijkcode goe…
A26: yes | B26: compound | C26: opstelling van gedragscodes | D26: de opstelling van gedragscodes | E26: opstelling | F26: compound | G26: telling | H26: telling | I26: 0.6 | O26: 2 | P26: 32016R0679:40:1:1 | Q26: De lidstaten, de toezichthoudende autoriteiten, het Comité en de Commissie bevorderen de opstelling van gedragscodes die, met inachtneming van de specifieke kenmerken van de diverse gegevensverwerkingssectoren en de specifieke behoeften van kleine, middelgrote en mi…
A27: yes | B27: compound | C27: opzetten en onderhouden van een EU-databank met de informatie betreffende bedoelde AI-systemen met een hoog risico die zijn geregistreerd en AI-systemen die niet als AI-systemen met een hoog risico worden beschouwd en die zijn geregistreerd | D27: het opzetten en onderhouden van een EU-databank met de in de leden 2 en 3 van dit artikel bedoelde informatie betreffende in artikel 6, lid 2, bedoelde AI-systemen met een hoog risico die overeenkomstig de artikelen 49 en 60 zijn geregistreerd en AI-systemen die niet als AI-systemen met een hoog risico worden beschouwd op grond van artikel 6, lid 3, en die zijn geregistreerd overeenkomstig artikel 6, lid 4 en artikel 49 | E27: eudatabank | F27: compound | G27: databank | H27: gegevensbank | I27: 0.6 | O27: 1 | P27: 32024R1689:71:1:3 | Q27: De Commissie zorgt in samenwerking met de lidstaten voor het opzetten en onderhouden van een EU-databank met de in de leden 2 en 3 van dit artikel bedoelde informatie betreffende in artikel 6, lid 2, bedoelde AI-systemen met een hoog risico die overeenkomstig de artikelen 49 en 60 zijn geregistreerd en AI-systemen die niet als AI-systemen met een hoog risico worden beschouwd op grond van artikel 6, lid 3, en die zijn geregistreerd overeenkomstig artikel 6, lid 4 en artikel 49. Bij het vaststellen van de functionele specificaties van een dergelijke databank raadpleegt de Commissie de deskundigen ter zake, en bij het bijwerk…
A28: yes | B28: compound | C28: regelgevingsspecificaties van elke sector, met de bestaande mechanismen voor governance, conformiteitsbeoordeling en handhaving en met de autoriteiten die zijn vastgesteld | D28: de regelgevingsspecificaties van elke sector, met de bestaande mechanismen voor governance, conformiteitsbeoordeling en handhaving en met de autoriteiten die daarin zijn vastgesteld | E28: regelgevingsspecificatie | F28: compound | G28: specificatie | H28: technische specificatie | I28: 0.6 | O28: 1 | P28: 32024R1689:112:12:20 | Q28: …handelingen, die betrekking heeft op sectorale harmonisatie-wetgeving van de Unie zoals vermeld in bijlage I, afdeling B, wordt rekening gehouden met de regelgevingsspecificaties van elke sector, met de bestaande mechanismen voor governance, conformiteitsbeoordeling en handhaving en met de autoriteiten die daarin zijn vastgesteld.
A29: yes | B29: compound | C29: toestemming tot toestemming | D29: de toestemming of machtiging tot toestemming | E29: toestemming | F29: compound | G29: stemming | H29: stemming | I29: 0.6 | O29: 1 | P29: 32016R0679:8:1:1 | Q29: …rechtmatig wanneer het kind ten minste 16 jaar is. Wanneer het kind jonger is dan 16 jaar is zulke verwerking slechts rechtmatig indien en voor zover de toestemming of machtiging tot toestemming in dit verband wordt verleend door de persoon die de ouderlijke verantwoordelijkheid voor het kind draagt. De lidstaten kunnen dienaangaande bij wet …
A30: yes | B30: compound | C30: transparantieverplichtingen | D30: de transparantieverplichtingen van dit lid | E30: transparantieverplichting | F30: compound | G30: verplichting | H30: contract | I30: 0.6 | O30: 1 | P30: 32024R1689:50:4:9 | Q30: …zoeken of te vervolgen. Wanneer de content deel uitmaakt van een kennelijk artistiek, creatief, satirisch, fictief of analoog werk of programma, zijn de transparantieverplichtingen van dit lid beperkt tot de openbaarmaking van het bestaan van dergelijke gegenereerde of bewerkte content op een passende wijze die de weergave of het genot van …
A31: yes | B31: compound | C31: vastgelegde vertrouwelijkheidsverplichtingen | D31: de in artikel 78 vastgelegde vertrouwelijkheidsverplichtingen | E31: vertrouwelijkheidsverplichting | F31: compound | G31: verplichting | H31: contract | I31: 0.6 | O31: 1 | P31: 32024R1689:70:5:9 | Q31: Bij de uitvoering van hun taken voldoen de nationale bevoegde autoriteiten aan de in artikel 78 vastgelegde vertrouwelijkheidsverplichtingen.
A32: yes | B32: embedding p20-47 | C32: ontwikkeling van benchmarks en meetmethoden | D32: de ontwikkeling van benchmarks en meetmethoden | E32: ontwikkeling | F32: embedding | H32: onderzoek en ontwikkeling | I32: 0.2896 | J32: 43.9 | K32: benchmarking | L32: 0.2098 | O32: 1 | P32: 32024R1689:15:2:2 | Q32: …en, moedigt de Commissie, in samenwerking met relevante belanghebbenden en organisaties, zoals metrologie- en benchmarkingautoriteiten, waar passend, de ontwikkeling van benchmarks en meetmethoden aan.
A33: yes | B33: embedding p20-47 | C33: handelingen | E33: handeling | F33: embedding | H33: vondeling | I33: 0.2882 | J33: 43.5 | O33: 1 | P33: 32016R0679:52:3:4 | Q33: De leden van toezichthoudende autoriteiten verrichten geen handelingen die onverenigbaar zijn met hun taken en verrichten gedurende hun ambtstermijn geen al dan niet bezoldigde beroepswerkzaamheden die onverenigbaar zijn…
A34: yes | B34: embedding p20-47 | C34: kopie | D34: een kopie | E34: kopie | F34: embedding | H34: fotokopie | I34: 0.2853 | J34: 42.7 | K34: microkopie | L34: 0.2684 | M34: koe | N34: 0.2075 | O34: 1 | P34: 32024R1689:61:2:4 | Q34: De geïnformeerde toestemming wordt gedateerd en gedocumenteerd en er wordt een kopie verstrekt aan de proefpersonen of hun wettelijke vertegenwoordiger.
A35: yes | B35: embedding p20-47 | C35: rectificatie van hem betreffende onjuiste persoonsgegevens | E35: rectificatie | F35: embedding | H35: richtlijn inzake het hergebruik van overheidsinformatie. | I35: 0.265 | J35: 37.3 | K35: recht op privacy | L35: 0.205 | M35: beroep tot nietigverklaring (EU) | N35: 0.2043 | O35: 1 | P35: 32016R0679:16:whole:1 | Q35: De betrokkene heeft het recht om van de verwerkingsverantwoordelijke onverwijld rectificatie van hem betreffende onjuiste persoonsgegevens te verkrijgen. Met inachtneming van de doeleinden van de verwerking heeft de betrokkene het recht vervollediging van onvolledige persoonsgegevens te …
A36: yes | B36: embedding p20-47 | C36: mogelijkheid | D36: van die mogelijkheid | E36: mogelijkheid | F36: embedding | H36: aanbod | I36: 0.257 | J36: 35.2 | K36: bestemming | L36: 0.2412 | M36: beslissing | N36: 0.2267 | O36: 2 | P36: 32024R1689:43:3:5 | Q36: …ling door een derde partij, mits die fabrikant alle geharmoniseerde normen voor alle relevante voorschriften heeft toegepast, kan de fabrikant alleen van die mogelijkheid gebruikmaken als hij ook geharmoniseerde normen of in voorkomend geval gemeenschappelijke specificaties als bedoeld in artikel 41 heeft toegepast, vo…
A37: yes | B37: embedding p20-47 | C37: Omvattende registers van strafrechtelijke veroordelingen | E37: register | F37: embedding | H37: strafregister | I37: 0.2448 | J37: 31.9 | K37: voltrekking van de straf | L37: 0.2021 | O37: 1 | P37: 32016R0679:10:whole:2 | Q37: …g is toegestaan bij Unierechtelijke of lidstaatrechtelijke bepalingen die passende waarborgen voor de rechten en vrijheden van de betrokkenen bieden. Omvattende registers van strafrechtelijke veroordelingen mogen alleen worden bijgehouden onder toezicht van de overheid.
A38: yes | B38: embedding p20-47 | C38: positieve conformiteitsbeoordelingsresultaten | E38: conformiteitsbeoordelingsresultat | F38: embedding | H38: conformiteitscontrole | I38: 0.2432 | J38: 31.5 | K38: positieve arbeidsbeleving | L38: 0.224 | O38: 1 | P38: 32024R1689:45:3:12 | Q38: …iteiten voor dezelfde soorten AI-systemen verrichten, relevante informatie over negatieve conformiteitsbeoordelingsresultaten, en op verzoek ook over positieve conformiteitsbeoordelingsresultaten.
A39: yes | B39: embedding p20-47 | C39: persoonsgegevens en alle informatie die noodzakelijk is voor de uitvoering van haar taken | D39: alle persoonsgegevens en alle informatie die noodzakelijk is voor de uitvoering van haar taken | E39: persoonsgegeven | F39: embedding | H39: Registratie en beoordeling van en autorisatie en beperkingen ten aanzien van chemische stoffen | I39: 0.2361 | J39: 29.6 | K39: persoonlijke gegevens | L39: 0.2328 | M39: gegevensbescherming | N39: 0.2223 | O39: 1 | P39: 32016R0679:58:1:4 | Q39: …r in kennis te stellen van een beweerde inbreuk op deze verordening; e) van de verwerkingsverantwoordelijke en de verwerker toegang te verkrijgen tot alle persoonsgegevens en alle informatie die noodzakelijk is voor de uitvoering van haar taken; en f) toegang te verkrijgen tot alle bedrijfsruimten van de verwerkingsverantwoordelijke en de verwerker, daaronder begrepen tot alle uitrustingen e…
A40: yes | B40: embedding p20-47 | C40: onderbouwing van het trainen | D40: een volledige en gedetailleerde beschrijving van het proces en de onderbouwing van het trainen, testen en valideren van het AI-systeem | E40: onderbouwing | F40: embedding | H40: onderontwikkeling | I40: 0.2248 | J40: 26.6 | K40: onderbezetting | L40: 0.209 | O40: 1 | P40: 32024R1689:59:1:11 | Q40: …estomgeving worden bijgehouden voor de duur van de deelname aan de testomgeving, tenzij anders is bepaald in het Unierecht of het nationale recht; i) een volledige en gedetailleerde beschrijving van het proces en de onderbouwing van het trainen, testen en valideren van het AI-systeem wordt samen met de testresultaten bewaard als onderdeel van de in bijlage IV bedoelde technische documentatie; j) een korte samenvatting van het in d…
...

Sheet Summary
A1: stratum | B1: objects | C1: in sample | D1: judged | E1: correct | F1: partial | G1: wrong | H1: unclear | I1: precision (strict) | J1: precision (lenient)
A2: phrase | B2: =COUNTIFS(Validate!$B$2:$B$875,A2) -> 51 | C2: =COUNTIFS(Validate!$B$2:$B$875,A2,Validate!$A$2:$A$875,"yes") -> 10 | D2: =COUNTIFS(Validate!$B$2:$B$875,A2,Validate!$R$2:$R$875,"<>") -> 0 | E2: =COUNTIFS(Validate!$B$2:$B$875,A2,Validate!$R$2:$R$875,"correct") -> 0 | F2: =COUNTIFS(Validate!$B$2:$B$875,A2,Validate!$R$2:$R$875,"partial") -> 0 | G2: =COUNTIFS(Validate!$B$2:$B$875,A2,Validate!$R$2:$R$875,"wrong") -> 0 | H2: =COUNTIFS(Validate!$B$2:$B$875,A2,Validate!$R$2:$R$875,"unclear") -> 0 | I2: =IFERROR(E2/(D2-H2),"") | J2: =IFERROR((E2+F2)/(D2-H2),"")
A3: head | B3: =COUNTIFS(Validate!$B$2:$B$875,A3) -> 139 | C3: =COUNTIFS(Validate!$B$2:$B$875,A3,Validate!$A$2:$A$875,"yes") -> 10 | D3: =COUNTIFS(Validate!$B$2:$B$875,A3,Validate!$R$2:$R$875,"<>") -> 0 | E3: =COUNTIFS(Validate!$B$2:$B$875,A3,Validate!$R$2:$R$875,"correct") -> 0 | F3: =COUNTIFS(Validate!$B$2:$B$875,A3,Validate!$R$2:$R$875,"partial") -> 0 | G3: =COUNTIFS(Validate!$B$2:$B$875,A3,Validate!$R$2:$R$875,"wrong") -> 0 | H3: =COUNTIFS(Validate!$B$2:$B$875,A3,Validate!$R$2:$R$875,"unclear") -> 0 | I3: =IFERROR(E3/(D3-H3),"") | J3: =IFERROR((E3+F3)/(D3-H3),"")
A4: compound | B4: =COUNTIFS(Validate!$B$2:$B$875,A4) -> 39 | C4: =COUNTIFS(Validate!$B$2:$B$875,A4,Validate!$A$2:$A$875,"yes") -> 10 | D4: =COUNTIFS(Validate!$B$2:$B$875,A4,Validate!$R$2:$R$875,"<>") -> 0 | E4: =COUNTIFS(Validate!$B$2:$B$875,A4,Validate!$R$2:$R$875,"correct") -> 0 | F4: =COUNTIFS(Validate!$B$2:$B$875,A4,Validate!$R$2:$R$875,"partial") -> 0 | G4: =COUNTIFS(Validate!$B$2:$B$875,A4,Validate!$R$2:$R$875,"wrong") -> 0 | H4: =COUNTIFS(Validate!$B$2:$B$875,A4,Validate!$R$2:$R$875,"unclear") -> 0 | I4: =IFERROR(E4/(D4-H4),"") | J4: =IFERROR((E4+F4)/(D4-H4),"")
A5: embedding p20-47 | B5: =COUNTIFS(Validate!$B$2:$B$875,A5) -> 193 | C5: =COUNTIFS(Validate!$B$2:$B$875,A5,Validate!$A$2:$A$875,"yes") -> 10 | D5: =COUNTIFS(Validate!$B$2:$B$875,A5,Validate!$R$2:$R$875,"<>") -> 0 | E5: =COUNTIFS(Validate!$B$2:$B$875,A5,Validate!$R$2:$R$875,"correct") -> 0 | F5: =COUNTIFS(Validate!$B$2:$B$875,A5,Validate!$R$2:$R$875,"partial") -> 0 | G5: =COUNTIFS(Validate!$B$2:$B$875,A5,Validate!$R$2:$R$875,"wrong") -> 0 | H5: =COUNTIFS(Validate!$B$2:$B$875,A5,Validate!$R$2:$R$875,"unclear") -> 0 | I5: =IFERROR(E5/(D5-H5),"") | J5: =IFERROR((E5+F5)/(D5-H5),"")
A6: embedding p47-73 | B6: =COUNTIFS(Validate!$B$2:$B$875,A6) -> 184 | C6: =COUNTIFS(Validate!$B$2:$B$875,A6,Validate!$A$2:$A$875,"yes") -> 10 | D6: =COUNTIFS(Validate!$B$2:$B$875,A6,Validate!$R$2:$R$875,"<>") -> 0 | E6: =COUNTIFS(Validate!$B$2:$B$875,A6,Validate!$R$2:$R$875,"correct") -> 0 | F6: =COUNTIFS(Validate!$B$2:$B$875,A6,Validate!$R$2:$R$875,"partial") -> 0 | G6: =COUNTIFS(Validate!$B$2:$B$875,A6,Validate!$R$2:$R$875,"wrong") -> 0 | H6: =COUNTIFS(Validate!$B$2:$B$875,A6,Validate!$R$2:$R$875,"unclear") -> 0 | I6: =IFERROR(E6/(D6-H6),"") | J6: =IFERROR((E6+F6)/(D6-H6),"")
A7: embedding p73-100 | B7: =COUNTIFS(Validate!$B$2:$B$875,A7) -> 126 | C7: =COUNTIFS(Validate!$B$2:$B$875,A7,Validate!$A$2:$A$875,"yes") -> 10 | D7: =COUNTIFS(Validate!$B$2:$B$875,A7,Validate!$R$2:$R$875,"<>") -> 0 | E7: =COUNTIFS(Validate!$B$2:$B$875,A7,Validate!$R$2:$R$875,"correct") -> 0 | F7: =COUNTIFS(Validate!$B$2:$B$875,A7,Validate!$R$2:$R$875,"partial") -> 0 | G7: =COUNTIFS(Validate!$B$2:$B$875,A7,Validate!$R$2:$R$875,"wrong") -> 0 | H7: =COUNTIFS(Validate!$B$2:$B$875,A7,Validate!$R$2:$R$875,"unclear") -> 0 | I7: =IFERROR(E7/(D7-H7),"") | J7: =IFERROR((E7+F7)/(D7-H7),"")
A8: unmapped | B8: =COUNTIFS(Validate!$B$2:$B$875,A8) -> 142 | C8: =COUNTIFS(Validate!$B$2:$B$875,A8,Validate!$A$2:$A$875,"yes") -> 10 | D8: =COUNTIFS(Validate!$B$2:$B$875,A8,Validate!$R$2:$R$875,"<>") -> 0 | E8: =COUNTIFS(Validate!$B$2:$B$875,A8,Validate!$R$2:$R$875,"correct") -> 0 | F8: =COUNTIFS(Validate!$B$2:$B$875,A8,Validate!$R$2:$R$875,"partial") -> 0 | G8: =COUNTIFS(Validate!$B$2:$B$875,A8,Validate!$R$2:$R$875,"wrong") -> 0 | H8: =COUNTIFS(Validate!$B$2:$B$875,A8,Validate!$R$2:$R$875,"unclear") -> 0 | I8: =IFERROR(E8/(D8-H8),"") | J8: =IFERROR((E8+F8)/(D8-H8),"")
A9: total | B9: =SUM(B2:B8) -> 874 | C9: =SUM(C2:C8) -> 70 | D9: =SUM(D2:D8) -> 0 | E9: =SUM(E2:E8) -> 0 | F9: =SUM(F2:F8) -> 0 | G9: =SUM(G2:G8) -> 0 | H9: =SUM(H2:H8) -> 0 | I9: =IFERROR(E9/(D9-H9),"") | J9: =IFERROR((E9+F9)/(D9-H9),"")
A11: Precision excludes 'unclear'. Strict = correct only; lenient = correct + partial.
A12: For 'unmapped', precision means: share of objects rightly left unmapped.
A13: Embedding bands split the range above the fallback percentile (20) into three equal parts.
A14: Precision on a sample of ~10 per stratum is a rough indication (±15 points or so); judge more rows where decisions depend on it.

Sheet Norms
A1: norm_id | B1: object | C1: units | D1: level | E1: cand_1 | F1: conf_1 | G1: cand_2 | H1: cand_3
A2: 32024R1689:4:whole:1 | B2: maatregelen | C2: maatregelen | D2: embedding | E2: bestuursmaatregel | F2: 0.3025 | G2: verkeersregels | H2: gezondheidsregels
A3: 32024R1689:4:whole:2 | B3: hun technische kennis, ervaring, onderwijs en opleiding en de context waarin de AI-systemen zullen worden gebruikt, evenals met de personen of groepen personen ten aanzien van wie de AI-systemen zullen worden gebruikt | C3: technische kennis, ervaring, onderwijs en opleiding en de context waarin de AI-systemen zullen worden gebruikt, evenals met de personen of groepen personen ten aanzien van wie de AI-systemen zullen worden gebruikt
A4: 32024R1689:5:2:1 | B4: noodzakelijke en evenredige waarborgen en voorwaarden | C4: noodzakelijke en evenredige waarborgen | voorwaarden | D4: head | E4: vooruitbetaling | F4: 0.8 | G4: arbeidsvoorwaarden | H4: prijsregels
A5: 32024R1689:5:2:2 | B5: Het gebruik van systemen voor biometrische identificatie op afstand in real time in openbare ruimten met het oog op de rechtshandhaving | C5: systemen voor biometrische identificatie op afstand in real time in openbare ruimten met het oog op de rechtshandhaving
A6: 32024R1689:5:2:3 | B6: het volgende
A7: 32024R1689:5:2:4 | B7: met het gebruik van dergelijke systemen | C7: systemen | D7: embedding | E7: styreen | F7: 0.2157 | G7: systeemexpert
A8: 32024R1689:5:2:5 | B8: Het gebruik van het systeem voor biometrische identificatie op afstand in real time in openbare ruimten | C8: systeem voor biometrische identificatie op afstand in real time in openbare ruimten
A9: 32024R1689:5:4:6 | B9: ten minste de in lid 6 bepaalde informatie | C9: informatie | D9: phrase | E9: informatie | F9: 1
A10: 32024R1689:5:4:7 | B10: gevoelige operationele gegevens | C10: gevoelige operationele gegevens | D10: embedding | E10: transactionele gegevens | F10: 0.3179 | G10: gevoelig gebied | H10: machineleesbare gegevens
A11: 32024R1689:5:4:8 | B11: elk gebruik van een systeem voor biometrische identificatie op afstand in real time in openbare ruimten met het oog op de rechtshandhaving | C11: systeem voor biometrische identificatie op afstand in real time in openbare ruimten met het oog op de rechtshandhaving
A12: 32024R1689:5:5:9 | B12: om te voorzien in de mogelijkheid om volledig of gedeeltelijk toestemming te verlenen voor het gebruik van systemen voor biometrische identificatie op afstand in real time in openbare ruimten met het oog op de rechtshandhaving | C12: mogelijkheid om volledig of gedeeltelijk toestemming te verlenen voor het gebruik van systemen voor biometrische identificatie op afstand in real time in openbare ruimten met het oog op de rechtshandhaving
A13: 32024R1689:5:5:10 | B13: de noodzakelijke gedetailleerde regels | C13: noodzakelijke gedetailleerde regels | D13: embedding | E13: betere regelgeving | F13: 0.2895 | G13: verkeersregels | H13: verkeersvoorschriften
A14: 32024R1689:5:5:11 | B14: de Commissie | C14: Commissie | D14: embedding | E14: Commissie Statistiek | F14: 0.4103 | G14: conferentie | H14: comitologie
A15: 32024R1689:5:5:12 | B15: restrictievere wetgeving inzake het gebruik van systemen voor biometrische identificatie op afstand | C15: restrictievere wetgeving inzake het gebruik van systemen voor biometrische identificatie op afstand | D15: head | E15: wetgeving | F15: 0.8
A16: 32024R1689:5:5:13 | B16: voor welke doelstellingen van lid 1, eerste alinea, punt h), en voor welke strafbare feiten als bedoeld in punt h), iii), daarvan de bevoegde autoriteiten deze systemen mogen gebruiken met het oog op de rechtshandhaving | C16: welke doelstellingen en voor welke strafbare feiten de bevoegde autoriteiten deze systemen mogen gebruiken met het oog op de rechtshandhaving | D16: compound | E16: telling | F16: 0.6
A17: 32024R1689:5:6:14 | B17: een sjabloon | C17: sjabloon | D17: embedding | E17: sojaboon | F17: 0.3099
A18: 32024R1689:5:6:15 | B18: jaarverslagen | C18: jaarverslagen | D18: phrase | E18: verslag over de werkzaamheden | F18: 1
A19: 32024R1689:5:7:16 | B19: jaarverslagen | C19: jaarverslagen | D19: phrase | E19: verslag over de werkzaamheden | F19: 1
A20: 32024R1689:5:7:17 | B20: gevoelige operationele gegevens | C20: gevoelige operationele gegevens | D20: embedding | E20: transactionele gegevens | F20: 0.3179 | G20: gevoelig gebied | H20: machineleesbare gegevens
A21: 32024R1689:6:1:1 | B21: een AI-systeem als AI-systeem met een hoog risico | C21: AI-systeem als AI-systeem met een hoog risico
A22: 32024R1689:6:4:2 | B22: de documentatie van de beoordeling | C22: documentatie van de beoordeling | D22: head | E22: documentatie | F22: 0.8
A23: 32024R1689:6:4:3 | B23: zijn beoordeling | C23: beoordeling | D23: embedding | E23: projectbeoordeling | F23: 0.4328 | G23: beoordelingsbevoegdheid | H23: beroepsbeoordeling
A24: 32024R1689:6:4:4 | B24: de registratieverplichting van artikel 49, lid 2 | C24: registratieverplichting | D24: compound | E24: contract | F24: 0.6
A25: 32024R1689:6:5:5 | B25: richtsnoeren | C25: richtsnoeren | D25: embedding | E25: snoeien | F25: 0.2049
A26: 32024R1689:6:6:6 | B26: gedelegeerde handelingen | C26: gedelegeerde handelingen | D26: embedding | E26: gedelegeerde verordening | F26: 0.4057 | G26: gedelegeerde wetgeving | H26: gedelegeerd besluit
A27: 32024R1689:6:7:7 | B27: gedelegeerde handelingen | C27: gedelegeerde handelingen | D27: embedding | E27: gedelegeerde verordening | F27: 0.4057 | G27: gedelegeerde wetgeving | H27: gedelegeerd besluit
A28: 32024R1689:7:1:1 | B28: gedelegeerde handelingen | C28: gedelegeerde handelingen | D28: embedding | E28: gedelegeerde verordening | F28: 0.4057 | G28: gedelegeerde wetgeving | H28: gedelegeerd besluit
A29: 32024R1689:7:2:2 | B29: de volgende criteria | C29: criteria
A30: 32024R1689:7:3:3 | B30: gedelegeerde handelingen | C30: gedelegeerde handelingen | D30: embedding | E30: gedelegeerde verordening | F30: 0.4057 | G30: gedelegeerde wetgeving | H30: gedelegeerd besluit
A31: 32024R1689:8:1:1 | B31: de eisen van deze afdeling | C31: eisen | D31: embedding | E31: ei | F31: 0.2589
A32: 32024R1689:8:1:2 | B32: het in artikel 9 bedoelde systeem voor risicobeheer | C32: systeem voor risicobeheer | D32: embedding | E32: risicobeheer | F32: 0.4629 | G32: wetenschappelijk risicobeheer | H32: bedrijfsbeheerssysteem
A33: 32024R1689:8:2:3 | B33: dat hun product volledig voldoet aan alle toepasselijke vereisten uit hoofde van de toepasselijke harmonisatiewetgeving van de Unie | C33: product volledig voldoet aan alle toepasselijke vereisten uit hoofde van de toepasselijke harmonisatiewetgeving van de Unie
A34: 32024R1689:8:2:4 | B34: de nodige test- en rapportageprocessen en door hen verstrekte informatie en documentatie over hun product | C34: nodige test- en rapportageprocessen en door hen verstrekte informatie en documentatie over hun product | D34: embedding | E34: informatie en documentatie | F34: 0.2916 | G34: Registratie en beoordeling van en autorisatie en beperkingen ten aanzien van chemische stoffen | H34: onderzoek en ontwikkeling
A35: 32024R1689:9:1:1 | B35: een systeem voor risicobeheer | C35: systeem voor risicobeheer | D35: embedding | E35: risicobeheer | F35: 0.4629 | G35: wetenschappelijk risicobeheer | H35: bedrijfsbeheerssysteem
A36: 32024R1689:9:1:2 | B36: een systeem voor risicobeheer | C36: systeem voor risicobeheer | D36: embedding | E36: risicobeheer | F36: 0.4629 | G36: wetenschappelijk risicobeheer | H36: bedrijfsbeheerssysteem
A37: 32024R1689:9:1:3 | B37: een systeem voor risicobeheer | C37: systeem voor risicobeheer | D37: embedding | E37: risicobeheer | F37: 0.4629 | G37: wetenschappelijk risicobeheer | H37: bedrijfsbeheerssysteem
A38: 32024R1689:9:1:4 | B38: een systeem voor risicobeheer | C38: systeem voor risicobeheer | D38: embedding | E38: risicobeheer | F38: 0.4629 | G38: wetenschappelijk risicobeheer | H38: bedrijfsbeheerssysteem
A39: 32024R1689:9:4:5 | B39: de effecten en mogelijke wisselwerking die voortvloeien uit de gecombineerde toepassing van de in deze afdeling uiteengezette eisen | C39: effecten en mogelijke wisselwerking die voortvloeien uit de gecombineerde toepassing van de uiteengezette eisen | D39: head | E39: effecten | F39: 0.8
A40: 32024R1689:9:5:6 | B40: zodanig dat het desbetreffende restrisico in verband met elk gevaar en het totale restrisico van de AI-systemen met een hoog risico aanvaardbaar wordt geacht | C40: restrisico in verband met elk gevaar en het totale restrisico van de AI-systemen met een hoog risico aanvaardbaar wordt geacht
...
