Workbook

Sheet Review
A1: # | B1: Norm A | C1: Object A | D1: Matched unit A | E1: Norm B | F1: Object B | G1: Matched unit B | H1: Same thing? | I1: Relation type | J1: Note | K1: Stratum | L1: Score | M1: Key relation | N1: Key | O1: Spec | P1: Direction
A2: 1 | B2: 32016R0679:40:5:9 | C2: advies | D2: advies | E2: 32016R0679:40:8:15 | F2: zijn advies | G2: advies | K2: 0.50-0.75 head | L2: 0.5642 | M2: head | N2: advies | O2: 0.5642 | P2: same
A3: 2 | B3: 32016R0679:60:10:25 | C3: de door hem met het oog op de naleving van het besluit getroffen maatregelen | D3: door hem met het oog op de naleving van het besluit getroffen maatregelen | E3: 32024R1689:5:5:13 | F3: voor welke doelstellingen van lid 1, eerste alinea, punt h), en voor welke strafbare feiten als bedoeld in punt h), iii), daarvan de bevoegde autoriteiten deze systemen mogen gebruiken met het oog op de rechtshandhaving | G3: welke doelstellingen en voor welke strafbare feiten de bevoegde autoriteiten deze systemen mogen gebruiken met het oog op de rechtshandhaving | K3: 0.50-0.75 noun | L3: 0.508 | M3: noun | N3: oog | O3: 0.7257 | P3: none
A4: 3 | B4: 32016R0679:58:3:23 | C4: certificeringen | D4: certificeringen | E4: 32024R1689:58:3:4 | F4: diensten die aan het inzetten voorafgaan, zoals begeleiding bij de uitvoering van deze verordening, op andere diensten die waarde toevoegen, zoals hulp bij normalisatiedocumenten en certificering, test- en experimenteervoorzieningen, Europese digitale-innovatiehubs en kenniscentra | G4: diensten die aan het inzetten voorafgaan, zoals begeleiding bij de uitvoering op andere diensten die waarde toevoegen, zoals hulp bij normalisatiedocumenten en certificering, test- en experimenteervoorzieningen, Europese digitale-innovatiehubs en kenniscentra | K4: 0.50-0.75 noun | L4: 0.5412 | M4: noun | N4: certificer | O4: 0.7731 | P4: none
A5: 4 | B5: 32016R0679:14:5:13 | C5: passende maatregelen | D5: passende maatregelen | E5: 32016R0679:84:1:1 | F5: de regels inzake andere sancties | G5: regels inzake andere sancties | K5: 0.00-0.50 tail | L5: 0.3116 | M5: tail | N5: regel | O5: 0.3895 | P5: a_narrower
A6: 5 | B6: 32016R0679:14:5:13 | C6: passende maatregelen | D6: passende maatregelen | E6: 32024R1689:15:5:6 | F6: maatregelen voor het voorkomen, traceren, reageren op, oplossen en beheersen van aanvallen waarmee een poging wordt gedaan tot het manipuleren van de dataset voor de training (de zogenaamde “datavervuiling”), van vooraf getrainde componenten die in de training zijn gebruikt (de zogenaamde “modelvervuiling”), van input die is gecreëerd om fouten van het model te veroorzaken (zogenaamde “vijandige voorbeelden” of “modelontwijking”), van aanvallen om vertrouwelijke gegevens te bemachtigen of van tekortkomingen van het model | G6: maatregelen voor het voorkomen, traceren, reageren op, oplossen en beheersen van aanvallen waarmee een poging wordt gedaan tot het manipuleren van de dataset voor de training (de zogenaamde datavervuiling), van vooraf getrainde componenten die in de training zijn gebruikt (de zogenaamde modelvervuiling), van input die is gecreëerd om fouten van het model te veroorzaken (zogenaamde vijandige voorbeelden of modelontwijking), van aanvallen om vertrouwelijke gegevens te bemachtigen of van tekortkomingen van het model | K6: 0.00-0.50 head | L6: 0.4031 | M6: head | N6: maatregel | O6: 0.4031 | P6: b_narrower
A7: 6 | B7: 32016R0679:16:whole:3 | C7: een aanvullende verklaring | D7: aanvullende verklaring | E7: 32024R1689:68:4:4 | F7: een belangenverklaring | G7: belangenverklaring | K7: 0.50-0.75 tail | L7: 0.5522 | M7: tail | N7: verklar | O7: 0.6902 | P7: b_narrower
A8: 7 | B8: 32024R1689:24:2:2 | C8: het AI-systeem met een hoog risico | D8: AI-systeem met een hoog risico | E8: 32024R1689:95:3:2 | F8: op een of meer AI-systemen | G8: of meer AI-systemen | K8: 0.00-0.50 head | L8: 0.4513 | M8: head | N8: aisystem | O8: 0.4513 | P8: a_narrower
A9: 8 | B9: 32024R1689:36:7:22 | C9: onterecht afgegeven certificaten | D9: onterecht afgegeven certificaten | E9: 32024R1689:36:7:24 | F9: de Commissie en de lidstaten | G9: Commissie | lidstaten | K9: zero same-group | L9: 0 | P9: none
A10: 9 | B10: 32024R1689:27:3:7 | C10: de verplichting tot kennisgeving | D10: verplichting tot kennisgeving | E10: 32024R1689:50:4:9 | F10: de transparantieverplichtingen van dit lid | G10: transparantieverplichtingen | K10: 0.00-0.50 eurovoc | L10: 0.4866 | M10: eurovoc | N10: http://eurovoc.europa.eu/164 | O10: 0.5407 | P10: b_narrower
A11: 10 | B11: 32016R0679:36:3:4 | C11: de doeleinden en de middelen van de voorgenomen verwerking | D11: doeleinden | middelen van de voorgenomen verwerking | E11: 32016R0679:36:3:7 | F11: de gegevensbeschermingseffectbeoordeling waarin bij artikel 35 is voorzien | G11: gegevensbeschermingseffectbeoordeling waarin is voorzien | K11: zero same-group | L11: 0 | P11: none
A12: 11 | B12: 32016R0679:58:1:2 | C12: alle voor de uitvoering van haar taken vereiste informatie | D12: voor de uitvoering van haar taken vereiste informatie | E12: 32024R1689:53:7:13 | F12: Informatie of documentatie | G12: Informatie | K12: 0.00-0.50 head | L12: 0.3737 | M12: head | N12: informatie | O12: 0.3737 | P12: a_narrower
A13: 12 | B13: 32016R0679:42:1:1 | C13: de invoering van certificeringsmechanismen voor gegevensbescherming en gegevensbeschermingszegels en -merktekens | D13: certificeringsmechanismen voor gegevensbescherming en gegevensbeschermingszegels en -merktekens | E13: 32016R0679:46:4:5 | F13: het in artikel 63 bedoelde coherentiemechanisme | G13: coherentiemechanisme | K13: 0.50-0.75 tail | L13: 0.5198 | M13: tail | N13: mechanism | O13: 0.6497 | P13: none
A14: 13 | B14: 32016R0679:97:4:5 | C14: de standpunten en bevindingen van het Europees Parlement, van de Raad, en van andere relevante instanties of bronnen | D14: bevindingen van het Europees Parlement | E14: 32024R1689:36:7:20 | F14: een verslag over haar bevindingen | G14: verslag over haar bevindingen | K14: 0.50-0.75 noun | L14: 0.5232 | M14: noun | N14: bevind | O14: 0.7474 | P14: none
A15: 14 | B15: 32024R1689:46:3:5 | C15: De in lid 1 bedoelde toelating | D15: toelating | E15: 32024R1689:46:4:8 | F15: die toelating | G15: toelating | K15: 0.75-1.00 head | L15: 0.7731 | M15: head | N15: toelat | O15: 0.7731 | P15: same
A16: 15 | B16: 32016R0679:59:whole:1 | C16: een verslag over haar activiteiten | D16: verslag over haar activiteiten | E16: 32024R1689:112:6:14 | F16: Dit verslag | G16: verslag | K16: 0.50-0.75 head | L16: 0.5253 | M16: head | N16: verslag | O16: 0.5253 | P16: a_narrower
A17: 16 | B17: 32024R1689:16:whole:6 | C17: de CE-markering | D17: CE-markering | E17: 32024R1689:24:1:1 | F17: of daarop de vereiste CE-markering is aangebracht, of het systeem vergezeld gaat van de in artikel 47 bedoelde EU-conformiteitsverklaring en gebruiksinstructies en of de aanbieder en importeur van dat systeem, naargelang het geval, hun respectievelijke verplichtingen als vastgelegd in artikel 16, punten b) en c), en artikel 23, lid 3, hebben nageleefd | G17: of de vereiste CE-markering is aangebracht, of het systeem vergezeld gaat van de EU-conformiteitsverklaring en gebruiksinstructies en of de aanbieder en importeur van dat systeem, naargelang het geval, hun respectievelijke verplichtingen als vastgelegd hebben nageleefd | K17: 0.75-1.00 head | L17: 0.7731 | M17: head | N17: cemarker | O17: 0.7731 | P17: b_narrower
A18: 17 | B18: 32016R0679:57:4:35 | C18: aan het verzoek | D18: verzoek | E18: 32016R0679:61:4:7 | F18: dit verzoek | G18: verzoek | K18: 0.75-1.00 eurovoc | L18: 0.7606 | M18: eurovoc | N18: http://eurovoc.europa.eu/2363 | O18: 0.8451 | P18: same
A19: 18 | B19: 32016R0679:60:7:11 | C19: het besluit | D19: besluit | E19: 32016R0679:65:3:6 | F19: zijn besluit | G19: besluit | K19: 0.00-0.50 eurovoc | L19: 0.4916 | M19: eurovoc | N19: http://eurovoc.europa.eu/2669 | O19: 0.5462 | P19: same
A20: 19 | B20: 32016R0679:57:1:28 | C20: toestemming | D20: toestemming | E20: 32016R0679:57:3:33 | F20: haar taken | G20: taken | K20: zero same-group | L20: 0 | P20: none
A21: 20 | B21: 32024R1689:71:1:1 | C21: de deskundigen ter zake | D21: deskundigen ter zake | E21: 32024R1689:71:3:5 | F21: De in afdeling C van bijlage VIII vermelde gegevens | G21: gegevens | K21: zero same-group | L21: 0 | P21: none
A22: 21 | B22: 32016R0679:11:1:1 | C22: aanvullende gegevens ter identificatie van de betrokkene bij te houden, te verkrijgen of te verwerken | D22: aanvullende gegevens ter identificatie van de betrokkene bij te houden, te verkrijgen of te verwerken | E22: 32016R0679:36:3:6 | F22: de contactgegevens van de functionaris voor gegevensbescherming | G22: contactgegevens van de functionaris voor gegevensbescherming | K22: 0.00-0.50 eurovoc | L22: 0.4288 | M22: eurovoc | N22: http://eurovoc.europa.eu/5181 | O22: 0.4765 | P22: b_narrower
A23: 22 | B23: 32016R0679:46:4:5 | C23: het in artikel 63 bedoelde coherentiemechanisme | D23: coherentiemechanisme | E23: 32016R0679:57:1:23 | F23: de invoering van certificeringsmechanismen voor gegevensbescherming en van gegevensbeschermingszegels en -merktekens overeenkomstig artikel 42, lid 1 | G23: certificeringsmechanismen voor gegevensbescherming en van gegevensbeschermingszegels en -merktekens | K23: 0.50-0.75 tail | L23: 0.5198 | M23: tail | N23: mechanism | O23: 0.6497 | P23: none
A24: 23 | B24: 32016R0679:52:2:2 | C24: instructies | D24: instructies | E24: 32024R1689:67:8:10 | F24: adviezen, aanbevelingen en schriftelijke bijdragen | G24: aanbevelingen | K24: 0.50-0.75 eurovoc | L24: 0.6958 | M24: eurovoc | N24: http://eurovoc.europa.eu/2926 | O24: 0.7731 | P24: none
A25: 24 | B25: 32016R0679:45:5:5 | C25: het in lid 3 van dit artikel bedoelde besluit | D25: besluit | E25: 32016R0679:65:2:1 | F25: Het in lid 1 bedoelde besluit | G25: besluit | K25: 0.00-0.50 eurovoc | L25: 0.4916 | M25: eurovoc | N25: http://eurovoc.europa.eu/2669 | O25: 0.5462 | P25: same
A26: 25 | B26: 32016R0679:14:1:3 | C26: de contactgegevens van de functionaris voor gegevensbescherming | D26: contactgegevens van de functionaris voor gegevensbescherming | E26: 32016R0679:58:1:4 | F26: alle persoonsgegevens en alle informatie die noodzakelijk is voor de uitvoering van haar taken | G26: persoonsgegevens en alle informatie die noodzakelijk is voor de uitvoering van haar taken | K26: 0.00-0.50 tail | L26: 0.384 | M26: tail | N26: gegev | O26: 0.48 | P26: none
A27: 26 | B27: 32024R1689:49:2:2 | C27: zichzelf en dat systeem | D27: zichzelf en dat systeem | E27: 32024R1689:9:6:12 | F27: AI-systemen met een hoog risico | G27: AI-systemen met een hoog risico | K27: 0.00-0.50 tail | L27: 0.346 | M27: tail | N27: system | O27: 0.4325 | P27: b_narrower
A28: 27 | B28: 32016R0679:39:1:5 | C28: naleving van deze verordening, van andere Unierechtelijke of lidstaatrechtelijke gegevensbeschermingsbepalingen en van het beleid van de verwerkingsverantwoordelijke of de verwerker met betrekking tot de bescherming van persoonsgegevens, met inbegrip van de toewijzing van verantwoordelijkheden, bewustmaking en opleiding van het bij de verwerking betrokken personeel en de betreffende audits | D28: Unierechtelijke of lidstaatrechtelijke gegevensbeschermingsbepalingen en van het beleid van de verwerkingsverantwoordelijke of de verwerker met betrekking tot de bescherming van persoonsgegevens, met inbegrip van de toewijzing van verantwoordelijkheden, bewustmaking en opleiding van het bij de verwerking betrokken personeel en de betreffende audits | E28: 32024R1689:53:1:6 | F28: beleid | G28: beleid | K28: 0.50-0.75 noun | L28: 0.5916 | M28: noun | N28: beleid | O28: 0.8451 | P28: none
A29: 28 | B29: 32016R0679:97:1:1 | C29: een verslag | D29: verslag | E29: 32024R1689:112:6:14 | F29: Dit verslag | G29: verslag | K29: 0.50-0.75 head | L29: 0.5253 | M29: head | N29: verslag | O29: 0.5253 | P29: same
A30: 29 | B30: 32016R0679:40:10:16 | C30: passende bekendheid | D30: passende bekendheid | E30: 32016R0679:57:1:4 | F30: Bijzondere aandacht | G30: Bijzondere aandacht | K30: 0.75-1.00 eurovoc | L30: 0.7606 | M30: eurovoc | N30: http://eurovoc.europa.eu/3329 | O30: 0.8451 | P30: none
A31: 30 | B31: 32024R1689:57:7:11 | C31: aanbieders en potentiële aanbieders die deelnemen aan de AI-testomgeving voor regelgeving | D31: aanbieders en potentiële aanbieders die deelnemen aan de AI-testomgeving voor regelgeving | E31: 32024R1689:59:2:13 | F31: de verwerking van persoonsgegevens in AI-testomgevingen voor regelgeving | G31: verwerking van persoonsgegevens in AI-testomgevingen voor regelgeving | K31: 0.50-0.75 noun | L31: 0.508 | M31: noun | N31: aitestomgev | O31: 0.7257 | P31: none
A32: 31 | B32: 32016R0679:79:2:3 | C32: Een dergelijke procedure | D32: procedure | E32: 32016R0679:81:2:2 | F32: zijn procedure | G32: procedure | K32: 0.50-0.75 eurovoc | L32: 0.5482 | M32: eurovoc | N32: http://eurovoc.europa.eu/2701 | O32: 0.6091 | P32: same
A33: 32 | B33: 32024R1689:81:1:1 | C33: de nationale maatregel | D33: nationale maatregel | E33: 32024R1689:81:1:3 | F33: of de nationale maatregel gerechtvaardigd is | G33: of de nationale maatregel gerechtvaardigd is | K33: 0.50-0.75 eurovoc | L33: 0.7241 | M33: eurovoc | N33: http://eurovoc.europa.eu/5739 | O33: 0.8046 | P33: same
... A38: 37 | B38: 32016R0679:75:6:6 | C38: de communicatie met andere instellingen en het brede publiek | D38: communicatie met andere instellingen | E38: 32024R1689:100:4:4 | F38: de instelling, het orgaan of de instantie van de Unie ten aanzien waarvan hij een procedure voert | G38: instelling, het orgaan of de instantie van de Unie ten aanzien waarvan hij een procedure voert | K38: 0.50-0.75 noun | L38: 0.5916 | M38: noun | N38: instell | O38: 0.8451 | P38: none
A39: 38 | B39: 32016R0679:60:12:28 | C39: de krachtens dit artikel vereiste informatie | D39: vereiste informatie | E39: 32016R0679:60:9:19 | F39: de klager | G39: klager | K39: zero same-group | L39: 0 | P39: none
A40: 39 | B40: 32016R0679:28:9:11 | C40: De in de leden 3 en 4 bedoelde overeenkomst of andere rechtshandeling | D40: rechtshandeling | E40: 32016R0679:43:9:14 | F40: Die uitvoeringshandelingen | G40: uitvoeringshandelingen | K40: 0.00-0.50 tail | L40: 0.384 | M40: tail | N40: handel | O40: 0.48 | P40: none
A41: 40 | B41: 32024R1689:11:1:10 | C41: ten minste de in bijlage IV uiteengezette elementen | D41: uiteengezette elementen | E41: 32024R1689:53:1:5 | F41: de in bijlage XII uiteengezette elementen | G41: uiteengezette elementen | K41: 0.75-1.00 eurovoc | L41: 0.7606 | M41: eurovoc | N41: http://eurovoc.europa.eu/3692 | O41: 0.8451 | P41: same
A42: 41 | B42: 32016R0679:40:11:17 | C42: alle goedgekeurde gedragscodes, wijzigingen en uitbreidingen | D42: wijzigingen | E42: 32016R0679:90:2:3 | F42: alle wijzigingen daarvan | G42: wijzigingen | K42: 0.75-1.00 eurovoc | L42: 0.7606 | M42: eurovoc | N42: http://eurovoc.europa.eu/1439 | O42: 0.8451 | P42: same
A43: 42 | B43: 32016R0679:20:2:4 | C43: de persoonsgegevens | D43: persoonsgegevens | E43: 32016R0679:37:4:5 | F43: een functionaris voor gegevensbescherming | G43: functionaris voor gegevensbescherming | K43: 0.00-0.50 eurovoc | L43: 0.4288 | M43: eurovoc | N43: http://eurovoc.europa.eu/5181 | O43: 0.4765 | P43: none
A44: 43 | B44: 32016R0679:70:1:5 | C44: richtsnoeren, aanbevelingen en beste praktijken | D44: richtsnoeren, aanbevelingen en beste praktijken | E44: 32016R0679:70:1:8 | F44: de praktische toepassing van de in de punten e) en f) bedoelde richtsnoeren, aanbevelingen en beste praktijken | G44: richtsnoeren, aanbevelingen en beste praktijken | K44: 0.75-1.00 head | L44: 0.7731 | M44: head | N44: aanbevel | O44: 0.7731 | P44: same
...

Sheet Summary
A1: Object filter: pair review summary
A3: Threshold (use a band edge) | B3: 0.5 | C3: Change this cell; the estimates below follow.
A5: Stratum | B5: Band from | C5: Key relation | D5: Population | E5: Sampled | F5: same | G5: related | H5: different | I5: unclear | J5: Judged | K5: Strict | L5: Lenient | M5: Pop (judged) | N5: Pop x strict | O5: Pop x lenient
A6: 0.00-0.50 head | B6: 0 | C6: head | D6: 4696 | E6: =COUNTIF(Review!$K$2:$K$116,$A6) | F6: =COUNTIFS(Review!$K$2:$K$116,$A6,Review!$H$2:$H$116,"same") | G6: =COUNTIFS(Review!$K$2:$K$116,$A6,Review!$H$2:$H$116,"related") | H6: =COUNTIFS(Review!$K$2:$K$116,$A6,Review!$H$2:$H$116,"different") | I6: =COUNTIFS(Review!$K$2:$K$116,$A6,Review!$H$2:$H$116,"unclear") | J6: =F6+G6+H6 | K6: =IF(J6=0,"",F6/J6) | L6: =IF(J6=0,"",(F6+G6)/J6) | M6: =IF(J6=0,0,D6) | N6: =IF(J6=0,0,D6*F6/J6) | O6: =IF(J6=0,0,D6*(F6+G6)/J6)
A7: 0.00-0.50 tail | B7: 0 | C7: tail | D7: 2642 | E7: =COUNTIF(Review!$K$2:$K$116,$A7) | F7: =COUNTIFS(Review!$K$2:$K$116,$A7,Review!$H$2:$H$116,"same") | G7: =COUNTIFS(Review!$K$2:$K$116,$A7,Review!$H$2:$H$116,"related") | H7: =COUNTIFS(Review!$K$2:$K$116,$A7,Review!$H$2:$H$116,"different") | I7: =COUNTIFS(Review!$K$2:$K$116,$A7,Review!$H$2:$H$116,"unclear") | J7: =F7+G7+H7 | K7: =IF(J7=0,"",F7/J7) | L7: =IF(J7=0,"",(F7+G7)/J7) | M7: =IF(J7=0,0,D7) | N7: =IF(J7=0,0,D7*F7/J7) | O7: =IF(J7=0,0,D7*(F7+G7)/J7)
A8: 0.00-0.50 eurovoc | B8: 0 | C8: eurovoc | D8: 1282 | E8: =COUNTIF(Review!$K$2:$K$116,$A8) | F8: =COUNTIFS(Review!$K$2:$K$116,$A8,Review!$H$2:$H$116,"same") | G8: =COUNTIFS(Review!$K$2:$K$116,$A8,Review!$H$2:$H$116,"related") | H8: =COUNTIFS(Review!$K$2:$K$116,$A8,Review!$H$2:$H$116,"different") | I8: =COUNTIFS(Review!$K$2:$K$116,$A8,Review!$H$2:$H$116,"unclear") | J8: =F8+G8+H8 | K8: =IF(J8=0,"",F8/J8) | L8: =IF(J8=0,"",(F8+G8)/J8) | M8: =IF(J8=0,0,D8) | N8: =IF(J8=0,0,D8*F8/J8) | O8: =IF(J8=0,0,D8*(F8+G8)/J8)
A9: 0.00-0.50 noun | B9: 0 | C9: noun | D9: 9862 | E9: =COUNTIF(Review!$K$2:$K$116,$A9) | F9: =COUNTIFS(Review!$K$2:$K$116,$A9,Review!$H$2:$H$116,"same") | G9: =COUNTIFS(Review!$K$2:$K$116,$A9,Review!$H$2:$H$116,"related") | H9: =COUNTIFS(Review!$K$2:$K$116,$A9,Review!$H$2:$H$116,"different") | I9: =COUNTIFS(Review!$K$2:$K$116,$A9,Review!$H$2:$H$116,"unclear") | J9: =F9+G9+H9 | K9: =IF(J9=0,"",F9/J9) | L9: =IF(J9=0,"",(F9+G9)/J9) | M9: =IF(J9=0,0,D9) | N9: =IF(J9=0,0,D9*F9/J9) | O9: =IF(J9=0,0,D9*(F9+G9)/J9)
A10: 0.50-0.75 head | B10: 0.5 | C10: head | D10: 2268 | E10: =COUNTIF(Review!$K$2:$K$116,$A10) | F10: =COUNTIFS(Review!$K$2:$K$116,$A10,Review!$H$2:$H$116,"same") | G10: =COUNTIFS(Review!$K$2:$K$116,$A10,Review!$H$2:$H$116,"related") | H10: =COUNTIFS(Review!$K$2:$K$116,$A10,Review!$H$2:$H$116,"different") | I10: =COUNTIFS(Review!$K$2:$K$116,$A10,Review!$H$2:$H$116,"unclear") | J10: =F10+G10+H10 | K10: =IF(J10=0,"",F10/J10) | L10: =IF(J10=0,"",(F10+G10)/J10) | M10: =IF(J10=0,0,D10) | N10: =IF(J10=0,0,D10*F10/J10) | O10: =IF(J10=0,0,D10*(F10+G10)/J10)
A11: 0.50-0.75 tail | B11: 0.5 | C11: tail | D11: 163 | E11: =COUNTIF(Review!$K$2:$K$116,$A11) | F11: =COUNTIFS(Review!$K$2:$K$116,$A11,Review!$H$2:$H$116,"same") | G11: =COUNTIFS(Review!$K$2:$K$116,$A11,Review!$H$2:$H$116,"related") | H11: =COUNTIFS(Review!$K$2:$K$116,$A11,Review!$H$2:$H$116,"different") | I11: =COUNTIFS(Review!$K$2:$K$116,$A11,Review!$H$2:$H$116,"unclear") | J11: =F11+G11+H11 | K11: =IF(J11=0,"",F11/J11) | L11: =IF(J11=0,"",(F11+G11)/J11) | M11: =IF(J11=0,0,D11) | N11: =IF(J11=0,0,D11*F11/J11) | O11: =IF(J11=0,0,D11*(F11+G11)/J11)
A12: 0.50-0.75 eurovoc | B12: 0.5 | C12: eurovoc | D12: 1738 | E12: =COUNTIF(Review!$K$2:$K$116,$A12) | F12: =COUNTIFS(Review!$K$2:$K$116,$A12,Review!$H$2:$H$116,"same") | G12: =COUNTIFS(Review!$K$2:$K$116,$A12,Review!$H$2:$H$116,"related") | H12: =COUNTIFS(Review!$K$2:$K$116,$A12,Review!$H$2:$H$116,"different") | I12: =COUNTIFS(Review!$K$2:$K$116,$A12,Review!$H$2:$H$116,"unclear") | J12: =F12+G12+H12 | K12: =IF(J12=0,"",F12/J12) | L12: =IF(J12=0,"",(F12+G12)/J12) | M12: =IF(J12=0,0,D12) | N12: =IF(J12=0,0,D12*F12/J12) | O12: =IF(J12=0,0,D12*(F12+G12)/J12)
A13: 0.50-0.75 noun | B13: 0.5 | C13: noun | D13: 516 | E13: =COUNTIF(Review!$K$2:$K$116,$A13) | F13: =COUNTIFS(Review!$K$2:$K$116,$A13,Review!$H$2:$H$116,"same") | G13: =COUNTIFS(Review!$K$2:$K$116,$A13,Review!$H$2:$H$116,"related") | H13: =COUNTIFS(Review!$K$2:$K$116,$A13,Review!$H$2:$H$116,"different") | I13: =COUNTIFS(Review!$K$2:$K$116,$A13,Review!$H$2:$H$116,"unclear") | J13: =F13+G13+H13 | K13: =IF(J13=0,"",F13/J13) | L13: =IF(J13=0,"",(F13+G13)/J13) | M13: =IF(J13=0,0,D13) | N13: =IF(J13=0,0,D13*F13/J13) | O13: =IF(J13=0,0,D13*(F13+G13)/J13)
A14: 0.75-1.00 head | B14: 0.75 | C14: head | D14: 179 | E14: =COUNTIF(Review!$K$2:$K$116,$A14) | F14: =COUNTIFS(Review!$K$2:$K$116,$A14,Review!$H$2:$H$116,"same") | G14: =COUNTIFS(Review!$K$2:$K$116,$A14,Review!$H$2:$H$116,"related") | H14: =COUNTIFS(Review!$K$2:$K$116,$A14,Review!$H$2:$H$116,"different") | I14: =COUNTIFS(Review!$K$2:$K$116,$A14,Review!$H$2:$H$116,"unclear") | J14: =F14+G14+H14 | K14: =IF(J14=0,"",F14/J14) | L14: =IF(J14=0,"",(F14+G14)/J14) | M14: =IF(J14=0,0,D14) | N14: =IF(J14=0,0,D14*F14/J14) | O14: =IF(J14=0,0,D14*(F14+G14)/J14)
A15: 0.75-1.00 eurovoc | B15: 0.75 | C15: eurovoc | D15: 50 | E15: =COUNTIF(Review!$K$2:$K$116,$A15) | F15: =COUNTIFS(Review!$K$2:$K$116,$A15,Review!$H$2:$H$116,"same") | G15: =COUNTIFS(Review!$K$2:$K$116,$A15,Review!$H$2:$H$116,"related") | H15: =COUNTIFS(Review!$K$2:$K$116,$A15,Review!$H$2:$H$116,"different") | I15: =COUNTIFS(Review!$K$2:$K$116,$A15,Review!$H$2:$H$116,"unclear") | J15: =F15+G15+H15 | K15: =IF(J15=0,"",F15/J15) | L15: =IF(J15=0,"",(F15+G15)/J15) | M15: =IF(J15=0,0,D15) | N15: =IF(J15=0,0,D15*F15/J15) | O15: =IF(J15=0,0,D15*(F15+G15)/J15)
A16: zero same-group | D16: 5238 | E16: =COUNTIF(Review!$K$2:$K$116,$A16) | F16: =COUNTIFS(Review!$K$2:$K$116,$A16,Review!$H$2:$H$116,"same") | G16: =COUNTIFS(Review!$K$2:$K$116,$A16,Review!$H$2:$H$116,"related") | H16: =COUNTIFS(Review!$K$2:$K$116,$A16,Review!$H$2:$H$116,"different") | I16: =COUNTIFS(Review!$K$2:$K$116,$A16,Review!$H$2:$H$116,"unclear") | J16: =F16+G16+H16 | K16: =IF(J16=0,"",F16/J16) | L16: =IF(J16=0,"",(F16+G16)/J16) | M16: =IF(J16=0,0,D16) | N16: =IF(J16=0,0,D16*F16/J16) | O16: =IF(J16=0,0,D16*(F16+G16)/J16)
A18: Estimates (weighted by stratum population)
A19: Scored pairs at or above threshold | D19: =SUMIFS($D$6:$D$16,$B$6:$B$16,">="&$B$3)
A20: Precision at or above threshold, strict | D20: =IFERROR(SUMIFS($N$6:$N$16,$B$6:$B$16,">="&$B$3)/SUMIFS($M$6:$M$16,$B$6:$B$16,">="&$B$3),"")
A21: Precision at or above threshold, lenient | D21: =IFERROR(SUMIFS($O$6:$O$16,$B$6:$B$16,">="&$B$3)/SUMIFS($M$6:$M$16,$B$6:$B$16,">="&$B$3),"")
A22: Lenient precision when 'head' decides (all bands) | D22: =IFERROR(SUMIFS($O$6:$O$16,$C$6:$C$16,"head")/SUMIFS($M$6:$M$16,$C$6:$C$16,"head"),"")
A23: Lenient precision when 'tail' decides (all bands) | D23: =IFERROR(SUMIFS($O$6:$O$16,$C$6:$C$16,"tail")/SUMIFS($M$6:$M$16,$C$6:$C$16,"tail"),"")
A24: Lenient precision when 'eurovoc' decides (all bands) | D24: =IFERROR(SUMIFS($O$6:$O$16,$C$6:$C$16,"eurovoc")/SUMIFS($M$6:$M$16,$C$6:$C$16,"eurovoc"),"")
A25: Lenient precision when 'noun' decides (all bands) | D25: =IFERROR(SUMIFS($O$6:$O$16,$C$6:$C$16,"noun")/SUMIFS($M$6:$M$16,$C$6:$C$16,"noun"),"")
A26: Recall proxy: zero same-group pairs judged same or related | D26: =IFERROR(INDEX($L$6:$L$16,MATCH("zero same-group",$A$6:$A$16,0)),"")
A27: Recall proxy: known pairs scoring at or above threshold | D27: =IFERROR(COUNTIFS(Review!$K$2:$K$116,"known",Review!$L$2:$L$116,">="&$B$3)/COUNTIF(Review!$K$2:$K$116,"known"),"")
A29: Relation type by direction flag (counts)
B30: duplicate | C30: contradiction | D30: lex specialis | E30: overlap | F30: none | G30: unclear
A31: same | B31: =COUNTIFS(Review!$P$2:$P$116,$A31,Review!$I$2:$I$116,"duplicate") | C31: =COUNTIFS(Review!$P$2:$P$116,$A31,Review!$I$2:$I$116,"contradiction") | D31: =COUNTIFS(Review!$P$2:$P$116,$A31,Review!$I$2:$I$116,"lex specialis") | E31: =COUNTIFS(Review!$P$2:$P$116,$A31,Review!$I$2:$I$116,"overlap") | F31: =COUNTIFS(Review!$P$2:$P$116,$A31,Review!$I$2:$I$116,"none") | G31: =COUNTIFS(Review!$P$2:$P$116,$A31,Review!$I$2:$I$116,"unclear")
A32: a_narrower | B32: =COUNTIFS(Review!$P$2:$P$116,$A32,Review!$I$2:$I$116,"duplicate") | C32: =COUNTIFS(Review!$P$2:$P$116,$A32,Review!$I$2:$I$116,"contradiction") | D32: =COUNTIFS(Review!$P$2:$P$116,$A32,Review!$I$2:$I$116,"lex specialis") | E32: =COUNTIFS(Review!$P$2:$P$116,$A32,Review!$I$2:$I$116,"overlap") | F32: =COUNTIFS(Review!$P$2:$P$116,$A32,Review!$I$2:$I$116,"none") | G32: =COUNTIFS(Review!$P$2:$P$116,$A32,Review!$I$2:$I$116,"unclear")
A33: b_narrower | B33: =COUNTIFS(Review!$P$2:$P$116,$A33,Review!$I$2:$I$116,"duplicate") | C33: =COUNTIFS(Review!$P$2:$P$116,$A33,Review!$I$2:$I$116,"contradiction") | D33: =COUNTIFS(Review!$P$2:$P$116,$A33,Review!$I$2:$I$116,"lex specialis") | E33: =COUNTIFS(Review!$P$2:$P$116,$A33,Review!$I$2:$I$116,"overlap") | F33: =COUNTIFS(Review!$P$2:$P$116,$A33,Review!$I$2:$I$116,"none") | G33: =COUNTIFS(Review!$P$2:$P$116,$A33,Review!$I$2:$I$116,"unclear")
A34: none | B34: =COUNTIFS(Review!$P$2:$P$116,$A34,Review!$I$2:$I$116,"duplicate") | C34: =COUNTIFS(Review!$P$2:$P$116,$A34,Review!$I$2:$I$116,"contradiction") | D34: =COUNTIFS(Review!$P$2:$P$116,$A34,Review!$I$2:$I$116,"lex specialis") | E34: =COUNTIFS(Review!$P$2:$P$116,$A34,Review!$I$2:$I$116,"overlap") | F34: =COUNTIFS(Review!$P$2:$P$116,$A34,Review!$I$2:$I$116,"none") | G34: =COUNTIFS(Review!$P$2:$P$116,$A34,Review!$I$2:$I$116,"unclear")

Sheet Instructions
A1: How to judge
A2: Fill in the yellow cells of the Review sheet, one row per pair. Judge only the objects.
A3: Same thing? same: both norms are about the same thing.
A4: related: overlapping, or one is a part, kind or case of the other.
A5: different: not about the same thing. unclear: cannot tell (not counted).
A6: Relation type (optional, from the full norms): duplicate, contradiction, lex specialis,
A7: overlap (related, but no conflict or repetition), none, unclear.
A8: Score, key and stratum are in hidden columns (right of Note): unhide them after judging.
A9: Strict precision counts 'same'; lenient counts 'same' or 'related'.
A10: With about 10 pairs per stratum each figure is rough (about +/-15 points); the weighted
A11: estimates combine strata and are more stable. Sample sizes: Summary, column E.
A13: Example (format only; not part of the sample)
... A17: Settings: per cell 10, zero same-group 15, bands [0.5, 0.75], group parts 2, seed 42
