Workbook

Sheet Instructions
A1: How to judge
A2: Fill in the yellow cells of the Review sheet, one row per pair. Judge only the objects.
A3: Same thing? same: both objects are the same thing.
A4: related: overlapping, or one is a part, kind or case of the other.
A5: different: not about the same thing. unclear: cannot tell (not counted).
A6: Broader? only when same or related: which object is broader?
A7: A broader / B broader / equal scope / can't say.
A8: Units show how each object was split; judge the objects as a whole.
A9: Scores are in the hidden 'key' sheet: leave it alone until you are done.
A10: When finished, save and run: python pair_review.py review --xlsx <this file>
A12: Example (format only; not part of the sample)
A13: Object A: de risicobeoordeling | Object B: een beoordeling van de risico's
A14: Same thing? same | Broader? equal scope | Note: same assessment, other wording

Sheet Review
A1: # | B1: Norm A | C1: Object A | D1: Units A | E1: Norm B | F1: Object B | G1: Units B | H1: Same thing? | I1: Broader? | J1: Note
A2: 1 | B2: 32016R0679:35:7:14 | C2: de beoogde maatregelen om de risico's aan te pakken, waaronder waarborgen, veiligheidsmaatregelen en mechanismen om de bescherming van persoonsgegevens te garanderen en om aan te tonen dat aan deze verordening is voldaan, met inachtneming van de rechten en gerechtvaardigde belangen van de betrokkenen en andere personen in kwestie | D2: beoogde maatregelen om de risico's aan te pakken, waaronder waarborgen, veiligheidsmaatregelen en mechanismen om de bescherming van persoonsgegevens te garanderen en om aan te tonen dat aan deze verordening is voldaan, met inachtneming van de rechten en gerechtvaardigde belangen van de betrokkenen en andere personen in kwestie | E2: 32024R1689:82:1:1 | F2: alle passende maatregelen | G2: passende maatregelen
A3: 2 | B3: 32024R1689:57:6:8 | C3: begeleiding, toezicht en ondersteuning | D3: begeleiding | toezicht | ondersteuning | E3: 32024R1689:74:11:10 | F3: coördinerende ondersteuning van gezamenlijke onderzoeken | G3: coördinerende ondersteuning van gezamenlijke onderzoeken
A4: 3 | B4: 32016R0679:35:8:15 | C4: de naleving van de in artikel 40 bedoelde goedgekeurde gedragscodes | D4: goedgekeurde gedragscodes | E4: 32016R0679:41:2:6 | F4: op de naleving van de bepalingen van de gedragscode door deze laatsten | G4: bepalingen van de gedragscode door deze laatsten
A5: 4 | B5: 32024R1689:16:whole:12 | C5: het AI-systeem met een hoog risico | D5: AI-systeem met een hoog risico | E5: 32024R1689:5:2:2 | F5: Het gebruik van systemen voor biometrische identificatie op afstand in real time in openbare ruimten met het oog op de rechtshandhaving | G5: systemen voor biometrische identificatie op afstand in real time in openbare ruimten met het oog op de rechtshandhaving
A6: 5 | B6: 32016R0679:11:2:2 | C6: de betrokkene | D6: betrokkene | E6: 32016R0679:49:1:2 | F6: de betrokkene | G6: betrokkene
A7: 6 | B7: 32016R0679:9:1:1 | C7: Verwerking van persoonsgegevens waaruit ras of etnische afkomst, politieke opvattingen, religieuze of levensbeschouwelijke overtuigingen, of het lidmaatschap van een vakbond blijken, en verwerking van genetische gegevens, biometrische gegevens met het oog op de unieke identificatie van een persoon, of gegevens over gezondheid, of gegevens met betrekking tot iemands seksueel gedrag of seksuele gerichtheid | D7: Verwerking van persoonsgegevens waaruit ras of etnische afkomst, politieke opvattingen, religieuze of levensbeschouwelijke overtuigingen, of het lidmaatschap van een vakbond blijkenmet betrekking tot iemands seksueel gedrag of seksuele gerichtheid | verwerking van genetische gegevens, biometrische gegevens met het oog op de unieke identificatie van een persoon | gegevens over gezondheid, of gegevens | E7: 32024R1689:5:2:2 | F7: Het gebruik van systemen voor biometrische identificatie op afstand in real time in openbare ruimten met het oog op de rechtshandhaving | G7: systemen voor biometrische identificatie op afstand in real time in openbare ruimten met het oog op de rechtshandhaving
A8: 7 | B8: 32024R1689:112:8:16 | C8: informatie | D8: informatie | E8: 32024R1689:11:1:9 | F8: over de noodzakelijke, op heldere en begrijpelijke wijze gestelde informatie | G8: noodzakelijke, op heldere en begrijpelijke wijze gestelde informatie
A9: 8 | B9: 32016R0679:44:whole:2 | C9: Alle bepalingen van dit hoofdstuk | D9: bepalingen | E9: 32016R0679:6:3:5 | F9: specifieke bepalingen | G9: specifieke bepalingen
A10: 9 | B10: 32024R1689:26:5:9 | C10: de monitoringsverplichting overeenkomstig de eerste alinea | D10: monitoringsverplichting | E10: 32024R1689:57:1:4 | F10: de verplichting uit hoofde van de eerste alinea | G10: verplichting
A11: 10 | B11: 32016R0679:24:1:1 | C11: passende technische en organisatorische maatregelen | D11: passende technische en organisatorische maatregelen | E11: 32024R1689:93:1:1 | F11: passende maatregelen | G11: passende maatregelen
A12: 11 | B12: 32016R0679:58:6:30 | C12: dat zijn toezichthoudende autoriteit, naast de in lid 1, 2 en 3 bedoelde bevoegdheden bijkomende bevoegdheden heeft | D12: toezichthoudende autoriteit, naast de bevoegdheden bijkomende bevoegdheden heeft | E12: 32024R1689:74:5:4 | F12: de in artikel 14, lid 4, punten d) en j), van die verordening bedoelde bevoegdheden | G12: bevoegdheden
A13: 12 | B13: 32016R0679:40:8:15 | C13: zijn advies | D13: advies | E13: 32024R1689:84:2:2 | F13: onafhankelijk technisch of wetenschappelijk advies | G13: onafhankelijk technisch of wetenschappelijk advies
... A121: 120 | B121: 32016R0679:70:1:18 | C121: samenwerking en effectieve bilaterale en multilaterale uitwisseling van informatie en beste praktijken tussen de toezichthoudende autoriteiten | D121: samenwerking tussen de toezichthoudende autoriteiten | effectieve bilaterale en multilaterale uitwisseling van informatie en beste praktijken | E121: 32016R0679:75:6:10 | F121: de voorbereiding, opstelling en bekendmaking van adviezen, besluiten inzake beslechting van geschillen tussen toezichthoudende autoriteiten, en andere teksten die het Comité vaststelt | G121: voorbereiding, opstelling en bekendmaking van adviezen, besluiten inzake beslechting van geschillen tussen toezichthoudende autoriteiten, en andere teksten die het Comité vaststelt

Sheet key
A1: # | B1: stratum | C1: level | D1: score | E1: relation | F1: key | G1: spec | H1: weight | I1: direction | J1: top_key | K1: sources | L1: unit_a | M1: unit_b
A2: 1 | B2: below | 0.40-0.50 | C2: 0.40-0.50 | D2: 0.4031 | E2: head | F2: maatregel | G2: 0.4031 | H2: 1 | I2: a_narrower | J2: no | K2: EU-EU | L2: beoogde maatregelen om de risico's aan te pakken, waaronder waarborgen, veiligheidsmaatregelen en mechanismen om de bescherming van persoonsgegevens te garanderen en om aan te tonen dat aan deze verordening is voldaan, met inachtneming van de rechten en gerechtvaardigde belangen van de betrokkenen en andere personen in kwestie | M2: passende maatregelen
A3: 2 | B3: above | head | 0.60+ | C3: 0.60+ | D3: 0.7474 | E3: head | F3: ondersteun | G3: 0.7474 | H3: 1 | I3: b_narrower | J3: no | K3: EU-EU | L3: ondersteuning | M3: coördinerende ondersteuning van gezamenlijke onderzoeken
A4: 3 | B4: above | head | 0.50-0.60 | C4: 0.50-0.60 | D4: 0.5708 | E4: head | F4: gedragscod | G4: 0.5708 | H4: 1 | I4: same | J4: no | K4: EU-EU | L4: goedgekeurde gedragscodes | M4: bepalingen van de gedragscode door deze laatsten
A5: 4 | B5: below | <0.40 | C5: <0.40 | D5: 0.346 | E5: tail | F5: system | G5: 0.4325 | H5: 0.8 | I5: a_narrower | J5: no | K5: EU-EU | L5: AI-systeem met een hoog risico | M5: systemen voor biometrische identificatie op afstand in real time in openbare ruimten met het oog op de rechtshandhaving
A6: 5 | B6: above | eurovoc | 0.60+ | C6: 0.60+ | D6: 0.6958 | E6: eurovoc | F6: http://eurovoc.europa.eu/c_b007a1dc | G6: 0.7731 | H6: 0.9 | I6: same | J6: no | K6: EU-EU | L6: betrokkene | M6: betrokkene
A7: 6 | B7: above | noun | 0.50+ | C7: 0.50-0.60 | D7: 0.508 | E7: noun | F7: oog | G7: 0.7257 | H7: 0.7 | J7: no | K7: EU-EU | L7: verwerking van genetische gegevens, biometrische gegevens met het oog op de unieke identificatie van een persoon | M7: systemen voor biometrische identificatie op afstand in real time in openbare ruimten met het oog op de rechtshandhaving
A8: 7 | B8: below | <0.40 | C8: <0.40 | D8: 0.3737 | E8: head | F8: informatie | G8: 0.3737 | H8: 1 | I8: b_narrower | J8: no | K8: EU-EU | L8: informatie | M8: noodzakelijke, op heldere en begrijpelijke wijze gestelde informatie
A9: 8 | B9: above | head | 0.60+ | C9: 0.60+ | D9: 0.6006 | E9: head | F9: bepal | G9: 0.6006 | H9: 1 | I9: same | J9: no | K9: EU-EU | L9: bepalingen | M9: specifieke bepalingen
A10: 9 | B10: below | 0.40-0.50 | C10: 0.40-0.50 | D10: 0.4866 | E10: eurovoc | F10: http://eurovoc.europa.eu/164 | G10: 0.5407 | H10: 0.9 | I10: a_narrower | J10: no | K10: EU-EU | L10: monitoringsverplichting | M10: verplichting
A11: 10 | B11: below | 0.40-0.50 | C11: 0.40-0.50 | D11: 0.4031 | E11: head | F11: maatregel | G11: 0.4031 | H11: 1 | I11: same | J11: no | K11: EU-EU | L11: passende technische en organisatorische maatregelen | M11: passende maatregelen
A12: 11 | B12: below | 0.40-0.50 | C12: 0.40-0.50 | D12: 0.4264 | E12: noun | F12: bevoegd | G12: 0.6091 | H12: 0.7 | J12: no | K12: EU-EU | L12: toezichthoudende autoriteit, naast de bevoegdheden bijkomende bevoegdheden heeft | M12: bevoegdheden
A13: 12 | B13: above | head | 0.50-0.60 | C13: 0.50-0.60 | D13: 0.5642 | E13: head | F13: advies | G13: 0.5642 | H13: 1 | I13: same | J13: yes | K13: EU-EU | L13: advies | M13: onafhankelijk technisch of wetenschappelijk advies
A14: 13 | B14: below | <0.40 | C14: <0.40 | D14: 0.3737 | E14: head | F14: informatie | G14: 0.3737 | H14: 1 | I14: b_narrower | J14: no | K14: EU-EU | L14: informatie | M14: Informatie of documentatie die overheidsinstanties of -organen wordt verkregen
A15: 14 | B15: above | noun | 0.50+ | C15: 0.50-0.60 | D15: 0.5632 | E15: noun | F15: document | G15: 0.8046 | H15: 0.7 | J15: no | K15: EU-EU | L15: Persoonsgegevens in officiële documenten | M15: documenten met betrekking tot die aanwijzingen
A16: 15 | B16: above | eurovoc | 0.50-0.60 | C16: 0.50-0.60 | D16: 0.5482 | E16: eurovoc | F16: http://eurovoc.europa.eu/2701 | G16: 0.6091 | H16: 0.9 | I16: same | J16: yes | K16: EU-EU | L16: procedures | M16: procedures
A17: 16 | B17: below | 0.40-0.50 | C17: 0.40-0.50 | D17: 0.4031 | E17: head | F17: maatregel | G17: 0.4031 | H17: 1 | I17: same | J17: no | K17: EU-EU | L17: passende technische en organisatorische maatregelen | M17: voorlopige maatregel
A18: 17 | B18: below | 0.40-0.50 | C18: 0.40-0.50 | D18: 0.4325 | E18: head | F18: persoonsgegev | G18: 0.4325 | H18: 1 | I18: b_narrower | J18: no | K18: EU-EU | L18: persoonsgegevens | M18: persoonsgegevens en alle informatie die noodzakelijk is voor de uitvoering van haar taken
A19: 18 | B19: below | 0.40-0.50 | C19: 0.40-0.50 | D19: 0.4396 | E19: noun | F19: verantwoord | G19: 0.628 | H19: 0.7 | J19: no | K19: EU-EU | L19: Unierechtelijke of lidstaatrechtelijke gegevensbeschermingsbepalingen en van het beleid van de verwerkingsverantwoordelijke of de verwerker met betrekking tot de bescherming van persoonsgegevens, met inbegrip van de toewijzing van verantwoordelijkheden, bewustmaking en opleiding van het bij de verwerking betrokken personeel en de betreffende audits | M19: verwerkingsverantwoordelijke
A20: 19 | B20: above | head | 0.60+ | C20: 0.60+ | D20: 0.8451 | E20: head | F20: opschort | G20: 0.8451 | H20: 1 | I20: b_narrower | J20: no | K20: EU-EU | L20: opschorting van gegevensstromen | M20: opschorting van het testen onder reële omstandigheden
A21: 20 | B21: below | 0.40-0.50 | C21: 0.40-0.50 | D21: 0.4094 | E21: noun | F21: gegevensbescherm | G21: 0.5849 | H21: 0.7 | J21: no | K21: EU-EU | L21: functionaris voor gegevensbescherming naar behoren en tijdig wordt betrokken bij alle aangelegenheden die verband houden met de bescherming van persoonsgegevens | M21: uitwisseling van kennis en documentatie over de wetgeving en de praktijk op het gebied van gegevensbescherming met voor gegevensbescherming bevoegde toezichthoudende autoriteiten van de hele wereld
A22: 21 | B22: above | head | 0.60+ | C22: 0.60+ | D22: 0.6182 | E22: head | F22: wijzig | G22: 0.6182 | H22: 1 | I22: same | J22: yes | K22: EU-EU | L22: latere wijzigingen | M22: wijzigingen
A23: 22 | B23: above | tail | 0.50+ | C23: 0.50-0.60 | D23: 0.5522 | E23: tail | F23: stand | G23: 0.6902 | H23: 0.8 | J23: no | K23: EU-EU | L23: bijstand | M23: omstandigheden die van invloed zijn op het toepassingsgebied van of de voorwaarden voor de aanmelding
A24: 23 | B24: below | 0.40-0.50 | C24: 0.40-0.50 | D24: 0.4288 | E24: eurovoc | F24: http://eurovoc.europa.eu/5181 | G24: 0.4765 | H24: 0.9 | J24: no | K24: EU-EU | L24: één functionaris voor gegevensbescherming | M24: persoonsgegevens of volledige categorieën van persoonsgegevens die in het register zijn opgeslagen
A25: 24 | B25: below | <0.40 | C25: <0.40 | D25: 0.2616 | E25: noun | F25: informatie | G25: 0.3737 | H25: 0.7 | J25: no | K25: EU-EU | L25: persoonsgegevens en alle informatie die noodzakelijk is voor de uitvoering van haar taken | M25: Informatie
A26: 25 | B26: above | eurovoc | 0.60+ | C26: 0.60+ | D26: 0.6079 | E26: eurovoc | F26: http://eurovoc.europa.eu/4818 | G26: 0.6754 | H26: 0.9 | I26: same | J26: no | K26: EU-EU | L26: lijst | M26: lijst
A27: 26 | B27: below | <0.40 | C27: <0.40 | D27: 0.336 | E27: noun | F27: handel | G27: 0.48 | H27: 0.7 | J27: no | K27: EU-EU | L27: gedelegeerde handelingen | M27: systeem voor monitoring na het in de handel brengen
A28: 27 | B28: below | 0.40-0.50 | C28: 0.40-0.50 | D28: 0.4464 | E28: tail | F28: plicht | G28: 0.558 | H28: 0.8 | I28: b_narrower | J28: no | K28: EU-EU | L28: plichten | M28: verplichting
A29: 28 | B29: above | tail | 0.50+ | C29: 0.60+ | D29: 0.6185 | E29: tail | F29: conformiteit | G29: 0.7731 | H29: 0.8 | I29: b_narrower | J29: no | K29: EU-EU | L29: conformiteit van de AI-systemen met een hoog risico met de voorschriften | M29: non-conformiteit
A30: 29 | B30: above | eurovoc | 0.50-0.60 | C30: 0.50-0.60 | D30: 0.5652 | E30: eurovoc | F30: http://eurovoc.europa.eu/3482 | G30: 0.628 | H30: 0.9 | J30: no | K30: EU-EU | L30: gedragscode | M30: werking van de gedragscode
A31: 30 | B31: above | head | 0.50-0.60 | C31: 0.50-0.60 | D31: 0.5205 | E31: head | F31: procedur | G31: 0.5205 | H31: 1 | I31: a_narrower | J31: yes | K31: EU-EU | L31: procedures voor de uitwisseling van informatie over bindende bedrijfsvoorschriften | M31: geschil- of gerechtelijke procedures
A32: 31 | B32: below | <0.40 | C32: <0.40 | D32: 0.2616 | E32: noun | F32: informatie | G32: 0.3737 | H32: 0.7 | J32: no | K32: EU-EU | L32: informatie | M32: voor de uitvoering van de certificeringsprocedure noodzakelijke informatie
A33: 32 | B33: below | 0.40-0.50 | C33: 0.40-0.50 | D33: 0.4832 | E33: noun | F33: identificatie | G33: 0.6902 | H33: 0.7 | J33: no | K33: EU-EU | L33: informatie die vereist is voor de identificatie van de harmonisatiewetgeving van de Unie waarop de verklaring betrekking heeft | M33: systeem voor biometrische identificatie op afstand in real time in openbare ruimten
A34: 33 | B34: above | eurovoc | 0.50-0.60 | C34: 0.50-0.60 | D34: 0.5652 | E34: eurovoc | F34: http://eurovoc.europa.eu/3099 | G34: 0.628 | H34: 0.9 | J34: yes | K34: EU-EU | L34: bindende bedrijfsvoorschriften | M34: regels
A35: 34 | B35: above | tail | 0.50+ | C35: 0.50-0.60 | D35: 0.5403 | E35: tail | F35: termijn | G35: 0.6754 | H35: 0.8 | I35: a_narrower | J35: no | K35: EU-EU | L35: ambtstermijn | M35: termijn
A36: 35 | B36: above | eurovoc | 0.50-0.60 | C36: 0.50-0.60 | D36: 0.5564 | E36: eurovoc | F36: http://eurovoc.europa.eu/2579 | G36: 0.6182 | H36: 0.9 | J36: yes | K36: EU-EU | L36: toezichthoudende autoriteit | M36: verzoek van een toezichthoudende autoriteit om te mogen deelnemen
A37: 36 | B37: above | eurovoc | 0.60+ | C37: 0.60+ | D37: 0.6079 | E37: eurovoc | F37: http://eurovoc.europa.eu/2907 | G37: 0.6754 | H37: 0.9 | J37: no | K37: EU-EU | L37: instelling, het orgaan of de instantie van de Unie ten aanzien waarvan hij een procedure voert | M37: of de deelnemers de doelstellingen van de praktijkcodes verwezenlijken en bijdragen aan de correcte toepassing
A38: 37 | B38: above | tail | 0.50+ | C38: 0.60+ | D38: 0.6437 | E38: tail | F38: omgev | G38: 0.8046 | H38: 0.8 | I38: a_narrower | J38: no | K38: EU-EU | L38: AI-testomgeving voor regelgeving | M38: functioneel gescheiden, geïsoleerde en beschermde omgeving voor dataverwerking
A39: 38 | B39: below | <0.40 | C39: <0.40 | D39: 0.3611 | E39: noun | F39: verwerk | G39: 0.5159 | H39: 0.7 | J39: no | K39: EU-EU | L39: rectificeren of wissen van persoonsgegevens of het beperken van verwerking | M39: rechtsgrond voor de verwerking
A40: 39 | B40: above | noun | 0.50+ | C40: 0.50-0.60 | D40: 0.5916 | E40: noun | F40: vereist | G40: 0.8451 | H40: 0.7 | J40: no | K40: EU-EU | L40: vereisten | M40: product volledig voldoet aan alle toepasselijke vereisten uit hoofde van de toepasselijke harmonisatiewetgeving van de Unie
...

Sheet levels
A1: stratum | B1: level | C1: N
A2: above | head | 0.60+ | B2: 0.60+ | C2: 1083
A3: above | eurovoc | 0.60+ | B3: 0.60+ | C3: 565
A4: above | tail | 0.50+ | B4: 0.60+ | C4: 17
A5: above | head | 0.50-0.60 | B5: 0.50-0.60 | C5: 1085
A6: above | eurovoc | 0.50-0.60 | B6: 0.50-0.60 | C6: 1084
A7: above | tail | 0.50+ | B7: 0.50-0.60 | C7: 136
A8: above | noun | 0.50+ | B8: 0.50-0.60 | C8: 430
A9: below | 0.40-0.50 | B9: 0.40-0.50 | C9: 5953
A10: below | <0.40 | B10: <0.40 | C10: 11868

Sheet Design
A1: Sample design
A2: What is validated. The object score of a pair is the specificity of the best key the two norms' objects share, times a weight for the kind of match (head 1.0, eurovoc 0.9, tail 0.8, noun 0.7). Pairs scoring 0.5 or more are passed on as candidates. The question for the labeller is whether the two objects are the same thing, related, or different. Population. The population is the 3,933,465 Stage A pairs. Of these, 22,221 share at least one key and have an object score; 3,833,350 involve a norm without any object unit and 94,348 involve two norms whose units share no key. Pairs without a score make no claim, so they are not sampled; their numbers are exact counts (table below). Related pairs among them cannot be measured here. Why these strata. The filter makes two claims: a pair at or above the threshold is related (precision), a scored pair below it is not related enough (pairs lost). Both are sampled. Score levels on each side of the threshold show whether the share of related pairs changes at the cut-off: 0.60+, 0.50-0.60, 0.40-0.50, <0.40. Two levels per side are the minimum to see a trend; more would leave too few judgements per level to see one. Above the threshold the levels are crossed with the relation of the deciding key, because candidates are what the pipeline uses and each relation's weight is a claim to test; noun and tail are not split, having almost no pairs at 0.6 or more. Below the threshold the levels alone are enough. Why these sizes. Candidates receive most judgements although they are a minority of scored pairs, because candidate precision is the main figure and the candidate cells are small. Every cell gets a floor; the rest goes to the largest cells. A norm appears in at most 2 sampled pairs. At 50% in every cell this gives about +/-12 points on candidate precision and +/-15 points on the share of related pairs below the threshold. Overall figures are weighted by N_h (the 'review' step), never by row count. Caveat. Keys are concentrated: pairs sharing a frequent key tend to be right or wrong together, so the intervals, which treat pairs as independent, are slightly optimistic.
A4: stratum | B4: side | C4: relation | D4: population N_h | E4: share of scored pairs | F4: n sampled | G4: why this stratum and this n
A5: above | head | 0.60+ | B5: above | C5: head | D5: 1083 | E5: =D5/SUM($D$5:$D$12) -> 0.048737681 | F5: 12 | G5: Does a higher score mean higher precision? (head, weight claim)
A6: above | head | 0.50-0.60 | B6: above | C6: head | D6: 1085 | E6: =D6/SUM($D$5:$D$12) -> 0.048827686 | F6: 20 | G6: Largest candidate cell, right at the threshold.
A7: above | eurovoc | 0.60+ | B7: above | C7: eurovoc | D7: 565 | E7: =D7/SUM($D$5:$D$12) -> 0.025426398 | F7: 10 | G7: Does a higher score mean higher precision? (eurovoc, weight claim)
A8: above | eurovoc | 0.50-0.60 | B8: above | C8: eurovoc | D8: 1084 | E8: =D8/SUM($D$5:$D$12) -> 0.048782683 | F8: 15 | G8: Second-largest candidate cell, right at the threshold. Also depends on the EuroVoc mapping.
A9: above | tail | 0.50+ | B9: above | C9: tail | D9: 153 | E9: =D9/SUM($D$5:$D$12) -> 0.0068853787 | F9: 8 | G9: tail keys (lower weight); too few above the threshold to split; floor only.
A10: above | noun | 0.50+ | B10: above | C10: noun | D10: 430 | E10: =D10/SUM($D$5:$D$12) -> 0.019351064 | F10: 8 | G10: noun keys (lower weight); too few above the threshold to split; floor only.
A11: below | 0.40-0.50 | B11: below | C11: all | D11: 5953 | E11: =D11/SUM($D$5:$D$12) -> 0.26789973 | F11: 22 | G11: Near misses just below the threshold: if as many are related as just above it, the threshold could come down.
A12: below | <0.40 | B12: below | C12: all | D12: 11868 | E12: =D12/SUM($D$5:$D$12) -> 0.53408937 | F12: 25 | G12: The bulk of scored pairs, mostly generic keys and low-weight noun/tail keys: how many related pairs are lost.
A13: total | D13: =SUM(D5:D12) -> 22221 | F13: =SUM(F5:F12) -> 120
A15: Exact counts (not sampled)
A16: pairs | B16: count | C16: share of Stage A
A17: Stage A pairs | B17: 3933465 | C17: =B17/$B$17 -> 1
A18: scored (sampled above) | B18: 22221 | C18: =B18/$B$17 -> 0.0056492177
A19: a norm without any object unit | B19: 3833350 | C19: =B19/$B$17 -> 0.97454789
A20: both norms have units, no shared key | B20: 94348 | C20: =B20/$B$17 -> 0.023985977
A22: Settings: threshold 0.5, upper 0.6, lower 0.4, max uses per norm 2, top keys 20, seed 42

Sheet Summary
A1: stratum | B1: population N_h | C1: rows | D1: judged | E1: same | F1: related | G1: different | H1: unclear | I1: strict | J1: lenient | K1: lenient 95% low | L1: lenient 95% high | N1: z
A2: above | head | 0.60+ | B2: 1083 | C2: =COUNTIFS(key!$B$2:$B$121,A2) -> 12 | D2: =COUNTIFS(key!$B$2:$B$121,A2,Review!$H$2:$H$121,"<>") -> 0 | E2: =COUNTIFS(key!$B$2:$B$121,A2,Review!$H$2:$H$121,"same") -> 0 | F2: =COUNTIFS(key!$B$2:$B$121,A2,Review!$H$2:$H$121,"related") -> 0 | G2: =COUNTIFS(key!$B$2:$B$121,A2,Review!$H$2:$H$121,"different") -> 0 | H2: =COUNTIFS(key!$B$2:$B$121,A2,Review!$H$2:$H$121,"unclear") -> 0 | I2: =IFERROR(E2/(D2-H2),"") | J2: =IFERROR((E2+F2)/(D2-H2),"") | K2: =IFERROR(MAX(0,(J2+$N$2^2/(2*(D2-H2)))/(1+$N$2^2/(D2-H2))-$N$2*SQRT(J2*(1-J2)/(D2-H2)+$N$2^2/(4*(D2-H2)^2))/(1+$N$2^2/(D2-H2))),"") | L2: =IFERROR(MIN(1,(J2+$N$2^2/(2*(D2-H2)))/(1+$N$2^2/(D2-H2))+$N$2*SQRT(J2*(1-J2)/(D2-H2)+$N$2^2/(4*(D2-H2)^2))/(1+$N$2^2/(D2-H2))),"") | N2: 1.96
A3: above | head | 0.50-0.60 | B3: 1085 | C3: =COUNTIFS(key!$B$2:$B$121,A3) -> 20 | D3: =COUNTIFS(key!$B$2:$B$121,A3,Review!$H$2:$H$121,"<>") -> 0 | E3: =COUNTIFS(key!$B$2:$B$121,A3,Review!$H$2:$H$121,"same") -> 0 | F3: =COUNTIFS(key!$B$2:$B$121,A3,Review!$H$2:$H$121,"related") -> 0 | G3: =COUNTIFS(key!$B$2:$B$121,A3,Review!$H$2:$H$121,"different") -> 0 | H3: =COUNTIFS(key!$B$2:$B$121,A3,Review!$H$2:$H$121,"unclear") -> 0 | I3: =IFERROR(E3/(D3-H3),"") | J3: =IFERROR((E3+F3)/(D3-H3),"") | K3: =IFERROR(MAX(0,(J3+$N$2^2/(2*(D3-H3)))/(1+$N$2^2/(D3-H3))-$N$2*SQRT(J3*(1-J3)/(D3-H3)+$N$2^2/(4*(D3-H3)^2))/(1+$N$2^2/(D3-H3))),"") | L3: =IFERROR(MIN(1,(J3+$N$2^2/(2*(D3-H3)))/(1+$N$2^2/(D3-H3))+$N$2*SQRT(J3*(1-J3)/(D3-H3)+$N$2^2/(4*(D3-H3)^2))/(1+$N$2^2/(D3-H3))),"")
A4: above | eurovoc | 0.60+ | B4: 565 | C4: =COUNTIFS(key!$B$2:$B$121,A4) -> 10 | D4: =COUNTIFS(key!$B$2:$B$121,A4,Review!$H$2:$H$121,"<>") -> 0 | E4: =COUNTIFS(key!$B$2:$B$121,A4,Review!$H$2:$H$121,"same") -> 0 | F4: =COUNTIFS(key!$B$2:$B$121,A4,Review!$H$2:$H$121,"related") -> 0 | G4: =COUNTIFS(key!$B$2:$B$121,A4,Review!$H$2:$H$121,"different") -> 0 | H4: =COUNTIFS(key!$B$2:$B$121,A4,Review!$H$2:$H$121,"unclear") -> 0 | I4: =IFERROR(E4/(D4-H4),"") | J4: =IFERROR((E4+F4)/(D4-H4),"") | K4: =IFERROR(MAX(0,(J4+$N$2^2/(2*(D4-H4)))/(1+$N$2^2/(D4-H4))-$N$2*SQRT(J4*(1-J4)/(D4-H4)+$N$2^2/(4*(D4-H4)^2))/(1+$N$2^2/(D4-H4))),"") | L4: =IFERROR(MIN(1,(J4+$N$2^2/(2*(D4-H4)))/(1+$N$2^2/(D4-H4))+$N$2*SQRT(J4*(1-J4)/(D4-H4)+$N$2^2/(4*(D4-H4)^2))/(1+$N$2^2/(D4-H4))),"")
A5: above | eurovoc | 0.50-0.60 | B5: 1084 | C5: =COUNTIFS(key!$B$2:$B$121,A5) -> 15 | D5: =COUNTIFS(key!$B$2:$B$121,A5,Review!$H$2:$H$121,"<>") -> 0 | E5: =COUNTIFS(key!$B$2:$B$121,A5,Review!$H$2:$H$121,"same") -> 0 | F5: =COUNTIFS(key!$B$2:$B$121,A5,Review!$H$2:$H$121,"related") -> 0 | G5: =COUNTIFS(key!$B$2:$B$121,A5,Review!$H$2:$H$121,"different") -> 0 | H5: =COUNTIFS(key!$B$2:$B$121,A5,Review!$H$2:$H$121,"unclear") -> 0 | I5: =IFERROR(E5/(D5-H5),"") | J5: =IFERROR((E5+F5)/(D5-H5),"") | K5: =IFERROR(MAX(0,(J5+$N$2^2/(2*(D5-H5)))/(1+$N$2^2/(D5-H5))-$N$2*SQRT(J5*(1-J5)/(D5-H5)+$N$2^2/(4*(D5-H5)^2))/(1+$N$2^2/(D5-H5))),"") | L5: =IFERROR(MIN(1,(J5+$N$2^2/(2*(D5-H5)))/(1+$N$2^2/(D5-H5))+$N$2*SQRT(J5*(1-J5)/(D5-H5)+$N$2^2/(4*(D5-H5)^2))/(1+$N$2^2/(D5-H5))),"")
A6: above | tail | 0.50+ | B6: 153 | C6: =COUNTIFS(key!$B$2:$B$121,A6) -> 8 | D6: =COUNTIFS(key!$B$2:$B$121,A6,Review!$H$2:$H$121,"<>") -> 0 | E6: =COUNTIFS(key!$B$2:$B$121,A6,Review!$H$2:$H$121,"same") -> 0 | F6: =COUNTIFS(key!$B$2:$B$121,A6,Review!$H$2:$H$121,"related") -> 0 | G6: =COUNTIFS(key!$B$2:$B$121,A6,Review!$H$2:$H$121,"different") -> 0 | H6: =COUNTIFS(key!$B$2:$B$121,A6,Review!$H$2:$H$121,"unclear") -> 0 | I6: =IFERROR(E6/(D6-H6),"") | J6: =IFERROR((E6+F6)/(D6-H6),"") | K6: =IFERROR(MAX(0,(J6+$N$2^2/(2*(D6-H6)))/(1+$N$2^2/(D6-H6))-$N$2*SQRT(J6*(1-J6)/(D6-H6)+$N$2^2/(4*(D6-H6)^2))/(1+$N$2^2/(D6-H6))),"") | L6: =IFERROR(MIN(1,(J6+$N$2^2/(2*(D6-H6)))/(1+$N$2^2/(D6-H6))+$N$2*SQRT(J6*(1-J6)/(D6-H6)+$N$2^2/(4*(D6-H6)^2))/(1+$N$2^2/(D6-H6))),"")
A7: above | noun | 0.50+ | B7: 430 | C7: =COUNTIFS(key!$B$2:$B$121,A7) -> 8 | D7: =COUNTIFS(key!$B$2:$B$121,A7,Review!$H$2:$H$121,"<>") -> 0 | E7: =COUNTIFS(key!$B$2:$B$121,A7,Review!$H$2:$H$121,"same") -> 0 | F7: =COUNTIFS(key!$B$2:$B$121,A7,Review!$H$2:$H$121,"related") -> 0 | G7: =COUNTIFS(key!$B$2:$B$121,A7,Review!$H$2:$H$121,"different") -> 0 | H7: =COUNTIFS(key!$B$2:$B$121,A7,Review!$H$2:$H$121,"unclear") -> 0 | I7: =IFERROR(E7/(D7-H7),"") | J7: =IFERROR((E7+F7)/(D7-H7),"") | K7: =IFERROR(MAX(0,(J7+$N$2^2/(2*(D7-H7)))/(1+$N$2^2/(D7-H7))-$N$2*SQRT(J7*(1-J7)/(D7-H7)+$N$2^2/(4*(D7-H7)^2))/(1+$N$2^2/(D7-H7))),"") | L7: =IFERROR(MIN(1,(J7+$N$2^2/(2*(D7-H7)))/(1+$N$2^2/(D7-H7))+$N$2*SQRT(J7*(1-J7)/(D7-H7)+$N$2^2/(4*(D7-H7)^2))/(1+$N$2^2/(D7-H7))),"")
A8: below | 0.40-0.50 | B8: 5953 | C8: =COUNTIFS(key!$B$2:$B$121,A8) -> 22 | D8: =COUNTIFS(key!$B$2:$B$121,A8,Review!$H$2:$H$121,"<>") -> 0 | E8: =COUNTIFS(key!$B$2:$B$121,A8,Review!$H$2:$H$121,"same") -> 0 | F8: =COUNTIFS(key!$B$2:$B$121,A8,Review!$H$2:$H$121,"related") -> 0 | G8: =COUNTIFS(key!$B$2:$B$121,A8,Review!$H$2:$H$121,"different") -> 0 | H8: =COUNTIFS(key!$B$2:$B$121,A8,Review!$H$2:$H$121,"unclear") -> 0 | I8: =IFERROR(E8/(D8-H8),"") | J8: =IFERROR((E8+F8)/(D8-H8),"") | K8: =IFERROR(MAX(0,(J8+$N$2^2/(2*(D8-H8)))/(1+$N$2^2/(D8-H8))-$N$2*SQRT(J8*(1-J8)/(D8-H8)+$N$2^2/(4*(D8-H8)^2))/(1+$N$2^2/(D8-H8))),"") | L8: =IFERROR(MIN(1,(J8+$N$2^2/(2*(D8-H8)))/(1+$N$2^2/(D8-H8))+$N$2*SQRT(J8*(1-J8)/(D8-H8)+$N$2^2/(4*(D8-H8)^2))/(1+$N$2^2/(D8-H8))),"")
A9: below | <0.40 | B9: 11868 | C9: =COUNTIFS(key!$B$2:$B$121,A9) -> 25 | D9: =COUNTIFS(key!$B$2:$B$121,A9,Review!$H$2:$H$121,"<>") -> 0 | E9: =COUNTIFS(key!$B$2:$B$121,A9,Review!$H$2:$H$121,"same") -> 0 | F9: =COUNTIFS(key!$B$2:$B$121,A9,Review!$H$2:$H$121,"related") -> 0 | G9: =COUNTIFS(key!$B$2:$B$121,A9,Review!$H$2:$H$121,"different") -> 0 | H9: =COUNTIFS(key!$B$2:$B$121,A9,Review!$H$2:$H$121,"unclear") -> 0 | I9: =IFERROR(E9/(D9-H9),"") | J9: =IFERROR((E9+F9)/(D9-H9),"") | K9: =IFERROR(MAX(0,(J9+$N$2^2/(2*(D9-H9)))/(1+$N$2^2/(D9-H9))-$N$2*SQRT(J9*(1-J9)/(D9-H9)+$N$2^2/(4*(D9-H9)^2))/(1+$N$2^2/(D9-H9))),"") | L9: =IFERROR(MIN(1,(J9+$N$2^2/(2*(D9-H9)))/(1+$N$2^2/(D9-H9))+$N$2*SQRT(J9*(1-J9)/(D9-H9)+$N$2^2/(4*(D9-H9)^2))/(1+$N$2^2/(D9-H9))),"")
A11: Per stratum, unweighted. Above the threshold 'lenient' is precision; below it, the share of related pairs that were lost.
A12: Weighted figures (candidate precision, score-level curve, pairs lost, direction): python pair_review.py review --xlsx <this file>
