Workbook

Sheet Instructions
A1: How to judge
A2: Each row of the Review sheet is a pair of norms, A and B. Judge only their actors: who is addressed by each norm. Use the norm texts.
A3: Actor relation?
A4: same both norms address the same actor (other wording counts).
A5: nested one actor is a kind or a part of the other (e.g. 'aanbieder van een AI-systeem met een hoog risico' in 'aanbieder').
A6: related different but closely related actors (two kinds of one actor), or a broad actor that may include the other.
A7: different different actors.
A8: unclear cannot tell from the texts (not counted).
A9: Narrower actor? only when 'same' or 'nested': A narrower / B narrower / equal / can't say.
A10: Actor units show how each actor phrase was split; judge the actor as a whole. When a norm has several actors, judge the closest pair.
A11: Scores are in the hidden 'key' sheet: leave it alone until you are done.
A12: When finished, save and run: python actor_pair_review.py review --xlsx <this file>
... A16: Actor relation? nested | Narrower actor? A narrower

Sheet Review
A1: # | B1: Norm A | C1: Actor A | D1: Actor units A | E1: Text A | F1: Norm B | G1: Actor B | H1: Actor units B | I1: Text B | J1: Actor relation? | K1: Narrower actor? | L1: Note
A2: 1 | B2: 32024R1689:100:7:10 | C2: De Europese Toezichthouder voor gegevensbescherming | D2: Europese Toezichthouder voor gegevensbescherming | F2: 32024R1689:112:13:22 | G2: de Commissie | H2: Commissie
A3: 2 | B3: 32024R1689:41:6:5 | C3: De Commissie | D3: Commissie | F3: 32016R0679:43:9:13 | G3: De Commissie | H3: Commissie
A4: 3 | B4: 32024R1689:16:whole:4 | C4: Aanbieders van AI-systemen met een hoog risico | D4: Aanbieders van AI-systemen met een hoog risico | E4: Aanbieders van AI-systemen met een hoog risico: a) zorgen ervoor dat hun AI-systemen met een hoog risico in overeenstemming zijn met de eisen van afdeling 2; b) vermelden op het AI-systeem met een hoog risico of, wanneer dit niet mogelijk is, op de verpakking of in de bij het product gevoegde documentatie, naargelang het geval, hun naam, geregistreerde handelsnaam of geregistreerd merk en hun contactadres; c) beschikken over een systeem voor kwaliteitsbeheer dat in overeenstemming is met artikel 17; d) bewaren de in artikel 18 bedoelde documentatie; e) bewaren de in artikel 19 bedoelde logs die automatisch door hun AI-systemen met een hoog risico zijn gegenereerd, wanneer zij hierover de controle hebben; f) zorgen ervoor dat voor het AI-systeem met een hoog risico de desbetreffende in artikel 43 bedoelde conformiteitsbeoordelingsprocedure wordt uitgevoerd voordat dit systeem in de handel wordt gebracht of in gebruik wordt gesteld; g) stellen een EU-conformiteitsverklaring op, in overeenstemming met artikel 47; h) brengen de CE-markering aan op het AI-systeem met een hoog risico of, wanneer dit niet mogelijk is, op de verpakking of in de bij het product gevoegde documentatie, om aan te geven dat aan deze verordening is voldaan, overeenkomstig artikel 48; i) leven de registratieverplichtingen als bedoeld in artikel 49, lid 1, na; j) nemen de noodzakelijke corrigerende maatregelen en verstrekken de uit hoofde van artikel 20 vereiste informatie; k) tonen op een met red | F4: 32016R0679:8:1:1 | G4: de persoon die de ouderlijke verantwoordelijkheid voor het kind draagt | H4: persoon | I4: Wanneer artikel 6, lid 1, punt a), van toepassing is in verband met een rechtstreeks aanbod van diensten van de informatiemaatschappij aan een kind, is de verwerking van persoonsgegevens van een kind rechtmatig wanneer het kind ten minste 16 jaar is. Wanneer het kind jonger is dan 16 jaar is zulke verwerking slechts rechtmatig indien en voor zover de toestemming of machtiging tot toestemming in dit verband wordt verleend door de persoon die de ouderlijke verantwoordelijkheid voor het kind draagt. De lidstaten kunnen dienaangaande bij wet voorzien in een lagere leeftijd, op voorwaarde dat die leeftijd niet onder 13 jaar ligt.
A5: 4 | B5: 32024R1689:28:2:5 | C5: De lidstaten | D5: lidstaten | F5: 32024R1689:36:3:7 | G5: een aangemelde instantie | H5: aangemelde instantie
A6: 5 | B6: 32016R0679:60:2:3 | C6: De leidende toezichthoudende autoriteit | D6: leidende toezichthoudende autoriteit | E6: De leidende toezichthoudende autoriteit kan te allen tijde andere betrokken toezichthoudende autoriteiten verzoeken wederzijdse bijstand overeenkomstig artikel 61 te verlenen, en kan gezamenlijke werkzaamheden ondernemen overeenkomstig artikel 62, in het bijzonder voor het uitvoeren van onderzoeken of voor het toezicht op de uitvoering van een maatregel betreffende een in een andere lidstaat gevestigde verwerkingsverantwoordelijke of verwerker. | F6: 32016R0679:61:4:7 | G6: De toezichthoudende autoriteit waaraan een verzoek om bijstand is gericht | H6: toezichthoudende autoriteit
A7: 6 | B7: 32024R1689:93:3:9 | C7: de Commissie | D7: Commissie | E7: Indien de aanbieder van het AI-model voor algemene doeleinden dat een systeemrisico vormt, tijdens de in lid 2 bedoelde gestructureerde dialoog toezeggingen doet om risicobeperkende maatregelen uit te voeren om een systeemrisico op Unieniveau aan te pakken, kan de Commissie die toezeggingen bij besluit bindend maken en verklaren dat er geen verdere gronden voor actie zijn. | F7: 32016R0679:55:2:3 | G7: de toezichthoudende autoriteit van de lidstaat in kwestie | H7: toezichthoudende autoriteit van de lidstaat in kwestie | I7: In het geval van verwerking door overheidsinstanties of door particuliere organen die handelen op grond van artikel 6, lid 1, onder c) of e), is de toezichthoudende autoriteit van de lidstaat in kwestie competent. In dergelijke gevallen is artikel 56 niet van toepassing.
A8: 7 | B8: 32024R1689:101:2:5 | C8: de Commissie | D8: Commissie | E8: Alvorens het besluit op grond van lid 1 vast te stellen, deelt de Commissie haar voorlopige bevindingen mee aan de aanbieder van het AI-model voor algemene doeleinden, en stelt zij hem in de gelegenheid te worden gehoord. | F8: 32016R0679:37:2:2 | G8: Een concern | H8: concern | I8: Een concern kan één functionaris voor gegevensbescherming benoemen, mits de functionaris voor gegevensbescherming vanuit elke vestiging makkelijk te contacteren is.
A9: 8 | B9: 32024R1689:70:6:10 | C9: de lidstaten | D9: lidstaten | F9: 32016R0679:59:whole:1 | G9: Elke toezichthoudende autoriteit | H9: toezichthoudende autoriteit | I9: Elke toezichthoudende autoriteit stelt jaarlijks een verslag over haar activiteiten op, met daarin mogelijk een lijst van de soorten gemelde inbreuken en de soorten maatregelen die overeenkomstig artikel 58, lid 2, worden genomen. Die verslagen worden toegezonden aan het nationale parlement, de regering en elke andere autoriteit die daartoe in het lidstatelijke recht is aangewezen. Zij worden ter beschikking gesteld van het publiek, de Commissie en het Comité.
A10: 9 | B10: 32016R0679:58:1:3 | C10: Elk toezichthoudende autoriteit | D10: toezichthoudende autoriteit | E10: Elk toezichthoudende autoriteit heeft alle volgende onderzoeksbevoegdheden om: a) de verwerkingsverantwoordelijke, de verwerker en, in voorkomend geval, de vertegenwoordiger van de verwerkingsverantwoordelijke of van verwerker te gelasten alle voor de uitvoering van haar taken vereiste informatie te verstrekken; b) onderzoeken te verrichten in de vorm van gegevensbeschermingscontroles; c) een toetsing te verrichten van de overeenkomstig artikel 42, lid 7, afgegeven certificeringen; d) de verwerkingsverantwoordelijke of de verwerker in kennis te stellen van een beweerde inbreuk op deze verordening; e) van de verwerkingsverantwoordelijke en de verwerker toegang te verkrijgen tot alle persoonsgegevens en alle informatie die noodzakelijk is voor de uitvoering van haar taken; en f) toegang te verkrijgen tot alle bedrijfsruimten van de verwerkingsverantwoordelijke en de verwerker, daaronder begrepen tot alle uitrustingen en middelen voor gegevensverwerking, in overeenstemming met het uniale of lidstatelijke procesrecht. | F10: 32016R0679:65:6:13 | G10: De leidende toezichthoudende autoriteit of, in voorkomend geval, de toezichthoudende autoriteit waarbij de klacht is ingediend | H10: leidende toezichthoudende autoriteit | toezichthoudende autoriteit
A11: 10 | B11: 32016R0679:58:3:20 | C11: Elke toezichthoudende autoriteit | D11: toezichthoudende autoriteit | F11: 32016R0679:60:9:18 | G11: De leidende toezichthoudende autoriteit | H11: leidende toezichthoudende autoriteit
A12: 11 | B12: 32024R1689:56:3:3 | C12: Maatschappelijke organisaties, het bedrijfsleven, de academische wereld en andere relevante belanghebbenden, zoals aanbieders verder in de AI-waardeketen en onafhankelijke deskundigen | D12: Maatschappelijke organisaties | relevante belanghebbenden | F12: 32024R1689:85:whole:3 | G12: elke natuurlijke of rechtspersoon die redenen heeft om van mening te zijn dat er inbreuk is gepleegd op de bepalingen van deze verordening | H12: natuurlijke of rechtspersoon | I12: Onverminderd andere administratieve of gerechtelijke rechtsmiddelen kan elke natuurlijke of rechtspersoon die redenen heeft om van mening te zijn dat er inbreuk is gepleegd op de bepalingen van deze verordening, klachten indienen bij de relevante markttoezichtautoriteit. Overeenkomstig Verordening (EU) 2019/1020 worden dergelijke klachten in aanmerking genomen ter uitvoering van markttoezichtactiviteiten en worden zij behandeld in overeenstemming met de specifieke procedures die de markttoezichtautoriteiten daartoe hebben vastgesteld.
A13: 12 | B13: 32024R1689:20:1:2 | C13: Aanbieders van AI-systemen met een hoog risico | D13: Aanbieders van AI-systemen met een hoog risico | E13: Aanbieders van AI-systemen met een hoog risico die van mening zijn of redenen hebben om aan te nemen dat een door hen in de handel gebracht of in gebruik gesteld AI-systeem met een hoog risico niet in overeenstemming is met deze verordening, nemen onmiddellijk de nodige corrigerende maatregelen om dat systeem naargelang het geval in overeenstemming te brengen, uit de handel te nemen, te deactiveren of terug te roepen. Zij stellen de distributeurs van het betrokken AI-systeem met een hoog risico en, indien van toepassing, de gebruiksverantwoordelijken, de gemachtigden en importeurs dienovereenkomstig in kennis. | F13: 32024R1689:27:2:3 | G13: de gebruiksverantwoordelijke | H13: gebruiksverantwoordelijke | I13: De verplichting als neergelegd in lid 1 is van toepassing op het eerste gebruik van een AI-systeem met een hoog risico. De gebruiksverantwoordelijke kan in soortgelijke gevallen gebruik maken van eerder uitgevoerde effectbeoordelingen op het gebied van de grondrechten of bestaande effectbeoordelingen die door de aanbieder zijn uitgevoerd. Indien de gebruiksverantwoordelijke tijdens het gebruik van het AI-systeem met een hoog risico ziet dat een van de in lid 1 vermelde elementen is gewijzigd of niet langer actueel is, neemt de gebruiksverantwoordelijke de nodige maatregelen om de informatie te actualiseren.
A14: 13 | B14: 32024R1689:27:3:5 | C14: de gebruiksverantwoordelijke | D14: gebruiksverantwoordelijke | F14: 32024R1689:92:5:6 | G14: De aanbieders van AI-modellen voor algemene doeleinden of hun vertegenwoordiger | H14: aanbieders van AI-modellen voor algemene doeleinden of hun vertegenwoordiger | I14: De aanbieders van AI-modellen voor algemene doeleinden of hun vertegenwoordiger verstrekken de gevraagde informatie. In het geval van rechtspersonen, bedrijven of firma’s of indien de aanbieder geen rechtspersoonlijkheid heeft, verlenen de personen die krachtens de wet of hun statuten gemachtigd zijn om hen te vertegenwoordigen, de gevraagde toegang namens de aanbieder van het betrokken AI-model voor algemene doeleinden.
A15: 14 | B15: 32024R1689:90:2:2 | C15: de Commissie | D15: Commissie | E15: Naar aanleiding van een dergelijke gekwalificeerde waarschuwing kan de Commissie via het AI-Bureau, na de AI-board in kennis gesteld te hebben, de in deze afdeling vastgelegde bevoegdheden uitoefenen om de aangelegenheid te beoordelen. Het AI-bureau stelt de AI-board in kennis van elke maatregel overeenkomstig de artikelen 91 tot en met 94. | F15: 32016R0679:51:2:3 | G15: de toezichthoudende autoriteiten | H15: toezichthoudende autoriteiten | I15: Elke toezichthoudende autoriteit draagt bij tot de consequente toepassing van deze verordening in de hele Unie. Daartoe werken de toezichthoudende autoriteiten onderling en met de Commissie samen overeenkomstig hoofdstuk VII.
A16: 15 | B16: 32024R1689:101:2:4 | C16: de Commissie | D16: Commissie | E16: Alvorens het besluit op grond van lid 1 vast te stellen, deelt de Commissie haar voorlopige bevindingen mee aan de aanbieder van het AI-model voor algemene doeleinden, en stelt zij hem in de gelegenheid te worden gehoord. | F16: 32016R0679:64:4:6 | G16: De toezichthoudende autoriteiten en de Commissie | H16: toezichthoudende autoriteiten en de Commissie
A17: 16 | B17: 32024R1689:93:3:9 | C17: de Commissie | D17: Commissie | E17: Indien de aanbieder van het AI-model voor algemene doeleinden dat een systeemrisico vormt, tijdens de in lid 2 bedoelde gestructureerde dialoog toezeggingen doet om risicobeperkende maatregelen uit te voeren om een systeemrisico op Unieniveau aan te pakken, kan de Commissie die toezeggingen bij besluit bindend maken en verklaren dat er geen verdere gronden voor actie zijn. | F17: 32016R0679:35:2:2 | G17: de verwerkingsverantwoordelijke | H17: verwerkingsverantwoordelijke | I17: Wanneer een functionaris voor gegevensbescherming is aangewezen, wint de verwerkingsverantwoordelijke bij het uitvoeren van een gegevensbeschermingseffectbeoordeling diens advies in.
A18: 17 | B18: 32016R0679:54:1:6 | C18: Elke lidstaat | D18: lidstaat | E18: Elke lidstaat regelt al het volgende bij wet: a) de oprichting van elke toezichthoudende autoriteit; b) de vereiste kwalificaties en voorwaarden om als lid te worden benoemd voor elke toezichthoudende autoriteit; c) de regels en procedures voor de benoeming van het lid of de leden van elke toezichthoudende autoriteit; d) de ambtstermijn van het lid of de leden van elke toezichthoudende autoriteit, die ten minste vier jaar bedraagt, behoudens de eerste ambtstermijn na 24 mei 2016, die korter kan zijn wanneer dat nodig is om de onafhankelijkheid van de toezichthoudende autoriteit door middel van een in de tijd gespreide benoemingsprocedure te beschermen; e) of het lid of de leden van elke toezichthoudende autoriteit opnieuw kan of kunnen worden benoemd en zo ja, hoe vaak; f) de voorwaarden in verband met de plichten van het lid of de leden en de personeelsleden van elke toezichthoudende autoriteit, de verboden op met die plichten onverenigbare handelingen, werkzaamheden en voordelen tijdens en na de ambtstermijn en de regels betreffende de beëindiging van de ambtstermijn onderscheidenlijk de arbeidsverhouding. | F18: 32016R0679:60:8:17 | G18: de toezichthoudende autoriteit waarbij de klacht is ingediend | H18: toezichthoudende autoriteit | I18: Ingeval een klacht is afgewezen of verworpen, stelt de toezichthoudende autoriteit waarbij de klacht is ingediend, in afwijking van lid 7, het besluit vast en deelt zij het mee aan de klager en stelt zij de verwerkingsverantwoordelijke ervan in kennis.
A19: 18 | B19: 32024R1689:77:3:7 | C19: De markttoezichtautoriteit | D19: markttoezichtautoriteit | E19: Indien de in lid 1 bedoelde documentatie ontoereikend is om vast te stellen of sprake is geweest van een inbreuk op verplichtingen krachtens het Unierecht ter bescherming van grondrechten, kunnen de in lid 1 bedoelde overheidsinstanties of -organen een met redenen omkleed verzoek bij de markttoezichtautoriteit indienen om het AI-systeem met een hoog risico met technische middelen te mogen testen. De markttoezichtautoriteit organiseert de testprocedure binnen een redelijke termijn na het verzoek en met nauwe betrokkenheid van de verzoekende overheidsinstantie of het verzoekende overheidsorgaan. | F19: 32016R0679:83:9:10 | G19: Die lidstaten | H19: lidstaten | I19: Wanneer het rechtsstelsel van de lidstaat niet voorziet in administratieve geldboeten, kan dit artikel aldus worden toegepast dat geldboeten worden geïnitieerd door de bevoegde toezichthoudende autoriteit en opgelegd door bevoegde nationale gerechten, waarbij wordt gewaarborgd dat deze rechtsmiddelen doeltreffend zijn en eenzelfde effect hebben als de door toezichthoudende autoriteiten opgelegde administratieve geldboeten. De boeten zijn in elk geval doeltreffend, evenredig en afschrikkend. Die lidstaten delen de Commissie uiterlijk op 25 mei 2018 de wetgevingsbepalingen mee die zij op grond van dit lid vaststellen, alsmede onverwijld alle latere wijzigingen daarvan en alle daarop van invloed zijnde wijzigingswetgeving.
A20: 19 | B20: 32024R1689:5:5:10 | C20: De betrokken lidstaten | D20: betrokken lidstaten | F20: 32016R0679:30:2:3 | G20: De verwerker, en, in voorkomend geval, de vertegenwoordiger van de verwerker | H20: verwerker | vertegenwoordiger van de verwerker | I20: De verwerker, en, in voorkomend geval, de vertegenwoordiger van de verwerker houdt een register van alle categorieën van verwerkingsactiviteiten die zij ten behoeve van een verwerkingsverantwoordelijke hebben verricht. Dit register bevat de volgende gegevens: a) de naam en de contactgegevens van de verwerkers en van iedere verwerkingsverantwoordelijke voor rekening waarvan de verwerker handelt, en, in voorkomend geval, van de vertegenwoordiger van de verwerkingsverantwoordelijke of de verwerker en van de functionaris voor gegevensbescherming; b) de categorieën van verwerkingen die voor rekening van iedere verwerkingsverantwoordelijke zijn uitgevoerd; c) indien van toepassing, doorgiften van persoonsgegevens aan een derde land of een internationale organisatie, onder vermelding van dat derde land of die internationale organisatie en, in geval van de in artikel 49, lid 1, tweede alinea, bedoelde doorgiften, de documenten inzake de passende waarborgen; d) indien mogelijk, een algemene beschrijving van de technische en organisatorische beveiligingsmaatregelen als bedoeld in artikel 32, lid 1.
A21: 20 | B21: 32024R1689:52:1:1 | C21: de betrokken aanbieder | D21: betrokken aanbieder | E21: Indien een AI-model voor algemene doeleinden voldoet aan de in artikel 51, lid 1, punt a), bedoelde voorwaarde, stelt de betrokken aanbieder de Commissie daarvan onverwijld in kennis, doch in ieder geval binnen twee weken nadat aan die eis is voldaan of nadat bekend is geworden dat aan die eis zal worden voldaan. Die kennisgeving bevat de informatie die nodig is om aan te tonen dat aan de desbetreffende eis is voldaan. Als de Commissie kennis krijgt van een AI-model voor algemene doeleinden dat systeemrisico’s vertoont waarvan zij niet in kennis is gesteld, kan zij besluiten dit model aan te wijzen als een model met een systeemrisico. | F21: 32024R1689:86:1:1 | G21: Elke getroffen persoon | H21: getroffen persoon | I21: Elke getroffen persoon op wie een besluit van toepassing is dat door de gebruiksverantwoordelijke wordt genomen op basis van de output van een in bijlage III vermeld AI-systeem met een hoog risico, met uitzondering van systemen die in punt 2 van die bijlage zijn vermeld, en dat rechtsgevolgen heeft voor die persoon, of op deze op vergelijkbare wijze aanzienlijke invloed heeft die hij of zij als nadelige gevolgen voor zijn of haar gezondheid, veiligheid of grondrechten beschouwt, heeft het recht om van de gebruiksverantwoordelijke duidelijke, inhoudelijke uitleg te verkrijgen bij de rol van het AI-systeem in de besluitvormingsprocedure en de voornaamste elementen van het genomen besluit.
A22: 21 | B22: 32024R1689:56:8:18 | C22: Het AI-bureau | D22: AI-bureau | F22: 32024R1689:91:3:3 | G22: de Commissie | H22: Commissie | I22: Op een terdege gemotiveerd verzoek van het wetenschappelijk panel kan de Commissie een verzoek om informatie tot een aanbieder van een AI-model voor algemene doeleinden richten, indien de toegang tot informatie noodzakelijk en evenredig is voor de uitvoering van de taken van het wetenschappelijk panel op grond van artikel 68, lid 2.
A23: 22 | B23: 32024R1689:56:6:12 | C23: De Commissie | D23: Commissie | F23: 32016R0679:38:3:5 | G23: De verwerkingsverantwoordelijke en de verwerker | H23: verwerkingsverantwoordelijke | verwerker | I23: De verwerkingsverantwoordelijke en de verwerker zorgen ervoor dat de functionaris voor gegevensbescherming geen instructies ontvangt met betrekking tot de uitvoering van die taken. Hij wordt door de verwerkingsverantwoordelijke of de verwerker niet ontslagen of gestraft voor de uitvoering van zijn taken. De functionaris voor gegevensbescherming brengt rechtstreeks verslag uit aan de hoogste leidinggevende van de verwerkingsverantwoordelijke of de verwerker.
A24: 23 | B24: 32024R1689:65:6:5 | C24: De permanente subgroep voor markttoezicht | D24: permanente subgroep voor markttoezicht | F24: 32016R0679:40:5:8 | G24: De in lid 2 van dit artikel bedoelde verenigingen en andere organen | H24: verenigingen | organen | I24: De in lid 2 van dit artikel bedoelde verenigingen en andere organen die voornemens zijn een gedragscode op te stellen of een bestaande gedragscode te wijzigen of uit te breiden, leggen de ontwerpgedragscode, de wijziging of uitbreiding voor aan de overeenkomstig artikel 51 bevoegde toezichthoudende autoriteit. De toezichthoudende autoriteit brengt advies uit over de vraag of de ontwerpgedragscode, de wijziging of uitbreiding strookt met deze verordening, en keurt deze ontwerpgedragscode, die wijziging of uitbreiding goed indien zij van oordeel is dat de code voldoende passende waarborgen biedt.
A25: 24 | B25: 32024R1689:36:7:26 | C25: die autoriteit | D25: autoriteit | F25: 32016R0679:35:4:5 | G25: De toezichthoudende autoriteit | H25: toezichthoudende autoriteit | I25: De toezichthoudende autoriteit stelt een lijst op van het soort verwerkingen waarvoor een gegevensbeschermingseffectbeoordeling overeenkomstig lid 1 verplicht is, en maakt deze openbaar. De toezichthoudende autoriteit deelt die lijsten mee aan het in artikel 68 bedoelde Comité.
A26: 25 | B26: 32016R0679:43:1:1 | C26: certificeringsorganen die over de passende deskundigheid met betrekking tot gegevensbescherming beschikt | D26: certificeringsorganen | E26: Onverminderd de taken en bevoegdheden van de bevoegde toezichthoudende autoriteit uit hoofde van de artikelen 57 en 58, gaan certificeringsorganen die over de passende deskundigheid met betrekking tot gegevensbescherming beschikt, wordt in voorkomend geval na kennisgeving aan de toezichthoudende autoriteit met het oog op de uitoefening van haar bevoegdheden overeenkomstig artikel 58, lid 2, punt h), over tot afgifte en verlenging van het certificaat. De lidstaten zorgen ervoor dat die certificeringsorganen worden geaccrediteerd door één van de volgende instanties: a) de toezichthoudende autoriteit die bevoegd is overeenkomstig artikel 55 of 56; b) de nationale accreditatie-instantie die is aangewezen in overeenstemming met Verordening (EG) nr. 765/2008 van het Europees Parlement en de Raad (20), in overeenstemming met EN-ISO/IEC 17065/2012 en met de aanvullende eisen die door de overeenkomstig artikel 55 of 56 bevoegde toezichthoudende autoriteit zijn vastgesteld. | F26: 32016R0679:51:1:1 | G26: Elke lidstaat | H26: lidstaat | I26: Elke lidstaat bepaalt dat één of meer onafhankelijke overheidsinstanties verantwoordelijk zijn voor het toezicht op de toepassing van deze verordening, teneinde de grondrechten en fundamentele vrijheden van natuurlijke personen in verband met de verwerking van hun persoonsgegevens te beschermen en het vrije verkeer van persoonsgegevens binnen de Unie te vergemakkelijken („toezichthoudende autoriteit”).
A27: 26 | B27: 32016R0679:14:1:3 | C27: de verwerkingsverantwoordelijke | D27: verwerkingsverantwoordelijke | E27: Wanneer persoonsgegevens niet van de betrokkene zijn verkregen, verstrekt de verwerkingsverantwoordelijke de betrokkene de volgende informatie: a) de identiteit en de contactgegevens van de verwerkingsverantwoordelijke en, in voorkomend geval, van de vertegenwoordiger van de verwerkingsverantwoordelijke; b) in voorkomend geval, de contactgegevens van de functionaris voor gegevensbescherming; c) de verwerkingsdoeleinden waarvoor de persoonsgegevens zijn bestemd, en de rechtsgrond voor de verwerking; d) de betrokken categorieën van persoonsgegevens; e) in voorkomend geval, de ontvangers of categorieën van ontvangers van de persoonsgegevens; f) in voorkomend geval, dat de verwerkingsverantwoordelijke het voornemen heeft de persoonsgegevens door te geven aan een ontvanger in een derde land of aan een internationale organisatie; of er al dan niet een adequaatheidsbesluit van de Commissie bestaat; of, in het geval van de in artikel 46, artikel 47 of artikel 49, lid 1, tweede alinea, bedoelde doorgiften, welke de passende of geschikte waarborgen zijn, hoe er een kopie van kan worden verkregen of waar ze kunnen worden geraadpleegd. | F27: 32016R0679:37:4:4 | G27: de verwerkingsverantwoordelijke of de verwerker of verenigingen en andere organen die categorieën van verwerkingsverantwoordelijken of verwerkers vertegenwoordigen | H27: verwerkingsverantwoordelijke | verwerker | verenigingen | organen | I27: In andere dan de in lid 1 bedoelde gevallen kunnen of, indien dat Unierechtelijk of lidstaatrechtelijk is verplicht, moeten de verwerkingsverantwoordelijke of de verwerker of verenigingen en andere organen die categorieën van verwerkingsverantwoordelijken of verwerkers vertegenwoordigen, een functionaris voor gegevensbescherming aanwijzen. De functionaris voor gegevensbescherming kan optreden voor dergelijke verenigingen en andere organen die categorieën van verwerkingsverantwoordelijken of verwerkers vertegenwoordigen.
A28: 27 | B28: 32016R0679:43:8:12 | C28: De Commissie | D28: Commissie | F28: 32016R0679:47:3:3 | G28: De Commissie | H28: Commissie | I28: De Commissie kan het model en de procedures voor de uitwisseling van informatie over bindende bedrijfsvoorschriften in de zin van dit artikel tussen verwerkingsverantwoordelijken, verwerkers en toezichthoudende autoriteiten nader bepalen. Deze uitvoeringshandelingen worden vastgesteld volgens de in artikel 93, lid 2, bedoelde onderzoeksprocedure.
A29: 28 | B29: 32016R0679:64:5:9 | C29: De voorzitter van het Comité | D29: voorzitter van het Comité | F29: 32016R0679:70:1:2 | G29: Het Comité | H29: Comité | I29: Het Comité zorgt ervoor dat deze verordening consequent wordt toegepast. Daartoe doet het Comité op eigen initiatief of, waar passend, op verzoek van de Commissie met name het volgende: a) toezien op en zorgen voor de juiste toepassing van deze verordening in de in de artikelen 64 en 65 bedoelde gevallen, onverminderd de taken van de nationale toezichthoudende autoriteiten; b) adviseren van de Commissie over aangelegenheden in verband met de bescherming van persoonsgegevens in de Unie, waaronder alle voorgestelde wijzigingen van deze verordening; c) adviseren van de Commissie over het mechanisme en de procedures voor de uitwisseling van informatie wat betreft bindende bedrijfsvoorschriften tussen verwerkingsverantwoordelijken, verwerkers, en toezichthoudende autoriteiten; d) uitvaardigen van richtsnoeren, aanbevelingen en beste praktijken inzake procedures voor het wissen van links, kopieën of reproducties van persoonsgegevens uit algemeen beschikbare communicatiediensten als bedoeld in artikel 17, lid 2; e) onderzoeken, op eigen initiatief of op verzoek van een van zijn leden dan wel op verzoek van de Commissie, van kwesties die betrekking hebben op de toepassing van deze verordening, en uitvaardigen van richtsnoeren, aanbevelingen en beste praktijken om te bevorderen dat deze verordening consequent wordt toegepast; f) uitvaardigen van richtsnoeren, aanbevelingen en beste praktijken in overeenstemming met punt e) van dit lid ter verdere specificatie van de criteria en
A30: 29 | B30: 32016R0679:24:1:1 | C30: de verwerkingsverantwoordelijke | D30: verwerkingsverantwoordelijke | E30: Rekening houdend met de aard, de omvang, de context en het doel van de verwerking, alsook met de qua waarschijnlijkheid en ernst uiteenlopende risico's voor de rechten en vrijheden van natuurlijke personen, treft de verwerkingsverantwoordelijke passende technische en organisatorische maatregelen om te waarborgen en te kunnen aantonen dat de verwerking in overeenstemming met deze verordening wordt uitgevoerd. Die maatregelen worden geëvalueerd en indien nodig geactualiseerd. | F30: 32016R0679:38:2:3 | G30: De verwerkingsverantwoordelijke en de verwerker | H30: verwerkingsverantwoordelijke | verwerker | I30: De verwerkingsverantwoordelijke en de verwerker ondersteunen de functionaris voor gegevensbescherming bij de vervulling van de in artikel 39 bedoelde taken door hem toegang te verschaffen tot persoonsgegevens en verwerkingsactiviteiten en door hem de benodigde middelen ter beschikking te stellen voor het vervullen van deze taken en het in stand houden van zijn deskundigheid.
A31: 30 | B31: 32024R1689:77:3:8 | C31: de in lid 1 bedoelde overheidsinstanties of -organen | D31: overheidsinstanties of -organen | E31: Indien de in lid 1 bedoelde documentatie ontoereikend is om vast te stellen of sprake is geweest van een inbreuk op verplichtingen krachtens het Unierecht ter bescherming van grondrechten, kunnen de in lid 1 bedoelde overheidsinstanties of -organen een met redenen omkleed verzoek bij de markttoezichtautoriteit indienen om het AI-systeem met een hoog risico met technische middelen te mogen testen. De markttoezichtautoriteit organiseert de testprocedure binnen een redelijke termijn na het verzoek en met nauwe betrokkenheid van de verzoekende overheidsinstantie of het verzoekende overheidsorgaan. | F31: 32016R0679:42:8:9 | G31: Het Comité | H31: Comité
A32: 31 | B32: 32024R1689:17:1:1 | C32: Aanbieders van AI-systemen met een hoog risico | D32: Aanbieders van AI-systemen met een hoog risico | E32: Aanbieders van AI-systemen met een hoog risico voorzien in een systeem voor kwaliteitsbeheer dat de naleving van deze verordening waarborgt. Dit systeem wordt op systematische en ordelijke wijze gedocumenteerd in de vorm van schriftelijke beleidslijnen, procedures en instructies en omvat ten minste de volgende aspecten: a) een strategie voor de naleving van de regelgeving, inclusief de naleving van de conformiteitsbeoordelingsprocedures en de procedures voor het beheer van de wijzigingen van het AI-systeem met een hoog risico; b) technieken, procedures en systematische maatregelen die moeten worden toegepast voor het ontwerp, de controle van het ontwerp en de verificatie van het ontwerp van het AI-systeem met een hoog risico; c) technieken, procedures en systematische maatregelen die moeten worden toegepast voor de ontwikkeling, de kwaliteitscontrole en de kwaliteitsborging van het AI-systeem met een hoog risico; d) procedures voor het inspecteren, testen en valideren die vóór, tijdens en na de ontwikkeling van het AI-systeem met een hoog risico moeten worden uitgevoerd en de regelmaat waarmee zij moeten worden uitgevoerd; e) technische specificaties, met inbegrip van normen, die moeten worden toegepast en, wanneer de relevante geharmoniseerde normen niet volledig worden toegepast of geen betrekking hebben op alle relevante eisen van afdeling 2, de middelen die worden gebruikt om ervoor te zorgen dat het AI-systeem met een hoog risico in overeenstemming is met deze eisen | F32: 32024R1689:55:2:2 | G32: aanbieders | H32: aanbieders
A33: 32 | B33: 32016R0679:26:3:3 | C33: de betrokkene | D33: betrokkene | F33: 32016R0679:77:1:1 | G33: iedere betrokkene | H33: betrokkene | I33: Onverminderd andere mogelijkheden van administratief beroep of een voorziening in rechte, heeft iedere betrokkene het recht een klacht in te dienen bij een toezichthoudende autoriteit, met name in de lidstaat waar hij gewoonlijk verblijft, hij zijn werkplek heeft of waar de beweerde inbreuk is begaan, indien hij van mening is dat de verwerking van hem betreffende persoonsgegevensinbreuk maakt op deze verordening.
A34: 33 | B34: 32024R1689:24:4:10 | C34: Een distributeur | D34: distributeur | E34: Een distributeur die van mening is of redenen heeft om, op grond van de informatie waarover hij beschikt, aan te nemen dat een AI-systeem met een hoog risico dat hij op de markt heeft aangeboden, niet in overeenstemming is met de eisen van afdeling 2, neemt de noodzakelijke corrigerende maatregelen om dat systeem in overeenstemming te brengen met deze eisen, uit de handel te nemen of terug te roepen of zorgt ervoor dat de aanbieder, de importeur of een eventuele betrokken operator, waar passend, dergelijke corrigerende maatregelen treft. Indien het AI-systeem met een hoog risico een risico vormt in de zin van artikel 79, lid 1, stelt de distributeur de aanbieder of importeur van het systeem en de autoriteiten die bevoegd zijn voor het betreffende AI-systeem met een hoog risico hiervan onmiddellijk in kennis, waarbij hij in het bijzonder de non-conformiteit en de eventueel getroffen corrigerende maatregelen uitvoerig beschrijft. | F34: 32024R1689:49:1:1 | G34: de aanbieder of in voorkomend geval de gemachtigde | H34: aanbieder | gemachtigde | I34: Alvorens een in bijlage III vermeld AI-systeem met een hoog risico, met uitzondering van de in punt 2 van bijlage III vermelde AI-systemen met een hoog risico, in de handel te brengen of in gebruik te stellen, registreert de aanbieder of in voorkomend geval de gemachtigde zichzelf en zijn systeem in de in artikel 71 bedoelde EU-databank.
A35: 34 | B35: 32024R1689:70:9:15 | C35: de Europese Toezichthouder voor gegevensbescherming | D35: Europese Toezichthouder voor gegevensbescherming | F35: 32016R0679:66:4:5 | G35: het Comité | H35: Comité | I35: In afwijking van artikel 64, lid 3, en van artikel 65, lid 2, wordt een als in de leden 2 en 3 bedoeld dringend advies of dringend bindend besluit binnen twee weken met gewone meerderheid van de leden van het Comité vastgesteld.
A36: 35 | B36: 32024R1689:22:1:1 | C36: Aanbieders die in derde landen zijn gevestigd | D36: Aanbieders | E36: Aanbieders die in derde landen zijn gevestigd, wijzen voordat zij hun AI-systemen met een hoog risico in de Unie in de handel brengen, middels een schriftelijke machtiging een gemachtigde aan die is gevestigd in de Unie. | F36: 32024R1689:56:5:4 | G36: de deelnemers aan de praktijkcodes | H36: deelnemers aan de praktijkcodes
A37: 36 | B37: 32024R1689:64:2:2 | C37: De lidstaten | D37: lidstaten | E37: De lidstaten faciliteren de aan het AI-bureau toevertrouwde taken, zoals weergegeven in deze verordening. | F37: 32024R1689:75:3:4 | G37: Markttoezichtautoriteiten | H37: Markttoezichtautoriteiten
A38: 37 | B38: 32024R1689:8:2:4 | C38: aanbieders | D38: aanbieders | E38: Indien een product een AI-systeem omvat waarop zowel de vereisten van deze verordening als die van de in bijlage I, afdeling A, vermelde harmonisatiewetgeving van de Unie van toepassing zijn, zijn aanbieders ervoor verantwoordelijk te waarborgen dat hun product volledig voldoet aan alle toepasselijke vereisten uit hoofde van de toepasselijke harmonisatiewetgeving van de Unie. Om te waarborgen dat de in lid 1 bedoelde AI-systemen met een hoog risico voldoen aan de eisen van deze afdeling en om te zorgen voor consistentie, dubbel werk te voorkomen en de extra lasten tot een minimum te beperken, hebben aanbieders de keuze om in voorkomend geval de nodige test- en rapportageprocessen en door hen verstrekte informatie en documentatie over hun product op te nemen in de reeds bestaande documentatie en procedures die vereist zijn uit hoofde van de in bijlage I, afdeling A, bedoelde harmonisatiewetgeving van de Unie. | F38: 32024R1689:17:3:5 | G38: Aanbieders van AI-systemen met een hoog risico | H38: Aanbieders van AI-systemen met een hoog risico | I38: Aanbieders van AI-systemen met een hoog risico die onderworpen zijn aan verplichtingen met betrekking tot kwaliteitsbeheersystemen of een gelijkwaardige functie uit hoofde van het desbetreffende sectorale Unierecht, kunnen de in lid 1 genoemde aspecten opnemen als onderdeel van de op grond van dat recht vastgestelde kwaliteitsbeheersystemen.
A39: 38 | B39: 32024R1689:46:5:12 | C39: de Commissie | D39: Commissie | E39: Indien binnen 15 kalenderdagen na de ontvangst van in lid 3 bedoelde kennisgeving door een lidstaat bezwaren worden geopperd tegen een door een markttoezichtautoriteit van een andere lidstaat verstrekte toelating, of wanneer de Commissie de toelating in strijd met het Unierecht acht of de conclusie van de lidstaten ten aanzien van de conformiteit van het systeem als bedoeld in lid 3 ongegrond acht, treedt de Commissie onverwijld in overleg met de relevante lidstaat. De betrokken operatoren worden geraadpleegd en hebben de mogelijkheid hun standpunten uiteen te zetten. Met het oog daarop besluit de Commissie of de toelating gerechtvaardigd is. De Commissie richt haar besluit aan de betrokken lidstaat en de relevante operatoren. | F39: 32024R1689:92:3:4 | G39: de Commissie | H39: Commissie | I39: Voor de toepassing van lid 1 kan de Commissie verzoeken om toegang tot het betrokken AI-model voor algemene doeleinden via API’s of andere passende technische middelen en instrumenten, waaronder de broncode.
A40: 39 | B40: 32024R1689:65:6:7 | C40: vertegenwoordigers van het in artikel 67 bedoelde adviesforum | D40: vertegenwoordigers van het adviesforum | F40: 32016R0679:8:2:4 | G40: de verwerkingsverantwoordelijke | H40: verwerkingsverantwoordelijke | I40: Met inachtneming van de beschikbare technologie doet de verwerkingsverantwoordelijke redelijke inspanningen om in dergelijke gevallen te controleren of de persoon die de ouderlijke verantwoordelijkheid voor het kind draagt, toestemming heeft gegeven of machtiging tot toestemming heeft verleend.
...

Sheet key
A1: # | B1: stratum | C1: level | D1: score | E1: relation | F1: detail_from | G1: actor_a | H1: actor_b | I1: unit_a | J1: unit_b | K1: direction | L1: sources | M1: top_same_id | N1: pair_id
A2: 1 | B2: different | same document | C2: different | D2: -0.25 | E2: different | F2: scorer | G2: KEY:EU:europese_toezichthouder_voor_gegevensbescherming | H2: KEY:EU:commissie | I2: Europese Toezichthouder voor gegevensbescherming | J2: Commissie | L2: EU-EU | M2: no | N2: 766577
A3: 2 | B3: same | both exact | C3: same | D3: 1 | E3: same | F3: scorer | G3: KEY:EU:commissie | H3: KEY:EU:commissie | I3: Commissie | J3: Commissie | L3: EU-EU | M3: yes | N3: 366329
A4: 3 | B4: weak | broad covers mapped | C4: weak | D4: 0.2 | E4: broad_covers | F4: scorer | G4: 32024R1689:aanbieder | H4: class:person | I4: Aanbieders van AI-systemen met een hoog risico | J4: persoon | L4: EU-EU | M4: yes | N4: 123498
A5: 4 | B5: different | same document | C5: different | D5: -0.25 | E5: different | F5: scorer | G5: KEY:EU:lidstaat | H5: 32024R1689:aangemelde_instantie | I5: lidstaten | J5: aangemelde instantie | L5: EU-EU | M5: no | N5: 247369
A6: 5 | B6: nested | C6: nested | D6: 0.7 | E6: subtype | F6: scorer | G6: KEY:32016R0679:leidende_toezichthoudende_autoriteit | H6: 32016R0679:toezichthoudende_autoriteit | I6: leidende toezichthoudende autoriteit | J6: toezichthoudende autoriteit | K6: a_narrower | L6: EU-EU | M6: no | N6: 967725
A7: 6 | B7: different | other documents | C7: different | D7: -0.25 | E7: different | F7: scorer | G7: KEY:EU:commissie | H7: 32016R0679:toezichthoudende_autoriteit | I7: Commissie | J7: toezichthoudende autoriteit van de lidstaat in kwestie | L7: EU-EU | M7: yes | N7: 741343
A8: 7 | B8: different | other documents | C8: different | D8: -0.25 | E8: different | F8: scorer | G8: KEY:EU:commissie | H8: 32016R0679:concern | I8: Commissie | J8: concern | L8: EU-EU | M8: yes | N8: 770107
A9: 8 | B9: nested | C9: nested | D9: 0.7 | E9: subtype | F9: scorer | G9: KEY:EU:lidstaat | H9: 32016R0679:toezichthoudende_autoriteit | I9: lidstaten | J9: toezichthoudende autoriteit | K9: b_narrower | L9: EU-EU | M9: no | N9: 621160
A10: 9 | B10: same | both exact | C10: same | D10: 1 | E10: same | F10: scorer | G10: 32016R0679:toezichthoudende_autoriteit | H10: 32016R0679:toezichthoudende_autoriteit | I10: toezichthoudende autoriteit | J10: toezichthoudende autoriteit | L10: EU-EU | M10: yes | N10: 959785
A11: 10 | B11: nested | C11: nested | D11: 0.7 | E11: subtype | F11: scorer | G11: 32016R0679:toezichthoudende_autoriteit | H11: KEY:32016R0679:leidende_toezichthoudende_autoriteit | I11: toezichthoudende autoriteit | J11: leidende toezichthoudende autoriteit | K11: b_narrower | L11: EU-EU | M11: yes | N11: 963972
A12: 11 | B12: weak | both broad, same class | C12: weak | D12: 0.2 | E12: broad_same_class | F12: scorer | G12: class:person | H12: class:person | I12: relevante belanghebbenden | J12: natuurlijke of rechtspersoon | L12: EU-EU | M12: no | N12: 497085
A13: 12 | B13: weak | siblings | C13: weak | D13: 0.2 | E13: sibling | F13: scorer | G13: 32024R1689:aanbieder | H13: 32024R1689:gebruiksverantwoordelijke | I13: Aanbieders van AI-systemen met een hoog risico | J13: gebruiksverantwoordelijke | L13: EU-EU | M13: yes | N13: 152953
A14: 13 | B14: weak | siblings | C14: weak | D14: 0.2 | E14: sibling | F14: scorer | G14: 32024R1689:gebruiksverantwoordelijke | H14: 32024R1689:aanbieder | I14: gebruiksverantwoordelijke | J14: aanbieders van AI-modellen voor algemene doeleinden of hun vertegenwoordiger | L14: EU-EU | M14: no | N14: 238015
A15: 14 | B15: different | other documents | C15: different | D15: -0.25 | E15: different | F15: scorer | G15: KEY:EU:commissie | H15: 32016R0679:toezichthoudende_autoriteit | I15: Commissie | J15: toezichthoudende autoriteiten | L15: EU-EU | M15: yes | N15: 721056
A16: 15 | B16: same | shortened match | C16: same | D16: 1 | E16: same | F16: scorer | G16: KEY:EU:commissie | H16: KEY:EU:commissie | I16: Commissie | J16: toezichthoudende autoriteiten en de Commissie | L16: EU-EU | M16: yes | N16: 769729
A17: 16 | B17: different | other documents | C17: different | D17: -0.25 | E17: different | F17: scorer | G17: KEY:EU:commissie | H17: 32016R0679:verwerkingsverantwoordelijke | I17: Commissie | J17: verwerkingsverantwoordelijke | L17: EU-EU | M17: yes | N17: 741161
A18: 17 | B18: nested | C18: nested | D18: 0.7 | E18: subtype | F18: scorer | G18: KEY:EU:lidstaat | H18: 32016R0679:toezichthoudende_autoriteit | I18: lidstaat | J18: toezichthoudende autoriteit | K18: b_narrower | L18: EU-EU | M18: no | N18: 944927
A19: 18 | B19: different | other documents | C19: different | D19: -0.25 | E19: different | F19: scorer | G19: 32024R1689:markttoezichtautoriteit | H19: KEY:EU:lidstaat | I19: markttoezichtautoriteit | J19: lidstaten | L19: EU-EU | M19: no | N19: 676091
A20: 19 | B20: different | other documents | C20: different | D20: -0.25 | E20: different | F20: scorer | G20: KEY:EU:lidstaat | H20: 32016R0679:verwerker | I20: betrokken lidstaten | J20: verwerker | L20: EU-EU | M20: no | N20: 16333
A21: 20 | B21: weak | broad covers mapped | C21: weak | D21: 0.2 | E21: broad_covers | F21: scorer | G21: 32024R1689:aanbieder | H21: class:person | I21: betrokken aanbieder | J21: getroffen persoon | L21: EU-EU | M21: yes | N21: 461631
A22: 21 | B22: nested | C22: nested | D22: 0.7 | E22: part_of | F22: scorer | G22: 32024R1689:aibureau | H22: KEY:EU:commissie | I22: AI-bureau | J22: Commissie | K22: a_narrower | L22: EU-EU | M22: no | N22: 511922
A23: 22 | B23: different | other documents | C23: different | D23: -0.25 | E23: different | F23: scorer | G23: KEY:EU:commissie | H23: 32016R0679:verwerkingsverantwoordelijke | I23: Commissie | J23: verwerkingsverantwoordelijke | L23: EU-EU | M23: yes | N23: 506308
A24: 23 | B24: weak | broad covers mapped | C24: weak | D24: 0.2 | E24: broad_covers | F24: scorer | G24: KEY:32024R1689:permanente_subgroep_voor_markttoezicht | H24: class:body | I24: permanente subgroep voor markttoezicht | J24: organen | L24: EU-EU | M24: no | N24: 587472
A25: 24 | B25: weak | broad covers mapped | C25: weak | D25: 0.2 | E25: broad_covers | F25: scorer | G25: class:authority | H25: 32016R0679:toezichthoudende_autoriteit | I25: autoriteit | J25: toezichthoudende autoriteit | L25: EU-EU | M25: no | N25: 336774
A26: 25 | B26: different | same document | C26: different | D26: -0.25 | E26: different | F26: scorer | G26: KEY:32016R0679:certificeringsorgaan | H26: KEY:EU:lidstaat | I26: certificeringsorganen | J26: lidstaat | L26: EU-EU | M26: no | N26: 918316
A27: 26 | B27: same | both exact | C27: same | D27: 1 | E27: same | F27: scorer | G27: 32016R0679:verwerkingsverantwoordelijke | H27: 32016R0679:verwerkingsverantwoordelijke | I27: verwerkingsverantwoordelijke | J27: verwerkingsverantwoordelijke | L27: EU-EU | M27: no | N27: 822067
A28: 27 | B28: same | both exact | C28: same | D28: 1 | E28: same | F28: scorer | G28: KEY:EU:commissie | H28: KEY:EU:commissie | I28: Commissie | J28: Commissie | L28: EU-EU | M28: yes | N28: 922489
A29: 28 | B29: nested | C29: nested | D29: 0.7 | E29: part_of | F29: scorer | G29: KEY:32016R0679:voorzitter | H29: KEY:32016R0679:comite | I29: voorzitter van het Comité | J29: Comité | K29: a_narrower | L29: EU-EU | M29: no | N29: 979523
A30: 29 | B30: same | both exact | C30: same | D30: 1 | E30: same | F30: scorer | G30: 32016R0679:verwerkingsverantwoordelijke | H30: 32016R0679:verwerkingsverantwoordelijke | I30: verwerkingsverantwoordelijke | J30: verwerkingsverantwoordelijke | L30: EU-EU | M30: no | N30: 847367
A31: 30 | B31: weak | broad covers mapped | C31: weak | D31: 0.2 | E31: broad_covers | F31: scorer | G31: class:body | H31: KEY:32016R0679:comite | I31: overheidsinstanties of -organen | J31: Comité | L31: EU-EU | M31: no | N31: 676546
A32: 31 | B32: same | shortened match | C32: same | D32: 1 | E32: same | F32: scorer | G32: 32024R1689:aanbieder | H32: 32024R1689:aanbieder | I32: Aanbieders van AI-systemen met een hoog risico | J32: aanbieders | L32: EU-EU | M32: yes | N32: 134947
A33: 32 | B33: same | both exact | C33: same | D33: 1 | E33: same | F33: scorer | G33: 32016R0679:de_betrokkene | H33: 32016R0679:de_betrokkene | I33: betrokkene | J33: betrokkene | L33: EU-EU | M33: no | N33: 854665
A34: 33 | B34: weak | siblings | C34: weak | D34: 0.2 | E34: sibling | F34: scorer | G34: 32024R1689:distributeur | H34: 32024R1689:aanbieder | I34: distributeur | J34: aanbieder | L34: EU-EU | M34: no | N34: 182660
A35: 34 | B35: different | other documents | C35: different | D35: -0.25 | E35: different | F35: scorer | G35: KEY:EU:europese_toezichthouder_voor_gegevensbescherming | H35: KEY:32016R0679:comite | I35: Europese Toezichthouder voor gegevensbescherming | J35: Comité | L35: EU-EU | M35: no | N35: 625552
A36: 35 | B36: weak | broad covers mapped | C36: weak | D36: 0.2 | E36: broad_covers | F36: scorer | G36: 32024R1689:aanbieder | H36: class:party | I36: Aanbieders | J36: deelnemers aan de praktijkcodes | L36: EU-EU | M36: yes | N36: 158363
A37: 36 | B37: different | same document | C37: different | D37: -0.25 | E37: different | F37: scorer | G37: KEY:EU:lidstaat | H37: 32024R1689:markttoezichtautoriteit | I37: lidstaten | J37: Markttoezichtautoriteiten | L37: EU-EU | M37: no | N37: 582566
A38: 37 | B38: same | shortened match | C38: same | D38: 1 | E38: same | F38: scorer | G38: 32024R1689:aanbieder | H38: 32024R1689:aanbieder | I38: aanbieders | J38: Aanbieders van AI-systemen met een hoog risico | L38: EU-EU | M38: yes | N38: 44662
A39: 38 | B39: same | both exact | C39: same | D39: 1 | E39: same | F39: scorer | G39: KEY:EU:commissie | H39: KEY:EU:commissie | I39: Commissie | J39: Commissie | L39: EU-EU | M39: yes | N39: 415344
A40: 39 | B40: weak | broad covers mapped | C40: weak | D40: 0.2 | E40: broad_covers | F40: scorer | G40: class:party | H40: 32016R0679:verwerkingsverantwoordelijke | I40: vertegenwoordigers van het adviesforum | J40: verwerkingsverantwoordelijke | L40: EU-EU | M40: no | N40: 589071
...

Sheet Design
A1: Sample design
A2: What is validated. For each Stage A pair the actor score compares the actors of the two norms: same (1.0, same actor ID), nested (0.7, one actor is a kind or part of the other), weak (0.2, two kinds of one actor, or a broad actor that may include the other), different (-0.25, two unrelated actors from a shared document). The labeller answers the same question from the norm texts: do the two norms address the same actor? Population. 976,662 Stage A pairs. 342,691 have a score and are sampled. 457,049 involve a norm without a usable actor and 176,922 are 'unknown' (both norms have an actor, but no relation is known); these score 0, make no claim, and are exact counts (table below). Related actors among them cannot be measured here. Note that an EU and a Dutch actor ID are never related, so EU-Dutch pairs are only ever weak (through broad classes) or unknown. Why these strata. The strata are the score levels, split by the relation behind each pair, because each relation can fail in its own way: 'same' by exact or by shortened match; 'weak' as siblings, a broad class covering a mapped actor, or two broad actors; 'different' within one document (where a missed relation is most likely) or across documents. Nested is small and kept whole. Why these sizes. Weak and different hold most scored pairs, so they get most judgements; same and nested are small but make the strongest claims, so they get floors. A norm appears in at most 2 sampled pairs. With this allocation the weighted agreement over all scored pairs is known to about +/-11 points at 80% agreement (+/-13 at 50%). Overall figures are weighted by N_h (the 'review' step), never by row count. Relations. Taken from ActorScorer with the scoring run's relations and inventory.
A4: stratum | B4: level | C4: population N_h | D4: share of scored pairs | E4: n sampled | F4: why this stratum and this n
A5: same | both exact | B5: same | C5: 29995 | D5: =IFERROR(C5/SUM($C$5:$C$12),0) -> 0.087527831 | E5: 15 | F5: Most same pairs: both norms map to the same ID by an exact match. Checks the mapping of the common actors.
A6: same | shortened match | B6: same | C6: 7259 | D6: =IFERROR(C6/SUM($C$5:$C$12),0) -> 0.021182348 | E6: 10 | F6: Same ID reached by dropping words from at least one actor: the riskier route to 'same'.
A7: nested | B7: nested | C7: 23095 | D7: =IFERROR(C7/SUM($C$5:$C$12),0) -> 0.067393074 | E7: 20 | F7: One actor is a kind or part of the other (subtype, part_of). Also used to check the direction flag.
A8: weak | siblings | B8: weak | C8: 7421 | D8: =IFERROR(C8/SUM($C$5:$C$12),0) -> 0.021655077 | E8: 12 | F8: Two kinds of one actor (and curated can_be_same / linked relations).
A9: weak | broad covers mapped | B9: weak | C9: 12829 | D9: =IFERROR(C9/SUM($C$5:$C$12),0) -> 0.037436058 | E9: 18 | F9: A broad (fallback) actor whose class fits the other's mapped actor: the largest weak cell.
A10: weak | both broad, same class | B10: weak | C10: 398 | D10: =IFERROR(C10/SUM($C$5:$C$12),0) -> 0.0011613961 | E10: 10 | F10: Two broad actors of the same class: the weakest evidence.
A11: different | same document | B11: different | C11: 172024 | D11: =IFERROR(C11/SUM($C$5:$C$12),0) -> 0.50197992 | E11: 18 | F11: Both mapped, no relation, norms from one document: the likeliest place to miss a relation.
A12: different | other documents | B12: different | C12: 89670 | D12: =IFERROR(C12/SUM($C$5:$C$12),0) -> 0.2616643 | E12: 17 | F12: Both mapped, no relation, IDs valid in a shared document but norms from different documents.
A13: total | C13: =SUM(C5:C12) -> 342691 | E13: =SUM(E5:E12) -> 120
A15: Exact counts (not sampled)
A16: pairs | B16: count | C16: share of Stage A
A17: Stage A pairs | B17: 976662 | C17: =B17/$B$17 -> 1
A18: scored (sampled above) | B18: 342691 | C18: =B18/$B$17 -> 0.35087983
A19: a norm without a usable actor | B19: 457049 | C19: =B19/$B$17 -> 0.4679705
A20: ... with a norm of status not_actor | B20: 167622 | C20: =B20/$B$17 -> 0.17162744
A21: ... with a norm of status missing | B21: 230907 | C21: =B21/$B$17 -> 0.23642468
A22: ... with a norm of status pronoun | B22: 99859 | C22: =B22/$B$17 -> 0.1022452
A23: ... with a norm of status no_units | B23: 4053 | C23: =B23/$B$17 -> 0.0041498492
A24: unknown: both have an actor, no relation known | B24: 176922 | C24: =B24/$B$17 -> 0.18114967
A25: ... EU-EU | B25: 176922 | C25: =B25/$B$17 -> 0.18114967
A26: ... EU-NL | B26: 0 | C26: =B26/$B$17 -> 0
A27: ... NL-NL | B27: 0 | C27: =B27/$B$17 -> 0
A28: A pair can have two norms without an actor of different status, so the status lines overlap.
A29: Settings: max uses per norm 2, seed 42, check unknown 0, relations from ActorScorer

Sheet Summary
A1: stratum | B1: expected label | C1: population N_h | D1: rows | E1: judged | F1: same | G1: nested | H1: related | I1: different | J1: unclear | K1: agreement | L1: agree 95% low | M1: agree 95% high | N1: share same/nested | Q1: z
A2: same | both exact | B2: same | C2: 29995 | D2: =COUNTIFS(key!$B$2:$B$121,A2) -> 15 | E2: =COUNTIFS(key!$B$2:$B$121,A2,Review!$J$2:$J$121,"<>") -> 0 | F2: =COUNTIFS(key!$B$2:$B$121,A2,Review!$J$2:$J$121,"same") -> 0 | G2: =COUNTIFS(key!$B$2:$B$121,A2,Review!$J$2:$J$121,"nested") -> 0 | H2: =COUNTIFS(key!$B$2:$B$121,A2,Review!$J$2:$J$121,"related") -> 0 | I2: =COUNTIFS(key!$B$2:$B$121,A2,Review!$J$2:$J$121,"different") -> 0 | J2: =COUNTIFS(key!$B$2:$B$121,A2,Review!$J$2:$J$121,"unclear") -> 0 | K2: =IFERROR(COUNTIFS(key!$B$2:$B$121,A2,Review!$J$2:$J$121,B2)/(E2-J2),"") | L2: =IFERROR(MAX(0,(K2+$Q$2^2/(2*(E2-J2)))/(1+$Q$2^2/(E2-J2))-$Q$2*SQRT(K2*(1-K2)/(E2-J2)+$Q$2^2/(4*(E2-J2)^2))/(1+$Q$2^2/(E2-J2))),"") | M2: =IFERROR(MIN(1,(K2+$Q$2^2/(2*(E2-J2)))/(1+$Q$2^2/(E2-J2))+$Q$2*SQRT(K2*(1-K2)/(E2-J2)+$Q$2^2/(4*(E2-J2)^2))/(1+$Q$2^2/(E2-J2))),"") | N2: =IFERROR((F2+G2)/(E2-J2),"") | Q2: 1.96
A3: same | shortened match | B3: same | C3: 7259 | D3: =COUNTIFS(key!$B$2:$B$121,A3) -> 10 | E3: =COUNTIFS(key!$B$2:$B$121,A3,Review!$J$2:$J$121,"<>") -> 0 | F3: =COUNTIFS(key!$B$2:$B$121,A3,Review!$J$2:$J$121,"same") -> 0 | G3: =COUNTIFS(key!$B$2:$B$121,A3,Review!$J$2:$J$121,"nested") -> 0 | H3: =COUNTIFS(key!$B$2:$B$121,A3,Review!$J$2:$J$121,"related") -> 0 | I3: =COUNTIFS(key!$B$2:$B$121,A3,Review!$J$2:$J$121,"different") -> 0 | J3: =COUNTIFS(key!$B$2:$B$121,A3,Review!$J$2:$J$121,"unclear") -> 0 | K3: =IFERROR(COUNTIFS(key!$B$2:$B$121,A3,Review!$J$2:$J$121,B3)/(E3-J3),"") | L3: =IFERROR(MAX(0,(K3+$Q$2^2/(2*(E3-J3)))/(1+$Q$2^2/(E3-J3))-$Q$2*SQRT(K3*(1-K3)/(E3-J3)+$Q$2^2/(4*(E3-J3)^2))/(1+$Q$2^2/(E3-J3))),"") | M3: =IFERROR(MIN(1,(K3+$Q$2^2/(2*(E3-J3)))/(1+$Q$2^2/(E3-J3))+$Q$2*SQRT(K3*(1-K3)/(E3-J3)+$Q$2^2/(4*(E3-J3)^2))/(1+$Q$2^2/(E3-J3))),"") | N3: =IFERROR((F3+G3)/(E3-J3),"")
A4: nested | B4: nested | C4: 23095 | D4: =COUNTIFS(key!$B$2:$B$121,A4) -> 20 | E4: =COUNTIFS(key!$B$2:$B$121,A4,Review!$J$2:$J$121,"<>") -> 0 | F4: =COUNTIFS(key!$B$2:$B$121,A4,Review!$J$2:$J$121,"same") -> 0 | G4: =COUNTIFS(key!$B$2:$B$121,A4,Review!$J$2:$J$121,"nested") -> 0 | H4: =COUNTIFS(key!$B$2:$B$121,A4,Review!$J$2:$J$121,"related") -> 0 | I4: =COUNTIFS(key!$B$2:$B$121,A4,Review!$J$2:$J$121,"different") -> 0 | J4: =COUNTIFS(key!$B$2:$B$121,A4,Review!$J$2:$J$121,"unclear") -> 0 | K4: =IFERROR(COUNTIFS(key!$B$2:$B$121,A4,Review!$J$2:$J$121,B4)/(E4-J4),"") | L4: =IFERROR(MAX(0,(K4+$Q$2^2/(2*(E4-J4)))/(1+$Q$2^2/(E4-J4))-$Q$2*SQRT(K4*(1-K4)/(E4-J4)+$Q$2^2/(4*(E4-J4)^2))/(1+$Q$2^2/(E4-J4))),"") | M4: =IFERROR(MIN(1,(K4+$Q$2^2/(2*(E4-J4)))/(1+$Q$2^2/(E4-J4))+$Q$2*SQRT(K4*(1-K4)/(E4-J4)+$Q$2^2/(4*(E4-J4)^2))/(1+$Q$2^2/(E4-J4))),"") | N4: =IFERROR((F4+G4)/(E4-J4),"")
A5: weak | siblings | B5: related | C5: 7421 | D5: =COUNTIFS(key!$B$2:$B$121,A5) -> 12 | E5: =COUNTIFS(key!$B$2:$B$121,A5,Review!$J$2:$J$121,"<>") -> 0 | F5: =COUNTIFS(key!$B$2:$B$121,A5,Review!$J$2:$J$121,"same") -> 0 | G5: =COUNTIFS(key!$B$2:$B$121,A5,Review!$J$2:$J$121,"nested") -> 0 | H5: =COUNTIFS(key!$B$2:$B$121,A5,Review!$J$2:$J$121,"related") -> 0 | I5: =COUNTIFS(key!$B$2:$B$121,A5,Review!$J$2:$J$121,"different") -> 0 | J5: =COUNTIFS(key!$B$2:$B$121,A5,Review!$J$2:$J$121,"unclear") -> 0 | K5: =IFERROR(COUNTIFS(key!$B$2:$B$121,A5,Review!$J$2:$J$121,B5)/(E5-J5),"") | L5: =IFERROR(MAX(0,(K5+$Q$2^2/(2*(E5-J5)))/(1+$Q$2^2/(E5-J5))-$Q$2*SQRT(K5*(1-K5)/(E5-J5)+$Q$2^2/(4*(E5-J5)^2))/(1+$Q$2^2/(E5-J5))),"") | M5: =IFERROR(MIN(1,(K5+$Q$2^2/(2*(E5-J5)))/(1+$Q$2^2/(E5-J5))+$Q$2*SQRT(K5*(1-K5)/(E5-J5)+$Q$2^2/(4*(E5-J5)^2))/(1+$Q$2^2/(E5-J5))),"") | N5: =IFERROR((F5+G5)/(E5-J5),"")
A6: weak | broad covers mapped | B6: related | C6: 12829 | D6: =COUNTIFS(key!$B$2:$B$121,A6) -> 18 | E6: =COUNTIFS(key!$B$2:$B$121,A6,Review!$J$2:$J$121,"<>") -> 0 | F6: =COUNTIFS(key!$B$2:$B$121,A6,Review!$J$2:$J$121,"same") -> 0 | G6: =COUNTIFS(key!$B$2:$B$121,A6,Review!$J$2:$J$121,"nested") -> 0 | H6: =COUNTIFS(key!$B$2:$B$121,A6,Review!$J$2:$J$121,"related") -> 0 | I6: =COUNTIFS(key!$B$2:$B$121,A6,Review!$J$2:$J$121,"different") -> 0 | J6: =COUNTIFS(key!$B$2:$B$121,A6,Review!$J$2:$J$121,"unclear") -> 0 | K6: =IFERROR(COUNTIFS(key!$B$2:$B$121,A6,Review!$J$2:$J$121,B6)/(E6-J6),"") | L6: =IFERROR(MAX(0,(K6+$Q$2^2/(2*(E6-J6)))/(1+$Q$2^2/(E6-J6))-$Q$2*SQRT(K6*(1-K6)/(E6-J6)+$Q$2^2/(4*(E6-J6)^2))/(1+$Q$2^2/(E6-J6))),"") | M6: =IFERROR(MIN(1,(K6+$Q$2^2/(2*(E6-J6)))/(1+$Q$2^2/(E6-J6))+$Q$2*SQRT(K6*(1-K6)/(E6-J6)+$Q$2^2/(4*(E6-J6)^2))/(1+$Q$2^2/(E6-J6))),"") | N6: =IFERROR((F6+G6)/(E6-J6),"")
A7: weak | both broad, same class | B7: related | C7: 398 | D7: =COUNTIFS(key!$B$2:$B$121,A7) -> 10 | E7: =COUNTIFS(key!$B$2:$B$121,A7,Review!$J$2:$J$121,"<>") -> 0 | F7: =COUNTIFS(key!$B$2:$B$121,A7,Review!$J$2:$J$121,"same") -> 0 | G7: =COUNTIFS(key!$B$2:$B$121,A7,Review!$J$2:$J$121,"nested") -> 0 | H7: =COUNTIFS(key!$B$2:$B$121,A7,Review!$J$2:$J$121,"related") -> 0 | I7: =COUNTIFS(key!$B$2:$B$121,A7,Review!$J$2:$J$121,"different") -> 0 | J7: =COUNTIFS(key!$B$2:$B$121,A7,Review!$J$2:$J$121,"unclear") -> 0 | K7: =IFERROR(COUNTIFS(key!$B$2:$B$121,A7,Review!$J$2:$J$121,B7)/(E7-J7),"") | L7: =IFERROR(MAX(0,(K7+$Q$2^2/(2*(E7-J7)))/(1+$Q$2^2/(E7-J7))-$Q$2*SQRT(K7*(1-K7)/(E7-J7)+$Q$2^2/(4*(E7-J7)^2))/(1+$Q$2^2/(E7-J7))),"") | M7: =IFERROR(MIN(1,(K7+$Q$2^2/(2*(E7-J7)))/(1+$Q$2^2/(E7-J7))+$Q$2*SQRT(K7*(1-K7)/(E7-J7)+$Q$2^2/(4*(E7-J7)^2))/(1+$Q$2^2/(E7-J7))),"") | N7: =IFERROR((F7+G7)/(E7-J7),"")
A8: different | same document | B8: different | C8: 172024 | D8: =COUNTIFS(key!$B$2:$B$121,A8) -> 18 | E8: =COUNTIFS(key!$B$2:$B$121,A8,Review!$J$2:$J$121,"<>") -> 0 | F8: =COUNTIFS(key!$B$2:$B$121,A8,Review!$J$2:$J$121,"same") -> 0 | G8: =COUNTIFS(key!$B$2:$B$121,A8,Review!$J$2:$J$121,"nested") -> 0 | H8: =COUNTIFS(key!$B$2:$B$121,A8,Review!$J$2:$J$121,"related") -> 0 | I8: =COUNTIFS(key!$B$2:$B$121,A8,Review!$J$2:$J$121,"different") -> 0 | J8: =COUNTIFS(key!$B$2:$B$121,A8,Review!$J$2:$J$121,"unclear") -> 0 | K8: =IFERROR(COUNTIFS(key!$B$2:$B$121,A8,Review!$J$2:$J$121,B8)/(E8-J8),"") | L8: =IFERROR(MAX(0,(K8+$Q$2^2/(2*(E8-J8)))/(1+$Q$2^2/(E8-J8))-$Q$2*SQRT(K8*(1-K8)/(E8-J8)+$Q$2^2/(4*(E8-J8)^2))/(1+$Q$2^2/(E8-J8))),"") | M8: =IFERROR(MIN(1,(K8+$Q$2^2/(2*(E8-J8)))/(1+$Q$2^2/(E8-J8))+$Q$2*SQRT(K8*(1-K8)/(E8-J8)+$Q$2^2/(4*(E8-J8)^2))/(1+$Q$2^2/(E8-J8))),"") | N8: =IFERROR((F8+G8)/(E8-J8),"")
