Workbook

Sheet Instructions
A1: Actor mapping review
A2: Each row of the Review sheet is an actor unit in a norm (census rows show up to 3 norms that use the same unit). 'Assigned' is what the system mapped the unit to. Judge whether that is right, from the norm text and the actor phrase. The Inventory sheet lists every known actor with its definition.
A3: Assessment (yellow)
A4: Assigned an actor [ID]:
A5: correct the unit is this actor.
A6: partial right actor family but too broad or too narrow (another entry fits better), or right for some census contexts only.
A7: wrong another actor, or not an actor at all.
A8: Assigned 'an actor of class X (no inventory entry)':
A9: correct an actor, no inventory entry fits, and class X fits.
A10: partial an actor and class X fits, but an inventory entry fits (missed entry).
A11: wrong the class does not fit, or it is not an actor.
A12: Assigned 'not an actor (dropped)':
... A23: Unit: de Autoriteit Consument en Markt | Assigned: not an actor (dropped) | Assessment: wrong | What is wrong?: actor, not in inventory | Correct actor: Autoriteit Consument en Markt

Sheet Review
A1: # | B1: Norm(s) | C1: Actor phrase | D1: Unit | E1: Text | F1: Assigned | G1: Assigned: definition or source | H1: Assessment | I1: What is wrong? | J1: Correct actor | K1: Note
A2: 1 | B2: BWBR0009950:4.10:6:10 | C2: Een aanbieder van een openbaar elektronisch communicatienetwerk waarover een openbare elektronische communicatiedienst wordt verzorgd | D2: aanbieder van een openbaar elektronisch communicatienetwerk waarover een openbare elektronische communicatiedienst wordt verzorgd | E2: Een aanbieder van een openbaar elektronisch communicatienetwerk waarover een openbare elektronische communicatiedienst wordt verzorgd zorgt ervoor dat zijn netwerk zodanig is ingericht dat de aanbieders, bedoeld in het vijfde lid, de daar bedoelde verplichtingen kunnen nakomen. | F2: aanbieder van een openbaar elektronisch communicatienetwerk [BWBR0009950:aanbieder_van_een_openbaar_elektronisch_communicatienetwerk] | G2: Defined in BWBR0009950 art. 5.1: degene die in eigen naam en voor eigen rekening kabels ten dienste van een dergelijk netwerk aanlegt, instandhoudt en opruimt.
A3: 2 | B3: 32024R1689:26:8:15 | C3: deze gebruiksverantwoordelijke | D3: gebruiksverantwoordelijke | E3: Gebruiksverantwoordelijken van AI-systemen met een hoog risico die de hoedanigheid van overheidsinstanties of instellingen, organen of instanties van de Unie hebben, leven de in artikel 49 bedoelde registratieverplichtingen na. Wanneer deze gebruiksverantwoordelijke vaststellen dat het AI-systeem met een hoog risico dat zij voornemens zijn te gebruiken niet in de in artikel 71 bedoelde EU-databank is geregistreerd, gebruiken zij dat systeem niet en stellen zij de aanbieder of de distributeur daarvan in kennis. | F3: gebruiksverantwoordelijke [32024R1689:gebruiksverantwoordelijke] | G3: Defined in 32024R1689 art. 3: een natuurlijke of rechtspersoon, overheidsinstantie, agentschap of ander orgaan die/dat een AI-systeem onder eigen verantwoordelijkheid gebruikt, tenzij het AI-systeem wordt gebruikt in het kader van een persoonlijke niet-beroepsactiviteit
A4: 3 | B4: 32024R1689:60:4:9 | C4: de aanbieder of potentiële aanbieder | D4: potentiële aanbieder | E4: Aanbieders of potentiële aanbieders mogen alleen testen onder reële omstandigheden als is voldaan aan alle volgende voorwaarden: a) de aanbieder of potentiële aanbieder heeft een plan voor tests onder reële omstandigheden opgesteld en ingediend bij de markttoezichtautoriteit in de lidstaat waar onder reële omstandigheden moet worden getest; b) de markttoezichtautoriteit in de lidstaat waar onder reële omstandigheden moet worden getest, heeft het testen onder reële omstandigheden en het plan voor tests onder reële omstandigheden goedgekeurd; indien de markttoezichtautoriteit binnen dertig dagen geen antwoord heeft gegeven, worden het testen onder reële omstandigheden en het plan voor tests onder reële omstandigheden geacht te zijn goedgekeurd; indien het nationale recht niet voorziet in een stilzwijgende goedkeuring, blijft het testen onder reële omstandigheden onderworpen aan een toestemming; c) de aanbieder of potentiële aanbieder, met uitzondering van aanbieders of potentiële aanbieders van in de punten 1, 6 en 7 van bijlage III bedoelde AI-systemen met een hoog risico op de gebieden rechtshandhaving, migratie, asiel en grenstoezichtsbeheer en AI-systemen met een hoog risico als bedoeld in punt 2 van bijlage III, heeft het testen onder reële omstandigheden geregistreerd overeenkomstig artikel 71, lid 4, met een Uniebreed uniek identificatienummer en de in bijlage IX gespecificeerde informatie; de aanbieder of potentiële aanbieder van in de punten 1, 6 en 7 van bijlage II | F4: aanbieder [32024R1689:aanbieder] | G4: Defined in 32024R1689 art. 3: een natuurlijke of rechtspersoon, overheidsinstantie, agentschap of ander orgaan die/dat een AI-systeem of een AI-model voor algemene doeleinden ontwikkelt of laat ontwikkelen en dat systeem of model in de handel brengt of het AI-systeem in gebruik stelt onder de eigen naam of merk, al dan niet tegen betaling
A5: 4 | B5: 32024R1689:25:4:15 | C5: derden die andere instrumenten, diensten, processen of onderdelen dan AI-modellen voor algemene doeleinden onder een vrije en opensource licentie toegankelijk maken voor het publiek | D5: derden | E5: De aanbieder van een AI-systeem met een hoog risico en de derde partij die instrumenten, diensten, onderdelen of processen voor AI-systemen levert die worden gebruikt of geïntegreerd in een AI-systeem met een hoog risico, preciseren in een schriftelijke overeenkomst de nodige informatie, capaciteiten, technische toegang en andere bijstand, op basis van de algemeen erkende stand van de techniek, om de aanbieder van het AI-systeem met een hoog risico in staat te stellen volledig te voldoen aan de verplichtingen van deze verordening. Dit lid is niet van toepassing op derden die andere instrumenten, diensten, processen of onderdelen dan AI-modellen voor algemene doeleinden onder een vrije en opensource licentie toegankelijk maken voor het publiek. Het AI-bureau kan vrijwillige modelvoorwaarden ontwikkelen en aanbevelen voor contracten tussen aanbieders van AI-systemen met een hoog risico en derden die instrumenten, diensten, componenten of processen leveren die worden gebruikt of geïntegreerd in AI-systemen met een hoog risico. Bij de ontwikkeling van die vrijwillige modelvoorwaarden moet het AI-bureau rekening houden met de contractuele eisen die kunnen gelden in specifieke sectoren of businesscases. De vrijwillige modelvoorwaarden worden gepubliceerd en kosteloos beschikbaar gesteld in een gemakkelijk bruikbaar elektronisch formaat. | F5: an actor of class 'party' (no inventory entry)
A6: 5 | B6: [1] 32016R0679:27:1:1 [2] 32016R0679:38:3:5 [3] 32016R0679:28:3:13 | C6: [1] de verwerkingsverantwoordelijke of de verwerker [2] De verwerkingsverantwoordelijke en de verwerker [3] de verwerker | D6: verwerker | E6: [1] Wanneer artikel 3, lid 2, van toepassing is, wijst de verwerkingsverantwoordelijke of de verwerker schriftelijk een vertegenwoordiger in de Unie aan. [2] De verwerkingsverantwoordelijke en de verwerker zorgen ervoor dat de functionaris voor gegevensbescherming geen instructies ontvangt met betrekking tot de uitvoering van die taken. Hij wordt door de verwerkingsverantwoordelijke of de verwerker niet ontslagen of gestraft voor de uitvoering van zijn taken. De functionaris voor gegevensbescherming brengt rechtstreeks verslag uit aan de hoogste leidinggevende van de verwerkingsverantwoordelijke of de verwerker. [3] De verwerking door een verwerker wordt geregeld in een overeenkomst of andere rechtshandeling krachtens het Unierecht of het lidstatelijke recht die de verwerker ten aanzien van de verwerkingsverantwoordelijke bindt, en waarin het onderwerp en de duur van de verwerking, de aard en het doel van de verwerking, het soort persoonsgegevens en de categorieën van betrokkenen, en de rechten en verplichtingen van de verwerkingsverantwoordelijke worden omschreven. Die overeenkomst of andere rechtshandelin | F6: verwerker [32016R0679:verwerker] | G6: Defined in 32016R0679 art. 4: een natuurlijke persoon of rechtspersoon, een overheidsinstantie, een dienst of een ander orgaan die/dat ten behoeve van de verwerkingsverantwoordelijke persoonsgegevens verwerkt
A7: 6 | B7: BWBR0009950:6a.6:7:13 | C7: de voorschriften | D7: voorschriften | E7: Voor zover de voorschriften technische normen of specificaties bevatten, stroken deze met de normen, bedoeld in artikel 39, eerste en tweede lid, van richtlijn (EU) 2018/1972. | F7: not an actor (dropped)
A8: 7 | B8: BWBR0009950:7.4:2:2 | C8: Maatregelen van aanbieders van internettoegangsdiensten en voor het publiek beschikbare interpersoonlijke communicatiediensten | D8: Maatregelen van aanbieders van internettoegangsdiensten en voor het publiek beschikbare interpersoonlijke communicatiediensten | E8: Maatregelen van aanbieders van internettoegangsdiensten en voor het publiek beschikbare interpersoonlijke communicatiediensten om de kwaliteit van hun dienstverlening te waarborgen zijn in overeenstemming met de netneutraliteitsverordening. | F8: not an actor (dropped)
A9: 8 | B9: [1] 32022L2555:34:8:11 [2] 32016R0679:46:5:6 [3] 32022L2555:9:1:1 | C9: [1] die lidstaat [2] een lidstaat of een toezichthoudende autoriteit [3] Elke lidstaat | D9: lidstaat | E9: [1] Indien het rechtsstelsel van een lidstaat niet in administratieve geldboeten voorziet, zorgt die lidstaat ervoor dat dit artikel aldus wordt toegepast dat de geldboete wordt geïnitieerd door de bevoegde autoriteit en wordt opgelegd door de bevoegde nationale rechterlijke instanties, waarbij wordt gewaarborgd dat die wettelijke voorzieningen doeltreffend zijn en van gelijke werking zijn als de door bevoegde autoriteiten opgelegde administratieve geldboeten. De opgelegde geldboeten zijn in elk gev [2] Toestemmingen die een lidstaat of een toezichthoudende autoriteit op grond van artikel 26, lid 2, van Richtlijn 95/46/EG heeft verleend, blijven geldig totdat zij door die toezichthoudende autoriteit, indien nodig, worden gewijzigd, vervangen of ingetrokken. De besluiten die de Commissie op grond van artikel 26, lid 4, van Richtlijn 95/46/EG heeft vastgesteld, blijven van kracht totdat zij bij een overeenkomstig lid 2 van dit artikel vastgesteld besluit van de Commissie, indien nodig, worden gew [3] Elke lidstaat gaat over tot het aanwijzen of instellen van een of meer bevoegde autoriteiten die verantwoordelijk zijn voor het beheer van grootschalige cyberbeveiligingsincidenten en crises (cybercrisisbeheerautoriteiten). De lidstaten zien erop toe dat die autoriteiten beschikken over voldoende middelen om de hun toegewezen taken doeltreffend en efficiënt uit te voeren. De lidstaten zorgen voor samenhang met de bestaande kaders voor algemene nationale crisisbeheersing. | F9: lidstaat [KEY:EU:lidstaat] | G9: Known actor (not defined), class state, valid in eu.
A10: 9 | B10: BWBR0052872:39:3:6 | C10: het centrale contactpunt | D10: centrale contactpunt | E10: Op verzoek van het CSIRT of de bevoegde autoriteit stuurt het centrale contactpunt de op grond van de artikelen 25 en 33 ontvangen meldingen door naar de centrale contactpunten van de andere betrokken lidstaten van de Europese Unie. | F10: not an actor (dropped)
A11: 10 | B11: [1] BWBR0009950:4.11:3:5 [2] BWBR0009950:7.1:2:7 [3] BWBR0009950:11.11:5:9 | C11: [1] Een aanbieder [2] Een aanbieder als bedoeld in het eerste lid [3] de desbetreffende aanbieder | D11: aanbieder | E11: [1] Een aanbieder die een nummer behorende tot een door de Autoriteit Consument en Markt op grond van het tweede lid aangewezen categorie niet heeft toegekend gekregen op grond van een aanvraag doet, indien hij het nummer niet langer in gebruik heeft, hiervan mededeling aan de Autoriteit Consument en Markt. Na ontvangst van de in de vorige zin bedoelde mededeling stelt de Autoriteit Consument en Markt de aanbieder naar wie de toekenning van het nummer op grond van het tweede lid is teruggegaan hierv [2] Een aanbieder als bedoeld in het eerste lid verstrekt een consument kosteloos en voorafgaand aan het sluiten van de overeenkomst een beknopte en gemakkelijk leesbare samenvatting van de overeenkomst met gebruikmaking van het daartoe overeenkomstig artikel 102, derde lid, tweede alinea, van richtlijn (EU) 2018/1972 vastgestelde model. In die samenvatting zijn de belangrijkste elementen van de informatie, bedoeld in het eerste lid, opgenomen, waaronder ten minste: a. de naam, het adres en de cont [3] Indien bij het onderzoek blijkt dat het oproepende nummer toebehoort aan een abonnee van een andere aanbieder, verleent de desbetreffende aanbieder op een daartoe strekkend verzoek van de met het onderzoek belaste aanbieder medewerking aan het onderzoek en verstrekt, indien het onderzoek daartoe aanleiding geeft, de beschikbare op het oproepende nummer betrekking hebbende naam-, adres-, postcode- en woonplaatsgegevens aan de aanbieder die met het onderzoek belast is. | F11: an actor of class 'party' (no inventory entry)
A12: 11 | B12: [1] 32024R1689:95:2:3 [2] 32024R1689:50:7:19 [3] 32024R1689:65:8:21 | C12: [1] Het AI-bureau en de lidstaten [2] Het AI-bureau [3] Het AI-bureau | D12: AI-bureau | E12: [1] Het AI-bureau en de lidstaten faciliteren de opstelling van gedragscodes met betrekking tot de vrijwillige toepassing, onder meer door gebruiksverantwoordelijken, van specifieke voorschriften voor alle AI-systemen, op basis van duidelijke doelstellingen en kernprestatie-indicatoren om de verwezenlijking van die doelstellingen te meten, met inbegrip van elementen zoals, maar niet beperkt tot: a) toepasselijke elementen waarin de ethische richtsnoeren van de Unie voor betrouwbare AI voorzien; b) [2] Het AI-bureau stimuleert en faciliteert de opstelling van praktijkcodes op het niveau van de Unie om de doeltreffende uitvoering van de verplichtingen met betrekking tot de opsporing en het labelen van kunstmatig gegenereerde of bewerkte content te vergemakkelijken. De Commissie kan uitvoeringshandelingen vaststellen om die praktijkcodes overeenkomstig de procedure van artikel 56, lid 6, goed te keuren. Indien zij de code ontoereikend acht, kan de Commissie volgens de onderzoeksprocedure van art [3] De AI-board wordt voorgezeten door een van de vertegenwoordigers van de lidstaten. Het AI-bureau verzorgt het secretariaat van de AI-board, roept op verzoek van de voorzitter de vergaderingen bijeen en stelt de agenda op overeenkomstig de taken van de AI-board krachtens deze verordening en overeenkomstig zijn reglement. | F12: AI-bureau [32024R1689:aibureau] | G12: Defined in 32024R1689 art. 3: de taak van de Commissie waarbij zij bijdraagt aan de uitvoering van, de monitoring van en het toezicht op AI-systemen en AI-modellen voor algemene doeleinden, en AI-governance, als bepaald in het besluit van de Commissie van 24 januari 2024; verwijzingen in deze verordening naar het AI-bureau worden begrepen als verwijzingen naar de Commissie
A13: 12 | B13: BWBR0009950:14a.11:3:6 | C13: Een beursgenoteerde betrokken partij, een aangesloten instelling, centraal instituut, intermediair, instelling in het buitenland of buitenlandse instelling met een functie vergelijkbaar met die van het centraal instituut | D13: instelling in het buitenland | E13: Een beursgenoteerde betrokken partij, een aangesloten instelling, centraal instituut, intermediair, instelling in het buitenland of buitenlandse instelling met een functie vergelijkbaar met die van het centraal instituut verleent medewerking aan de Minister bij de tenuitvoerlegging van het eerste lid. | F13: instelling in het buitenland [BWBR0009950:instelling_in_het_buitenland] | G13: Defined in BWBR0009950 art. 14a.1: instelling als bedoeld in artikel 49a, onderdeel b, van de Wet giraal effectenverkeer
A14: 13 | B14: BWBR0009950:3.20a:6:7 | C14: De vergunninghouder, bedoeld in het eerste lid | D14: vergunninghouder | E14: De vergunninghouder, bedoeld in het eerste lid, is aansprakelijk voor de naleving door de huurder van de bij of krachtens deze wet gestelde regels met betrekking tot het frequentiegebruik door de vergunninghouder en van de aan de vergunning verbonden voorschriften en beperkingen en wordt in voorkomend geval aangemerkt als overtreder in de zin van artikel 5.1 van de Algemene wet bestuursrecht. | F14: an actor of class 'party' (no inventory entry)
A15: 14 | B15: 32016R0679:43:3:7 | C15: die eisen | D15: eisen | E15: De accreditatie van de in de leden 1 en 2 van dit artikel bedoelde certificeringsorganen vindt plaats op basis van criteria die zijn goedgekeurd door de op grond van artikel 55 of 56 bevoegde toezichthoudende autoriteit of, overeenkomstig artikel 63, door het Comité. In het geval van een accreditatie in de zin van lid 1, punt b), van dit artikel zijn die eisen een aanvulling op de eisen van Verordening (EG) nr. 765/2008 en de technische regels die een beschrijving van de methoden en procedures van de certificeringsorganen geven. | F15: not an actor (dropped)
A16: 15 | B16: [1] 32022R2554:15:whole:3 [2] 32022R2554:28:9:36 [3] 32022R2554:20:whole:4 | C16: [1] De ETA’s [2] De ETA’s [3] De ETA’s | D16: ETA’s | E16: [1] De ETA’s stellen via het Gemengd Comité en in overleg met het Agentschap van de Europese Unie voor cyberbeveiliging (Enisa), gemeenschappelijke ontwerpen van technische reguleringsnormen op met het doel: a) nadere elementen te specificeren die moeten worden opgenomen in de beleidslijnen, procedures, protocollen en instrumenten met betrekking tot ICT-beveiliging als bedoeld in artikel 9, lid 2, teneinde de veiligheid van netwerken te garanderen, passende waarborgen tegen inbreuken en misbruik va [2] De ETA’s ontwikkelen via het Gemengd Comité ontwerpen van technische uitvoeringsnormen voor de vaststelling van standaardmodellen ten behoeve van het in lid 3 bedoelde informatieregister, waarin informatie wordt opgenomen inzake het gebruik van ICT-diensten die voor alle contractuele overeenkomsten van toepassing is. De ETA’s leggen deze ontwerpen van technische uitvoeringsnormen uiterlijk op 17 januari 2024 voor aan de Commissie. Aan de Commissie wordt de bevoegdheid verleend om de in de eerst [3] De ETA’s ontwikkelen via het Gemengd Comité en in overleg met Enisa en de ECB: a) gemeenschappelijke ontwerpen van technische reguleringsnormen om: i) de inhoud van de rapporten voor ernstige ICT-gerelateerde incidenten vast te stellen, waarbij de in artikel 18, lid 1, vastgelegde criteria worden gehanteerd en verdere elementen worden opgenomen, zoals bijzonderheden voor de vaststelling van de relevantie van rapportage voor andere lidstaten en voor het bepalen of het incident al dan niet een er | F16: not an actor (dropped)
A17: 16 | B17: BWBR0009950:11.3a:3:3 | C17: De kennisgeving aan de Autoriteit persoonsgegevens en de persoon wiens persoonsgegevens het betreft | D17: kennisgeving aan de Autoriteit persoonsgegevens en de persoon | E17: De kennisgeving aan de Autoriteit persoonsgegevens en de persoon wiens persoonsgegevens het betreft, omvat in ieder geval de aard van de inbreuk in verband met persoonsgegevens, de instanties waar meer informatie over de inbreuk kan worden verkregen en de aanbevolen maatregelen om de negatieve gevolgen van de inbreuk te beperken. De kennisgeving aan de Autoriteit persoonsgegevens omvat tevens de gevolgen van de inbreuk op de persoonsgegevens en de maatregelen die de aanbieder voorstelt of heeft getroffen om de inbreuk aan te pakken. | F17: not an actor (dropped)
A18: 17 | B18: BWBR0040940:35:6:9 | C18: De verwerkingsverantwoordelijke en belanghebbende | D18: verwerkingsverantwoordelijke | E18: De rechtbank kan partijen en anderen verzoeken binnen een door haar te bepalen termijn schriftelijke inlichtingen te geven en onder hen berustende stukken in te zenden. De verwerkingsverantwoordelijke en belanghebbende zijn verplicht aan dit verzoek te voldoen. De artikelen 8:45, tweede en derde lid, en 8:29 van de Algemene wet bestuursrecht zijn van overeenkomstige toepassing. | F18: an actor of class 'party' (no inventory entry)
A19: 18 | B19: BWBR0009950:14a.10:2:2 | C19: degene aan wie een verbod op grond van artikel 14a.4 is opgelegd | D19: degene | E19: Het is degene aan wie een verbod op grond van artikel 14a.4 is opgelegd verboden de zeggenschap bedoeld in dat verbod, of een deel daarvan, over te dragen aan: a. een ongewenst persoon, b. een persoon aan wie een verbod op grond van artikel 14a.4 is opgelegd, c. een persoon die nauwe banden heeft met of onder invloed staat van een persoon als bedoeld onder a of b. | F19: not an actor (dropped)
A20: 19 | B20: 32024R1689:56:6:16 | C20: Het AI-bureau en de AI-board | D20: AI-board | E20: Het AI-bureau en de AI-board monitoren en evalueren regelmatig of de deelnemers de doelstellingen van de praktijkcodes verwezenlijken en bijdragen aan de correcte toepassing van deze verordening. Het AI-bureau en de AI-board beoordelen of de praktijkcodes betrekking hebben op de verplichtingen van de artikelen 53 en 55, en monitoren en evalueren regelmatig of de doelstellingen daarvan worden verwezenlijkt. Zij maken hun beoordeling of de praktijkcodes toereikend zijn bekend. De Commissie kan door middel van een uitvoeringshandeling een praktijkcode goedkeuren en deze binnen de Unie een algemene geldigheid verlenen. Die uitvoeringshandeling wordt vastgesteld volgens de in artikel 98, lid 2, bedoelde onderzoeksprocedure. | F20: AI-board [KEY:32024R1689:aiboard] | G20: Known actor (not defined), class body, valid in 32024R1689. Aliases: Europese raad voor artificiële intelligentie.
A21: 20 | B21: BWBR0040940:14:1:1 | C21: De Autoriteit persoonsgegevens | D21: Autoriteit persoonsgegevens | E21: De Autoriteit persoonsgegevens is bevoegd om de taken uit te voeren en de bevoegdheden uit te oefenen die bij of krachtens de verordening zijn toegekend aan de toezichthoudende autoriteit. | F21: not an actor (dropped)
A22: 21 | B22: BWBR0009950:14a.7:2:3 | C22: Een aangesloten instelling, centraal instituut, intermediair, instelling in het buitenland, bewaarder van een beleggingsinstelling en buitenlandse instelling met een functie vergelijkbaar met die van het centraal instituut | D22: bewaarder van een beleggingsinstelling en buitenlandse instelling met een functie | E22: Een aangesloten instelling, centraal instituut, intermediair, instelling in het buitenland, bewaarder van een beleggingsinstelling en buitenlandse instelling met een functie vergelijkbaar met die van het centraal instituut onthouden zich van gedragingen waardoor degene die in strijd met artikel 14a.4, eerste lid, overwegende zeggenschap heeft in een beursgenoteerde betrokken partij, in strijd met het bepaalde in het eerste lid kan handelen. | F22: not an actor (dropped)
A23: 22 | B23: 32024R1689:4:whole:1 | C23: Aanbieders en gebruiksverantwoordelijken van AI-systemen | D23: gebruiksverantwoordelijken | E23: Aanbieders en gebruiksverantwoordelijken van AI-systemen nemen maatregelen om, zoveel als mogelijk, te zorgen voor een toereikend niveau van AI-geletterdheid bij hun personeel en andere personen die namens hen AI-systemen exploiteren en gebruiken, en houden daarbij rekening met hun technische kennis, ervaring, onderwijs en opleiding en de context waarin de AI-systemen zullen worden gebruikt, evenals met de personen of groepen personen ten aanzien van wie de AI-systemen zullen worden gebruikt. | F23: gebruiksverantwoordelijke [32024R1689:gebruiksverantwoordelijke] | G23: Defined in 32024R1689 art. 3: een natuurlijke of rechtspersoon, overheidsinstantie, agentschap of ander orgaan die/dat een AI-systeem onder eigen verantwoordelijkheid gebruikt, tenzij het AI-systeem wordt gebruikt in het kader van een persoonlijke niet-beroepsactiviteit
A24: 23 | B24: BWBR0052872:49:6:7 | C24: Onze Minister van Economische Zaken | D24: Onze Minister van Economische Zaken | E24: Bij regeling van Onze Minister van Economische Zaken kunnen nadere regels worden gesteld ten aanzien van het bepaalde in dit artikel. | F24: Onze Minister [BWBR0052872:onze_minister] | G24: Defined in BWBR0052872 art. 1: Onze Minister van Justitie en Veiligheid
A25: 24 | B25: BWBR0052872:51:2:4 | C25: De bevoegde autoriteiten, de CSIRT’s en het centrale contactpunt | D25: CSIRT’s | E25: De bevoegde autoriteiten, de CSIRT’s en het centrale contactpunt werken voor de doeltreffende en doelmatige uitvoering van hun taken uit hoofde van deze wet samen met de volgende instanties in Nederland en wisselen in het kader van die samenwerking alle daarvoor noodzakelijke gegevens uit, waaronder persoonsgegevens: a. de politie, het openbaar ministerie en de bijzondere opsporingsdiensten, genoemd in artikel 2 van de Wet op de bijzondere opsporingsdiensten; b. de Autoriteit persoonsgegevens; c. de nationale bevoegde autoriteiten, bedoeld in de Verordening (EG) nr. 300/2008 en Verordening (EU) 2018/1139; d. Onze Minister van Economische Zaken uit hoofde van de Verordening (EU) nr. 910/2014; e. de bevoegde autoriteiten uit hoofde van de Verordening (EU) 2022/2554; f. Onze Minister van Economische Zaken uit hoofde van de Richtlijn (EU) 2018/1972; g. de bevoegde autoriteiten, bedoeld in artikel 8 van de Wet weerbaarheid kritieke entiteiten; h. de inlichtingen- en veiligheidsdiensten, bedoeld in de Wet op de inlichtingen- en veiligheidsdiensten 2017; en i. de bij of krachtens algemene maatregel van bestuur aangewezen autoriteiten. | F25: CSIRT [BWBR0052872:csirt] | G25: Defined in BWBR0052872 art. 1: een Computer security incident response team, bedoeld in artikel 10 van de NIS2-richtlijn en bedoeld in artikel 16
A26: 25 | B26: 32022R2554:49:2:7 | C26: De bevoegde autoriteiten, de ETA’s en de ECB | D26: ECB | E26: De bevoegde autoriteiten, de ETA’s en de ECB werken onderling nauw samen en wisselen informatie uit om hun taken overeenkomstig de artikelen 47 tot en met 54 te verrichten. Zij coördineren ten nauwste hun toezicht teneinde inbreuken op deze verordening op te sporen en te corrigeren, goede praktijken te ontwikkelen en te stimuleren, samenwerking te vergemakkelijken, een consistente interpretatie van ter zake geldende bepalingen te bevorderen, en in geval van meningsverschil rechtsgebiedoverschrijdende beoordelingen te geven. | F26: not an actor (dropped)
A27: 26 | B27: 32022L2555:19:6:16 | C27: De samenwerkingsgroep | D27: samenwerkingsgroep | E27: De collegiale toetsingen omvatten fysieke of virtuele bezoeken ter plaatse en informatie-uitwisselingen elders. In overeenstemming met het beginsel van goede samenwerking verstrekt de aan een collegiale toetsing onderworpen lidstaat de aangewezen cyberbeveiligingsdeskundigen de informatie die nodig is voor de beoordeling, onverminderd het Unie- of nationale recht inzake de bescherming van vertrouwelijke of gerubriceerde informatie en de bescherming van essentiële staatsfuncties, zoals de nationale veiligheid. De samenwerkingsgroep ontwikkelt in samenwerking met de Commissie en Enisa passende gedragscodes ter ondersteuning van de werkmethoden van de aangewezen cyberbeveiligingsdeskundigen. Alle informatie die via de collegiale toetsing wordt verkregen, wordt uitsluitend voor dat doel gebruikt. De cyberbeveiligingsdeskundigen die aan de collegiale toetsing deelnemen, maken geen gevoelige of vertrouwelijke informatie die zij uit hoofde van die collegiale toetsing hebben verkregen, bekend aan derden. | F27: not an actor (dropped)
A28: 27 | B28: 32022L2555:30:1:1 | C28: essentiële en belangrijke entiteiten | D28: essentiële en belangrijke entiteiten | E28: De lidstaten zorgen ervoor dat, naast de in artikel 23 geregelde meldingsplicht, op vrijwillige basis meldingen bij de CSIRT’s of, indien van toepassing, de bevoegde autoriteiten kunnen worden ingediend door: a) essentiële en belangrijke entiteiten betreffende cyberdreigingen en bijna-incidenten; b) andere dan in punt a) bedoelde entiteiten, ongeacht of zij binnen het toepassingsgebied van deze richtlijn vallen, wat significante incidenten, cyberdreigingen en bijna-incidenten betreft. | F28: entiteit [32022L2555:entiteit] | G28: Defined in 32022L2555 art. 6: een natuurlijke of rechtspersoon die als zodanig is opgericht en erkend volgens het nationale recht van zijn vestigingsplaats, en die in eigen naam rechten kan uitoefenen en aan verplichtingen kan worden onderworpen
A29: 28 | B29: BWBR0009950:11.9:1:2 | C29: De aanbieder van een openbaar elektronisch communicatienetwerk en de aanbieder van een openbare elektronische communicatiedienst die door middel van dat netwerk of als onderdeel van die dienst nummeridentificatie aanbiedt | D29: aanbieder van een openbaar elektronisch communicatienetwerk | E29: De aanbieder van een openbaar elektronisch communicatienetwerk en de aanbieder van een openbare elektronische communicatiedienst die door middel van dat netwerk of als onderdeel van die dienst nummeridentificatie aanbiedt, biedt: a. aan iedere oproepende gebruiker onderscheidenlijk abonnee mogelijkheden aan om kosteloos de verstrekking van het nummer van het oproepende netwerkaansluitpunt dan wel een nummer waarmee een individuele gebruiker kan worden geïdentificeerd te blokkeren onderscheidenlijk de verstrekking van nummers van oproepende netwerkaansluitpunten dan wel nummers waarmee individuele gebruikers kunnen worden geïdentificeerd voor elke afzonderlijke abonneelijn te blokkeren; b. aan iedere opgeroepen abonnee mogelijkheden aan om: 1°. de verstrekking van het nummer van het oproepende netwerkaansluitpunt dan wel een nummer waarmee een individuele gebruiker kan worden geïdentificeerd te verhinderen; 2°. oproepen waarbij de verstrekking van het nummer van het oproepende netwerkaansluitpunt dan wel een nummer waarmee een individuele gebruiker kan worden geïdentificeerd is geblokkeerd, te weigeren; 3°. indien nummeridentificatie als bedoeld in artikel 1.1, wordt aangeboden, kosteloos de verstrekking van het nummer van het opgeroepen netwerkaansluitpunt dan wel een nummer waarmee een individuele gebruiker kan worden geïdentificeerd aan het oproepende netwerkaansluitpunt te blokkeren. | F29: aanbieder van een openbaar elektronisch communicatienetwerk [BWBR0009950:aanbieder_van_een_openbaar_elektronisch_communicatienetwerk] | G29: Defined in BWBR0009950 art. 5.1: degene die in eigen naam en voor eigen rekening kabels ten dienste van een dergelijk netwerk aanlegt, instandhoudt en opruimt.
A30: 29 | B30: BWBR0009950:15.7b:2:4 | C30: De ambtenaar die gebruik heeft gemaakt van de bevoegdheid, bedoeld in het eerste lid | D30: ambtenaar | E30: De ambtenaar die gebruik heeft gemaakt van de bevoegdheid, bedoeld in het eerste lid, maakt daarvan een schriftelijk verslag op waarin hij vermeldt: a. zijn naam of nummer en hoedanigheid; b. de motivering van de noodzaak tot uitoefening van de bevoegdheid; c. de voorschriften op de naleving waarvan wordt toegezien; d. het adres, waaronder indien van toepassing, het elektronische adres, waar de uitrusting of het radioapparaat is verkregen en, voor zover bekend, de omschrijving van de betrokken marktdeelnemer; e. de onjuiste of onvolledige gegevens die bij de handelingen ten behoeve van het verkrijgen van de uitrusting of het radioapparaat zijn verstrekt; f. de wijze waarop en het tijdvak waarin de handelingen hebben plaatsgevonden; g. hetgeen tijdens het onderzoek van de uitrusting of het radioapparaat is verricht, gebleken en overigens is voorgevallen. | F30: not an actor (dropped)
A31: 30 | B31: BWBR0052872:36:2:4 | C31: Het CSIRT | D31: CSIRT | E31: Het CSIRT verleent aanvullende technische ondersteuning indien de betrokken entiteit daar om verzoekt. | F31: CSIRT [BWBR0052872:csirt] | G31: Defined in BWBR0052872 art. 1: een Computer security incident response team, bedoeld in artikel 10 van de NIS2-richtlijn en bedoeld in artikel 16
A32: 31 | B32: 32022L2555:23:4:9 | C32: de betrokken entiteiten | D32: betrokken entiteiten | E32: De lidstaten zorgen ervoor dat de betrokken entiteiten, voor de in lid 1 bedoelde melding, bij het CSIRT of, indien van toepassing, de bevoegde autoriteit: a) onverwijld en in elk geval binnen 24 uur nadat zij kennis hebben gekregen van het significante incident, een vroegtijdige waarschuwing geven, waarin, indien van toepassing, wordt aangegeven of het significante incident vermoedelijk door een onrechtmatige of kwaadwillige handeling is veroorzaakt, dan wel grensoverschrijdende gevolgen zou kunnen hebben; b) onverwijld en in elk geval binnen 72 uur nadat zij kennis hebben gekregen van het significante incident, een incidentmelding indienen met, indien van toepassing, een update van de in punt a) bedoelde informatie, een initiële beoordeling van het significante incident, met inbegrip van de ernst en de gevolgen ervan en, indien beschikbaar, de indicatoren voor aantasting; c) op verzoek van het CSIRT of, indien van toepassing, de bevoegde autoriteit, een tussentijds verslag indienen over relevante updates van de situatie; d) uiterlijk één maand na de indiening van het in punt b) bedoelde incidentmelding, een eindverslag indienen waarin het volgende is opgenomen: i) een gedetailleerde beschrijving van het incident, met inbegrip van de ernst en de gevolgen ervan; ii) het soort bedreiging of de grondoorzaak die waarschijnlijk tot het incident heeft geleid; iii) toegepaste en lopende risicobeperkende maatregelen; iv) in voorkomend geval, de grensoverschrijdende gevolgen | F32: entiteit [32022L2555:entiteit] | G32: Defined in 32022L2555 art. 6: een natuurlijke of rechtspersoon die als zodanig is opgericht en erkend volgens het nationale recht van zijn vestigingsplaats, en die in eigen naam rechten kan uitoefenen en aan verplichtingen kan worden onderworpen
A33: 32 | B33: [1] BWBR0048156:9:8:16 [2] BWBR0048156:11:8:9 [3] BWBR0048156:14:8:15 | C33: [1] Onze Minister [2] Onze Minister [3] Onze Minister | D33: Onze Minister | E33: [1] Een erkenning kan op verzoek van de houder worden ingetrokken. Onze Minister kan bij dit besluit de houder verplichten zijn activiteiten voort te zetten gedurende een door Onze Minister te bepalen periode, voor zover dat nodig is om continuïteit van betrouwbare toegang tot elektronische dienstverlening te borgen. [2] Onze Minister weigert een aanvraag tot erkenning, indien zwaarwegende redenen zich tegen erkenning verzetten. Van dergelijke redenen is sprake in geval ernstig gevaar bestaat dat de erkenning mede zal worden gebruikt om strafbare feiten te plegen of uit strafbare feiten verkregen of te verkrijgen voordelen te benutten of anderszins de betrouwbaarheid en veiligheid van het Nederlandse stelsel voor elektronische dienstverlening in gevaar komt. [3] Van een besluit als bedoeld in dit artikel doet Onze Minister mededeling in de Staatscourant. | F33: Onze Minister [BWBR0048156:onze_minister] | G33: Defined in BWBR0048156 art. 1: Onze Minister van Binnenlandse Zaken en Koninkrijksrelaties
A34: 33 | B34: 32024R1689:17:1:2 | C34: Dit systeem | D34: systeem | E34: Aanbieders van AI-systemen met een hoog risico voorzien in een systeem voor kwaliteitsbeheer dat de naleving van deze verordening waarborgt. Dit systeem wordt op systematische en ordelijke wijze gedocumenteerd in de vorm van schriftelijke beleidslijnen, procedures en instructies en omvat ten minste de volgende aspecten: a) een strategie voor de naleving van de regelgeving, inclusief de naleving van de conformiteitsbeoordelingsprocedures en de procedures voor het beheer van de wijzigingen van het AI-systeem met een hoog risico; b) technieken, procedures en systematische maatregelen die moeten worden toegepast voor het ontwerp, de controle van het ontwerp en de verificatie van het ontwerp van het AI-systeem met een hoog risico; c) technieken, procedures en systematische maatregelen die moeten worden toegepast voor de ontwikkeling, de kwaliteitscontrole en de kwaliteitsborging van het AI-systeem met een hoog risico; d) procedures voor het inspecteren, testen en valideren die vóór, tijdens en na de ontwikkeling van het AI-systeem met een hoog risico moeten worden uitgevoerd en de regelmaat waarmee zij moeten worden uitgevoerd; e) technische specificaties, met inbegrip van normen, die moeten worden toegepast en, wanneer de relevante geharmoniseerde normen niet volledig worden toegepast of geen betrekking hebben op alle relevante eisen van afdeling 2, de middelen die worden gebruikt om ervoor te zorgen dat het AI-systeem met een hoog risico in overeenstemming is met deze eisen | F34: not an actor (dropped)
A35: 34 | B35: 32022R2554:30:2:5 | C35: De contractuele overeenkomsten inzake het gebruik van ICT-diensten | D35: contractuele overeenkomsten inzake het gebruik van ICT-diensten | E35: De contractuele overeenkomsten inzake het gebruik van ICT-diensten bevatten ten minste de volgende elementen: a) een duidelijke en volledige beschrijving van alle door de derde aanbieder van ICT-diensten te leveren functies en ICT-diensten, met vermelding of het uitbesteden van een ICT-dienst die een kritieke of belangrijke functie ondersteunt, of van materiële onderdelen daarvan, is toegestaan en indien dit het geval is, welke voorwaarden op die uitbesteding van toepassing zijn; b) de locaties, met name de regio’s of landen, waar de contractueel overeengekomen of uitbestede functies en ICT-diensten moeten worden geleverd en waar gegevens moeten worden verwerkt, met inbegrip van de opslaglocatie, en de verplichting voor de derde aanbieder van ICT-diensten om de financiële entiteit vooraf in kennis te stellen indien hij voornemens is van locatie te veranderen; c) bepalingen inzake beschikbaarheid, authenticiteit, integriteit en vertrouwelijkheid met betrekking tot de bescherming van gegevens, met inbegrip van persoonsgegevens; d) bepalingen inzake het waarborgen van de toegang, het herstel en de teruggave in een gemakkelijk toegankelijk formaat van door de financiële entiteit verwerkte persoonsgegevens en niet-persoonsgebonden gegevens in geval van insolventie, afwikkeling of stopzetting van de bedrijfsactiviteiten van de derde aanbieder van ICT-diensten, of in geval van beëindiging van de contractuele overeenkomsten; e) beschrijvingen van het dienstenniveau, met inbegrip | F35: not an actor (dropped)
A36: 35 | B36: [1] 32016R0679:64:1:1 [2] 32016R0679:70:1:8 [3] 32016R0679:70:1:18 | C36: [1] Het Comité [2] Het Comité [3] Het Comité | D36: Comité | E36: [1] Het Comité brengt een advies uit wanneer een bevoegde toezichthoudende autoriteit voornemens is een van onderstaande maatregelen vast te stellen. Hiertoe deelt de bevoegde toezichthoudende autoriteit het Comité het ontwerpbesluit mee indien het: a) de vaststelling beoogt van een lijst van verwerkingen waarvoor de eis inzake een gegevensbeschermingseffectbeoordeling overeenkomstig artikel 35, lid 4, geldt; b) betrekking heeft op de vraag, overeenkomstig artikel 40, lid 7, of een gedragscode of [2] Het Comité zorgt ervoor dat deze verordening consequent wordt toegepast. Daartoe doet het Comité op eigen initiatief of, waar passend, op verzoek van de Commissie met name het volgende: a) toezien op en zorgen voor de juiste toepassing van deze verordening in de in de artikelen 64 en 65 bedoelde gevallen, onverminderd de taken van de nationale toezichthoudende autoriteiten; b) adviseren van de Commissie over aangelegenheden in verband met de bescherming van persoonsgegevens in de Unie, waarond [3] Het Comité zorgt ervoor dat deze verordening consequent wordt toegepast. Daartoe doet het Comité op eigen initiatief of, waar passend, op verzoek van de Commissie met name het volgende: a) toezien op en zorgen voor de juiste toepassing van deze verordening in de in de artikelen 64 en 65 bedoelde gevallen, onverminderd de taken van de nationale toezichthoudende autoriteiten; b) adviseren van de Commissie over aangelegenheden in verband met de bescherming van persoonsgegevens in de Unie, waarond | F36: Comité [KEY:32016R0679:comite] | G36: Known actor (not defined), class body, valid in 32016R0679. Aliases: Europees Comité voor gegevensbescherming.
A37: 36 | B37: 32016R0679:26:1:3 | C37: twee of meer verwerkingsverantwoordelijken | D37: twee of meer verwerkingsverantwoordelijken | E37: Wanneer twee of meer verwerkingsverantwoordelijken gezamenlijk de doeleinden en middelen van de verwerking bepalen, zijn zij gezamenlijke verwerkingsverantwoordelijken. Zij stellen op transparante wijze hun respectieve verantwoordelijkheden voor de nakoming van de verplichtingen uit hoofde van deze verordening vast, met name met betrekking tot de uitoefening van de rechten van de betrokkene en hun respectieve verplichtingen om de in de artikelen 13 en 14 bedoelde informatie te verstrekken, door middel van een onderlinge regeling, tenzij en voor zover de respectieve verantwoordelijkheden van de verwerkingsverantwoordelijken zijn vastgesteld bij een Unierechtelijke of lidstaatrechtelijke bepaling die op de verwerkingsverantwoordelijken van toepassing is. In de regeling kan een contactpunt voor betrokkenen worden aangewezen. | F37: verwerkingsverantwoordelijke [32016R0679:verwerkingsverantwoordelijke] | G37: Defined in 32016R0679 art. 4: een natuurlijke persoon of rechtspersoon, een overheidsinstantie, een dienst of een ander orgaan die/dat, alleen of samen met anderen, het doel van en de middelen voor de verwerking van persoonsgegevens vaststelt; wanneer de doelstellingen van en de middelen voor deze verwerking in het Unierecht of het lidstatelijke recht worden vastgesteld, kan daarin worden bepaald wie de verwerkingsverantwoordelijke is of volgens welke criteria deze wordt aangewezen
A38: 37 | B38: BWBR0009950:11.5a:3:3 | C38: de aanbieder van de dienst met toegevoegde waarde | D38: aanbieder van de dienst met toegevoegde waarde | E38: De verwerking van de gegevens ten behoeve van de levering van een dienst met toegevoegde waarde als bedoeld in het eerste lid, onderdeel b, is slechts toegestaan voor zover en voor zolang dat noodzakelijk is voor de levering van de desbetreffende dienst. In afwijking van de eerste volzin mag de aanbieder van de dienst met toegevoegde waarde die gegevens verwerken die noodzakelijk zijn voor het opstellen van een factuur. Artikel 11.5, tweede lid, laatste volzin, is van overeenkomstige toepassing. | F38: an actor of class 'party' (no inventory entry)
A39: 38 | B39: 32022L2555:32:2:3 | C39: de gecontroleerde entiteit | D39: gecontroleerde entiteit | E39: De lidstaten zorgen ervoor dat de bevoegde autoriteiten bij de uitoefening van hun toezichthoudende taken met betrekking tot essentiële entiteiten de bevoegdheid hebben om deze entiteiten te onderwerpen aan ten minste: a) inspecties ter plaatse en toezicht elders, met inbegrip van steekproefsgewijze controles die worden uitgevoerd door daartoe opgeleide professionals; b) regelmatige en gerichte beveiligingsaudits die worden uitgevoerd door een onafhankelijke instantie of een bevoegde autoriteit; c) ad-hocaudits, ook in gevallen waarin dat gerechtvaardigd is op grond van een significant incident of inbreuk op deze richtlijn door de essentiële entiteit; d) beveiligingsscans op basis van objectieve, niet-discriminerende, eerlijke en transparante risicobeoordelingscriteria, indien nodig in samenwerking met de betrokken entiteit; e) verzoeken om informatie die nodig is om de door de betrokken entiteit genomen maatregelen voor het beheer van cyberbeveiligingsrisico’s te beoordelen, met inbegrip van gedocumenteerd cyberbeveiligingsbeleid, alsmede de naleving van de verplichting op grond van artikel 27 om bij de bevoegde autoriteiten informatie in te dienen; f) verzoeken om toegang tot gegevens, documenten en informatie die nodig zijn voor de uitoefening van hun toezichthoudende taken; g) verzoeken om bewijs van de uitvoering van het cyberbeveiligingsbeleid, zoals de resultaten van beveiligingsaudits die door een gekwalificeerde auditor zijn uitgevoerd en de respectieve onderl | F39: entiteit [32022L2555:entiteit] | G39: Defined in 32022L2555 art. 6: een natuurlijke of rechtspersoon die als zodanig is opgericht en erkend volgens het nationale recht van zijn vestigingsplaats, en die in eigen naam rechten kan uitoefenen en aan verplichtingen kan worden onderworpen
A40: 39 | B40: 32022R2554:12:3:13 | C40: centrale tegenpartij | D40: centrale tegenpartij | E40: Wanneer financiële entiteiten back-upgegevens terugzetten met behulp van eigen systemen, maken zij gebruik van ICT-systemen die fysiek of logisch gescheiden zijn van het bron-ICT-systeem. De ICT-systemen zijn tegen ongeoorloofde toegang of beschadiging van ICT beveiligd en maken het mogelijk diensten indien nodig tijdig terug te zetten met gebruikmaking van gegevens en systeemback-ups. Voor centrale tegenpartijen maken de herstelplannen het herstel mogelijk van alle transacties ten tijde van de verstoring, om de centrale tegenpartij in staat te stellen haar activiteiten met zekerheid voort te zetten en de transactie af te wikkelen op de geplande datum. Aanbieders van datarapporteringsdiensten houden daarnaast voldoende middelen aan en beschikken over back-up- en terugzetfaciliteiten om hun diensten te allen tijde aan te bieden en te onderhouden. | F40: centrale tegenpartij [32022R2554:centrale_tegenpartij] | G40: Defined in 32022R2554 art. 3: een centrale tegenpartij in de zin van artikel 2, punt 1), van Verordening (EU) nr. 648/2012
...

Sheet Inventory
A1: id | B1: label | C1: aliases | D1: kind | E1: valid in | F1: class | G1: part of | H1: definition or source
A2: 32024R1689:aanbieder | B2: aanbieder | D2: defined | E2: 32024R1689 | F2: party | H2: een natuurlijke of rechtspersoon, overheidsinstantie, agentschap of ander orgaan die/dat een AI-systeem of een AI-model voor algemene doeleinden ontwikkelt of laat ontwikkelen en dat systeem of model in de handel brengt of het AI-systeem in gebruik stelt onder de eigen naam of merk, al dan niet tegen betaling
A3: 32024R1689:gebruiksverantwoordelijke | B3: gebruiksverantwoordelijke | D3: defined | E3: 32024R1689 | F3: party | H3: een natuurlijke of rechtspersoon, overheidsinstantie, agentschap of ander orgaan die/dat een AI-systeem onder eigen verantwoordelijkheid gebruikt, tenzij het AI-systeem wordt gebruikt in het kader van een persoonlijke niet-beroepsactiviteit
A4: 32024R1689:gemachtigde | B4: gemachtigde | D4: defined | E4: 32024R1689 | F4: party | H4: een natuurlijke of rechtspersoon die zich bevindt of gevestigd is in de Unie die een schriftelijke machtiging heeft gekregen en aanvaard van een aanbieder van een AI-systeem of een AI-model voor algemene doeleinden om namens die aanbieder de verplichtingen en procedures van deze verordening respectievelijk na te komen en uit te voeren
A5: 32024R1689:importeur | B5: importeur | D5: defined | E5: 32024R1689 | F5: party | H5: een natuurlijke of rechtspersoon die zich bevindt of gevestigd is in de Unie die een AI-systeem in de handel brengt dat de naam of het merk van een in een derde land gevestigde natuurlijke of rechtspersoon draagt
A6: 32024R1689:distributeur | B6: distributeur | D6: defined | E6: 32024R1689 | F6: party | H6: een andere natuurlijke persoon of rechtspersoon in de toeleveringsketen dan de aanbieder of de importeur, die een AI-systeem in de Unie op de markt aanbiedt
A7: 32024R1689:operator | B7: operator | D7: defined | E7: 32024R1689 | F7: party | H7: een aanbieder, productfabrikant, gebruiksverantwoordelijke, gemachtigde, importeur of distributeur
A8: 32024R1689:aanmeldende_autoriteit | B8: aanmeldende autoriteit | D8: defined | E8: 32024R1689 | F8: authority | H8: de nationale autoriteit die verantwoordelijk is voor het opzetten en uitvoeren van de noodzakelijke procedures voor de beoordeling, aanwijzing en kennisgeving van de conformiteitsbeoordelingsinstanties en de monitoring hiervan
A9: 32024R1689:conformiteitsbeoordelingsinstantie | B9: conformiteitsbeoordelingsinstantie | D9: defined | E9: 32024R1689 | F9: body | H9: een instantie die als derde partij conformiteits-beoordelingsactiviteiten verricht, zoals onder meer testen, certificeren en inspecteren
A10: 32024R1689:aangemelde_instantie | B10: aangemelde instantie | D10: defined | E10: 32024R1689 | F10: body | H10: een conformiteitsbeoordelingsinstantie die overeenkomstig deze verordening en andere relevante harmonisatiewetgeving van de Unie, is aangemeld
A11: 32024R1689:markttoezichtautoriteit | B11: markttoezichtautoriteit | D11: defined | E11: 32024R1689 | F11: authority | H11: de nationale autoriteit die de activiteiten verricht en maatregelen neemt als bedoeld in Verordening (EU) 2019/1020
A12: 32024R1689:rechtshandhavingsinstantie | B12: rechtshandhavingsinstantie | D12: defined | E12: 32024R1689 | F12: body | H12: a) iedere overheidsinstantie die bevoegd is voor de voorkoming van, het onderzoek naar, de opsporing en de vervolging van strafbare feiten of de uitvoering van straffen, met inbegrip van de bescherming tegen en de voorkoming van gevaren voor de openbare veiligheid, of b) ieder ander orgaan dat of iedere andere entiteit die krachtens het recht van de lidstaten is gemachtigd openbaar gezag en openbare bevoegdheden uit te oefenen met het oog op de voorkoming van, het onderzoek naar, de opsporing en
A13: 32024R1689:aibureau | B13: AI-bureau | D13: defined | E13: 32024R1689 | F13: body | H13: de taak van de Commissie waarbij zij bijdraagt aan de uitvoering van, de monitoring van en het toezicht op AI-systemen en AI-modellen voor algemene doeleinden, en AI-governance, als bepaald in het besluit van de Commissie van 24 januari 2024; verwijzingen in deze verordening naar het AI-bureau worden begrepen als verwijzingen naar de Commissie
... A121: BWBR0048156:organen_personen_en_colleges_als_bedoeld_in_artikel_1_1_tweede_lid_van_de_algemene_wet_bestuursrecht | B121: organen, personen en colleges als bedoeld in artikel 1:1, tweede lid, van de Algemene wet bestuursrecht | D121: defined | E121: BWBR0048156 | F121: body | H121: organen als bedoeld in artikel 2, eerste lid, onderdelen a tot en met d, van de Wet administratieve rechtspraak BES».
A122: KEY:EU:commissie | B122: Commissie | C122: Europese Commissie | D122: key | E122: eu | F122: institution | H122: curated
A123: KEY:EU:lidstaat | B123: lidstaat | D123: key | E123: eu | F123: state | H123: curated
A124: KEY:EU:europees_parlement | B124: Europees Parlement | D124: key | E124: eu | F124: institution | H124: curated
A125: KEY:EU:raad | B125: Raad | C125: Raad van de Europese Unie | D125: key | E125: eu | F125: institution | H125: curated
A126: KEY:EU:hof_van_justitie | B126: Hof van Justitie | C126: Hof van Justitie van de Europese Unie | D126: key | E126: eu | F126: institution | H126: curated
A127: KEY:EU:europese_toezichthouder_voor_gegevensbescherming | B127: Europese Toezichthouder voor gegevensbescherming | D127: key | E127: eu | F127: authority | H127: curated
A128: KEY:EU:gerecht | B128: gerecht | C128: bevoegd gerecht; nationaal gerecht | D128: key | E128: eu | F128: institution | H128: curated
A129: KEY:EU:overheidsinstantie | B129: overheidsinstantie | D129: key | E129: eu | F129: authority | H129: curated
A130: KEY:EU:nationale_accreditatieinstantie | B130: nationale accreditatie-instantie | C130: accreditatie-instantie | D130: key | E130: eu | F130: body | H130: curated
A131: KEY:32016R0679:comite | B131: Comité | C131: Europees Comité voor gegevensbescherming | D131: key | E131: 32016R0679 | F131: body | H131: curated
A132: KEY:32016R0679:voorzitter | B132: voorzitter | C132: voorzitter van het Comité | D132: key | E132: 32016R0679 | F132: office | G132: KEY:32016R0679:comite | H132: curated
A133: KEY:32016R0679:secretariaat | B133: secretariaat | C133: secretariaat van het Comité | D133: key | E133: 32016R0679 | F133: office | G133: KEY:32016R0679:comite | H133: curated
A134: KEY:32016R0679:leidende_toezichthoudende_autoriteit | B134: leidende toezichthoudende autoriteit | D134: key | E134: 32016R0679 | F134: authority | H134: curated
A135: KEY:32016R0679:functionaris_voor_gegevensbescherming | B135: functionaris voor gegevensbescherming | D135: key | E135: 32016R0679 | F135: office | H135: curated
A136: KEY:32016R0679:certificeringsorgaan | B136: certificeringsorgaan | D136: key | E136: 32016R0679 | F136: body | H136: curated
A137: KEY:32016R0679:vereniging | B137: vereniging | C137: verenigingen en andere organen die categorieën van verwerkingsverantwoordelijken of verwerkers vertegenwoordigen | D137: key | E137: 32016R0679 | F137: party | H137: curated
A138: KEY:32024R1689:aiboard | B138: AI-board | C138: Europese raad voor artificiële intelligentie | D138: key | E138: 32024R1689 | F138: body | H138: curated
A139: KEY:32024R1689:adviesforum | B139: adviesforum | D139: key | E139: 32024R1689 | F139: body | H139: curated
A140: KEY:32024R1689:wetenschappelijk_panel | B140: wetenschappelijk panel | C140: wetenschappelijk panel van onafhankelijke deskundigen | D140: key | E140: 32024R1689 | F140: body | H140: curated
A141: KEY:32024R1689:productfabrikant | B141: productfabrikant | D141: key | E141: 32024R1689 | F141: party | H141: curated
A142: KEY:32024R1689:permanente_subgroep_voor_markttoezicht | B142: permanente subgroep voor markttoezicht | C142: subgroep | D142: key | E142: 32024R1689 | F142: body | G142: KEY:32024R1689:aiboard | H142: curated
A143: KEY:32024R1689:gegevensbeschermingsautoriteit | B143: gegevensbeschermingsautoriteit | C143: nationale gegevensbeschermingsautoriteit | D143: key | E143: 32024R1689 | F143: authority | H143: curated
A144: KEY:32024R1689:civielebeschermingsautoriteit | B144: civielebeschermingsautoriteit | D144: key | E144: 32024R1689 | F144: authority | H144: curated
A145: KEY:32024R1689:kmo | B145: kmo | C145: kmo, met inbegrip van start-ups | D145: key | E145: 32024R1689 | F145: party | H145: curated

Sheet key
A1: # | B1: stratum | C1: kind | D1: source | E1: level | F1: unit | G1: result | H1: actor_id | I1: fallback_class | J1: role_keys | K1: occ_EU | L1: occ_NL | M1: group_occ | N1: norm_ids
A2: 1 | B2: NL | shortened | C2: sample | D2: NL | E2: shortened | F2: aanbieder van een openbaar elektronisch communicatienetwerk waarover een openbare elektronische communicatiedienst wordt verzorgd | G2: BWBR0009950:aanbieder_van_een_openbaar_elektronisch_communicatienetwerk | H2: BWBR0009950:aanbieder_van_een_openbaar_elektronisch_communicatienetwerk | J2: aanbieder open elektronisch communicatienetwerk waarover open elektronisch communicatiedienst wordt verzorgd / aanbieder open elektronisch communicatienetwerk waarover open elektronisch communicatiedienst wordt / aanbieder open elektronisch communicatienetwerk waarover open elektronisch communicatiedienst / aanbieder open elektronisch communicatienetwerk waarover open elektronisch / aanbieder open elektronisch communicatienetwerk waarover open / aanbieder open elektronisch communicatienetwerk waarover / aanbieder open elektronisch communicatienetwerk / aanbieder open elektronisch / aanbieder open / aanbieder | K2: 0 | L2: 0 | M2: 1 | N2: BWBR0009950:4.10:6:10
A3: 2 | B3: EU | exact | C3: sample | D3: EU | E3: exact | F3: gebruiksverantwoordelijke | G3: 32024R1689:gebruiksverantwoordelijke | H3: 32024R1689:gebruiksverantwoordelijke | J3: gebruiksverantwoord | K3: 0 | L3: 0 | M3: 11 | N3: 32024R1689:26:8:15
A4: 3 | B4: EU | shortened | C4: sample | D4: EU | E4: shortened | F4: potentiële aanbieder | G4: 32024R1689:aanbieder | H4: 32024R1689:aanbieder | J4: potentiel aanbieder / aanbieder | K4: 0 | L4: 0 | M4: 12 | N4: 32024R1689:60:4:9
A5: 4 | B5: EU | fallback | C5: sample | D5: EU | E5: fallback | F5: derden | G5: class:party | I5: party | J5: derd | K5: 0 | L5: 0 | M5: 2 | N5: 32024R1689:25:4:15
A6: 5 | B6: census | C6: census | D6: EU | E6: exact | F6: verwerker | G6: 32016R0679:verwerker | H6: 32016R0679:verwerker | J6: verwerker | K6: 51 | L6: 0 | M6: 51 | N6: 32016R0679:27:1:1, 32016R0679:38:3:5, 32016R0679:28:3:13
A7: 6 | B7: NL | not_actor | C7: sample | D7: NL | E7: not_actor | F7: voorschriften | G7: not_actor | J7: voorschrift | K7: 0 | L7: 0 | M7: 1 | N7: BWBR0009950:6a.6:7:13
A8: 7 | B8: NL | not_actor | C8: sample | D8: NL | E8: not_actor | F8: Maatregelen van aanbieders van internettoegangsdiensten en voor het publiek beschikbare interpersoonlijke communicatiediensten | G8: not_actor | J8: maatregel aanbieder internettoegangsdienst publiek beschik interperson communicatiedienst / maatregel aanbieder internettoegangsdienst publiek beschik interperson / maatregel aanbieder internettoegangsdienst publiek beschik / maatregel aanbieder internettoegangsdienst publiek / maatregel aanbieder internettoegangsdienst / maatregel aanbieder / maatregel | K8: 0 | L8: 0 | M8: 1 | N8: BWBR0009950:7.4:2:2
A9: 8 | B9: census | C9: census | D9: EU | E9: exact | F9: lidstaat | G9: KEY:EU:lidstaat | H9: KEY:EU:lidstaat | J9: lidstat | K9: 63 | L9: 0 | M9: 63 | N9: 32022L2555:34:8:11, 32016R0679:46:5:6, 32022L2555:9:1:1
A10: 9 | B10: NL | not_actor | C10: sample | D10: NL | E10: not_actor | F10: centrale contactpunt | G10: not_actor | J10: central contactpunt / contactpunt | K10: 0 | L10: 0 | M10: 19 | N10: BWBR0052872:39:3:6
A11: 10 | B11: census | C11: census | D11: NL | E11: fallback | F11: aanbieder | G11: class:party | I11: party | J11: aanbieder | K11: 0 | L11: 56 | M11: 56 | N11: BWBR0009950:4.11:3:5, BWBR0009950:7.1:2:7, BWBR0009950:11.11:5:9
A12: 11 | B12: census | C12: census | D12: EU | E12: exact | F12: AI-bureau | G12: 32024R1689:aibureau | H12: 32024R1689:aibureau | J12: aibureau | K12: 47 | L12: 0 | M12: 47 | N12: 32024R1689:95:2:3, 32024R1689:50:7:19, 32024R1689:65:8:21
A13: 12 | B13: NL | exact | C13: sample | D13: NL | E13: exact | F13: instelling in het buitenland | G13: BWBR0009950:instelling_in_het_buitenland | H13: BWBR0009950:instelling_in_het_buitenland | J13: instell buitenland / instell | K13: 0 | L13: 0 | M13: 4 | N13: BWBR0009950:14a.11:3:6
A14: 13 | B14: NL | fallback | C14: sample | D14: NL | E14: fallback | F14: vergunninghouder | G14: class:party | I14: party | J14: vergunninghouder | K14: 0 | L14: 0 | M14: 2 | N14: BWBR0009950:3.20a:6:7
A15: 14 | B15: EU | not_actor | C15: sample | D15: EU | E15: not_actor | F15: eisen | G15: not_actor | J15: eis | K15: 0 | L15: 0 | M15: 2 | N15: 32016R0679:43:3:7
A16: 15 | B16: census | C16: census | D16: EU | E16: not_actor | F16: ETA’s | G16: not_actor | J16: eta | K16: 53 | L16: 0 | M16: 53 | N16: 32022R2554:15:whole:3, 32022R2554:28:9:36, 32022R2554:20:whole:4
A17: 16 | B17: NL | not_actor | C17: sample | D17: NL | E17: not_actor | F17: kennisgeving aan de Autoriteit persoonsgegevens en de persoon | G17: not_actor | J17: kennisgev autoriteit persoonsgegeven person / kennisgev autoriteit persoonsgegeven / kennisgev autoriteit / kennisgev | K17: 0 | L17: 0 | M17: 1 | N17: BWBR0009950:11.3a:3:3
A18: 17 | B18: NL | fallback | C18: sample | D18: NL | E18: fallback | F18: verwerkingsverantwoordelijke | G18: class:party | I18: party | J18: verwerkingsverantwoord | K18: 0 | L18: 0 | M18: 8 | N18: BWBR0040940:35:6:9
A19: 18 | B19: NL | not_actor | C19: sample | D19: NL | E19: not_actor | F19: degene | G19: not_actor | J19: deg | K19: 0 | L19: 0 | M19: 9 | N19: BWBR0009950:14a.10:2:2
A20: 19 | B20: EU | exact | C20: sample | D20: EU | E20: exact | F20: AI-board | G20: KEY:32024R1689:aiboard | H20: KEY:32024R1689:aiboard | J20: aiboard | K20: 0 | L20: 0 | M20: 35 | N20: 32024R1689:56:6:16
A21: 20 | B21: NL | not_actor | C21: sample | D21: NL | E21: not_actor | F21: Autoriteit persoonsgegevens | G21: not_actor | J21: autoriteit persoonsgegeven / persoonsgegeven | K21: 0 | L21: 0 | M21: 32 | N21: BWBR0040940:14:1:1
